Workbook

Sheet Credit Card Charge
A1: Reference number | B1: CC account | C1: Line: Amount | D1: Name | E1: Type | F1: Line: Account | G1: Credit | H1: Currency | I1: Location | J1: Exchange Rate | K1: Global tax calculation | L1: Update Credit Card Charge | M1: Line: Billable status | N1: Line: Class | O1: Line: Customer | P1: Line: Tax code | Q1: Line: Description | R1: Line: Tax amount | S1: Line: Markup percent | T1: Item: Product | U1: Item: Quantity | V1: Item: Unit price | W1: Payment method | X1: Memo | Y1: Txn date | Z1: Txn source | AA1: Total tax | AB1: Transaction Location Type | AC1: Attachment: File Link | AD1: Attachment: Id | AE1: Attachment: Attach to email
B2: ='QBO Transactions'!$U4 | C2: ='QBO Transactions'!$S4 | D2: ='QBO Transactions'!$R4 | F2: ='QBO Transactions'!$X4 | N2: ='QBO Transactions'!$Y4 | Q2: ='QBO Transactions'!$T4 | X2: =Q2 | Y2: ='QBO Transactions'!$Q4
B3: ='QBO Transactions'!$U5 | C3: ='QBO Transactions'!$S5 | D3: ='QBO Transactions'!$R5 | F3: ='QBO Transactions'!$X5 | N3: ='QBO Transactions'!$Y5 | Q3: ='QBO Transactions'!$T5 | X3: =Q3 | Y3: ='QBO Transactions'!$Q5
B4: ='QBO Transactions'!$U6 | C4: ='QBO Transactions'!$S6 | D4: ='QBO Transactions'!$R6 | F4: ='QBO Transactions'!$X6 | N4: ='QBO Transactions'!$Y6 | Q4: ='QBO Transactions'!$T6 | X4: =Q4 | Y4: ='QBO Transactions'!$Q6
B5: ='QBO Transactions'!$U7 | C5: ='QBO Transactions'!$S7 | D5: ='QBO Transactions'!$R7 | F5: ='QBO Transactions'!$X7 | N5: ='QBO Transactions'!$Y7 | Q5: ='QBO Transactions'!$T7 | X5: =Q5 | Y5: ='QBO Transactions'!$Q7
B6: ='QBO Transactions'!$U8 | C6: ='QBO Transactions'!$S8 | D6: ='QBO Transactions'!$R8 | F6: ='QBO Transactions'!$X8 | N6: ='QBO Transactions'!$Y8 | Q6: ='QBO Transactions'!$T8 | X6: =Q6 | Y6: ='QBO Transactions'!$Q8
B7: ='QBO Transactions'!$U9 | C7: ='QBO Transactions'!$S9 | D7: ='QBO Transactions'!$R9 | F7: ='QBO Transactions'!$X9 | N7: ='QBO Transactions'!$Y9 | Q7: ='QBO Transactions'!$T9 | X7: =Q7 | Y7: ='QBO Transactions'!$Q9
B8: ='QBO Transactions'!$U10 | C8: ='QBO Transactions'!$S10 | D8: ='QBO Transactions'!$R10 | F8: ='QBO Transactions'!$X10 | N8: ='QBO Transactions'!$Y10 | Q8: ='QBO Transactions'!$T10 | X8: =Q8 | Y8: ='QBO Transactions'!$Q10
B9: ='QBO Transactions'!$U11 | C9: ='QBO Transactions'!$S11 | D9: ='QBO Transactions'!$R11 | F9: ='QBO Transactions'!$X11 | N9: ='QBO Transactions'!$Y11 | Q9: ='QBO Transactions'!$T11 | X9: =Q9 | Y9: ='QBO Transactions'!$Q11
B10: ='QBO Transactions'!$U12 | C10: ='QBO Transactions'!$S12 | D10: ='QBO Transactions'!$R12 | F10: ='QBO Transactions'!$X12 | N10: ='QBO Transactions'!$Y12 | Q10: ='QBO Transactions'!$T12 | X10: =Q10 | Y10: ='QBO Transactions'!$Q12
B11: ='QBO Transactions'!$U13 | C11: ='QBO Transactions'!$S13 | D11: ='QBO Transactions'!$R13 | F11: ='QBO Transactions'!$X13 | N11: ='QBO Transactions'!$Y13 | Q11: ='QBO Transactions'!$T13 | X11: =Q11 | Y11: ='QBO Transactions'!$Q13
B12: ='QBO Transactions'!$U14 | C12: ='QBO Transactions'!$S14 | D12: ='QBO Transactions'!$R14 | F12: ='QBO Transactions'!$X14 | N12: ='QBO Transactions'!$Y14 | Q12: ='QBO Transactions'!$T14 | X12: =Q12 | Y12: ='QBO Transactions'!$Q14
B13: ='QBO Transactions'!$U15 | C13: ='QBO Transactions'!$S15 | D13: ='QBO Transactions'!$R15 | F13: ='QBO Transactions'!$X15 | N13: ='QBO Transactions'!$Y15 | Q13: ='QBO Transactions'!$T15 | X13: =Q13 | Y13: ='QBO Transactions'!$Q15
... B657: ='QBO Transactions'!$U659 | C657: ='QBO Transactions'!$S659 | D657: ='QBO Transactions'!$R659 | F657: ='QBO Transactions'!$X659 | N657: ='QBO Transactions'!$Y659 | Q657: ='QBO Transactions'!$T659 | X657: =Q657 | Y657: ='QBO Transactions'!$Q659

Sheet QBO Transactions
C1: Credit Card Account: | D1: Brex Credit Card | I1: Travel Vendor | K1: Taxi Vendor
B2: QBO Credit Card Transaction Data | I2: Food Vendor | K2: Office Vendor
B3: DATE | C3: DESCRIPTION | D3: Payee | E3: Category or Match | F3: SPENT | G3: RECEIVED | H3: xxx | I3: Payee Override | J3: Full Acct Override | K3: Parent Category Override | L3: Sub Category Override | M3: Dept Override | N3: Card # | O3: Card Name | P3: EE ID | Q3: Date | R3: Vendor | S3: Amount | T3: Updated Description | U3: Card Acct | V3: Parent Category | W3: Sub Category | X3: Line Acct | Y3: Department | Z3: Acct Check
B4: 46164 | C4: QANTASXXXXXXXX41055 MASTERCARD-544015XXXXXX7759-Mickenzi Krpec | E4: 61210 Sales & Marketing:Sales & Marketing- Travel Expenses:Airfare | F4: 8368.3 | I4: Travel Vendor | L4: Airfare | O4: =IF(C4="", "", TRIM(RIGHT(C4, LEN(C4) - FIND("@@", SUBSTITUTE(C4, "-", "@@", LEN(C4) - LEN(SUBSTITUTE(C4, "-", ""))))))) | P4: {=IFERROR(XLOOKUP(O4,'Department Listing'!$O$1:$O$395,'Department Listing'!$A$1:$A$395),IFERROR(XLOOKUP(O4,'Name Aliases'!$A$2:$A$1000,'Name Aliases'!$B$2:$B$1000),""))} | Q4: =IF(ISBLANK($C4),"",$B4) | R4: =IF(ISBLANK($C4),"",IF(ISBLANK($I4),$D4,$I4)) | S4: =IF(ISBLANK($C4),"",$F4 - $G4) | T4: =IF(ISBLANK($C4),"",C4) | U4: =IF(ISBLANK($C4),"",$D$1) | V4: {=IF(ISBLANK($B4),"",IF(ISBLANK($K4),IF(XLOOKUP($W4,'Category Mapping'!$C:$C,'Category Mapping'!$B:$B)="Travel",XLOOKUP($P4,'Department Listing'!$A:$A,'Department Listing'!$M:$M),XLOOKUP($W4,'Category Mapping'!$C:$C,'Category Mapping'!$D:$D)),$K4))} | W4: =IF(ISBLANK($B4),"",IF(ISBLANK($L4),RIGHT($E4,LEN($E4) - FIND("^",SUBSTITUTE($E4,":","^",LEN($E4) - LEN(SUBSTITUTE($E4,":",""))))),$L4)) | X4: =IF(ISBLANK($J4),$V4&$W4,$J4) | Y4: {=IF(ISBLANK($M4),IFERROR(XLOOKUP($P4,'Department Listing'!$A:$A,'Department Listing'!$L:$L),""),$M4)} | Z4: =IF(ISBLANK($B4),"",MATCH($X4,COA!$B:$B,0))
B5: 46170 | C5: Monument Charlestown Restaurant & Tavern MASTERCARD-544015XXXXXX7759-Mickenzi Krpec | E5: 61290 Sales & Marketing:Sales & Marketing- Travel Expenses:Other Travel Expenses | F5: 2764.88 | I5: Food Vendor | L5: Meals & Entertainment | O5: =IF(C5="", "", TRIM(RIGHT(C5, LEN(C5) - FIND("@@", SUBSTITUTE(C5, "-", "@@", LEN(C5) - LEN(SUBSTITUTE(C5, "-", ""))))))) | P5: {=IFERROR(XLOOKUP(O5,'Department Listing'!$O$1:$O$395,'Department Listing'!$A$1:$A$395),IFERROR(XLOOKUP(O5,'Name Aliases'!$A$2:$A$1000,'Name Aliases'!$B$2:$B$1000),""))} | Q5: =IF(ISBLANK($C5),"",$B5) | R5: =IF(ISBLANK($C5),"",IF(ISBLANK($I5),$D5,$I5)) | S5: =IF(ISBLANK($C5),"",$F5 - $G5) | T5: =IF(ISBLANK($C5),"",C5) | U5: =IF(ISBLANK($C5),"",$D$1) | V5: {=IF(ISBLANK($B5),"",IF(ISBLANK($K5),IF(XLOOKUP($W5,'Category Mapping'!$C:$C,'Category Mapping'!$B:$B)="Travel",XLOOKUP($P5,'Department Listing'!$A:$A,'Department Listing'!$M:$M),XLOOKUP($W5,'Category Mapping'!$C:$C,'Category Mapping'!$D:$D)),$K5))} | W5: =IF(ISBLANK($B5),"",IF(ISBLANK($L5),RIGHT($E5,LEN($E5) - FIND("^",SUBSTITUTE($E5,":","^",LEN($E5) - LEN(SUBSTITUTE($E5,":",""))))),$L5)) | X5: =IF(ISBLANK($J5),$V5&$W5,$J5) | Y5: {=IF(ISBLANK($M5),IFERROR(XLOOKUP($P5,'Department Listing'!$A:$A,'Department Listing'!$L:$L),""),$M5)} | Z5: =IF(ISBLANK($B5),"",MATCH($X5,COA!$B:$B,0))
B6: 46169 | C6: Bar Primi Penn District MASTERCARD-555671XXXXXX5731-Nikita Ashok | E6: 61240 Sales & Marketing:Sales & Marketing- Travel Expenses:Meals & Entertainment | F6: 2366.4 | I6: Food Vendor | O6: =IF(C6="", "", TRIM(RIGHT(C6, LEN(C6) - FIND("@@", SUBSTITUTE(C6, "-", "@@", LEN(C6) - LEN(SUBSTITUTE(C6, "-", ""))))))) | P6: {=IFERROR(XLOOKUP(O6,'Department Listing'!$O$1:$O$395,'Department Listing'!$A$1:$A$395),IFERROR(XLOOKUP(O6,'Name Aliases'!$A$2:$A$1000,'Name Aliases'!$B$2:$B$1000),""))} | Q6: =IF(ISBLANK($C6),"",$B6) | R6: =IF(ISBLANK($C6),"",IF(ISBLANK($I6),$D6,$I6)) | S6: =IF(ISBLANK($C6),"",$F6 - $G6) | T6: =IF(ISBLANK($C6),"",C6) | U6: =IF(ISBLANK($C6),"",$D$1) | V6: {=IF(ISBLANK($B6),"",IF(ISBLANK($K6),IF(XLOOKUP($W6,'Category Mapping'!$C:$C,'Category Mapping'!$B:$B)="Travel",XLOOKUP($P6,'Department Listing'!$A:$A,'Department Listing'!$M:$M),XLOOKUP($W6,'Category Mapping'!$C:$C,'Category Mapping'!$D:$D)),$K6))} | W6: =IF(ISBLANK($B6),"",IF(ISBLANK($L6),RIGHT($E6,LEN($E6) - FIND("^",SUBSTITUTE($E6,":","^",LEN($E6) - LEN(SUBSTITUTE($E6,":",""))))),$L6)) | X6: =IF(ISBLANK($J6),$V6&$W6,$J6) | Y6: {=IF(ISBLANK($M6),IFERROR(XLOOKUP($P6,'Department Listing'!$A:$A,'Department Listing'!$L:$L),""),$M6)} | Z6: =IF(ISBLANK($B6),"",MATCH($X6,COA!$B:$B,0))
B7: 46168 | C7: Bamboo HR MASTERCARD-544015XXXXXX0151-Eric Rabkin | D7: Bamboo HR | E7: 63310 General & Administrative:Software Licenses | F7: 1783.48 | O7: =IF(C7="", "", TRIM(RIGHT(C7, LEN(C7) - FIND("@@", SUBSTITUTE(C7, "-", "@@", LEN(C7) - LEN(SUBSTITUTE(C7, "-", ""))))))) | P7: {=IFERROR(XLOOKUP(O7,'Department Listing'!$O$1:$O$395,'Department Listing'!$A$1:$A$395),IFERROR(XLOOKUP(O7,'Name Aliases'!$A$2:$A$1000,'Name Aliases'!$B$2:$B$1000),""))} | Q7: =IF(ISBLANK($C7),"",$B7) | R7: =IF(ISBLANK($C7),"",IF(ISBLANK($I7),$D7,$I7)) | S7: =IF(ISBLANK($C7),"",$F7 - $G7) | T7: =IF(ISBLANK($C7),"",C7) | U7: =IF(ISBLANK($C7),"",$D$1) | V7: {=IF(ISBLANK($B7),"",IF(ISBLANK($K7),IF(XLOOKUP($W7,'Category Mapping'!$C:$C,'Category Mapping'!$B:$B)="Travel",XLOOKUP($P7,'Department Listing'!$A:$A,'Department Listing'!$M:$M),XLOOKUP($W7,'Category Mapping'!$C:$C,'Category Mapping'!$D:$D)),$K7))} | W7: =IF(ISBLANK($B7),"",IF(ISBLANK($L7),RIGHT($E7,LEN($E7) - FIND("^",SUBSTITUTE($E7,":","^",LEN($E7) - LEN(SUBSTITUTE($E7,":",""))))),$L7)) | X7: =IF(ISBLANK($J7),$V7&$W7,$J7) | Y7: {=IF(ISBLANK($M7),IFERROR(XLOOKUP($P7,'Department Listing'!$A:$A,'Department Listing'!$L:$L),""),$M7)} | Z7: =IF(ISBLANK($B7),"",MATCH($X7,COA!$B:$B,0))
B8: 46165 | C8: Back Bay Garage MASTERCARD-544015XXXXXX4926-Alta Abel | D8: Back Bay Garage | E8: 61220 Sales & Marketing:Sales & Marketing- Travel Expenses:Ground Transportation | F8: 1685 | O8: =IF(C8="", "", TRIM(RIGHT(C8, LEN(C8) - FIND("@@", SUBSTITUTE(C8, "-", "@@", LEN(C8) - LEN(SUBSTITUTE(C8, "-", ""))))))) | P8: {=IFERROR(XLOOKUP(O8,'Department Listing'!$O$1:$O$395,'Department Listing'!$A$1:$A$395),IFERROR(XLOOKUP(O8,'Name Aliases'!$A$2:$A$1000,'Name Aliases'!$B$2:$B$1000),""))} | Q8: =IF(ISBLANK($C8),"",$B8) | R8: =IF(ISBLANK($C8),"",IF(ISBLANK($I8),$D8,$I8)) | S8: =IF(ISBLANK($C8),"",$F8 - $G8) | T8: =IF(ISBLANK($C8),"",C8) | U8: =IF(ISBLANK($C8),"",$D$1) | V8: {=IF(ISBLANK($B8),"",IF(ISBLANK($K8),IF(XLOOKUP($W8,'Category Mapping'!$C:$C,'Category Mapping'!$B:$B)="Travel",XLOOKUP($P8,'Department Listing'!$A:$A,'Department Listing'!$M:$M),XLOOKUP($W8,'Category Mapping'!$C:$C,'Category Mapping'!$D:$D)),$K8))} | W8: =IF(ISBLANK($B8),"",IF(ISBLANK($L8),RIGHT($E8,LEN($E8) - FIND("^",SUBSTITUTE($E8,":","^",LEN($E8) - LEN(SUBSTITUTE($E8,":",""))))),$L8)) | X8: =IF(ISBLANK($J8),$V8&$W8,$J8) | Y8: {=IF(ISBLANK($M8),IFERROR(XLOOKUP($P8,'Department Listing'!$A:$A,'Department Listing'!$L:$L),""),$M8)} | Z8: =IF(ISBLANK($B8),"",MATCH($X8,COA!$B:$B,0))
B9: 46168 | C9: CustomCookies.com MASTERCARD-544015XXXXXX8091-Brooke Berg | E9: 63410 General & Administrative:Office Expenses:Office Supplies | F9: 1355 | I9: Customcookies.com | O9: =IF(C9="", "", TRIM(RIGHT(C9, LEN(C9) - FIND("@@", SUBSTITUTE(C9, "-", "@@", LEN(C9) - LEN(SUBSTITUTE(C9, "-", ""))))))) | P9: {=IFERROR(XLOOKUP(O9,'Department Listing'!$O$1:$O$395,'Department Listing'!$A$1:$A$395),IFERROR(XLOOKUP(O9,'Name Aliases'!$A$2:$A$1000,'Name Aliases'!$B$2:$B$1000),""))} | Q9: =IF(ISBLANK($C9),"",$B9) | R9: =IF(ISBLANK($C9),"",IF(ISBLANK($I9),$D9,$I9)) | S9: =IF(ISBLANK($C9),"",$F9 - $G9) | T9: =IF(ISBLANK($C9),"",C9) | U9: =IF(ISBLANK($C9),"",$D$1) | V9: {=IF(ISBLANK($B9),"",IF(ISBLANK($K9),IF(XLOOKUP($W9,'Category Mapping'!$C:$C,'Category Mapping'!$B:$B)="Travel",XLOOKUP($P9,'Department Listing'!$A:$A,'Department Listing'!$M:$M),XLOOKUP($W9,'Category Mapping'!$C:$C,'Category Mapping'!$D:$D)),$K9))} | W9: =IF(ISBLANK($B9),"",IF(ISBLANK($L9),RIGHT($E9,LEN($E9) - FIND("^",SUBSTITUTE($E9,":","^",LEN($E9) - LEN(SUBSTITUTE($E9,":",""))))),$L9)) | X9: =IF(ISBLANK($J9),$V9&$W9,$J9) | Y9: {=IF(ISBLANK($M9),IFERROR(XLOOKUP($P9,'Department Listing'!$A:$A,'Department Listing'!$L:$L),""),$M9)} | Z9: =IF(ISBLANK($B9),"",MATCH($X9,COA!$B:$B,0))
B10: 46165 | C10: Claude MASTERCARD-544015XXXXXX0151-Eric Rabkin | D10: Claude.AI | E10: 63310 General & Administrative:Software Licenses | F10: 1038.46 | O10: =IF(C10="", "", TRIM(RIGHT(C10, LEN(C10) - FIND("@@", SUBSTITUTE(C10, "-", "@@", LEN(C10) - LEN(SUBSTITUTE(C10, "-", ""))))))) | P10: {=IFERROR(XLOOKUP(O10,'Department Listing'!$O$1:$O$395,'Department Listing'!$A$1:$A$395),IFERROR(XLOOKUP(O10,'Name Aliases'!$A$2:$A$1000,'Name Aliases'!$B$2:$B$1000),""))} | Q10: =IF(ISBLANK($C10),"",$B10) | R10: =IF(ISBLANK($C10),"",IF(ISBLANK($I10),$D10,$I10)) | S10: =IF(ISBLANK($C10),"",$F10 - $G10) | T10: =IF(ISBLANK($C10),"",C10) | U10: =IF(ISBLANK($C10),"",$D$1) | V10: {=IF(ISBLANK($B10),"",IF(ISBLANK($K10),IF(XLOOKUP($W10,'Category Mapping'!$C:$C,'Category Mapping'!$B:$B)="Travel",XLOOKUP($P10,'Department Listing'!$A:$A,'Department Listing'!$M:$M),XLOOKUP($W10,'Category Mapping'!$C:$C,'Category Mapping'!$D:$D)),$K10))} | W10: =IF(ISBLANK($B10),"",IF(ISBLANK($L10),RIGHT($E10,LEN($E10) - FIND("^",SUBSTITUTE($E10,":","^",LEN($E10) - LEN(SUBSTITUTE($E10,":",""))))),$L10)) | X10: =IF(ISBLANK($J10),$V10&$W10,$J10) | Y10: {=IF(ISBLANK($M10),IFERROR(XLOOKUP($P10,'Department Listing'!$A:$A,'Department Listing'!$L:$L),""),$M10)} | Z10: =IF(ISBLANK($B10),"",MATCH($X10,COA!$B:$B,0))
B11: 46166 | C11: Claude MASTERCARD-544015XXXXXX0151-Eric Rabkin | D11: Claude.AI | E11: 63310 General & Administrative:Software Licenses | F11: 1037.63 | O11: =IF(C11="", "", TRIM(RIGHT(C11, LEN(C11) - FIND("@@", SUBSTITUTE(C11, "-", "@@", LEN(C11) - LEN(SUBSTITUTE(C11, "-", ""))))))) | P11: {=IFERROR(XLOOKUP(O11,'Department Listing'!$O$1:$O$395,'Department Listing'!$A$1:$A$395),IFERROR(XLOOKUP(O11,'Name Aliases'!$A$2:$A$1000,'Name Aliases'!$B$2:$B$1000),""))} | Q11: =IF(ISBLANK($C11),"",$B11) | R11: =IF(ISBLANK($C11),"",IF(ISBLANK($I11),$D11,$I11)) | S11: =IF(ISBLANK($C11),"",$F11 - $G11) | T11: =IF(ISBLANK($C11),"",C11) | U11: =IF(ISBLANK($C11),"",$D$1) | V11: {=IF(ISBLANK($B11),"",IF(ISBLANK($K11),IF(XLOOKUP($W11,'Category Mapping'!$C:$C,'Category Mapping'!$B:$B)="Travel",XLOOKUP($P11,'Department Listing'!$A:$A,'Department Listing'!$M:$M),XLOOKUP($W11,'Category Mapping'!$C:$C,'Category Mapping'!$D:$D)),$K11))} | W11: =IF(ISBLANK($B11),"",IF(ISBLANK($L11),RIGHT($E11,LEN($E11) - FIND("^",SUBSTITUTE($E11,":","^",LEN($E11) - LEN(SUBSTITUTE($E11,":",""))))),$L11)) | X11: =IF(ISBLANK($J11),$V11&$W11,$J11) | Y11: {=IF(ISBLANK($M11),IFERROR(XLOOKUP($P11,'Department Listing'!$A:$A,'Department Listing'!$L:$L),""),$M11)} | Z11: =IF(ISBLANK($B11),"",MATCH($X11,COA!$B:$B,0))
B12: 46165 | C12: Claude MASTERCARD-544015XXXXXX0151-Eric Rabkin | D12: Claude.AI | E12: 63310 General & Administrative:Software Licenses | F12: 1036.29 | O12: =IF(C12="", "", TRIM(RIGHT(C12, LEN(C12) - FIND("@@", SUBSTITUTE(C12, "-", "@@", LEN(C12) - LEN(SUBSTITUTE(C12, "-", ""))))))) | P12: {=IFERROR(XLOOKUP(O12,'Department Listing'!$O$1:$O$395,'Department Listing'!$A$1:$A$395),IFERROR(XLOOKUP(O12,'Name Aliases'!$A$2:$A$1000,'Name Aliases'!$B$2:$B$1000),""))} | Q12: =IF(ISBLANK($C12),"",$B12) | R12: =IF(ISBLANK($C12),"",IF(ISBLANK($I12),$D12,$I12)) | S12: =IF(ISBLANK($C12),"",$F12 - $G12) | T12: =IF(ISBLANK($C12),"",C12) | U12: =IF(ISBLANK($C12),"",$D$1) | V12: {=IF(ISBLANK($B12),"",IF(ISBLANK($K12),IF(XLOOKUP($W12,'Category Mapping'!$C:$C,'Category Mapping'!$B:$B)="Travel",XLOOKUP($P12,'Department Listing'!$A:$A,'Department Listing'!$M:$M),XLOOKUP($W12,'Category Mapping'!$C:$C,'Category Mapping'!$D:$D)),$K12))} | W12: =IF(ISBLANK($B12),"",IF(ISBLANK($L12),RIGHT($E12,LEN($E12) - FIND("^",SUBSTITUTE($E12,":","^",LEN($E12) - LEN(SUBSTITUTE($E12,":",""))))),$L12)) | X12: =IF(ISBLANK($J12),$V12&$W12,$J12) | Y12: {=IF(ISBLANK($M12),IFERROR(XLOOKUP($P12,'Department Listing'!$A:$A,'Department Listing'!$L:$L),""),$M12)} | Z12: =IF(ISBLANK($B12),"",MATCH($X12,COA!$B:$B,0))
B13: 46166 | C13: Claude MASTERCARD-544015XXXXXX0151-Eric Rabkin | D13: Claude.AI | E13: 63310 General & Administrative:Software Licenses | F13: 1036.22 | O13: =IF(C13="", "", TRIM(RIGHT(C13, LEN(C13) - FIND("@@", SUBSTITUTE(C13, "-", "@@", LEN(C13) - LEN(SUBSTITUTE(C13, "-", ""))))))) | P13: {=IFERROR(XLOOKUP(O13,'Department Listing'!$O$1:$O$395,'Department Listing'!$A$1:$A$395),IFERROR(XLOOKUP(O13,'Name Aliases'!$A$2:$A$1000,'Name Aliases'!$B$2:$B$1000),""))} | Q13: =IF(ISBLANK($C13),"",$B13) | R13: =IF(ISBLANK($C13),"",IF(ISBLANK($I13),$D13,$I13)) | S13: =IF(ISBLANK($C13),"",$F13 - $G13) | T13: =IF(ISBLANK($C13),"",C13) | U13: =IF(ISBLANK($C13),"",$D$1) | V13: {=IF(ISBLANK($B13),"",IF(ISBLANK($K13),IF(XLOOKUP($W13,'Category Mapping'!$C:$C,'Category Mapping'!$B:$B)="Travel",XLOOKUP($P13,'Department Listing'!$A:$A,'Department Listing'!$M:$M),XLOOKUP($W13,'Category Mapping'!$C:$C,'Category Mapping'!$D:$D)),$K13))} | W13: =IF(ISBLANK($B13),"",IF(ISBLANK($L13),RIGHT($E13,LEN($E13) - FIND("^",SUBSTITUTE($E13,":","^",LEN($E13) - LEN(SUBSTITUTE($E13,":",""))))),$L13)) | X13: =IF(ISBLANK($J13),$V13&$W13,$J13) | Y13: {=IF(ISBLANK($M13),IFERROR(XLOOKUP($P13,'Department Listing'!$A:$A,'Department Listing'!$L:$L),""),$M13)} | Z13: =IF(ISBLANK($B13),"",MATCH($X13,COA!$B:$B,0))
B14: 46165 | C14: Claude MASTERCARD-544015XXXXXX0151-Eric Rabkin | D14: Claude.AI | E14: 63310 General & Administrative:Software Licenses | F14: 1029.53 | O14: =IF(C14="", "", TRIM(RIGHT(C14, LEN(C14) - FIND("@@", SUBSTITUTE(C14, "-", "@@", LEN(C14) - LEN(SUBSTITUTE(C14, "-", ""))))))) | P14: {=IFERROR(XLOOKUP(O14,'Department Listing'!$O$1:$O$395,'Department Listing'!$A$1:$A$395),IFERROR(XLOOKUP(O14,'Name Aliases'!$A$2:$A$1000,'Name Aliases'!$B$2:$B$1000),""))} | Q14: =IF(ISBLANK($C14),"",$B14) | R14: =IF(ISBLANK($C14),"",IF(ISBLANK($I14),$D14,$I14)) | S14: =IF(ISBLANK($C14),"",$F14 - $G14) | T14: =IF(ISBLANK($C14),"",C14) | U14: =IF(ISBLANK($C14),"",$D$1) | V14: {=IF(ISBLANK($B14),"",IF(ISBLANK($K14),IF(XLOOKUP($W14,'Category Mapping'!$C:$C,'Category Mapping'!$B:$B)="Travel",XLOOKUP($P14,'Department Listing'!$A:$A,'Department Listing'!$M:$M),XLOOKUP($W14,'Category Mapping'!$C:$C,'Category Mapping'!$D:$D)),$K14))} | W14: =IF(ISBLANK($B14),"",IF(ISBLANK($L14),RIGHT($E14,LEN($E14) - FIND("^",SUBSTITUTE($E14,":","^",LEN($E14) - LEN(SUBSTITUTE($E14,":",""))))),$L14)) | X14: =IF(ISBLANK($J14),$V14&$W14,$J14) | Y14: {=IF(ISBLANK($M14),IFERROR(XLOOKUP($P14,'Department Listing'!$A:$A,'Department Listing'!$L:$L),""),$M14)} | Z14: =IF(ISBLANK($B14),"",MATCH($X14,COA!$B:$B,0))
B15: 46169 | C15: Csi Worldwide MASTERCARD-555671XXXXXX8308-Toni Manning | E15: 61290 Sales & Marketing:Sales & Marketing- Travel Expenses:Other Travel Expenses | F15: 1029.42 | I15: Office Vendor | L15: Dues & Subscriptions | O15: =IF(C15="", "", TRIM(RIGHT(C15, LEN(C15) - FIND("@@", SUBSTITUTE(C15, "-", "@@", LEN(C15) - LEN(SUBSTITUTE(C15, "-", ""))))))) | P15: {=IFERROR(XLOOKUP(O15,'Department Listing'!$O$1:$O$395,'Department Listing'!$A$1:$A$395),IFERROR(XLOOKUP(O15,'Name Aliases'!$A$2:$A$1000,'Name Aliases'!$B$2:$B$1000),""))} | Q15: =IF(ISBLANK($C15),"",$B15) | R15: =IF(ISBLANK($C15),"",IF(ISBLANK($I15),$D15,$I15)) | S15: =IF(ISBLANK($C15),"",$F15 - $G15) | T15: =IF(ISBLANK($C15),"",C15) | U15: =IF(ISBLANK($C15),"",$D$1) | V15: {=IF(ISBLANK($B15),"",IF(ISBLANK($K15),IF(XLOOKUP($W15,'Category Mapping'!$C:$C,'Category Mapping'!$B:$B)="Travel",XLOOKUP($P15,'Department Listing'!$A:$A,'Department Listing'!$M:$M),XLOOKUP($W15,'Category Mapping'!$C:$C,'Category Mapping'!$D:$D)),$K15))} | W15: =IF(ISBLANK($B15),"",IF(ISBLANK($L15),RIGHT($E15,LEN($E15) - FIND("^",SUBSTITUTE($E15,":","^",LEN($E15) - LEN(SUBSTITUTE($E15,":",""))))),$L15)) | X15: =IF(ISBLANK($J15),$V15&$W15,$J15) | Y15: {=IF(ISBLANK($M15),IFERROR(XLOOKUP($P15,'Department Listing'!$A:$A,'Department Listing'!$L:$L),""),$M15)} | Z15: =IF(ISBLANK($B15),"",MATCH($X15,COA!$B:$B,0))
B16: 46166 | C16: Claude MASTERCARD-544015XXXXXX0151-Eric Rabkin | D16: Claude.AI | E16: 63310 General & Administrative:Software Licenses | F16: 1029.01 | O16: =IF(C16="", "", TRIM(RIGHT(C16, LEN(C16) - FIND("@@", SUBSTITUTE(C16, "-", "@@", LEN(C16) - LEN(SUBSTITUTE(C16, "-", ""))))))) | P16: {=IFERROR(XLOOKUP(O16,'Department Listing'!$O$1:$O$395,'Department Listing'!$A$1:$A$395),IFERROR(XLOOKUP(O16,'Name Aliases'!$A$2:$A$1000,'Name Aliases'!$B$2:$B$1000),""))} | Q16: =IF(ISBLANK($C16),"",$B16) | R16: =IF(ISBLANK($C16),"",IF(ISBLANK($I16),$D16,$I16)) | S16: =IF(ISBLANK($C16),"",$F16 - $G16) | T16: =IF(ISBLANK($C16),"",C16) | U16: =IF(ISBLANK($C16),"",$D$1) | V16: {=IF(ISBLANK($B16),"",IF(ISBLANK($K16),IF(XLOOKUP($W16,'Category Mapping'!$C:$C,'Category Mapping'!$B:$B)="Travel",XLOOKUP($P16,'Department Listing'!$A:$A,'Department Listing'!$M:$M),XLOOKUP($W16,'Category Mapping'!$C:$C,'Category Mapping'!$D:$D)),$K16))} | W16: =IF(ISBLANK($B16),"",IF(ISBLANK($L16),RIGHT($E16,LEN($E16) - FIND("^",SUBSTITUTE($E16,":","^",LEN($E16) - LEN(SUBSTITUTE($E16,":",""))))),$L16)) | X16: =IF(ISBLANK($J16),$V16&$W16,$J16) | Y16: {=IF(ISBLANK($M16),IFERROR(XLOOKUP($P16,'Department Listing'!$A:$A,'Department Listing'!$L:$L),""),$M16)} | Z16: =IF(ISBLANK($B16),"",MATCH($X16,COA!$B:$B,0))
B17: 46165 | C17: Claude MASTERCARD-544015XXXXXX0151-Eric Rabkin | D17: Claude.AI | E17: 63310 General & Administrative:Software Licenses | F17: 1024.09 | O17: =IF(C17="", "", TRIM(RIGHT(C17, LEN(C17) - FIND("@@", SUBSTITUTE(C17, "-", "@@", LEN(C17) - LEN(SUBSTITUTE(C17, "-", ""))))))) | P17: {=IFERROR(XLOOKUP(O17,'Department Listing'!$O$1:$O$395,'Department Listing'!$A$1:$A$395),IFERROR(XLOOKUP(O17,'Name Aliases'!$A$2:$A$1000,'Name Aliases'!$B$2:$B$1000),""))} | Q17: =IF(ISBLANK($C17),"",$B17) | R17: =IF(ISBLANK($C17),"",IF(ISBLANK($I17),$D17,$I17)) | S17: =IF(ISBLANK($C17),"",$F17 - $G17) | T17: =IF(ISBLANK($C17),"",C17) | U17: =IF(ISBLANK($C17),"",$D$1) | V17: {=IF(ISBLANK($B17),"",IF(ISBLANK($K17),IF(XLOOKUP($W17,'Category Mapping'!$C:$C,'Category Mapping'!$B:$B)="Travel",XLOOKUP($P17,'Department Listing'!$A:$A,'Department Listing'!$M:$M),XLOOKUP($W17,'Category Mapping'!$C:$C,'Category Mapping'!$D:$D)),$K17))} | W17: =IF(ISBLANK($B17),"",IF(ISBLANK($L17),RIGHT($E17,LEN($E17) - FIND("^",SUBSTITUTE($E17,":","^",LEN($E17) - LEN(SUBSTITUTE($E17,":",""))))),$L17)) | X17: =IF(ISBLANK($J17),$V17&$W17,$J17) | Y17: {=IF(ISBLANK($M17),IFERROR(XLOOKUP($P17,'Department Listing'!$A:$A,'Department Listing'!$L:$L),""),$M17)} | Z17: =IF(ISBLANK($B17),"",MATCH($X17,COA!$B:$B,0))
B18: 46166 | C18: Claude MASTERCARD-544015XXXXXX0151-Eric Rabkin | D18: Claude.AI | E18: 63310 General & Administrative:Software Licenses | F18: 1023.44 | O18: =IF(C18="", "", TRIM(RIGHT(C18, LEN(C18) - FIND("@@", SUBSTITUTE(C18, "-", "@@", LEN(C18) - LEN(SUBSTITUTE(C18, "-", ""))))))) | P18: {=IFERROR(XLOOKUP(O18,'Department Listing'!$O$1:$O$395,'Department Listing'!$A$1:$A$395),IFERROR(XLOOKUP(O18,'Name Aliases'!$A$2:$A$1000,'Name Aliases'!$B$2:$B$1000),""))} | Q18: =IF(ISBLANK($C18),"",$B18) | R18: =IF(ISBLANK($C18),"",IF(ISBLANK($I18),$D18,$I18)) | S18: =IF(ISBLANK($C18),"",$F18 - $G18) | T18: =IF(ISBLANK($C18),"",C18) | U18: =IF(ISBLANK($C18),"",$D$1) | V18: {=IF(ISBLANK($B18),"",IF(ISBLANK($K18),IF(XLOOKUP($W18,'Category Mapping'!$C:$C,'Category Mapping'!$B:$B)="Travel",XLOOKUP($P18,'Department Listing'!$A:$A,'Department Listing'!$M:$M),XLOOKUP($W18,'Category Mapping'!$C:$C,'Category Mapping'!$D:$D)),$K18))} | W18: =IF(ISBLANK($B18),"",IF(ISBLANK($L18),RIGHT($E18,LEN($E18) - FIND("^",SUBSTITUTE($E18,":","^",LEN($E18) - LEN(SUBSTITUTE($E18,":",""))))),$L18)) | X18: =IF(ISBLANK($J18),$V18&$W18,$J18) | Y18: {=IF(ISBLANK($M18),IFERROR(XLOOKUP($P18,'Department Listing'!$A:$A,'Department Listing'!$L:$L),""),$M18)} | Z18: =IF(ISBLANK($B18),"",MATCH($X18,COA!$B:$B,0))
B19: 46166 | C19: Claude MASTERCARD-544015XXXXXX0151-Eric Rabkin | D19: Claude.AI | E19: 63310 General & Administrative:Software Licenses | F19: 1022.16 | O19: =IF(C19="", "", TRIM(RIGHT(C19, LEN(C19) - FIND("@@", SUBSTITUTE(C19, "-", "@@", LEN(C19) - LEN(SUBSTITUTE(C19, "-", ""))))))) | P19: {=IFERROR(XLOOKUP(O19,'Department Listing'!$O$1:$O$395,'Department Listing'!$A$1:$A$395),IFERROR(XLOOKUP(O19,'Name Aliases'!$A$2:$A$1000,'Name Aliases'!$B$2:$B$1000),""))} | Q19: =IF(ISBLANK($C19),"",$B19) | R19: =IF(ISBLANK($C19),"",IF(ISBLANK($I19),$D19,$I19)) | S19: =IF(ISBLANK($C19),"",$F19 - $G19) | T19: =IF(ISBLANK($C19),"",C19) | U19: =IF(ISBLANK($C19),"",$D$1) | V19: {=IF(ISBLANK($B19),"",IF(ISBLANK($K19),IF(XLOOKUP($W19,'Category Mapping'!$C:$C,'Category Mapping'!$B:$B)="Travel",XLOOKUP($P19,'Department Listing'!$A:$A,'Department Listing'!$M:$M),XLOOKUP($W19,'Category Mapping'!$C:$C,'Category Mapping'!$D:$D)),$K19))} | W19: =IF(ISBLANK($B19),"",IF(ISBLANK($L19),RIGHT($E19,LEN($E19) - FIND("^",SUBSTITUTE($E19,":","^",LEN($E19) - LEN(SUBSTITUTE($E19,":",""))))),$L19)) | X19: =IF(ISBLANK($J19),$V19&$W19,$J19) | Y19: {=IF(ISBLANK($M19),IFERROR(XLOOKUP($P19,'Department Listing'!$A:$A,'Department Listing'!$L:$L),""),$M19)} | Z19: =IF(ISBLANK($B19),"",MATCH($X19,COA!$B:$B,0))
B20: 46166 | C20: Claude MASTERCARD-544015XXXXXX0151-Eric Rabkin | D20: Claude.AI | E20: 63310 General & Administrative:Software Licenses | F20: 1020.56 | O20: =IF(C20="", "", TRIM(RIGHT(C20, LEN(C20) - FIND("@@", SUBSTITUTE(C20, "-", "@@", LEN(C20) - LEN(SUBSTITUTE(C20, "-", ""))))))) | P20: {=IFERROR(XLOOKUP(O20,'Department Listing'!$O$1:$O$395,'Department Listing'!$A$1:$A$395),IFERROR(XLOOKUP(O20,'Name Aliases'!$A$2:$A$1000,'Name Aliases'!$B$2:$B$1000),""))} | Q20: =IF(ISBLANK($C20),"",$B20) | R20: =IF(ISBLANK($C20),"",IF(ISBLANK($I20),$D20,$I20)) | S20: =IF(ISBLANK($C20),"",$F20 - $G20) | T20: =IF(ISBLANK($C20),"",C20) | U20: =IF(ISBLANK($C20),"",$D$1) | V20: {=IF(ISBLANK($B20),"",IF(ISBLANK($K20),IF(XLOOKUP($W20,'Category Mapping'!$C:$C,'Category Mapping'!$B:$B)="Travel",XLOOKUP($P20,'Department Listing'!$A:$A,'Department Listing'!$M:$M),XLOOKUP($W20,'Category Mapping'!$C:$C,'Category Mapping'!$D:$D)),$K20))} | W20: =IF(ISBLANK($B20),"",IF(ISBLANK($L20),RIGHT($E20,LEN($E20) - FIND("^",SUBSTITUTE($E20,":","^",LEN($E20) - LEN(SUBSTITUTE($E20,":",""))))),$L20)) | X20: =IF(ISBLANK($J20),$V20&$W20,$J20) | Y20: {=IF(ISBLANK($M20),IFERROR(XLOOKUP($P20,'Department Listing'!$A:$A,'Department Listing'!$L:$L),""),$M20)} | Z20: =IF(ISBLANK($B20),"",MATCH($X20,COA!$B:$B,0))
B21: 46165 | C21: Claude MASTERCARD-544015XXXXXX0151-Eric Rabkin | D21: Claude.AI | E21: 63310 General & Administrative:Software Licenses | F21: 1019.16 | O21: =IF(C21="", "", TRIM(RIGHT(C21, LEN(C21) - FIND("@@", SUBSTITUTE(C21, "-", "@@", LEN(C21) - LEN(SUBSTITUTE(C21, "-", ""))))))) | P21: {=IFERROR(XLOOKUP(O21,'Department Listing'!$O$1:$O$395,'Department Listing'!$A$1:$A$395),IFERROR(XLOOKUP(O21,'Name Aliases'!$A$2:$A$1000,'Name Aliases'!$B$2:$B$1000),""))} | Q21: =IF(ISBLANK($C21),"",$B21) | R21: =IF(ISBLANK($C21),"",IF(ISBLANK($I21),$D21,$I21)) | S21: =IF(ISBLANK($C21),"",$F21 - $G21) | T21: =IF(ISBLANK($C21),"",C21) | U21: =IF(ISBLANK($C21),"",$D$1) | V21: {=IF(ISBLANK($B21),"",IF(ISBLANK($K21),IF(XLOOKUP($W21,'Category Mapping'!$C:$C,'Category Mapping'!$B:$B)="Travel",XLOOKUP($P21,'Department Listing'!$A:$A,'Department Listing'!$M:$M),XLOOKUP($W21,'Category Mapping'!$C:$C,'Category Mapping'!$D:$D)),$K21))} | W21: =IF(ISBLANK($B21),"",IF(ISBLANK($L21),RIGHT($E21,LEN($E21) - FIND("^",SUBSTITUTE($E21,":","^",LEN($E21) - LEN(SUBSTITUTE($E21,":",""))))),$L21)) | X21: =IF(ISBLANK($J21),$V21&$W21,$J21) | Y21: {=IF(ISBLANK($M21),IFERROR(XLOOKUP($P21,'Department Listing'!$A:$A,'Department Listing'!$L:$L),""),$M21)} | Z21: =IF(ISBLANK($B21),"",MATCH($X21,COA!$B:$B,0))
B22: 46165 | C22: Claude MASTERCARD-544015XXXXXX0151-Eric Rabkin | D22: Claude.AI | E22: 63310 General & Administrative:Software Licenses | F22: 1018.67 | O22: =IF(C22="", "", TRIM(RIGHT(C22, LEN(C22) - FIND("@@", SUBSTITUTE(C22, "-", "@@", LEN(C22) - LEN(SUBSTITUTE(C22, "-", ""))))))) | P22: {=IFERROR(XLOOKUP(O22,'Department Listing'!$O$1:$O$395,'Department Listing'!$A$1:$A$395),IFERROR(XLOOKUP(O22,'Name Aliases'!$A$2:$A$1000,'Name Aliases'!$B$2:$B$1000),""))} | Q22: =IF(ISBLANK($C22),"",$B22) | R22: =IF(ISBLANK($C22),"",IF(ISBLANK($I22),$D22,$I22)) | S22: =IF(ISBLANK($C22),"",$F22 - $G22) | T22: =IF(ISBLANK($C22),"",C22) | U22: =IF(ISBLANK($C22),"",$D$1) | V22: {=IF(ISBLANK($B22),"",IF(ISBLANK($K22),IF(XLOOKUP($W22,'Category Mapping'!$C:$C,'Category Mapping'!$B:$B)="Travel",XLOOKUP($P22,'Department Listing'!$A:$A,'Department Listing'!$M:$M),XLOOKUP($W22,'Category Mapping'!$C:$C,'Category Mapping'!$D:$D)),$K22))} | W22: =IF(ISBLANK($B22),"",IF(ISBLANK($L22),RIGHT($E22,LEN($E22) - FIND("^",SUBSTITUTE($E22,":","^",LEN($E22) - LEN(SUBSTITUTE($E22,":",""))))),$L22)) | X22: =IF(ISBLANK($J22),$V22&$W22,$J22) | Y22: {=IF(ISBLANK($M22),IFERROR(XLOOKUP($P22,'Department Listing'!$A:$A,'Department Listing'!$L:$L),""),$M22)} | Z22: =IF(ISBLANK($B22),"",MATCH($X22,COA!$B:$B,0))
B23: 46165 | C23: Claude MASTERCARD-544015XXXXXX0151-Eric Rabkin | D23: Claude.AI | E23: 63310 General & Administrative:Software Licenses | F23: 1018.34 | O23: =IF(C23="", "", TRIM(RIGHT(C23, LEN(C23) - FIND("@@", SUBSTITUTE(C23, "-", "@@", LEN(C23) - LEN(SUBSTITUTE(C23, "-", ""))))))) | P23: {=IFERROR(XLOOKUP(O23,'Department Listing'!$O$1:$O$395,'Department Listing'!$A$1:$A$395),IFERROR(XLOOKUP(O23,'Name Aliases'!$A$2:$A$1000,'Name Aliases'!$B$2:$B$1000),""))} | Q23: =IF(ISBLANK($C23),"",$B23) | R23: =IF(ISBLANK($C23),"",IF(ISBLANK($I23),$D23,$I23)) | S23: =IF(ISBLANK($C23),"",$F23 - $G23) | T23: =IF(ISBLANK($C23),"",C23) | U23: =IF(ISBLANK($C23),"",$D$1) | V23: {=IF(ISBLANK($B23),"",IF(ISBLANK($K23),IF(XLOOKUP($W23,'Category Mapping'!$C:$C,'Category Mapping'!$B:$B)="Travel",XLOOKUP($P23,'Department Listing'!$A:$A,'Department Listing'!$M:$M),XLOOKUP($W23,'Category Mapping'!$C:$C,'Category Mapping'!$D:$D)),$K23))} | W23: =IF(ISBLANK($B23),"",IF(ISBLANK($L23),RIGHT($E23,LEN($E23) - FIND("^",SUBSTITUTE($E23,":","^",LEN($E23) - LEN(SUBSTITUTE($E23,":",""))))),$L23)) | X23: =IF(ISBLANK($J23),$V23&$W23,$J23) | Y23: {=IF(ISBLANK($M23),IFERROR(XLOOKUP($P23,'Department Listing'!$A:$A,'Department Listing'!$L:$L),""),$M23)} | Z23: =IF(ISBLANK($B23),"",MATCH($X23,COA!$B:$B,0))
B24: 46166 | C24: Claude MASTERCARD-544015XXXXXX0151-Eric Rabkin | D24: Claude.AI | E24: 63310 General & Administrative:Software Licenses | F24: 1017.01 | O24: =IF(C24="", "", TRIM(RIGHT(C24, LEN(C24) - FIND("@@", SUBSTITUTE(C24, "-", "@@", LEN(C24) - LEN(SUBSTITUTE(C24, "-", ""))))))) | P24: {=IFERROR(XLOOKUP(O24,'Department Listing'!$O$1:$O$395,'Department Listing'!$A$1:$A$395),IFERROR(XLOOKUP(O24,'Name Aliases'!$A$2:$A$1000,'Name Aliases'!$B$2:$B$1000),""))} | Q24: =IF(ISBLANK($C24),"",$B24) | R24: =IF(ISBLANK($C24),"",IF(ISBLANK($I24),$D24,$I24)) | S24: =IF(ISBLANK($C24),"",$F24 - $G24) | T24: =IF(ISBLANK($C24),"",C24) | U24: =IF(ISBLANK($C24),"",$D$1) | V24: {=IF(ISBLANK($B24),"",IF(ISBLANK($K24),IF(XLOOKUP($W24,'Category Mapping'!$C:$C,'Category Mapping'!$B:$B)="Travel",XLOOKUP($P24,'Department Listing'!$A:$A,'Department Listing'!$M:$M),XLOOKUP($W24,'Category Mapping'!$C:$C,'Category Mapping'!$D:$D)),$K24))} | W24: =IF(ISBLANK($B24),"",IF(ISBLANK($L24),RIGHT($E24,LEN($E24) - FIND("^",SUBSTITUTE($E24,":","^",LEN($E24) - LEN(SUBSTITUTE($E24,":",""))))),$L24)) | X24: =IF(ISBLANK($J24),$V24&$W24,$J24) | Y24: {=IF(ISBLANK($M24),IFERROR(XLOOKUP($P24,'Department Listing'!$A:$A,'Department Listing'!$L:$L),""),$M24)} | Z24: =IF(ISBLANK($B24),"",MATCH($X24,COA!$B:$B,0))
B25: 46169 | C25: Claude MASTERCARD-544015XXXXXX0151-Eric Rabkin | D25: Claude.AI | E25: 63310 General & Administrative:Software Licenses | F25: 1015.91 | O25: =IF(C25="", "", TRIM(RIGHT(C25, LEN(C25) - FIND("@@", SUBSTITUTE(C25, "-", "@@", LEN(C25) - LEN(SUBSTITUTE(C25, "-", ""))))))) | P25: {=IFERROR(XLOOKUP(O25,'Department Listing'!$O$1:$O$395,'Department Listing'!$A$1:$A$395),IFERROR(XLOOKUP(O25,'Name Aliases'!$A$2:$A$1000,'Name Aliases'!$B$2:$B$1000),""))} | Q25: =IF(ISBLANK($C25),"",$B25) | R25: =IF(ISBLANK($C25),"",IF(ISBLANK($I25),$D25,$I25)) | S25: =IF(ISBLANK($C25),"",$F25 - $G25) | T25: =IF(ISBLANK($C25),"",C25) | U25: =IF(ISBLANK($C25),"",$D$1) | V25: {=IF(ISBLANK($B25),"",IF(ISBLANK($K25),IF(XLOOKUP($W25,'Category Mapping'!$C:$C,'Category Mapping'!$B:$B)="Travel",XLOOKUP($P25,'Department Listing'!$A:$A,'Department Listing'!$M:$M),XLOOKUP($W25,'Category Mapping'!$C:$C,'Category Mapping'!$D:$D)),$K25))} | W25: =IF(ISBLANK($B25),"",IF(ISBLANK($L25),RIGHT($E25,LEN($E25) - FIND("^",SUBSTITUTE($E25,":","^",LEN($E25) - LEN(SUBSTITUTE($E25,":",""))))),$L25)) | X25: =IF(ISBLANK($J25),$V25&$W25,$J25) | Y25: {=IF(ISBLANK($M25),IFERROR(XLOOKUP($P25,'Department Listing'!$A:$A,'Department Listing'!$L:$L),""),$M25)} | Z25: =IF(ISBLANK($B25),"",MATCH($X25,COA!$B:$B,0))
B26: 46166 | C26: Claude MASTERCARD-544015XXXXXX0151-Eric Rabkin | D26: Claude.AI | E26: 63310 General & Administrative:Software Licenses | F26: 1015.56 | O26: =IF(C26="", "", TRIM(RIGHT(C26, LEN(C26) - FIND("@@", SUBSTITUTE(C26, "-", "@@", LEN(C26) - LEN(SUBSTITUTE(C26, "-", ""))))))) | P26: {=IFERROR(XLOOKUP(O26,'Department Listing'!$O$1:$O$395,'Department Listing'!$A$1:$A$395),IFERROR(XLOOKUP(O26,'Name Aliases'!$A$2:$A$1000,'Name Aliases'!$B$2:$B$1000),""))} | Q26: =IF(ISBLANK($C26),"",$B26) | R26: =IF(ISBLANK($C26),"",IF(ISBLANK($I26),$D26,$I26)) | S26: =IF(ISBLANK($C26),"",$F26 - $G26) | T26: =IF(ISBLANK($C26),"",C26) | U26: =IF(ISBLANK($C26),"",$D$1) | V26: {=IF(ISBLANK($B26),"",IF(ISBLANK($K26),IF(XLOOKUP($W26,'Category Mapping'!$C:$C,'Category Mapping'!$B:$B)="Travel",XLOOKUP($P26,'Department Listing'!$A:$A,'Department Listing'!$M:$M),XLOOKUP($W26,'Category Mapping'!$C:$C,'Category Mapping'!$D:$D)),$K26))} | W26: =IF(ISBLANK($B26),"",IF(ISBLANK($L26),RIGHT($E26,LEN($E26) - FIND("^",SUBSTITUTE($E26,":","^",LEN($E26) - LEN(SUBSTITUTE($E26,":",""))))),$L26)) | X26: =IF(ISBLANK($J26),$V26&$W26,$J26) | Y26: {=IF(ISBLANK($M26),IFERROR(XLOOKUP($P26,'Department Listing'!$A:$A,'Department Listing'!$L:$L),""),$M26)} | Z26: =IF(ISBLANK($B26),"",MATCH($X26,COA!$B:$B,0))
B27: 46164 | C27: Claude MASTERCARD-544015XXXXXX0151-Eric Rabkin | D27: Claude.AI | E27: 63310 General & Administrative:Software Licenses | F27: 1015.12 | O27: =IF(C27="", "", TRIM(RIGHT(C27, LEN(C27) - FIND("@@", SUBSTITUTE(C27, "-", "@@", LEN(C27) - LEN(SUBSTITUTE(C27, "-", ""))))))) | P27: {=IFERROR(XLOOKUP(O27,'Department Listing'!$O$1:$O$395,'Department Listing'!$A$1:$A$395),IFERROR(XLOOKUP(O27,'Name Aliases'!$A$2:$A$1000,'Name Aliases'!$B$2:$B$1000),""))} | Q27: =IF(ISBLANK($C27),"",$B27) | R27: =IF(ISBLANK($C27),"",IF(ISBLANK($I27),$D27,$I27)) | S27: =IF(ISBLANK($C27),"",$F27 - $G27) | T27: =IF(ISBLANK($C27),"",C27) | U27: =IF(ISBLANK($C27),"",$D$1) | V27: {=IF(ISBLANK($B27),"",IF(ISBLANK($K27),IF(XLOOKUP($W27,'Category Mapping'!$C:$C,'Category Mapping'!$B:$B)="Travel",XLOOKUP($P27,'Department Listing'!$A:$A,'Department Listing'!$M:$M),XLOOKUP($W27,'Category Mapping'!$C:$C,'Category Mapping'!$D:$D)),$K27))} | W27: =IF(ISBLANK($B27),"",IF(ISBLANK($L27),RIGHT($E27,LEN($E27) - FIND("^",SUBSTITUTE($E27,":","^",LEN($E27) - LEN(SUBSTITUTE($E27,":",""))))),$L27)) | X27: =IF(ISBLANK($J27),$V27&$W27,$J27) | Y27: {=IF(ISBLANK($M27),IFERROR(XLOOKUP($P27,'Department Listing'!$A:$A,'Department Listing'!$L:$L),""),$M27)} | Z27: =IF(ISBLANK($B27),"",MATCH($X27,COA!$B:$B,0))
... B39: 46170 | C39: Claude MASTERCARD-544015XXXXXX0151-Eric Rabkin | D39: Claude.AI | E39: 63310 General & Administrative:Software Licenses | F39: 1009.49 | O39: =IF(C39="", "", TRIM(RIGHT(C39, LEN(C39) - FIND("@@", SUBSTITUTE(C39, "-", "@@", LEN(C39) - LEN(SUBSTITUTE(C39, "-", ""))))))) | P39: {=IFERROR(XLOOKUP(O39,'Department Listing'!$O$1:$O$395,'Department Listing'!$A$1:$A$395),IFERROR(XLOOKUP(O39,'Name Aliases'!$A$2:$A$1000,'Name Aliases'!$B$2:$B$1000),""))} | Q39: =IF(ISBLANK($C39),"",$B39) | R39: =IF(ISBLANK($C39),"",IF(ISBLANK($I39),$D39,$I39)) | S39: =IF(ISBLANK($C39),"",$F39 - $G39) | T39: =IF(ISBLANK($C39),"",C39) | U39: =IF(ISBLANK($C39),"",$D$1) | V39: {=IF(ISBLANK($B39),"",IF(ISBLANK($K39),IF(XLOOKUP($W39,'Category Mapping'!$C:$C,'Category Mapping'!$B:$B)="Travel",XLOOKUP($P39,'Department Listing'!$A:$A,'Department Listing'!$M:$M),XLOOKUP($W39,'Category Mapping'!$C:$C,'Category Mapping'!$D:$D)),$K39))} | W39: =IF(ISBLANK($B39),"",IF(ISBLANK($L39),RIGHT($E39,LEN($E39) - FIND("^",SUBSTITUTE($E39,":","^",LEN($E39) - LEN(SUBSTITUTE($E39,":",""))))),$L39)) | X39: =IF(ISBLANK($J39),$V39&$W39,$J39) | Y39: {=IF(ISBLANK($M39),IFERROR(XLOOKUP($P39,'Department Listing'!$A:$A,'Department Listing'!$L:$L),""),$M39)} | Z39: =IF(ISBLANK($B39),"",MATCH($X39,COA!$B:$B,0))
B40: 46165 | C40: MakeStickers.com MASTERCARD-544015XXXXXX8091-Brooke Berg | E40: 63410 General & Administrative:Office Expenses:Office Supplies | F40: 958.31 | I40: Makestickers.com | O40: =IF(C40="", "", TRIM(RIGHT(C40, LEN(C40) - FIND("@@", SUBSTITUTE(C40, "-", "@@", LEN(C40) - LEN(SUBSTITUTE(C40, "-", ""))))))) | P40: {=IFERROR(XLOOKUP(O40,'Department Listing'!$O$1:$O$395,'Department Listing'!$A$1:$A$395),IFERROR(XLOOKUP(O40,'Name Aliases'!$A$2:$A$1000,'Name Aliases'!$B$2:$B$1000),""))} | Q40: =IF(ISBLANK($C40),"",$B40) | R40: =IF(ISBLANK($C40),"",IF(ISBLANK($I40),$D40,$I40)) | S40: =IF(ISBLANK($C40),"",$F40 - $G40) | T40: =IF(ISBLANK($C40),"",C40) | U40: =IF(ISBLANK($C40),"",$D$1) | V40: {=IF(ISBLANK($B40),"",IF(ISBLANK($K40),IF(XLOOKUP($W40,'Category Mapping'!$C:$C,'Category Mapping'!$B:$B)="Travel",XLOOKUP($P40,'Department Listing'!$A:$A,'Department Listing'!$M:$M),XLOOKUP($W40,'Category Mapping'!$C:$C,'Category Mapping'!$D:$D)),$K40))} | W40: =IF(ISBLANK($B40),"",IF(ISBLANK($L40),RIGHT($E40,LEN($E40) - FIND("^",SUBSTITUTE($E40,":","^",LEN($E40) - LEN(SUBSTITUTE($E40,":",""))))),$L40)) | X40: =IF(ISBLANK($J40),$V40&$W40,$J40) | Y40: {=IF(ISBLANK($M40),IFERROR(XLOOKUP($P40,'Department Listing'!$A:$A,'Department Listing'!$L:$L),""),$M40)} | Z40: =IF(ISBLANK($B40),"",MATCH($X40,COA!$B:$B,0))
B41: 46165 | C41: Southwest Airlines MASTERCARD-544015XXXXXX8678-John Taylor | D41: Southwest Air | E41: 61210 Sales & Marketing:Sales & Marketing- Travel Expenses:Airfare | F41: 882.8 | O41: =IF(C41="", "", TRIM(RIGHT(C41, LEN(C41) - FIND("@@", SUBSTITUTE(C41, "-", "@@", LEN(C41) - LEN(SUBSTITUTE(C41, "-", ""))))))) | P41: {=IFERROR(XLOOKUP(O41,'Department Listing'!$O$1:$O$395,'Department Listing'!$A$1:$A$395),IFERROR(XLOOKUP(O41,'Name Aliases'!$A$2:$A$1000,'Name Aliases'!$B$2:$B$1000),""))} | Q41: =IF(ISBLANK($C41),"",$B41) | R41: =IF(ISBLANK($C41),"",IF(ISBLANK($I41),$D41,$I41)) | S41: =IF(ISBLANK($C41),"",$F41 - $G41) | T41: =IF(ISBLANK($C41),"",C41) | U41: =IF(ISBLANK($C41),"",$D$1) | V41: {=IF(ISBLANK($B41),"",IF(ISBLANK($K41),IF(XLOOKUP($W41,'Category Mapping'!$C:$C,'Category Mapping'!$B:$B)="Travel",XLOOKUP($P41,'Department Listing'!$A:$A,'Department Listing'!$M:$M),XLOOKUP($W41,'Category Mapping'!$C:$C,'Category Mapping'!$D:$D)),$K41))} | W41: =IF(ISBLANK($B41),"",IF(ISBLANK($L41),RIGHT($E41,LEN($E41) - FIND("^",SUBSTITUTE($E41,":","^",LEN($E41) - LEN(SUBSTITUTE($E41,":",""))))),$L41)) | X41: =IF(ISBLANK($J41),$V41&$W41,$J41) | Y41: {=IF(ISBLANK($M41),IFERROR(XLOOKUP($P41,'Department Listing'!$A:$A,'Department Listing'!$L:$L),""),$M41)} | Z41: =IF(ISBLANK($B41),"",MATCH($X41,COA!$B:$B,0))
B42: 46165 | C42: Jamie Cosgrove MASTERCARD-544015XXXXXX6112-Elyse Neumeier | E42: 63310 General & Administrative:Software Licenses | F42: 750 | I42: Office Vendor | L42: Dues & Subscriptions | O42: =IF(C42="", "", TRIM(RIGHT(C42, LEN(C42) - FIND("@@", SUBSTITUTE(C42, "-", "@@", LEN(C42) - LEN(SUBSTITUTE(C42, "-", ""))))))) | P42: {=IFERROR(XLOOKUP(O42,'Department Listing'!$O$1:$O$395,'Department Listing'!$A$1:$A$395),IFERROR(XLOOKUP(O42,'Name Aliases'!$A$2:$A$1000,'Name Aliases'!$B$2:$B$1000),""))} | Q42: =IF(ISBLANK($C42),"",$B42) | R42: =IF(ISBLANK($C42),"",IF(ISBLANK($I42),$D42,$I42)) | S42: =IF(ISBLANK($C42),"",$F42 - $G42) | T42: =IF(ISBLANK($C42),"",C42) | U42: =IF(ISBLANK($C42),"",$D$1) | V42: {=IF(ISBLANK($B42),"",IF(ISBLANK($K42),IF(XLOOKUP($W42,'Category Mapping'!$C:$C,'Category Mapping'!$B:$B)="Travel",XLOOKUP($P42,'Department Listing'!$A:$A,'Department Listing'!$M:$M),XLOOKUP($W42,'Category Mapping'!$C:$C,'Category Mapping'!$D:$D)),$K42))} | W42: =IF(ISBLANK($B42),"",IF(ISBLANK($L42),RIGHT($E42,LEN($E42) - FIND("^",SUBSTITUTE($E42,":","^",LEN($E42) - LEN(SUBSTITUTE($E42,":",""))))),$L42)) | X42: =IF(ISBLANK($J42),$V42&$W42,$J42) | Y42: {=IF(ISBLANK($M42),IFERROR(XLOOKUP($P42,'Department Listing'!$A:$A,'Department Listing'!$L:$L),""),$M42)} | Z42: =IF(ISBLANK($B42),"",MATCH($X42,COA!$B:$B,0))
B43: 46168 | C43: GUESTRS*PUROWARSZA MASTERCARD-544015XXXXXX5191-Samantha Purpura | E43: 61220 Sales & Marketing:Sales & Marketing- Travel Expenses:Ground Transportation | F43: 739.92 | I43: Hotel Vendor | L43: Lodging | O43: =IF(C43="", "", TRIM(RIGHT(C43, LEN(C43) - FIND("@@", SUBSTITUTE(C43, "-", "@@", LEN(C43) - LEN(SUBSTITUTE(C43, "-", ""))))))) | P43: {=IFERROR(XLOOKUP(O43,'Department Listing'!$O$1:$O$395,'Department Listing'!$A$1:$A$395),IFERROR(XLOOKUP(O43,'Name Aliases'!$A$2:$A$1000,'Name Aliases'!$B$2:$B$1000),""))} | Q43: =IF(ISBLANK($C43),"",$B43) | R43: =IF(ISBLANK($C43),"",IF(ISBLANK($I43),$D43,$I43)) | S43: =IF(ISBLANK($C43),"",$F43 - $G43) | T43: =IF(ISBLANK($C43),"",C43) | U43: =IF(ISBLANK($C43),"",$D$1) | V43: {=IF(ISBLANK($B43),"",IF(ISBLANK($K43),IF(XLOOKUP($W43,'Category Mapping'!$C:$C,'Category Mapping'!$B:$B)="Travel",XLOOKUP($P43,'Department Listing'!$A:$A,'Department Listing'!$M:$M),XLOOKUP($W43,'Category Mapping'!$C:$C,'Category Mapping'!$D:$D)),$K43))} | W43: =IF(ISBLANK($B43),"",IF(ISBLANK($L43),RIGHT($E43,LEN($E43) - FIND("^",SUBSTITUTE($E43,":","^",LEN($E43) - LEN(SUBSTITUTE($E43,":",""))))),$L43)) | X43: =IF(ISBLANK($J43),$V43&$W43,$J43) | Y43: {=IF(ISBLANK($M43),IFERROR(XLOOKUP($P43,'Department Listing'!$A:$A,'Department Listing'!$L:$L),""),$M43)} | Z43: =IF(ISBLANK($B43),"",MATCH($X43,COA!$B:$B,0))
B44: 46164 | C44: Marriott Union Square MASTERCARD-544015XXXXXX2445-Tyler Grimshaw | D44: Marriott | E44: 61230 Sales & Marketing:Sales & Marketing- Travel Expenses:Lodging | F44: 699.46 | O44: =IF(C44="", "", TRIM(RIGHT(C44, LEN(C44) - FIND("@@", SUBSTITUTE(C44, "-", "@@", LEN(C44) - LEN(SUBSTITUTE(C44, "-", ""))))))) | P44: {=IFERROR(XLOOKUP(O44,'Department Listing'!$O$1:$O$395,'Department Listing'!$A$1:$A$395),IFERROR(XLOOKUP(O44,'Name Aliases'!$A$2:$A$1000,'Name Aliases'!$B$2:$B$1000),""))} | Q44: =IF(ISBLANK($C44),"",$B44) | R44: =IF(ISBLANK($C44),"",IF(ISBLANK($I44),$D44,$I44)) | S44: =IF(ISBLANK($C44),"",$F44 - $G44) | T44: =IF(ISBLANK($C44),"",C44) | U44: =IF(ISBLANK($C44),"",$D$1) | V44: {=IF(ISBLANK($B44),"",IF(ISBLANK($K44),IF(XLOOKUP($W44,'Category Mapping'!$C:$C,'Category Mapping'!$B:$B)="Travel",XLOOKUP($P44,'Department Listing'!$A:$A,'Department Listing'!$M:$M),XLOOKUP($W44,'Category Mapping'!$C:$C,'Category Mapping'!$D:$D)),$K44))} | W44: =IF(ISBLANK($B44),"",IF(ISBLANK($L44),RIGHT($E44,LEN($E44) - FIND("^",SUBSTITUTE($E44,":","^",LEN($E44) - LEN(SUBSTITUTE($E44,":",""))))),$L44)) | X44: =IF(ISBLANK($J44),$V44&$W44,$J44) | Y44: {=IF(ISBLANK($M44),IFERROR(XLOOKUP($P44,'Department Listing'!$A:$A,'Department Listing'!$L:$L),""),$M44)} | Z44: =IF(ISBLANK($B44),"",MATCH($X44,COA!$B:$B,0))
B45: 46167 | C45: Air Canada MASTERCARD-555671XXXXXX3587-Pooja Manjeshwar | D45: Air Canada | E45: 61210 Sales & Marketing:Sales & Marketing- Travel Expenses:Airfare | F45: 646.62 | O45: =IF(C45="", "", TRIM(RIGHT(C45, LEN(C45) - FIND("@@", SUBSTITUTE(C45, "-", "@@", LEN(C45) - LEN(SUBSTITUTE(C45, "-", ""))))))) | P45: {=IFERROR(XLOOKUP(O45,'Department Listing'!$O$1:$O$395,'Department Listing'!$A$1:$A$395),IFERROR(XLOOKUP(O45,'Name Aliases'!$A$2:$A$1000,'Name Aliases'!$B$2:$B$1000),""))} | Q45: =IF(ISBLANK($C45),"",$B45) | R45: =IF(ISBLANK($C45),"",IF(ISBLANK($I45),$D45,$I45)) | S45: =IF(ISBLANK($C45),"",$F45 - $G45) | T45: =IF(ISBLANK($C45),"",C45) | U45: =IF(ISBLANK($C45),"",$D$1) | V45: {=IF(ISBLANK($B45),"",IF(ISBLANK($K45),IF(XLOOKUP($W45,'Category Mapping'!$C:$C,'Category Mapping'!$B:$B)="Travel",XLOOKUP($P45,'Department Listing'!$A:$A,'Department Listing'!$M:$M),XLOOKUP($W45,'Category Mapping'!$C:$C,'Category Mapping'!$D:$D)),$K45))} | W45: =IF(ISBLANK($B45),"",IF(ISBLANK($L45),RIGHT($E45,LEN($E45) - FIND("^",SUBSTITUTE($E45,":","^",LEN($E45) - LEN(SUBSTITUTE($E45,":",""))))),$L45)) | X45: =IF(ISBLANK($J45),$V45&$W45,$J45) | Y45: {=IF(ISBLANK($M45),IFERROR(XLOOKUP($P45,'Department Listing'!$A:$A,'Department Listing'!$L:$L),""),$M45)} | Z45: =IF(ISBLANK($B45),"",MATCH($X45,COA!$B:$B,0))
B46: 46168 | C46: FedEx MASTERCARD-544015XXXXXX0151-Eric Rabkin | D46: FedEx | E46: 63430 General & Administrative:Office Expenses:Shipping Expense | F46: 637.7 | O46: =IF(C46="", "", TRIM(RIGHT(C46, LEN(C46) - FIND("@@", SUBSTITUTE(C46, "-", "@@", LEN(C46) - LEN(SUBSTITUTE(C46, "-", ""))))))) | P46: {=IFERROR(XLOOKUP(O46,'Department Listing'!$O$1:$O$395,'Department Listing'!$A$1:$A$395),IFERROR(XLOOKUP(O46,'Name Aliases'!$A$2:$A$1000,'Name Aliases'!$B$2:$B$1000),""))} | Q46: =IF(ISBLANK($C46),"",$B46) | R46: =IF(ISBLANK($C46),"",IF(ISBLANK($I46),$D46,$I46)) | S46: =IF(ISBLANK($C46),"",$F46 - $G46) | T46: =IF(ISBLANK($C46),"",C46) | U46: =IF(ISBLANK($C46),"",$D$1) | V46: {=IF(ISBLANK($B46),"",IF(ISBLANK($K46),IF(XLOOKUP($W46,'Category Mapping'!$C:$C,'Category Mapping'!$B:$B)="Travel",XLOOKUP($P46,'Department Listing'!$A:$A,'Department Listing'!$M:$M),XLOOKUP($W46,'Category Mapping'!$C:$C,'Category Mapping'!$D:$D)),$K46))} | W46: =IF(ISBLANK($B46),"",IF(ISBLANK($L46),RIGHT($E46,LEN($E46) - FIND("^",SUBSTITUTE($E46,":","^",LEN($E46) - LEN(SUBSTITUTE($E46,":",""))))),$L46)) | X46: =IF(ISBLANK($J46),$V46&$W46,$J46) | Y46: {=IF(ISBLANK($M46),IFERROR(XLOOKUP($P46,'Department Listing'!$A:$A,'Department Listing'!$L:$L),""),$M46)} | Z46: =IF(ISBLANK($B46),"",MATCH($X46,COA!$B:$B,0))
B47: 46167 | C47: American Airlines MASTERCARD-544015XXXXXX5029-Austin Nadler | D47: American Airlines | E47: 61210 Sales & Marketing:Sales & Marketing- Travel Expenses:Airfare | F47: 594.8 | O47: =IF(C47="", "", TRIM(RIGHT(C47, LEN(C47) - FIND("@@", SUBSTITUTE(C47, "-", "@@", LEN(C47) - LEN(SUBSTITUTE(C47, "-", ""))))))) | P47: {=IFERROR(XLOOKUP(O47,'Department Listing'!$O$1:$O$395,'Department Listing'!$A$1:$A$395),IFERROR(XLOOKUP(O47,'Name Aliases'!$A$2:$A$1000,'Name Aliases'!$B$2:$B$1000),""))} | Q47: =IF(ISBLANK($C47),"",$B47) | R47: =IF(ISBLANK($C47),"",IF(ISBLANK($I47),$D47,$I47)) | S47: =IF(ISBLANK($C47),"",$F47 - $G47) | T47: =IF(ISBLANK($C47),"",C47) | U47: =IF(ISBLANK($C47),"",$D$1) | V47: {=IF(ISBLANK($B47),"",IF(ISBLANK($K47),IF(XLOOKUP($W47,'Category Mapping'!$C:$C,'Category Mapping'!$B:$B)="Travel",XLOOKUP($P47,'Department Listing'!$A:$A,'Department Listing'!$M:$M),XLOOKUP($W47,'Category Mapping'!$C:$C,'Category Mapping'!$D:$D)),$K47))} | W47: =IF(ISBLANK($B47),"",IF(ISBLANK($L47),RIGHT($E47,LEN($E47) - FIND("^",SUBSTITUTE($E47,":","^",LEN($E47) - LEN(SUBSTITUTE($E47,":",""))))),$L47)) | X47: =IF(ISBLANK($J47),$V47&$W47,$J47) | Y47: {=IF(ISBLANK($M47),IFERROR(XLOOKUP($P47,'Department Listing'!$A:$A,'Department Listing'!$L:$L),""),$M47)} | Z47: =IF(ISBLANK($B47),"",MATCH($X47,COA!$B:$B,0))
B48: 46168 | C48: Wegmans MASTERCARD-544015XXXXXX7759-Mickenzi Krpec | E48: 61240 Sales & Marketing:Sales & Marketing- Travel Expenses:Meals & Entertainment | F48: 507.74 | I48: Food Vendor | O48: =IF(C48="", "", TRIM(RIGHT(C48, LEN(C48) - FIND("@@", SUBSTITUTE(C48, "-", "@@", LEN(C48) - LEN(SUBSTITUTE(C48, "-", ""))))))) | P48: {=IFERROR(XLOOKUP(O48,'Department Listing'!$O$1:$O$395,'Department Listing'!$A$1:$A$395),IFERROR(XLOOKUP(O48,'Name Aliases'!$A$2:$A$1000,'Name Aliases'!$B$2:$B$1000),""))} | Q48: =IF(ISBLANK($C48),"",$B48) | R48: =IF(ISBLANK($C48),"",IF(ISBLANK($I48),$D48,$I48)) | S48: =IF(ISBLANK($C48),"",$F48 - $G48) | T48: =IF(ISBLANK($C48),"",C48) | U48: =IF(ISBLANK($C48),"",$D$1) | V48: {=IF(ISBLANK($B48),"",IF(ISBLANK($K48),IF(XLOOKUP($W48,'Category Mapping'!$C:$C,'Category Mapping'!$B:$B)="Travel",XLOOKUP($P48,'Department Listing'!$A:$A,'Department Listing'!$M:$M),XLOOKUP($W48,'Category Mapping'!$C:$C,'Category Mapping'!$D:$D)),$K48))} | W48: =IF(ISBLANK($B48),"",IF(ISBLANK($L48),RIGHT($E48,LEN($E48) - FIND("^",SUBSTITUTE($E48,":","^",LEN($E48) - LEN(SUBSTITUTE($E48,":",""))))),$L48)) | X48: =IF(ISBLANK($J48),$V48&$W48,$J48) | Y48: {=IF(ISBLANK($M48),IFERROR(XLOOKUP($P48,'Department Listing'!$A:$A,'Department Listing'!$L:$L),""),$M48)} | Z48: =IF(ISBLANK($B48),"",MATCH($X48,COA!$B:$B,0))
B49: 46164 | C49: Presidio Golf Course MASTERCARD-544015XXXXXX2445-Tyler Grimshaw | E49: 61240 Sales & Marketing:Sales & Marketing- Travel Expenses:Meals & Entertainment | F49: 501.28 | I49: Food Vendor | O49: =IF(C49="", "", TRIM(RIGHT(C49, LEN(C49) - FIND("@@", SUBSTITUTE(C49, "-", "@@", LEN(C49) - LEN(SUBSTITUTE(C49, "-", ""))))))) | P49: {=IFERROR(XLOOKUP(O49,'Department Listing'!$O$1:$O$395,'Department Listing'!$A$1:$A$395),IFERROR(XLOOKUP(O49,'Name Aliases'!$A$2:$A$1000,'Name Aliases'!$B$2:$B$1000),""))} | Q49: =IF(ISBLANK($C49),"",$B49) | R49: =IF(ISBLANK($C49),"",IF(ISBLANK($I49),$D49,$I49)) | S49: =IF(ISBLANK($C49),"",$F49 - $G49) | T49: =IF(ISBLANK($C49),"",C49) | U49: =IF(ISBLANK($C49),"",$D$1) | V49: {=IF(ISBLANK($B49),"",IF(ISBLANK($K49),IF(XLOOKUP($W49,'Category Mapping'!$C:$C,'Category Mapping'!$B:$B)="Travel",XLOOKUP($P49,'Department Listing'!$A:$A,'Department Listing'!$M:$M),XLOOKUP($W49,'Category Mapping'!$C:$C,'Category Mapping'!$D:$D)),$K49))} | W49: =IF(ISBLANK($B49),"",IF(ISBLANK($L49),RIGHT($E49,LEN($E49) - FIND("^",SUBSTITUTE($E49,":","^",LEN($E49) - LEN(SUBSTITUTE($E49,":",""))))),$L49)) | X49: =IF(ISBLANK($J49),$V49&$W49,$J49) | Y49: {=IF(ISBLANK($M49),IFERROR(XLOOKUP($P49,'Department Listing'!$A:$A,'Department Listing'!$L:$L),""),$M49)} | Z49: =IF(ISBLANK($B49),"",MATCH($X49,COA!$B:$B,0))
B50: 46168 | C50: Uber Eats MASTERCARD-544015XXXXXX7759-Mickenzi Krpec | D50: Uber Eats | E50: 61240 Sales & Marketing:Sales & Marketing- Travel Expenses:Meals & Entertainment | F50: 480.39 | O50: =IF(C50="", "", TRIM(RIGHT(C50, LEN(C50) - FIND("@@", SUBSTITUTE(C50, "-", "@@", LEN(C50) - LEN(SUBSTITUTE(C50, "-", ""))))))) | P50: {=IFERROR(XLOOKUP(O50,'Department Listing'!$O$1:$O$395,'Department Listing'!$A$1:$A$395),IFERROR(XLOOKUP(O50,'Name Aliases'!$A$2:$A$1000,'Name Aliases'!$B$2:$B$1000),""))} | Q50: =IF(ISBLANK($C50),"",$B50) | R50: =IF(ISBLANK($C50),"",IF(ISBLANK($I50),$D50,$I50)) | S50: =IF(ISBLANK($C50),"",$F50 - $G50) | T50: =IF(ISBLANK($C50),"",C50) | U50: =IF(ISBLANK($C50),"",$D$1) | V50: {=IF(ISBLANK($B50),"",IF(ISBLANK($K50),IF(XLOOKUP($W50,'Category Mapping'!$C:$C,'Category Mapping'!$B:$B)="Travel",XLOOKUP($P50,'Department Listing'!$A:$A,'Department Listing'!$M:$M),XLOOKUP($W50,'Category Mapping'!$C:$C,'Category Mapping'!$D:$D)),$K50))} | W50: =IF(ISBLANK($B50),"",IF(ISBLANK($L50),RIGHT($E50,LEN($E50) - FIND("^",SUBSTITUTE($E50,":","^",LEN($E50) - LEN(SUBSTITUTE($E50,":",""))))),$L50)) | X50: =IF(ISBLANK($J50),$V50&$W50,$J50) | Y50: {=IF(ISBLANK($M50),IFERROR(XLOOKUP($P50,'Department Listing'!$A:$A,'Department Listing'!$L:$L),""),$M50)} | Z50: =IF(ISBLANK($B50),"",MATCH($X50,COA!$B:$B,0))
B51: 46168 | C51: Uber Eats MASTERCARD-544015XXXXXX7759-Mickenzi Krpec | D51: Uber Eats | E51: 61240 Sales & Marketing:Sales & Marketing- Travel Expenses:Meals & Entertainment | F51: 469.84 | O51: =IF(C51="", "", TRIM(RIGHT(C51, LEN(C51) - FIND("@@", SUBSTITUTE(C51, "-", "@@", LEN(C51) - LEN(SUBSTITUTE(C51, "-", ""))))))) | P51: {=IFERROR(XLOOKUP(O51,'Department Listing'!$O$1:$O$395,'Department Listing'!$A$1:$A$395),IFERROR(XLOOKUP(O51,'Name Aliases'!$A$2:$A$1000,'Name Aliases'!$B$2:$B$1000),""))} | Q51: =IF(ISBLANK($C51),"",$B51) | R51: =IF(ISBLANK($C51),"",IF(ISBLANK($I51),$D51,$I51)) | S51: =IF(ISBLANK($C51),"",$F51 - $G51) | T51: =IF(ISBLANK($C51),"",C51) | U51: =IF(ISBLANK($C51),"",$D$1) | V51: {=IF(ISBLANK($B51),"",IF(ISBLANK($K51),IF(XLOOKUP($W51,'Category Mapping'!$C:$C,'Category Mapping'!$B:$B)="Travel",XLOOKUP($P51,'Department Listing'!$A:$A,'Department Listing'!$M:$M),XLOOKUP($W51,'Category Mapping'!$C:$C,'Category Mapping'!$D:$D)),$K51))} | W51: =IF(ISBLANK($B51),"",IF(ISBLANK($L51),RIGHT($E51,LEN($E51) - FIND("^",SUBSTITUTE($E51,":","^",LEN($E51) - LEN(SUBSTITUTE($E51,":",""))))),$L51)) | X51: =IF(ISBLANK($J51),$V51&$W51,$J51) | Y51: {=IF(ISBLANK($M51),IFERROR(XLOOKUP($P51,'Department Listing'!$A:$A,'Department Listing'!$L:$L),""),$M51)} | Z51: =IF(ISBLANK($B51),"",MATCH($X51,COA!$B:$B,0))
...

Sheet Card Mapping
B2: Card Number (last 4 Digits) | C2: Card Name | D2: Department | E2: EE ID | H2: Amex Accounts
B3: 2011 | C3: Matt Keyes | D3: 200- Datadog:230- Sales | E3: 104 | H3: Amex Plat 2 *51005
B4: 2219 | C4: Toni Manning | D4: 100- Operations:120- Marketing | E4: 121 | H4: Amex Plat *12006
B5: 3159 | C5: John Taylor | D5: 300- ServiceNow:330- Sales | E5: 118 | H5: Amex Centurion *01008
H6: Brex Credit Card
B7: 2193 | C7: Jacob McKenna | D7: 300- ServiceNow:320- Engineering | E7: 120 | H7: Amex Delta *13003
B8: 1302 | C8: Andrew Bissel | D8: 200- Datadog:220- Engineering | E8: 135
B9: 2110 | C9: Chris Breiner | D9: 200- Datadog:230- Sales | E9: 115
B10: 2094 | C10: Jon Lawer | D10: 300- ServiceNow:330- Sales | E10: 113
B11: 2243 | C11: Scott Lane | D11: 300- ServiceNow:330- Sales | E11: 132
B12: 2169 | C12: R Faria De Oliveira | D12: 200- Datadog:220- Engineering | E12: 125
B13: 2086 | C13: Richard Upshall | D13: 200- Datadog:230- Sales | E13: 112
B14: 2201 | C14: Eric Ledyard | D14: 100- Operations:110- G&A | E14: 123
B15: 2006 | C15: Tameem Hourani | D15: 100- Operations:110- G&A | E15: 1
B16: 1933 | C16: Nikita Ashok | D16: 100- Operations:120- Marketing | E16: 111
B17: 3418 | C17: Alta Abel | D17: 100- Operations:110- G&A | E17: 69
B18: 2675 | C18: Chloe Brant | D18: 300- ServiceNow:330- Sales | E18: 77
B19: 2170 | C19: Josh Van Harn | D19: 300- ServiceNow:330- Sales | E19: 23
... B125: 1799 | C125: Jacob Woolf | D125: 300- ServiceNow:320- Engineering | E125: 194
B126: 1823 | C126: Teresa Bobst | E126: 188
B127: 1856 | C127: Tim Lee | E127: 213
B128: 2813 | C128: Ona Kolosky | D128: 300- ServiceNow:320- Engineering | E128: 198
B129: 1864 | C129: Timothy Lau | D129: 200- Datadog:220- Engineering | E129: 210
B130: 1872 | C130: Sakshi Sasalate | D130: 300- ServiceNow:320- Engineering | E130: 209
B131: 1724 | C131: Sarah Dwyer | D131: 200- Datadog:210- Delivery | E131: 183
B132: 0151 | C132: Eric Rabkin | D132: 100- Operations:110- G&A | E132: 246
C133: Kyle Bense | D133: 300- ServiceNow:320- Engineering | E133: 252
C134: James O'Shaughnessy | D134: 300- ServiceNow:310- Delivery | E134: 239
C135: Cody Sanderford | D135: 300- ServiceNow:320- Engineering | E135: 245
C136: Harry Tomczyk | D136: 300- ServiceNow:330- Sales | E136: 251

Sheet Category Mapping
B3: Account Type | C3: Sub Account | D3: Parent Category
B4: Travel | C4: Airfare
B5: G&A | C5: Contractors | D5: General & Administrative:
B6: G&A | C6: Dues & Subscriptions | D6: General & Administrative:Office Expenses:
B7: Travel | C7: Ground Transportation
B8: G&A | C8: Hardware & Peripherals | D8: General & Administrative:Office Expenses:
B9: Travel | C9: Lodging
B10: Travel | C10: Meals & Entertainment
B11: G&A | C11: Office Supplies | D11: General & Administrative:Office Expenses:
B12: S&M | C12: Other Marketing Expenses | D12: Sales & Marketing:Marketing Expenses:
B13: Travel | C13: Other Travel Expenses
B14: G&A | C14: Shipping Expense | D14: General & Administrative:Office Expenses:
B15: G&A | C15: Software Licenses | D15: General & Administrative:
B16: G&A | C16: Misc. Taxes & Licenses | D16: General & Administrative:
B17: G&A | C17: Utilities | D17: General & Administrative:Office Expenses:
B18: G&A | C18: Communication Expense | D18: General & Administrative:Office Expenses:
B19: G&A | C19: Charitable Contribution | D19: General & Administrative:
B20: G&A | C20: General & Administrative:Office Expenses:Rent & Lease | D20: General & Administrative:

Sheet COA
B1: All QBO Accounts
B2: 45904
B4: BOA Checking 4855
B5: Brex Checking
B6: Cash
B7: Checking (Citizens)
B8: Northern Bank Checking 3097
B9: Accounts Receivable
B10: Accounts Receivable (A/R)
B11: Accounts Receivable (A/R) - CAD
B12: Accounts Receivable (A/R) - EUR
B13: Accounts Receivable (A/R) - GBP
B14: Asset Clearing
B15: Credit Card Receivables (deleted)
... B223: Other Expenses:Reconciliation Discrepancies

Sheet Instructions
B2: Purpose: Import Amex transactions with accurate department, account and description into QuickBooks Online
B4: Instructions
B5: 1. Duplicate File and ensure file name has today's date and the Amex account being entered
B6: 2. Review credit card transactions in QuickBooks, and manually enter credit card credits using "Card Mapping" tab as a reference. Ensure Vendor Name, Account, Department fields are populated and you add " - " & the Employee name to the end of the Memo field
B7: 3. CTRL+H Find and Replace "-" for " - "
B8: 4. Sort the transactions in QuickBooks based on Date
B9: 5. Export transactions from QuickBooks
B10: 6. Copy exported transactions, paste values in cells B-F of the "QBO Transactions" tab
B11: 7. Review Columns K-F of "QBO transactions" to ensure all cells are populated.
B12: 8. Ensure Column Q of "QBO Transactions" is showing the correct card account. Update in Cell D1 if incorrect
B13: 9. Filter Column R, Line Acct by each individual account to ensure transactions are coded accurately
B14: 10. Ensure transactions on "Credit Card Charge" tab, the transaction importer, match what's on "QBO Transactions" tab (transaction count and amount match)

Sheet Name Aliases
A1: Brex Name | B1: EE ID | C1: BambooHR Name | D1: Confirmed | E1: Note

Sheet Department Listing
A1: Employee # | B1: First Name | C1: Last Name | D1: Last name, First name | E1: Hire Date | F1: Employment Status | G1: Employment Status: Date | H1: Division | I1: Department | J1: Location | K1: Billable Status | L1: QBO Department | M1: Prefix- Travel | N1: Prefix- Payroll
A2: 1 | B2: Tameem | C2: Hourani | D2: Hourani, Tameem | E2: 43651 | F2: Owner/Partner | G2: 43651 | H2: Operations | I2: Operations | J2: Boylston | K2: No | L2: 400- Synechron:410- Digital platforms G&A | M2: General & Administrative:G&A- Travel Expenses: | N2: General & Administrative:G&A- Personnel Expenses: | O2: =B2&" "&C2
A3: 2 | B3: Jonathan | C3: Giara | D3: Giara, Jonathan | E3: 43647 | F3: Full-Time | G3: 43773 | H3: ServiceNow | I3: Engineering | J3: Remote | K3: Yes | L3: 300- ServiceNow:320- Engineering | M3: Cost of Goods Sold:COGS- Travel Expenses: | N3: Cost of Goods Sold:COGS- Personnel Expense: | O3: =B3&" "&C3
A4: 3 | B4: Connor | C4: Brackett | D4: Brackett, Connor | E4: 43773 | F4: Full-Time | G4: 43773 | H4: ServiceNow | I4: Sales | J4: Boylston | K4: No | L4: 300- ServiceNow:330- Sales | M4: Sales & Marketing:Sales & Marketing- Travel Expenses: | N4: Sales & Marketing:Sales & Marketing- Personnel Expenses: | O4: =B4&" "&C4
A5: 4 | B5: Jeffrey | C5: Mu | D5: Mu, Jeffrey | E5: 43754 | F5: Full-Time | G5: 43754 | H5: ServiceNow | I5: Engineering | J5: Boylston | K5: Yes | L5: 300- ServiceNow:320- Engineering | M5: Cost of Goods Sold:COGS- Travel Expenses: | N5: Cost of Goods Sold:COGS- Personnel Expense: | O5: =B5&" "&C5
A6: 5 | B6: James | C6: Craveiro | D6: Craveiro, James | E6: 43871 | F6: Terminated | G6: 44835 | H6: Datadog | I6: Engineering | J6: Remote | K6: Yes | L6: 200- Datadog:220- Engineering | M6: Cost of Goods Sold:COGS- Travel Expenses: | N6: Cost of Goods Sold:COGS- Personnel Expense: | O6: =B6&" "&C6
A7: 6 | B7: Kristopher | C7: Borodiansky | D7: Borodiansky, Kristopher | E7: 43857 | F7: Terminated | G7: 43886 | H7: Datadog | I7: Engineering | J7: Remote | K7: Yes | L7: 200- Datadog:220- Engineering | M7: Cost of Goods Sold:COGS- Travel Expenses: | N7: Cost of Goods Sold:COGS- Personnel Expense: | O7: =B7&" "&C7
