Workbook

Sheet Department Listing
A1: Employee # | B1: First Name | C1: Last Name | D1: Last name, First name | E1: Gender | F1: Hire Date | G1: Employment Status | H1: Employment Status: Date | I1: Division | J1: Department | K1: Location | L1: Job Title | M1: Teams | N1: Billable Status | O1: Employee Level | P1: State | Q1: QBO Department | R1: Prefix- Travel | S1: Prefix- Payroll
A2: 1 | B2: Tameem | C2: Hourani | D2: Hourani, Tameem | E2: Male | F2: 43651 | G2: Full-Time | H2: 45884 | I2: Operations | J2: Operations | K2: Boylston | L2: Principal | M2: 400- Synechron:410- Digital platforms G&A | N2: No | O2: L7 | P2: MA | Q2: =M2 -> 400- Synechron:410- Digital platforms G&A | R2: {=IF($N2="Yes","Cost of Goods Sold:COGS- Travel Expenses:",IF($N2="No",XLOOKUP($Q2,Key!$I:$I,Key!$J:$J),"Review Billable Status"))} -> General & Administrative:G&A- Travel Expenses: | S2: {=IF($N2="Yes","Cost of Goods Sold:COGS- Personnel Expense:",IF($N2="No",XLOOKUP($Q2,Key!$I:$I,Key!$K:$K),"Review Billable Status"))} -> General & Administrative:G&A- Personnel Expenses:
A3: 2 | B3: Jonathan | C3: Giara | D3: Giara, Jonathan | E3: Male | F3: 43647 | G3: Full-Time | H3: 43773 | I3: ServiceNow | J3: Engineering | K3: Remote | L3: ServiceNow Architect | M3: 300- ServiceNow:320- Engineering | N3: Yes | O3: L5 | P3: IL | Q3: =M3 -> 300- ServiceNow:320- Engineering | R3: {=IF($N3="Yes","Cost of Goods Sold:COGS- Travel Expenses:",IF($N3="No",XLOOKUP($Q3,Key!$I:$I,Key!$J:$J),"Review Billable Status"))} -> Cost of Goods Sold:COGS- Travel Expenses: | S3: {=IF($N3="Yes","Cost of Goods Sold:COGS- Personnel Expense:",IF($N3="No",XLOOKUP($Q3,Key!$I:$I,Key!$K:$K),"Review Billable Status"))} -> Cost of Goods Sold:COGS- Personnel Expense:
A4: 3 | B4: Connor | C4: Brackett | D4: Brackett, Connor | E4: Male | F4: 43773 | G4: Full-Time | H4: 43773 | I4: ServiceNow | J4: Sales | K4: Boylston | L4: Director of Sales | M4: 300- ServiceNow:330- Sales | N4: No | O4: L5 | P4: MA | Q4: =M4 -> 300- ServiceNow:330- Sales | R4: {=IF($N4="Yes","Cost of Goods Sold:COGS- Travel Expenses:",IF($N4="No",XLOOKUP($Q4,Key!$I:$I,Key!$J:$J),"Review Billable Status"))} -> Sales & Marketing:Sales & Marketing- Travel Expenses: | S4: {=IF($N4="Yes","Cost of Goods Sold:COGS- Personnel Expense:",IF($N4="No",XLOOKUP($Q4,Key!$I:$I,Key!$K:$K),"Review Billable Status"))} -> Sales & Marketing:Sales & Marketing- Personnel Expenses:
A5: 4 | B5: Jeffrey | C5: Mu | D5: Mu, Jeffrey | E5: Male | F5: 43754 | G5: Full-Time | H5: 43754 | I5: ServiceNow | J5: Engineering | K5: Boylston | L5: Sr ServiceNow Engineer | M5: 300- ServiceNow:320- Engineering | N5: Yes | O5: L3 | P5: NY | Q5: =M5 -> 300- ServiceNow:320- Engineering | R5: {=IF($N5="Yes","Cost of Goods Sold:COGS- Travel Expenses:",IF($N5="No",XLOOKUP($Q5,Key!$I:$I,Key!$J:$J),"Review Billable Status"))} -> Cost of Goods Sold:COGS- Travel Expenses: | S5: {=IF($N5="Yes","Cost of Goods Sold:COGS- Personnel Expense:",IF($N5="No",XLOOKUP($Q5,Key!$I:$I,Key!$K:$K),"Review Billable Status"))} -> Cost of Goods Sold:COGS- Personnel Expense:
A6: 7 | B6: Erik | C6: Williams | D6: Williams, Erik | E6: Male | F6: 43885 | G6: Full-Time | H6: 43885 | I6: Operations | J6: Strategy | K6: Remote | L6: Sr Engagement Manager | M6: 400- Synechron:410- Digital platforms G&A | N6: Yes | O6: L4 | P6: NH | Q6: =M6 -> 400- Synechron:410- Digital platforms G&A | R6: {=IF($N6="Yes","Cost of Goods Sold:COGS- Travel Expenses:",IF($N6="No",XLOOKUP($Q6,Key!$I:$I,Key!$J:$J),"Review Billable Status"))} -> Cost of Goods Sold:COGS- Travel Expenses: | S6: {=IF($N6="Yes","Cost of Goods Sold:COGS- Personnel Expense:",IF($N6="No",XLOOKUP($Q6,Key!$I:$I,Key!$K:$K),"Review Billable Status"))} -> Cost of Goods Sold:COGS- Personnel Expense:
A7: 8 | B7: Logan | C7: Rohloff | D7: Rohloff, Logan | E7: Male | F7: 43906 | G7: Full-Time | H7: 43906 | I7: Datadog | J7: Engineering | K7: Boylston | L7: Sr Engineering Manager - Datadog | M7: 200- Datadog:230- Sales | N7: Yes | O7: L4 | P7: MA | Q7: =M7 -> 200- Datadog:230- Sales | R7: {=IF($N7="Yes","Cost of Goods Sold:COGS- Travel Expenses:",IF($N7="No",XLOOKUP($Q7,Key!$I:$I,Key!$J:$J),"Review Billable Status"))} -> Cost of Goods Sold:COGS- Travel Expenses: | S7: {=IF($N7="Yes","Cost of Goods Sold:COGS- Personnel Expense:",IF($N7="No",XLOOKUP($Q7,Key!$I:$I,Key!$K:$K),"Review Billable Status"))} -> Cost of Goods Sold:COGS- Personnel Expense:
A8: 9 | B8: Reese | C8: Boisse | D8: Boisse, Reese | E8: Male | F8: 43927 | G8: Full-Time | H8: 43927 | I8: ServiceNow | J8: Sales | K8: Boylston | L8: Sr Solutions Engineer | M8: 300- ServiceNow:330- Sales | N8: No | O8: L3 | P8: MA | Q8: =M8 -> 300- ServiceNow:330- Sales | R8: {=IF($N8="Yes","Cost of Goods Sold:COGS- Travel Expenses:",IF($N8="No",XLOOKUP($Q8,Key!$I:$I,Key!$J:$J),"Review Billable Status"))} -> Sales & Marketing:Sales & Marketing- Travel Expenses: | S8: {=IF($N8="Yes","Cost of Goods Sold:COGS- Personnel Expense:",IF($N8="No",XLOOKUP($Q8,Key!$I:$I,Key!$K:$K),"Review Billable Status"))} -> Sales & Marketing:Sales & Marketing- Personnel Expenses:
A9: 10 | B9: Reuben | C9: Stump | D9: Stump, Reuben | E9: Male | F9: 43985 | G9: Full-Time | H9: 43985 | I9: Datadog | J9: Engineering | K9: Remote | L9: Principal Cloud Architect | M9: 200- Datadog:220- Engineering | N9: Yes | O9: L5 | P9: PA | Q9: =M9 -> 200- Datadog:220- Engineering | R9: {=IF($N9="Yes","Cost of Goods Sold:COGS- Travel Expenses:",IF($N9="No",XLOOKUP($Q9,Key!$I:$I,Key!$J:$J),"Review Billable Status"))} -> Cost of Goods Sold:COGS- Travel Expenses: | S9: {=IF($N9="Yes","Cost of Goods Sold:COGS- Personnel Expense:",IF($N9="No",XLOOKUP($Q9,Key!$I:$I,Key!$K:$K),"Review Billable Status"))} -> Cost of Goods Sold:COGS- Personnel Expense:
A10: 12 | B10: Elias | C10: Kapetanopoulos | D10: Kapetanopoulos, Elias | E10: Male | F10: 44060 | G10: Full-Time | H10: 44060 | I10: ServiceNow | J10: Engineering | K10: Boylston | L10: Director of Engineering - ServiceNow | M10: 300- ServiceNow:320- Engineering | N10: No | O10: L5 | P10: MA | Q10: =M10 -> 300- ServiceNow:320- Engineering | R10: {=IF($N10="Yes","Cost of Goods Sold:COGS- Travel Expenses:",IF($N10="No",XLOOKUP($Q10,Key!$I:$I,Key!$J:$J),"Review Billable Status"))} -> General & Administrative:G&A- Travel Expenses: | S10: {=IF($N10="Yes","Cost of Goods Sold:COGS- Personnel Expense:",IF($N10="No",XLOOKUP($Q10,Key!$I:$I,Key!$K:$K),"Review Billable Status"))} -> General & Administrative:G&A- Personnel Expenses:
A11: 14 | B11: Christian | C11: Moua | D11: Moua, Christian | E11: Male | F11: 44088 | G11: Full-Time | H11: 44088 | I11: ServiceNow | J11: Engineering | K11: Boylston | L11: ServiceNow Engineer | M11: 300- ServiceNow:320- Engineering | N11: Yes | O11: L2 | P11: RI | Q11: =M11 -> 300- ServiceNow:320- Engineering | R11: {=IF($N11="Yes","Cost of Goods Sold:COGS- Travel Expenses:",IF($N11="No",XLOOKUP($Q11,Key!$I:$I,Key!$J:$J),"Review Billable Status"))} -> Cost of Goods Sold:COGS- Travel Expenses: | S11: {=IF($N11="Yes","Cost of Goods Sold:COGS- Personnel Expense:",IF($N11="No",XLOOKUP($Q11,Key!$I:$I,Key!$K:$K),"Review Billable Status"))} -> Cost of Goods Sold:COGS- Personnel Expense:
A12: 15 | B12: Jesse | C12: Eddy | D12: Eddy, Jesse | E12: Male | F12: 44102 | G12: Full-Time | H12: 44102 | I12: Datadog | J12: Sales | K12: Boylston | L12: Sr Account Executive | M12: 200- Datadog:230- Sales | N12: No | O12: L3 | P12: MA | Q12: =M12 -> 200- Datadog:230- Sales | R12: {=IF($N12="Yes","Cost of Goods Sold:COGS- Travel Expenses:",IF($N12="No",XLOOKUP($Q12,Key!$I:$I,Key!$J:$J),"Review Billable Status"))} -> Sales & Marketing:Sales & Marketing- Travel Expenses: | S12: {=IF($N12="Yes","Cost of Goods Sold:COGS- Personnel Expense:",IF($N12="No",XLOOKUP($Q12,Key!$I:$I,Key!$K:$K),"Review Billable Status"))} -> Sales & Marketing:Sales & Marketing- Personnel Expenses:
A13: 18 | B13: Tomas | C13: Cespedes | D13: Cespedes, Tomas | E13: Male | F13: 44151 | G13: Full-Time | H13: 44151 | I13: Datadog | J13: Sales | K13: Boylston | L13: Sr Solutions Engineer | M13: 200- Datadog:230- Sales | N13: No | O13: L4 | P13: MA | Q13: =M13 -> 200- Datadog:230- Sales | R13: {=IF($N13="Yes","Cost of Goods Sold:COGS- Travel Expenses:",IF($N13="No",XLOOKUP($Q13,Key!$I:$I,Key!$J:$J),"Review Billable Status"))} -> Sales & Marketing:Sales & Marketing- Travel Expenses: | S13: {=IF($N13="Yes","Cost of Goods Sold:COGS- Personnel Expense:",IF($N13="No",XLOOKUP($Q13,Key!$I:$I,Key!$K:$K),"Review Billable Status"))} -> Sales & Marketing:Sales & Marketing- Personnel Expenses:
... A160: 269 | B160: Brian | C160: McGonigal | D160: McGonigal, Brian | E160: Male | F160: 46118 | G160: Full-Time | H160: 46118 | I160: ServiceNow | J160: Sales | K160: Remote | L160: Account Executive | M160: 300- ServiceNow:330- Sales | N160: No | O160: L3 | P160: NJ | Q160: =M160 -> 300- ServiceNow:330- Sales | R160: {=IF($N160="Yes","Cost of Goods Sold:COGS- Travel Expenses:",IF($N160="No",XLOOKUP($Q160,Key!$I:$I,Key!$J:$J),"Review Billable Status"))} -> Sales & Marketing:Sales & Marketing- Travel Expenses: | S160: {=IF($N160="Yes","Cost of Goods Sold:COGS- Personnel Expense:",IF($N160="No",XLOOKUP($Q160,Key!$I:$I,Key!$K:$K),"Review Billable Status"))} -> Sales & Marketing:Sales & Marketing- Personnel Expenses:
A161: 270 | B161: James | C161: Dean | D161: Dean, James | F161: 46209 | G161: Full-Time | H161: 46209 | I161: Datadog | J161: Sales | K161: Non-US | L161: Principal Solutions Engineer | M161: 200- Datadog:230- Sales | N161: No | O161: L4 | P161: Kent | Q161: =M161 -> 200- Datadog:230- Sales | R161: {=IF($N161="Yes","Cost of Goods Sold:COGS- Travel Expenses:",IF($N161="No",XLOOKUP($Q161,Key!$I:$I,Key!$J:$J),"Review Billable Status"))} -> Sales & Marketing:Sales & Marketing- Travel Expenses: | S161: {=IF($N161="Yes","Cost of Goods Sold:COGS- Personnel Expense:",IF($N161="No",XLOOKUP($Q161,Key!$I:$I,Key!$K:$K),"Review Billable Status"))} -> Sales & Marketing:Sales & Marketing- Personnel Expenses:
A162: 271 | B162: Marsha | C162: Whitman | D162: Whitman, Marsha | E162: Female | F162: 46133 | G162: Full-Time | H162: 46133 | I162: ServiceNow | J162: Project Management | K162: Boylston | L162: Senior Program Manager | M162: 300- ServiceNow:310- Delivery | N162: Yes | O162: L4 | P162: MA | Q162: =M162 -> 300- ServiceNow:310- Delivery | R162: {=IF($N162="Yes","Cost of Goods Sold:COGS- Travel Expenses:",IF($N162="No",XLOOKUP($Q162,Key!$I:$I,Key!$J:$J),"Review Billable Status"))} -> Cost of Goods Sold:COGS- Travel Expenses: | S162: {=IF($N162="Yes","Cost of Goods Sold:COGS- Personnel Expense:",IF($N162="No",XLOOKUP($Q162,Key!$I:$I,Key!$K:$K),"Review Billable Status"))} -> Cost of Goods Sold:COGS- Personnel Expense:
A163: 273 | B163: Michael | C163: Button | D163: Button, Michael | E163: Male | F163: 46153 | G163: Paid Intern | H163: 46153 | I163: Operations | J163: Operations | K163: Boylston | L163: IT Support | M163: 100- Operations:110- G&A | N163: No | O163: L0 | P163: MA | Q163: =M163 -> 100- Operations:110- G&A | R163: {=IF($N163="Yes","Cost of Goods Sold:COGS- Travel Expenses:",IF($N163="No",XLOOKUP($Q163,Key!$I:$I,Key!$J:$J),"Review Billable Status"))} -> General & Administrative:G&A- Travel Expenses: | S163: {=IF($N163="Yes","Cost of Goods Sold:COGS- Personnel Expense:",IF($N163="No",XLOOKUP($Q163,Key!$I:$I,Key!$K:$K),"Review Billable Status"))} -> General & Administrative:G&A- Personnel Expenses:
A164: 274 | B164: Robin | C164: Wiggs | D164: Wiggs, Robin | E164: Male | F164: 46132 | G164: Full-Time | H164: 46132 | I164: Datadog | J164: Engineering | K164: Non-US | L164: Sr Cloud Engineer | M164: 200- Datadog:220- Engineering | N164: Yes | O164: L3 | P164: West Sussex | Q164: =M164 -> 200- Datadog:220- Engineering | R164: {=IF($N164="Yes","Cost of Goods Sold:COGS- Travel Expenses:",IF($N164="No",XLOOKUP($Q164,Key!$I:$I,Key!$J:$J),"Review Billable Status"))} -> Cost of Goods Sold:COGS- Travel Expenses: | S164: {=IF($N164="Yes","Cost of Goods Sold:COGS- Personnel Expense:",IF($N164="No",XLOOKUP($Q164,Key!$I:$I,Key!$K:$K),"Review Billable Status"))} -> Cost of Goods Sold:COGS- Personnel Expense:
A165: 275 | B165: John | C165: Fennell | D165: Fennell, John | E165: Male | F165: 46160 | G165: Full-Time | H165: 46160 | I165: Operations | J165: Marketing | K165: Boylston | L165: Associate Brand Manager | M165: 100- Operations:120- Marketing | N165: No | O165: L2 | P165: MA | Q165: =M165 -> 100- Operations:120- Marketing | R165: {=IF($N165="Yes","Cost of Goods Sold:COGS- Travel Expenses:",IF($N165="No",XLOOKUP($Q165,Key!$I:$I,Key!$J:$J),"Review Billable Status"))} -> Sales & Marketing:Sales & Marketing- Travel Expenses: | S165: {=IF($N165="Yes","Cost of Goods Sold:COGS- Personnel Expense:",IF($N165="No",XLOOKUP($Q165,Key!$I:$I,Key!$K:$K),"Review Billable Status"))} -> Sales & Marketing:Sales & Marketing- Personnel Expenses:
A166: 276 | B166: Vivian | C166: Wu | D166: Wu, Vivian | E166: Female | F166: 46153 | G166: Full-Time | H166: 46153 | I166: Operations | J166: People Operations | K166: Boylston | L166: People Ops Generalist | M166: 100- Operations:110- G&A | N166: No | O166: L1 | P166: MA | Q166: =M166 -> 100- Operations:110- G&A | R166: {=IF($N166="Yes","Cost of Goods Sold:COGS- Travel Expenses:",IF($N166="No",XLOOKUP($Q166,Key!$I:$I,Key!$J:$J),"Review Billable Status"))} -> General & Administrative:G&A- Travel Expenses: | S166: {=IF($N166="Yes","Cost of Goods Sold:COGS- Personnel Expense:",IF($N166="No",XLOOKUP($Q166,Key!$I:$I,Key!$K:$K),"Review Billable Status"))} -> General & Administrative:G&A- Personnel Expenses:
A167: 277 | B167: Jackson | C167: Mendes | D167: Mendes, Jackson | E167: Male | F167: 46160 | G167: Paid Intern | H167: 46160 | I167: ServiceNow | J167: Engineering | K167: Boylston | L167: ServiceNow Intern | M167: 300- ServiceNow:320- Engineering | N167: No | O167: L0 | P167: CT | Q167: =M167 -> 300- ServiceNow:320- Engineering | R167: {=IF($N167="Yes","Cost of Goods Sold:COGS- Travel Expenses:",IF($N167="No",XLOOKUP($Q167,Key!$I:$I,Key!$J:$J),"Review Billable Status"))} -> General & Administrative:G&A- Travel Expenses: | S167: {=IF($N167="Yes","Cost of Goods Sold:COGS- Personnel Expense:",IF($N167="No",XLOOKUP($Q167,Key!$I:$I,Key!$K:$K),"Review Billable Status"))} -> General & Administrative:G&A- Personnel Expenses:
A168: 278 | B168: Samantha | C168: Purpura | D168: Purpura, Samantha | E168: Female | F168: 46153 | G168: Full-Time | H168: 46153 | I168: Operations | J168: Operations | K168: Boylston | L168: Platform Operations Coordinator | M168: 400- Synechron:410- Digital platforms G&A | N168: No | O168: L1 | P168: MA | Q168: =M168 -> 400- Synechron:410- Digital platforms G&A | R168: {=IF($N168="Yes","Cost of Goods Sold:COGS- Travel Expenses:",IF($N168="No",XLOOKUP($Q168,Key!$I:$I,Key!$J:$J),"Review Billable Status"))} -> General & Administrative:G&A- Travel Expenses: | S168: {=IF($N168="Yes","Cost of Goods Sold:COGS- Personnel Expense:",IF($N168="No",XLOOKUP($Q168,Key!$I:$I,Key!$K:$K),"Review Billable Status"))} -> General & Administrative:G&A- Personnel Expenses:
A169: 283 | B169: Jamie | C169: Cosgrove | D169: Cosgrove, Jamie | F169: 46140 | G169: Contractor/Consultant | H169: 46140 | I169: Operations | J169: Operations | K169: Boylston | M169: 100- Operations:110- G&A | N169: No | P169: MA | Q169: =M169 -> 100- Operations:110- G&A | R169: {=IF($N169="Yes","Cost of Goods Sold:COGS- Travel Expenses:",IF($N169="No",XLOOKUP($Q169,Key!$I:$I,Key!$J:$J),"Review Billable Status"))} -> General & Administrative:G&A- Travel Expenses: | S169: {=IF($N169="Yes","Cost of Goods Sold:COGS- Personnel Expense:",IF($N169="No",XLOOKUP($Q169,Key!$I:$I,Key!$K:$K),"Review Billable Status"))} -> General & Administrative:G&A- Personnel Expenses:
A170: 284 | B170: Lenny | C170: Caraballo | D170: Caraballo, Lenny | F170: 46181 | G170: Full-Time | H170: 46181 | I170: Datadog | J170: MDD | K170: Boylston | L170: Managed Datadog Engineer | M170: 200- Datadog:220- Engineering | N170: No | O170: L2 | P170: MA | Q170: =M170 -> 200- Datadog:220- Engineering | R170: {=IF($N170="Yes","Cost of Goods Sold:COGS- Travel Expenses:",IF($N170="No",XLOOKUP($Q170,Key!$I:$I,Key!$J:$J),"Review Billable Status"))} -> General & Administrative:G&A- Travel Expenses: | S170: {=IF($N170="Yes","Cost of Goods Sold:COGS- Personnel Expense:",IF($N170="No",XLOOKUP($Q170,Key!$I:$I,Key!$K:$K),"Review Billable Status"))} -> General & Administrative:G&A- Personnel Expenses:
A171: 285 | B171: Anthony | C171: Nguyen | D171: Nguyen, Anthony | F171: 46209 | I171: Datadog | J171: Engineering | M171: 200- Datadog:220- Engineering | N171: No | P171: VIC | Q171: =M171 -> 200- Datadog:220- Engineering | R171: {=IF($N171="Yes","Cost of Goods Sold:COGS- Travel Expenses:",IF($N171="No",XLOOKUP($Q171,Key!$I:$I,Key!$J:$J),"Review Billable Status"))} -> General & Administrative:G&A- Travel Expenses: | S171: {=IF($N171="Yes","Cost of Goods Sold:COGS- Personnel Expense:",IF($N171="No",XLOOKUP($Q171,Key!$I:$I,Key!$K:$K),"Review Billable Status"))} -> General & Administrative:G&A- Personnel Expenses:
A172: 286 | B172: Paulina | C172: Mateo | D172: Mateo, Paulina | F172: 46181 | G172: Full-Time | H172: 46181 | I172: ServiceNow | J172: Project Management | K172: Boylston | L172: OCM Specialist | M172: 300- ServiceNow:310- Delivery | N172: Yes | O172: L1 | P172: MA | Q172: =M172 -> 300- ServiceNow:310- Delivery | R172: {=IF($N172="Yes","Cost of Goods Sold:COGS- Travel Expenses:",IF($N172="No",XLOOKUP($Q172,Key!$I:$I,Key!$J:$J),"Review Billable Status"))} -> Cost of Goods Sold:COGS- Travel Expenses: | S172: {=IF($N172="Yes","Cost of Goods Sold:COGS- Personnel Expense:",IF($N172="No",XLOOKUP($Q172,Key!$I:$I,Key!$K:$K),"Review Billable Status"))} -> Cost of Goods Sold:COGS- Personnel Expense:
A173: 287 | B173: Kean | C173: Weng, Yap | D173: Weng, Yap, Kean | F173: 46195 | N173: Yes | P173: AB | Q173: =M173 | R173: {=IF($N173="Yes","Cost of Goods Sold:COGS- Travel Expenses:",IF($N173="No",XLOOKUP($Q173,Key!$I:$I,Key!$J:$J),"Review Billable Status"))} -> Cost of Goods Sold:COGS- Travel Expenses: | S173: {=IF($N173="Yes","Cost of Goods Sold:COGS- Personnel Expense:",IF($N173="No",XLOOKUP($Q173,Key!$I:$I,Key!$K:$K),"Review Billable Status"))} -> Cost of Goods Sold:COGS- Personnel Expense:
A174: 289 | B174: Jared | C174: Kennedy | D174: Kennedy, Jared | F174: 46212 | I174: Datadog | J174: Sales | M174: 200- Datadog:230- Sales | N174: No | P174: NSW | Q174: =M174 -> 200- Datadog:230- Sales | R174: {=IF($N174="Yes","Cost of Goods Sold:COGS- Travel Expenses:",IF($N174="No",XLOOKUP($Q174,Key!$I:$I,Key!$J:$J),"Review Billable Status"))} -> Sales & Marketing:Sales & Marketing- Travel Expenses: | S174: {=IF($N174="Yes","Cost of Goods Sold:COGS- Personnel Expense:",IF($N174="No",XLOOKUP($Q174,Key!$I:$I,Key!$K:$K),"Review Billable Status"))} -> Sales & Marketing:Sales & Marketing- Personnel Expenses:

Sheet HC by Month
S1: COR | T1: =SUMIFS(T$13:T$1006,$S$13:$S$1006,$S1) -> 36 | U1: =SUMIFS(U$13:U$1006,$S$13:$S$1006,$S1) -> 36 | V1: =SUMIFS(V$13:V$1006,$S$13:$S$1006,$S1) -> 36 | W1: =SUMIFS(W$13:W$1006,$S$13:$S$1006,$S1) -> 37 | X1: =SUMIFS(X$13:X$1006,$S$13:$S$1006,$S1) -> 39 | Y1: =SUMIFS(Y$13:Y$1006,$S$13:$S$1006,$S1) -> 42 | Z1: =SUMIFS(Z$13:Z$1006,$S$13:$S$1006,$S1) -> 43 | AA1: =SUMIFS(AA$13:AA$1006,$S$13:$S$1006,$S1) -> 44 | ... BA1: =SUMIFS(BA$13:BA$1006,$S$13:$S$1006,$S1) -> 112
S2: S&M | T2: =SUMIFS(T$13:T$1006,$S$13:$S$1006,$S2) -> 16 | U2: =SUMIFS(U$13:U$1006,$S$13:$S$1006,$S2) -> 16 | V2: =SUMIFS(V$13:V$1006,$S$13:$S$1006,$S2) -> 18 | W2: =SUMIFS(W$13:W$1006,$S$13:$S$1006,$S2) -> 19 | X2: =SUMIFS(X$13:X$1006,$S$13:$S$1006,$S2) -> 20 | Y2: =SUMIFS(Y$13:Y$1006,$S$13:$S$1006,$S2) -> 21 | Z2: =SUMIFS(Z$13:Z$1006,$S$13:$S$1006,$S2) -> 21 | AA2: =SUMIFS(AA$13:AA$1006,$S$13:$S$1006,$S2) -> 21 | ... BA2: =SUMIFS(BA$13:BA$1006,$S$13:$S$1006,$S2) -> 32
S3: G&A | T3: =SUMIFS(T$13:T$1006,$S$13:$S$1006,$S3) -> 8 | U3: =SUMIFS(U$13:U$1006,$S$13:$S$1006,$S3) -> 8 | V3: =SUMIFS(V$13:V$1006,$S$13:$S$1006,$S3) -> 8 | W3: =SUMIFS(W$13:W$1006,$S$13:$S$1006,$S3) -> 8 | X3: =SUMIFS(X$13:X$1006,$S$13:$S$1006,$S3) -> 8 | Y3: =SUMIFS(Y$13:Y$1006,$S$13:$S$1006,$S3) -> 9 | Z3: =SUMIFS(Z$13:Z$1006,$S$13:$S$1006,$S3) -> 9 | AA3: =SUMIFS(AA$13:AA$1006,$S$13:$S$1006,$S3) -> 9 | ... BA3: =SUMIFS(BA$13:BA$1006,$S$13:$S$1006,$S3) -> 18
S4: Pd Intern | T4: =SUMIFS(T$13:T$1006,$S$13:$S$1006,$S4) -> 0 | U4: =SUMIFS(U$13:U$1006,$S$13:$S$1006,$S4) -> 0 | V4: =SUMIFS(V$13:V$1006,$S$13:$S$1006,$S4) -> 0 | W4: =SUMIFS(W$13:W$1006,$S$13:$S$1006,$S4) -> 0 | X4: =SUMIFS(X$13:X$1006,$S$13:$S$1006,$S4) -> 0 | Y4: =SUMIFS(Y$13:Y$1006,$S$13:$S$1006,$S4) -> 0 | Z4: =SUMIFS(Z$13:Z$1006,$S$13:$S$1006,$S4) -> 0 | AA4: =SUMIFS(AA$13:AA$1006,$S$13:$S$1006,$S4) -> 0 | ... BA4: =SUMIFS(BA$13:BA$1006,$S$13:$S$1006,$S4) -> 6
S5: Contractor | T5: =SUMIFS(T$13:T$1006,$S$13:$S$1006,$S5) -> 0 | U5: =SUMIFS(U$13:U$1006,$S$13:$S$1006,$S5) -> 0 | V5: =SUMIFS(V$13:V$1006,$S$13:$S$1006,$S5) -> 0 | W5: =SUMIFS(W$13:W$1006,$S$13:$S$1006,$S5) -> 0 | X5: =SUMIFS(X$13:X$1006,$S$13:$S$1006,$S5) -> 0 | Y5: =SUMIFS(Y$13:Y$1006,$S$13:$S$1006,$S5) -> 0 | Z5: =SUMIFS(Z$13:Z$1006,$S$13:$S$1006,$S5) -> 0 | AA5: =SUMIFS(AA$13:AA$1006,$S$13:$S$1006,$S5) -> 0 | ... BA5: =SUMIFS(BA$13:BA$1006,$S$13:$S$1006,$S5) -> 1
S7: Ck | T7: =SUM(T$13:T$1006)-SUM(T$1:T$5) -> 2 | U7: =SUM(U$13:U$1006)-SUM(U$1:U$5) -> 2 | V7: =SUM(V$13:V$1006)-SUM(V$1:V$5) -> 2 | W7: =SUM(W$13:W$1006)-SUM(W$1:W$5) -> 2 | X7: =SUM(X$13:X$1006)-SUM(X$1:X$5) -> 2 | Y7: =SUM(Y$13:Y$1006)-SUM(Y$1:Y$5) -> 2 | Z7: =SUM(Z$13:Z$1006)-SUM(Z$1:Z$5) -> 2 | AA7: =SUM(AA$13:AA$1006)-SUM(AA$1:AA$5) -> 2 | ... BA7: =SUM(BA$13:BA$1006)-SUM(BA$1:BA$5) -> 4
S8: Termed | AK8: 4 | AL8: 3 | AM8: 0 | AN8: 2 | AO8: 3 | AP8: 3 | AQ8: 0 | AR8: 1 | AS8: 3 | AT8: 3
S9: Attrition | AO9: =AO8/SUM(AO1:AO3) -> 0.022222222 | AP9: =AP8/SUM(AP1:AP3) -> 0.021428571 | AQ9: =AQ8/SUM(AQ1:AQ3) -> 0 | AR9: =AR8/SUM(AR1:AR3) -> 0.0066225166 | AS9: =AS8/SUM(AS1:AS3) -> 0.019354839 | AT9: =AT8/SUM(AT1:AT3) -> 0.018987342 | AU9: =AU8/SUM(AU1:AU3) -> 0 | AV9: =AV8/SUM(AV1:AV3) -> 0 | ... BA9: =BA8/SUM(BA1:BA3) -> 0
S10: Voluntary | AN10: 1 | AO10: 2 | AP10: 1 | AQ10: 0 | AR10: 1 | AS10: 1 | AT10: 3
S11: MoM Chg | T11: =SUM(T1:T5)-SUM(S1:S5) -> 60 | U11: =SUM(U1:U5)-SUM(T1:T5) -> 0 | V11: =SUM(V1:V5)-SUM(U1:U5) -> 2 | W11: =SUM(W1:W5)-SUM(V1:V5) -> 2 | X11: =SUM(X1:X5)-SUM(W1:W5) -> 3 | Y11: =SUM(Y1:Y5)-SUM(X1:X5) -> 5 | Z11: =SUM(Z1:Z5)-SUM(Y1:Y5) -> 1 | AA11: =SUM(AA1:AA5)-SUM(Z1:Z5) -> 1 | ... BA11: =SUM(BA1:BA5)-SUM(AZ1:AZ5) -> 0
A12: Employee # | B12: First Name | C12: Last Name | D12: Last name, First name | E12: Gender | F12: Hire Date | G12: Employment Status | H12: Employment Status: Date | I12: Division | J12: Department | K12: Location | L12: Job Title | M12: Billable Status | N12: Employee Level | O12: State | P12: QBO Department | Q12: Prefix- Travel | R12: Prefix- Payroll | S12: Dept | T12: 45382 | U12: 45412 | V12: 45443 | W12: 45473 | X12: 45504 | Y12: 45535 | Z12: 45565 | AA12: 45596 | AB12: 45626 | AC12: 45657 | AD12: 45688 | AE12: 45716 | AF12: 45747 | AG12: 45777 | AH12: 45808 | AI12: 45838 | AJ12: 45869 | AK12: 45900 | AL12: 45930 | AM12: 45961 | AN12: 45991 | AO12: 46022 | AP12: 46053 | AQ12: 46081 | AR12: 46112 | AS12: 46142 | AT12: 46173 | AU12: 46203 | AV12: 46234 | AW12: 46265 | AX12: 46295 | AY12: 46326 | AZ12: 46356 | BA12: 46387
A13: 1 | B13: Tameem | C13: Hourani | D13: Hourani, Tameem | E13: Male | F13: 43651 | G13: Full-Time | H13: 45884 | I13: Operations | J13: Operations | K13: Boylston | L13: Principal | M13: No | N13: L7 | O13: MA | P13: 400- Synechron:410- Digital platforms G&A | Q13: {=IF($M13="Yes","Cost of Goods Sold:COGS- Travel Expenses:",IF($M13="No",XLOOKUP($P13,Key!$I:$I,Key!$J:$J),"Review Billable Status"))} -> General & Administrative:G&A- Travel Expenses: | R13: {=IF($M13="Yes","Cost of Goods Sold:COGS- Personnel Expense:",IF($M13="No",XLOOKUP($P13,Key!$I:$I,Key!$K:$K),"Review Billable Status"))} -> General & Administrative:G&A- Personnel Expenses: | S13: {=IF($G13="Paid Intern","PD Intern",IF($G13="Contractor/Consultant","Contractor",XLOOKUP(M13&P13,Key!$M:$M,Key!$L:$L)))} -> G&A | T13: =IF(OR($F13>T$12,AND($G13="Terminated",T$12>=$H13)),0,1) -> 1 | U13: =IF(OR($F13>U$12,AND($G13="Terminated",U$12>=$H13)),0,1) -> 1 | V13: =IF(OR($F13>V$12,AND($G13="Terminated",V$12>=$H13)),0,1) -> 1 | W13: =IF(OR($F13>W$12,AND($G13="Terminated",W$12>=$H13)),0,1) -> 1 | X13: =IF(OR($F13>X$12,AND($G13="Terminated",X$12>=$H13)),0,1) -> 1 | Y13: =IF(OR($F13>Y$12,AND($G13="Terminated",Y$12>=$H13)),0,1) -> 1 | Z13: =IF(OR($F13>Z$12,AND($G13="Terminated",Z$12>=$H13)),0,1) -> 1 | AA13: =IF(OR($F13>AA$12,AND($G13="Terminated",AA$12>=$H13)),0,1) -> 1 | ... BA13: =IF(OR($F13>BA$12,AND($G13="Terminated",BA$12>=$H13)),0,1) -> 1
A14: 2 | B14: Jonathan | C14: Giara | D14: Giara, Jonathan | E14: Male | F14: 43647 | G14: Full-Time | H14: 43773 | I14: ServiceNow | J14: Engineering | K14: Remote | L14: ServiceNow Architect | M14: Yes | N14: L5 | O14: IL | P14: 300- ServiceNow:320- Engineering | Q14: {=IF($M14="Yes","Cost of Goods Sold:COGS- Travel Expenses:",IF($M14="No",XLOOKUP($P14,Key!$I:$I,Key!$J:$J),"Review Billable Status"))} -> Cost of Goods Sold:COGS- Travel Expenses: | R14: {=IF($M14="Yes","Cost of Goods Sold:COGS- Personnel Expense:",IF($M14="No",XLOOKUP($P14,Key!$I:$I,Key!$K:$K),"Review Billable Status"))} -> Cost of Goods Sold:COGS- Personnel Expense: | S14: {=IF($G14="Paid Intern","PD Intern",IF($G14="Contractor/Consultant","Contractor",XLOOKUP(M14&P14,Key!$M:$M,Key!$L:$L)))} -> COR | T14: =IF(OR($F14>T$12,AND($G14="Terminated",T$12>=$H14)),0,1) -> 1 | U14: =IF(OR($F14>U$12,AND($G14="Terminated",U$12>=$H14)),0,1) -> 1 | V14: =IF(OR($F14>V$12,AND($G14="Terminated",V$12>=$H14)),0,1) -> 1 | W14: =IF(OR($F14>W$12,AND($G14="Terminated",W$12>=$H14)),0,1) -> 1 | X14: =IF(OR($F14>X$12,AND($G14="Terminated",X$12>=$H14)),0,1) -> 1 | Y14: =IF(OR($F14>Y$12,AND($G14="Terminated",Y$12>=$H14)),0,1) -> 1 | Z14: =IF(OR($F14>Z$12,AND($G14="Terminated",Z$12>=$H14)),0,1) -> 1 | AA14: =IF(OR($F14>AA$12,AND($G14="Terminated",AA$12>=$H14)),0,1) -> 1 | ... BA14: =IF(OR($F14>BA$12,AND($G14="Terminated",BA$12>=$H14)),0,1) -> 1
A15: 3 | B15: Connor | C15: Brackett | D15: Brackett, Connor | E15: Male | F15: 43773 | G15: Full-Time | H15: 43773 | I15: ServiceNow | J15: Sales | K15: Boylston | L15: Director of Sales | M15: No | N15: L5 | O15: MA | P15: 300- ServiceNow:330- Sales | Q15: {=IF($M15="Yes","Cost of Goods Sold:COGS- Travel Expenses:",IF($M15="No",XLOOKUP($P15,Key!$I:$I,Key!$J:$J),"Review Billable Status"))} -> Sales & Marketing:Sales & Marketing- Travel Expenses: | R15: {=IF($M15="Yes","Cost of Goods Sold:COGS- Personnel Expense:",IF($M15="No",XLOOKUP($P15,Key!$I:$I,Key!$K:$K),"Review Billable Status"))} -> Sales & Marketing:Sales & Marketing- Personnel Expenses: | S15: {=IF($G15="Paid Intern","PD Intern",IF($G15="Contractor/Consultant","Contractor",XLOOKUP(M15&P15,Key!$M:$M,Key!$L:$L)))} -> S&M | T15: =IF(OR($F15>T$12,AND($G15="Terminated",T$12>=$H15)),0,1) -> 1 | U15: =IF(OR($F15>U$12,AND($G15="Terminated",U$12>=$H15)),0,1) -> 1 | V15: =IF(OR($F15>V$12,AND($G15="Terminated",V$12>=$H15)),0,1) -> 1 | W15: =IF(OR($F15>W$12,AND($G15="Terminated",W$12>=$H15)),0,1) -> 1 | X15: =IF(OR($F15>X$12,AND($G15="Terminated",X$12>=$H15)),0,1) -> 1 | Y15: =IF(OR($F15>Y$12,AND($G15="Terminated",Y$12>=$H15)),0,1) -> 1 | Z15: =IF(OR($F15>Z$12,AND($G15="Terminated",Z$12>=$H15)),0,1) -> 1 | AA15: =IF(OR($F15>AA$12,AND($G15="Terminated",AA$12>=$H15)),0,1) -> 1 | ... BA15: =IF(OR($F15>BA$12,AND($G15="Terminated",BA$12>=$H15)),0,1) -> 1
A16: 4 | B16: Jeffrey | C16: Mu | D16: Mu, Jeffrey | E16: Male | F16: 43754 | G16: Full-Time | H16: 43754 | I16: ServiceNow | J16: Engineering | K16: Boylston | L16: Sr ServiceNow Engineer | M16: Yes | N16: L3 | O16: NY | P16: 300- ServiceNow:320- Engineering | Q16: {=IF($M16="Yes","Cost of Goods Sold:COGS- Travel Expenses:",IF($M16="No",XLOOKUP($P16,Key!$I:$I,Key!$J:$J),"Review Billable Status"))} -> Cost of Goods Sold:COGS- Travel Expenses: | R16: {=IF($M16="Yes","Cost of Goods Sold:COGS- Personnel Expense:",IF($M16="No",XLOOKUP($P16,Key!$I:$I,Key!$K:$K),"Review Billable Status"))} -> Cost of Goods Sold:COGS- Personnel Expense: | S16: {=IF($G16="Paid Intern","PD Intern",IF($G16="Contractor/Consultant","Contractor",XLOOKUP(M16&P16,Key!$M:$M,Key!$L:$L)))} -> COR | T16: =IF(OR($F16>T$12,AND($G16="Terminated",T$12>=$H16)),0,1) -> 1 | U16: =IF(OR($F16>U$12,AND($G16="Terminated",U$12>=$H16)),0,1) -> 1 | V16: =IF(OR($F16>V$12,AND($G16="Terminated",V$12>=$H16)),0,1) -> 1 | W16: =IF(OR($F16>W$12,AND($G16="Terminated",W$12>=$H16)),0,1) -> 1 | X16: =IF(OR($F16>X$12,AND($G16="Terminated",X$12>=$H16)),0,1) -> 1 | Y16: =IF(OR($F16>Y$12,AND($G16="Terminated",Y$12>=$H16)),0,1) -> 1 | Z16: =IF(OR($F16>Z$12,AND($G16="Terminated",Z$12>=$H16)),0,1) -> 1 | AA16: =IF(OR($F16>AA$12,AND($G16="Terminated",AA$12>=$H16)),0,1) -> 1 | ... BA16: =IF(OR($F16>BA$12,AND($G16="Terminated",BA$12>=$H16)),0,1) -> 1
A17: 7 | B17: Erik | C17: Williams | D17: Williams, Erik | E17: Male | F17: 43885 | G17: Full-Time | H17: 43885 | I17: Operations | J17: Strategy | K17: Remote | L17: Sr Engagement Manager | M17: Yes | N17: L4 | O17: NH | P17: 400- Synechron:410- Digital platforms G&A | Q17: {=IF($M17="Yes","Cost of Goods Sold:COGS- Travel Expenses:",IF($M17="No",XLOOKUP($P17,Key!$I:$I,Key!$J:$J),"Review Billable Status"))} -> Cost of Goods Sold:COGS- Travel Expenses: | R17: {=IF($M17="Yes","Cost of Goods Sold:COGS- Personnel Expense:",IF($M17="No",XLOOKUP($P17,Key!$I:$I,Key!$K:$K),"Review Billable Status"))} -> Cost of Goods Sold:COGS- Personnel Expense: | S17: {=IF($G17="Paid Intern","PD Intern",IF($G17="Contractor/Consultant","Contractor",XLOOKUP(M17&P17,Key!$M:$M,Key!$L:$L)))} -> #N/A | T17: =IF(OR($F17>T$12,AND($G17="Terminated",T$12>=$H17)),0,1) -> 1 | U17: =IF(OR($F17>U$12,AND($G17="Terminated",U$12>=$H17)),0,1) -> 1 | V17: =IF(OR($F17>V$12,AND($G17="Terminated",V$12>=$H17)),0,1) -> 1 | W17: =IF(OR($F17>W$12,AND($G17="Terminated",W$12>=$H17)),0,1) -> 1 | X17: =IF(OR($F17>X$12,AND($G17="Terminated",X$12>=$H17)),0,1) -> 1 | Y17: =IF(OR($F17>Y$12,AND($G17="Terminated",Y$12>=$H17)),0,1) -> 1 | Z17: =IF(OR($F17>Z$12,AND($G17="Terminated",Z$12>=$H17)),0,1) -> 1 | AA17: =IF(OR($F17>AA$12,AND($G17="Terminated",AA$12>=$H17)),0,1) -> 1 | ... BA17: =IF(OR($F17>BA$12,AND($G17="Terminated",BA$12>=$H17)),0,1) -> 1
A18: 8 | B18: Logan | C18: Rohloff | D18: Rohloff, Logan | E18: Male | F18: 43906 | G18: Full-Time | H18: 43906 | I18: Datadog | J18: Engineering | K18: Boylston | L18: Sr Engineering Manager - Datadog | M18: Yes | N18: L4 | O18: MA | P18: 200- Datadog:230- Sales | Q18: {=IF($M18="Yes","Cost of Goods Sold:COGS- Travel Expenses:",IF($M18="No",XLOOKUP($P18,Key!$I:$I,Key!$J:$J),"Review Billable Status"))} -> Cost of Goods Sold:COGS- Travel Expenses: | R18: {=IF($M18="Yes","Cost of Goods Sold:COGS- Personnel Expense:",IF($M18="No",XLOOKUP($P18,Key!$I:$I,Key!$K:$K),"Review Billable Status"))} -> Cost of Goods Sold:COGS- Personnel Expense: | S18: {=IF($G18="Paid Intern","PD Intern",IF($G18="Contractor/Consultant","Contractor",XLOOKUP(M18&P18,Key!$M:$M,Key!$L:$L)))} -> #N/A | T18: =IF(OR($F18>T$12,AND($G18="Terminated",T$12>=$H18)),0,1) -> 1 | U18: =IF(OR($F18>U$12,AND($G18="Terminated",U$12>=$H18)),0,1) -> 1 | V18: =IF(OR($F18>V$12,AND($G18="Terminated",V$12>=$H18)),0,1) -> 1 | W18: =IF(OR($F18>W$12,AND($G18="Terminated",W$12>=$H18)),0,1) -> 1 | X18: =IF(OR($F18>X$12,AND($G18="Terminated",X$12>=$H18)),0,1) -> 1 | Y18: =IF(OR($F18>Y$12,AND($G18="Terminated",Y$12>=$H18)),0,1) -> 1 | Z18: =IF(OR($F18>Z$12,AND($G18="Terminated",Z$12>=$H18)),0,1) -> 1 | AA18: =IF(OR($F18>AA$12,AND($G18="Terminated",AA$12>=$H18)),0,1) -> 1 | ... BA18: =IF(OR($F18>BA$12,AND($G18="Terminated",BA$12>=$H18)),0,1) -> 1
A19: 9 | B19: Reese | C19: Boisse | D19: Boisse, Reese | E19: Male | F19: 43927 | G19: Full-Time | H19: 43927 | I19: ServiceNow | J19: Sales | K19: Boylston | L19: Sr Solutions Engineer | M19: No | N19: L3 | O19: MA | P19: 300- ServiceNow:330- Sales | Q19: {=IF($M19="Yes","Cost of Goods Sold:COGS- Travel Expenses:",IF($M19="No",XLOOKUP($P19,Key!$I:$I,Key!$J:$J),"Review Billable Status"))} -> Sales & Marketing:Sales & Marketing- Travel Expenses: | R19: {=IF($M19="Yes","Cost of Goods Sold:COGS- Personnel Expense:",IF($M19="No",XLOOKUP($P19,Key!$I:$I,Key!$K:$K),"Review Billable Status"))} -> Sales & Marketing:Sales & Marketing- Personnel Expenses: | S19: {=IF($G19="Paid Intern","PD Intern",IF($G19="Contractor/Consultant","Contractor",XLOOKUP(M19&P19,Key!$M:$M,Key!$L:$L)))} -> S&M | T19: =IF(OR($F19>T$12,AND($G19="Terminated",T$12>=$H19)),0,1) -> 1 | U19: =IF(OR($F19>U$12,AND($G19="Terminated",U$12>=$H19)),0,1) -> 1 | V19: =IF(OR($F19>V$12,AND($G19="Terminated",V$12>=$H19)),0,1) -> 1 | W19: =IF(OR($F19>W$12,AND($G19="Terminated",W$12>=$H19)),0,1) -> 1 | X19: =IF(OR($F19>X$12,AND($G19="Terminated",X$12>=$H19)),0,1) -> 1 | Y19: =IF(OR($F19>Y$12,AND($G19="Terminated",Y$12>=$H19)),0,1) -> 1 | Z19: =IF(OR($F19>Z$12,AND($G19="Terminated",Z$12>=$H19)),0,1) -> 1 | AA19: =IF(OR($F19>AA$12,AND($G19="Terminated",AA$12>=$H19)),0,1) -> 1 | ... BA19: =IF(OR($F19>BA$12,AND($G19="Terminated",BA$12>=$H19)),0,1) -> 1
A20: 10 | B20: Reuben | C20: Stump | D20: Stump, Reuben | E20: Male | F20: 43985 | G20: Full-Time | H20: 43985 | I20: Datadog | J20: Engineering | K20: Remote | L20: Principal Cloud Architect | M20: Yes | N20: L5 | O20: PA | P20: 200- Datadog:220- Engineering | Q20: {=IF($M20="Yes","Cost of Goods Sold:COGS- Travel Expenses:",IF($M20="No",XLOOKUP($P20,Key!$I:$I,Key!$J:$J),"Review Billable Status"))} -> Cost of Goods Sold:COGS- Travel Expenses: | R20: {=IF($M20="Yes","Cost of Goods Sold:COGS- Personnel Expense:",IF($M20="No",XLOOKUP($P20,Key!$I:$I,Key!$K:$K),"Review Billable Status"))} -> Cost of Goods Sold:COGS- Personnel Expense: | S20: {=IF($G20="Paid Intern","PD Intern",IF($G20="Contractor/Consultant","Contractor",XLOOKUP(M20&P20,Key!$M:$M,Key!$L:$L)))} -> COR | T20: =IF(OR($F20>T$12,AND($G20="Terminated",T$12>=$H20)),0,1) -> 1 | U20: =IF(OR($F20>U$12,AND($G20="Terminated",U$12>=$H20)),0,1) -> 1 | V20: =IF(OR($F20>V$12,AND($G20="Terminated",V$12>=$H20)),0,1) -> 1 | W20: =IF(OR($F20>W$12,AND($G20="Terminated",W$12>=$H20)),0,1) -> 1 | X20: =IF(OR($F20>X$12,AND($G20="Terminated",X$12>=$H20)),0,1) -> 1 | Y20: =IF(OR($F20>Y$12,AND($G20="Terminated",Y$12>=$H20)),0,1) -> 1 | Z20: =IF(OR($F20>Z$12,AND($G20="Terminated",Z$12>=$H20)),0,1) -> 1 | AA20: =IF(OR($F20>AA$12,AND($G20="Terminated",AA$12>=$H20)),0,1) -> 1 | ... BA20: =IF(OR($F20>BA$12,AND($G20="Terminated",BA$12>=$H20)),0,1) -> 1
A21: 12 | B21: Elias | C21: Kapetanopoulos | D21: Kapetanopoulos, Elias | E21: Male | F21: 44060 | G21: Full-Time | H21: 44060 | I21: ServiceNow | J21: Engineering | K21: Boylston | L21: Director of Engineering - ServiceNow | M21: No | N21: L5 | O21: MA | P21: 300- ServiceNow:320- Engineering | Q21: {=IF($M21="Yes","Cost of Goods Sold:COGS- Travel Expenses:",IF($M21="No",XLOOKUP($P21,Key!$I:$I,Key!$J:$J),"Review Billable Status"))} -> General & Administrative:G&A- Travel Expenses: | R21: {=IF($M21="Yes","Cost of Goods Sold:COGS- Personnel Expense:",IF($M21="No",XLOOKUP($P21,Key!$I:$I,Key!$K:$K),"Review Billable Status"))} -> General & Administrative:G&A- Personnel Expenses: | S21: {=IF($G21="Paid Intern","PD Intern",IF($G21="Contractor/Consultant","Contractor",XLOOKUP(M21&P21,Key!$M:$M,Key!$L:$L)))} -> G&A | T21: =IF(OR($F21>T$12,AND($G21="Terminated",T$12>=$H21)),0,1) -> 1 | U21: =IF(OR($F21>U$12,AND($G21="Terminated",U$12>=$H21)),0,1) -> 1 | V21: =IF(OR($F21>V$12,AND($G21="Terminated",V$12>=$H21)),0,1) -> 1 | W21: =IF(OR($F21>W$12,AND($G21="Terminated",W$12>=$H21)),0,1) -> 1 | X21: =IF(OR($F21>X$12,AND($G21="Terminated",X$12>=$H21)),0,1) -> 1 | Y21: =IF(OR($F21>Y$12,AND($G21="Terminated",Y$12>=$H21)),0,1) -> 1 | Z21: =IF(OR($F21>Z$12,AND($G21="Terminated",Z$12>=$H21)),0,1) -> 1 | AA21: =IF(OR($F21>AA$12,AND($G21="Terminated",AA$12>=$H21)),0,1) -> 1 | ... BA21: =IF(OR($F21>BA$12,AND($G21="Terminated",BA$12>=$H21)),0,1) -> 1
A22: 14 | B22: Christian | C22: Moua | D22: Moua, Christian | E22: Male | F22: 44088 | G22: Full-Time | H22: 44088 | I22: ServiceNow | J22: Engineering | K22: Boylston | L22: ServiceNow Engineer | M22: Yes | N22: L2 | O22: RI | P22: 300- ServiceNow:320- Engineering | Q22: {=IF($M22="Yes","Cost of Goods Sold:COGS- Travel Expenses:",IF($M22="No",XLOOKUP($P22,Key!$I:$I,Key!$J:$J),"Review Billable Status"))} -> Cost of Goods Sold:COGS- Travel Expenses: | R22: {=IF($M22="Yes","Cost of Goods Sold:COGS- Personnel Expense:",IF($M22="No",XLOOKUP($P22,Key!$I:$I,Key!$K:$K),"Review Billable Status"))} -> Cost of Goods Sold:COGS- Personnel Expense: | S22: {=IF($G22="Paid Intern","PD Intern",IF($G22="Contractor/Consultant","Contractor",XLOOKUP(M22&P22,Key!$M:$M,Key!$L:$L)))} -> COR | T22: =IF(OR($F22>T$12,AND($G22="Terminated",T$12>=$H22)),0,1) -> 1 | U22: =IF(OR($F22>U$12,AND($G22="Terminated",U$12>=$H22)),0,1) -> 1 | V22: =IF(OR($F22>V$12,AND($G22="Terminated",V$12>=$H22)),0,1) -> 1 | W22: =IF(OR($F22>W$12,AND($G22="Terminated",W$12>=$H22)),0,1) -> 1 | X22: =IF(OR($F22>X$12,AND($G22="Terminated",X$12>=$H22)),0,1) -> 1 | Y22: =IF(OR($F22>Y$12,AND($G22="Terminated",Y$12>=$H22)),0,1) -> 1 | Z22: =IF(OR($F22>Z$12,AND($G22="Terminated",Z$12>=$H22)),0,1) -> 1 | AA22: =IF(OR($F22>AA$12,AND($G22="Terminated",AA$12>=$H22)),0,1) -> 1 | ... BA22: =IF(OR($F22>BA$12,AND($G22="Terminated",BA$12>=$H22)),0,1) -> 1
A23: 15 | B23: Jesse | C23: Eddy | D23: Eddy, Jesse | E23: Male | F23: 44102 | G23: Full-Time | H23: 44102 | I23: Datadog | J23: Sales | K23: Boylston | L23: Sr Account Executive | M23: No | N23: L3 | O23: MA | P23: 200- Datadog:230- Sales | Q23: {=IF($M23="Yes","Cost of Goods Sold:COGS- Travel Expenses:",IF($M23="No",XLOOKUP($P23,Key!$I:$I,Key!$J:$J),"Review Billable Status"))} -> Sales & Marketing:Sales & Marketing- Travel Expenses: | R23: {=IF($M23="Yes","Cost of Goods Sold:COGS- Personnel Expense:",IF($M23="No",XLOOKUP($P23,Key!$I:$I,Key!$K:$K),"Review Billable Status"))} -> Sales & Marketing:Sales & Marketing- Personnel Expenses: | S23: {=IF($G23="Paid Intern","PD Intern",IF($G23="Contractor/Consultant","Contractor",XLOOKUP(M23&P23,Key!$M:$M,Key!$L:$L)))} -> S&M | T23: =IF(OR($F23>T$12,AND($G23="Terminated",T$12>=$H23)),0,1) -> 1 | U23: =IF(OR($F23>U$12,AND($G23="Terminated",U$12>=$H23)),0,1) -> 1 | V23: =IF(OR($F23>V$12,AND($G23="Terminated",V$12>=$H23)),0,1) -> 1 | W23: =IF(OR($F23>W$12,AND($G23="Terminated",W$12>=$H23)),0,1) -> 1 | X23: =IF(OR($F23>X$12,AND($G23="Terminated",X$12>=$H23)),0,1) -> 1 | Y23: =IF(OR($F23>Y$12,AND($G23="Terminated",Y$12>=$H23)),0,1) -> 1 | Z23: =IF(OR($F23>Z$12,AND($G23="Terminated",Z$12>=$H23)),0,1) -> 1 | AA23: =IF(OR($F23>AA$12,AND($G23="Terminated",AA$12>=$H23)),0,1) -> 1 | ... BA23: =IF(OR($F23>BA$12,AND($G23="Terminated",BA$12>=$H23)),0,1) -> 1
A24: 18 | B24: Tomas | C24: Cespedes | D24: Cespedes, Tomas | E24: Male | F24: 44151 | G24: Full-Time | H24: 44151 | I24: Datadog | J24: Sales | K24: Boylston | L24: Sr Solutions Engineer | M24: No | N24: L4 | O24: MA | P24: 200- Datadog:230- Sales | Q24: {=IF($M24="Yes","Cost of Goods Sold:COGS- Travel Expenses:",IF($M24="No",XLOOKUP($P24,Key!$I:$I,Key!$J:$J),"Review Billable Status"))} -> Sales & Marketing:Sales & Marketing- Travel Expenses: | R24: {=IF($M24="Yes","Cost of Goods Sold:COGS- Personnel Expense:",IF($M24="No",XLOOKUP($P24,Key!$I:$I,Key!$K:$K),"Review Billable Status"))} -> Sales & Marketing:Sales & Marketing- Personnel Expenses: | S24: {=IF($G24="Paid Intern","PD Intern",IF($G24="Contractor/Consultant","Contractor",XLOOKUP(M24&P24,Key!$M:$M,Key!$L:$L)))} -> S&M | T24: =IF(OR($F24>T$12,AND($G24="Terminated",T$12>=$H24)),0,1) -> 1 | U24: =IF(OR($F24>U$12,AND($G24="Terminated",U$12>=$H24)),0,1) -> 1 | V24: =IF(OR($F24>V$12,AND($G24="Terminated",V$12>=$H24)),0,1) -> 1 | W24: =IF(OR($F24>W$12,AND($G24="Terminated",W$12>=$H24)),0,1) -> 1 | X24: =IF(OR($F24>X$12,AND($G24="Terminated",X$12>=$H24)),0,1) -> 1 | Y24: =IF(OR($F24>Y$12,AND($G24="Terminated",Y$12>=$H24)),0,1) -> 1 | Z24: =IF(OR($F24>Z$12,AND($G24="Terminated",Z$12>=$H24)),0,1) -> 1 | AA24: =IF(OR($F24>AA$12,AND($G24="Terminated",AA$12>=$H24)),0,1) -> 1 | ... BA24: =IF(OR($F24>BA$12,AND($G24="Terminated",BA$12>=$H24)),0,1) -> 1
... A171: 269 | B171: Brian | C171: McGonigal | D171: McGonigal, Brian | E171: Male | F171: 46118 | G171: Full-Time | H171: 46118 | I171: ServiceNow | J171: Sales | K171: Remote | L171: Account Executive | M171: No | N171: L3 | O171: NJ | P171: 300- ServiceNow:330- Sales | Q171: {=IF($M171="Yes","Cost of Goods Sold:COGS- Travel Expenses:",IF($M171="No",XLOOKUP($P171,Key!$I:$I,Key!$J:$J),"Review Billable Status"))} -> Sales & Marketing:Sales & Marketing- Travel Expenses: | R171: {=IF($M171="Yes","Cost of Goods Sold:COGS- Personnel Expense:",IF($M171="No",XLOOKUP($P171,Key!$I:$I,Key!$K:$K),"Review Billable Status"))} -> Sales & Marketing:Sales & Marketing- Personnel Expenses: | S171: {=IF($G171="Paid Intern","PD Intern",IF($G171="Contractor/Consultant","Contractor",XLOOKUP(M171&P171,Key!$M:$M,Key!$L:$L)))} -> S&M | T171: =IF(OR($F171>T$12,AND($G171="Terminated",T$12>=$H171)),0,1) -> 0 | U171: =IF(OR($F171>U$12,AND($G171="Terminated",U$12>=$H171)),0,1) -> 0 | V171: =IF(OR($F171>V$12,AND($G171="Terminated",V$12>=$H171)),0,1) -> 0 | W171: =IF(OR($F171>W$12,AND($G171="Terminated",W$12>=$H171)),0,1) -> 0 | X171: =IF(OR($F171>X$12,AND($G171="Terminated",X$12>=$H171)),0,1) -> 0 | Y171: =IF(OR($F171>Y$12,AND($G171="Terminated",Y$12>=$H171)),0,1) -> 0 | Z171: =IF(OR($F171>Z$12,AND($G171="Terminated",Z$12>=$H171)),0,1) -> 0 | AA171: =IF(OR($F171>AA$12,AND($G171="Terminated",AA$12>=$H171)),0,1) -> 0 | ... BA171: =IF(OR($F171>BA$12,AND($G171="Terminated",BA$12>=$H171)),0,1) -> 1
A172: 270 | B172: James | C172: Dean | D172: Dean, James | F172: 46209 | G172: Full-Time | H172: 46209 | I172: Datadog | J172: Sales | K172: Non-US | L172: Principal Solutions Engineer | M172: No | N172: L4 | O172: Kent | P172: 200- Datadog:230- Sales | Q172: {=IF($M172="Yes","Cost of Goods Sold:COGS- Travel Expenses:",IF($M172="No",XLOOKUP($P172,Key!$I:$I,Key!$J:$J),"Review Billable Status"))} -> Sales & Marketing:Sales & Marketing- Travel Expenses: | R172: {=IF($M172="Yes","Cost of Goods Sold:COGS- Personnel Expense:",IF($M172="No",XLOOKUP($P172,Key!$I:$I,Key!$K:$K),"Review Billable Status"))} -> Sales & Marketing:Sales & Marketing- Personnel Expenses: | S172: {=IF($G172="Paid Intern","PD Intern",IF($G172="Contractor/Consultant","Contractor",XLOOKUP(M172&P172,Key!$M:$M,Key!$L:$L)))} -> S&M | T172: =IF(OR($F172>T$12,AND($G172="Terminated",T$12>=$H172)),0,1) -> 0 | U172: =IF(OR($F172>U$12,AND($G172="Terminated",U$12>=$H172)),0,1) -> 0 | V172: =IF(OR($F172>V$12,AND($G172="Terminated",V$12>=$H172)),0,1) -> 0 | W172: =IF(OR($F172>W$12,AND($G172="Terminated",W$12>=$H172)),0,1) -> 0 | X172: =IF(OR($F172>X$12,AND($G172="Terminated",X$12>=$H172)),0,1) -> 0 | Y172: =IF(OR($F172>Y$12,AND($G172="Terminated",Y$12>=$H172)),0,1) -> 0 | Z172: =IF(OR($F172>Z$12,AND($G172="Terminated",Z$12>=$H172)),0,1) -> 0 | AA172: =IF(OR($F172>AA$12,AND($G172="Terminated",AA$12>=$H172)),0,1) -> 0 | ... BA172: =IF(OR($F172>BA$12,AND($G172="Terminated",BA$12>=$H172)),0,1) -> 1
A173: 271 | B173: Marsha | C173: Whitman | D173: Whitman, Marsha | E173: Female | F173: 46133 | G173: Full-Time | H173: 46133 | I173: ServiceNow | J173: Project Management | K173: Boylston | L173: Senior Program Manager | M173: Yes | N173: L4 | O173: MA | P173: 300- ServiceNow:310- Delivery | Q173: {=IF($M173="Yes","Cost of Goods Sold:COGS- Travel Expenses:",IF($M173="No",XLOOKUP($P173,Key!$I:$I,Key!$J:$J),"Review Billable Status"))} -> Cost of Goods Sold:COGS- Travel Expenses: | R173: {=IF($M173="Yes","Cost of Goods Sold:COGS- Personnel Expense:",IF($M173="No",XLOOKUP($P173,Key!$I:$I,Key!$K:$K),"Review Billable Status"))} -> Cost of Goods Sold:COGS- Personnel Expense: | S173: {=IF($G173="Paid Intern","PD Intern",IF($G173="Contractor/Consultant","Contractor",XLOOKUP(M173&P173,Key!$M:$M,Key!$L:$L)))} -> COR | T173: =IF(OR($F173>T$12,AND($G173="Terminated",T$12>=$H173)),0,1) -> 0 | U173: =IF(OR($F173>U$12,AND($G173="Terminated",U$12>=$H173)),0,1) -> 0 | V173: =IF(OR($F173>V$12,AND($G173="Terminated",V$12>=$H173)),0,1) -> 0 | W173: =IF(OR($F173>W$12,AND($G173="Terminated",W$12>=$H173)),0,1) -> 0 | X173: =IF(OR($F173>X$12,AND($G173="Terminated",X$12>=$H173)),0,1) -> 0 | Y173: =IF(OR($F173>Y$12,AND($G173="Terminated",Y$12>=$H173)),0,1) -> 0 | Z173: =IF(OR($F173>Z$12,AND($G173="Terminated",Z$12>=$H173)),0,1) -> 0 | AA173: =IF(OR($F173>AA$12,AND($G173="Terminated",AA$12>=$H173)),0,1) -> 0 | ... BA173: =IF(OR($F173>BA$12,AND($G173="Terminated",BA$12>=$H173)),0,1) -> 1
A174: 273 | B174: Michael | C174: Button | D174: Button, Michael | E174: Male | F174: 46153 | G174: Paid Intern | H174: 46153 | I174: Operations | J174: Operations | K174: Boylston | L174: IT Support | M174: No | N174: L0 | O174: MA | P174: 100- Operations:110- G&A | Q174: {=IF($M174="Yes","Cost of Goods Sold:COGS- Travel Expenses:",IF($M174="No",XLOOKUP($P174,Key!$I:$I,Key!$J:$J),"Review Billable Status"))} -> General & Administrative:G&A- Travel Expenses: | R174: {=IF($M174="Yes","Cost of Goods Sold:COGS- Personnel Expense:",IF($M174="No",XLOOKUP($P174,Key!$I:$I,Key!$K:$K),"Review Billable Status"))} -> General & Administrative:G&A- Personnel Expenses: | S174: {=IF($G174="Paid Intern","PD Intern",IF($G174="Contractor/Consultant","Contractor",XLOOKUP(M174&P174,Key!$M:$M,Key!$L:$L)))} -> PD Intern | T174: =IF(OR($F174>T$12,AND($G174="Terminated",T$12>=$H174)),0,1) -> 0 | U174: =IF(OR($F174>U$12,AND($G174="Terminated",U$12>=$H174)),0,1) -> 0 | V174: =IF(OR($F174>V$12,AND($G174="Terminated",V$12>=$H174)),0,1) -> 0 | W174: =IF(OR($F174>W$12,AND($G174="Terminated",W$12>=$H174)),0,1) -> 0 | X174: =IF(OR($F174>X$12,AND($G174="Terminated",X$12>=$H174)),0,1) -> 0 | Y174: =IF(OR($F174>Y$12,AND($G174="Terminated",Y$12>=$H174)),0,1) -> 0 | Z174: =IF(OR($F174>Z$12,AND($G174="Terminated",Z$12>=$H174)),0,1) -> 0 | AA174: =IF(OR($F174>AA$12,AND($G174="Terminated",AA$12>=$H174)),0,1) -> 0 | ... BA174: =IF(OR($F174>BA$12,AND($G174="Terminated",BA$12>=$H174)),0,1) -> 1
A175: 274 | B175: Robin | C175: Wiggs | D175: Wiggs, Robin | E175: Male | F175: 46132 | G175: Full-Time | H175: 46132 | I175: Datadog | J175: Engineering | K175: Non-US | L175: Sr Cloud Engineer | M175: Yes | N175: L3 | O175: West Sussex | P175: 200- Datadog:220- Engineering | Q175: {=IF($M175="Yes","Cost of Goods Sold:COGS- Travel Expenses:",IF($M175="No",XLOOKUP($P175,Key!$I:$I,Key!$J:$J),"Review Billable Status"))} -> Cost of Goods Sold:COGS- Travel Expenses: | R175: {=IF($M175="Yes","Cost of Goods Sold:COGS- Personnel Expense:",IF($M175="No",XLOOKUP($P175,Key!$I:$I,Key!$K:$K),"Review Billable Status"))} -> Cost of Goods Sold:COGS- Personnel Expense: | S175: {=IF($G175="Paid Intern","PD Intern",IF($G175="Contractor/Consultant","Contractor",XLOOKUP(M175&P175,Key!$M:$M,Key!$L:$L)))} -> COR | T175: =IF(OR($F175>T$12,AND($G175="Terminated",T$12>=$H175)),0,1) -> 0 | U175: =IF(OR($F175>U$12,AND($G175="Terminated",U$12>=$H175)),0,1) -> 0 | V175: =IF(OR($F175>V$12,AND($G175="Terminated",V$12>=$H175)),0,1) -> 0 | W175: =IF(OR($F175>W$12,AND($G175="Terminated",W$12>=$H175)),0,1) -> 0 | X175: =IF(OR($F175>X$12,AND($G175="Terminated",X$12>=$H175)),0,1) -> 0 | Y175: =IF(OR($F175>Y$12,AND($G175="Terminated",Y$12>=$H175)),0,1) -> 0 | Z175: =IF(OR($F175>Z$12,AND($G175="Terminated",Z$12>=$H175)),0,1) -> 0 | AA175: =IF(OR($F175>AA$12,AND($G175="Terminated",AA$12>=$H175)),0,1) -> 0 | ... BA175: =IF(OR($F175>BA$12,AND($G175="Terminated",BA$12>=$H175)),0,1) -> 1
A176: 275 | B176: John | C176: Fennell | D176: Fennell, John | E176: Male | F176: 46160 | G176: Full-Time | H176: 46160 | I176: Operations | J176: Marketing | K176: Boylston | L176: Associate Brand Manager | M176: No | N176: L2 | O176: MA | P176: 100- Operations:120- Marketing | Q176: {=IF($M176="Yes","Cost of Goods Sold:COGS- Travel Expenses:",IF($M176="No",XLOOKUP($P176,Key!$I:$I,Key!$J:$J),"Review Billable Status"))} -> Sales & Marketing:Sales & Marketing- Travel Expenses: | R176: {=IF($M176="Yes","Cost of Goods Sold:COGS- Personnel Expense:",IF($M176="No",XLOOKUP($P176,Key!$I:$I,Key!$K:$K),"Review Billable Status"))} -> Sales & Marketing:Sales & Marketing- Personnel Expenses: | S176: {=IF($G176="Paid Intern","PD Intern",IF($G176="Contractor/Consultant","Contractor",XLOOKUP(M176&P176,Key!$M:$M,Key!$L:$L)))} -> S&M | T176: =IF(OR($F176>T$12,AND($G176="Terminated",T$12>=$H176)),0,1) -> 0 | U176: =IF(OR($F176>U$12,AND($G176="Terminated",U$12>=$H176)),0,1) -> 0 | V176: =IF(OR($F176>V$12,AND($G176="Terminated",V$12>=$H176)),0,1) -> 0 | W176: =IF(OR($F176>W$12,AND($G176="Terminated",W$12>=$H176)),0,1) -> 0 | X176: =IF(OR($F176>X$12,AND($G176="Terminated",X$12>=$H176)),0,1) -> 0 | Y176: =IF(OR($F176>Y$12,AND($G176="Terminated",Y$12>=$H176)),0,1) -> 0 | Z176: =IF(OR($F176>Z$12,AND($G176="Terminated",Z$12>=$H176)),0,1) -> 0 | AA176: =IF(OR($F176>AA$12,AND($G176="Terminated",AA$12>=$H176)),0,1) -> 0 | ... BA176: =IF(OR($F176>BA$12,AND($G176="Terminated",BA$12>=$H176)),0,1) -> 1
A177: 276 | B177: Vivian | C177: Wu | D177: Wu, Vivian | E177: Female | F177: 46153 | G177: Full-Time | H177: 46153 | I177: Operations | J177: People Operations | K177: Boylston | L177: People Ops Generalist | M177: No | N177: L1 | O177: MA | P177: 100- Operations:110- G&A | Q177: {=IF($M177="Yes","Cost of Goods Sold:COGS- Travel Expenses:",IF($M177="No",XLOOKUP($P177,Key!$I:$I,Key!$J:$J),"Review Billable Status"))} -> General & Administrative:G&A- Travel Expenses: | R177: {=IF($M177="Yes","Cost of Goods Sold:COGS- Personnel Expense:",IF($M177="No",XLOOKUP($P177,Key!$I:$I,Key!$K:$K),"Review Billable Status"))} -> General & Administrative:G&A- Personnel Expenses: | S177: {=IF($G177="Paid Intern","PD Intern",IF($G177="Contractor/Consultant","Contractor",XLOOKUP(M177&P177,Key!$M:$M,Key!$L:$L)))} -> G&A | T177: =IF(OR($F177>T$12,AND($G177="Terminated",T$12>=$H177)),0,1) -> 0 | U177: =IF(OR($F177>U$12,AND($G177="Terminated",U$12>=$H177)),0,1) -> 0 | V177: =IF(OR($F177>V$12,AND($G177="Terminated",V$12>=$H177)),0,1) -> 0 | W177: =IF(OR($F177>W$12,AND($G177="Terminated",W$12>=$H177)),0,1) -> 0 | X177: =IF(OR($F177>X$12,AND($G177="Terminated",X$12>=$H177)),0,1) -> 0 | Y177: =IF(OR($F177>Y$12,AND($G177="Terminated",Y$12>=$H177)),0,1) -> 0 | Z177: =IF(OR($F177>Z$12,AND($G177="Terminated",Z$12>=$H177)),0,1) -> 0 | AA177: =IF(OR($F177>AA$12,AND($G177="Terminated",AA$12>=$H177)),0,1) -> 0 | ... BA177: =IF(OR($F177>BA$12,AND($G177="Terminated",BA$12>=$H177)),0,1) -> 1
A178: 277 | B178: Jackson | C178: Mendes | D178: Mendes, Jackson | E178: Male | F178: 46160 | G178: Paid Intern | H178: 46160 | I178: ServiceNow | J178: Engineering | K178: Boylston | L178: ServiceNow Intern | M178: No | N178: L0 | O178: CT | P178: 300- ServiceNow:320- Engineering | Q178: {=IF($M178="Yes","Cost of Goods Sold:COGS- Travel Expenses:",IF($M178="No",XLOOKUP($P178,Key!$I:$I,Key!$J:$J),"Review Billable Status"))} -> General & Administrative:G&A- Travel Expenses: | R178: {=IF($M178="Yes","Cost of Goods Sold:COGS- Personnel Expense:",IF($M178="No",XLOOKUP($P178,Key!$I:$I,Key!$K:$K),"Review Billable Status"))} -> General & Administrative:G&A- Personnel Expenses: | S178: {=IF($G178="Paid Intern","PD Intern",IF($G178="Contractor/Consultant","Contractor",XLOOKUP(M178&P178,Key!$M:$M,Key!$L:$L)))} -> PD Intern | T178: =IF(OR($F178>T$12,AND($G178="Terminated",T$12>=$H178)),0,1) -> 0 | U178: =IF(OR($F178>U$12,AND($G178="Terminated",U$12>=$H178)),0,1) -> 0 | V178: =IF(OR($F178>V$12,AND($G178="Terminated",V$12>=$H178)),0,1) -> 0 | W178: =IF(OR($F178>W$12,AND($G178="Terminated",W$12>=$H178)),0,1) -> 0 | X178: =IF(OR($F178>X$12,AND($G178="Terminated",X$12>=$H178)),0,1) -> 0 | Y178: =IF(OR($F178>Y$12,AND($G178="Terminated",Y$12>=$H178)),0,1) -> 0 | Z178: =IF(OR($F178>Z$12,AND($G178="Terminated",Z$12>=$H178)),0,1) -> 0 | AA178: =IF(OR($F178>AA$12,AND($G178="Terminated",AA$12>=$H178)),0,1) -> 0 | ... BA178: =IF(OR($F178>BA$12,AND($G178="Terminated",BA$12>=$H178)),0,1) -> 1
A179: 278 | B179: Samantha | C179: Purpura | D179: Purpura, Samantha | E179: Female | F179: 46153 | G179: Full-Time | H179: 46153 | I179: Operations | J179: Operations | K179: Boylston | L179: Platform Operations Coordinator | M179: No | N179: L1 | O179: MA | P179: 400- Synechron:410- Digital platforms G&A | Q179: {=IF($M179="Yes","Cost of Goods Sold:COGS- Travel Expenses:",IF($M179="No",XLOOKUP($P179,Key!$I:$I,Key!$J:$J),"Review Billable Status"))} -> General & Administrative:G&A- Travel Expenses: | R179: {=IF($M179="Yes","Cost of Goods Sold:COGS- Personnel Expense:",IF($M179="No",XLOOKUP($P179,Key!$I:$I,Key!$K:$K),"Review Billable Status"))} -> General & Administrative:G&A- Personnel Expenses: | S179: {=IF($G179="Paid Intern","PD Intern",IF($G179="Contractor/Consultant","Contractor",XLOOKUP(M179&P179,Key!$M:$M,Key!$L:$L)))} -> G&A | T179: =IF(OR($F179>T$12,AND($G179="Terminated",T$12>=$H179)),0,1) -> 0 | U179: =IF(OR($F179>U$12,AND($G179="Terminated",U$12>=$H179)),0,1) -> 0 | V179: =IF(OR($F179>V$12,AND($G179="Terminated",V$12>=$H179)),0,1) -> 0 | W179: =IF(OR($F179>W$12,AND($G179="Terminated",W$12>=$H179)),0,1) -> 0 | X179: =IF(OR($F179>X$12,AND($G179="Terminated",X$12>=$H179)),0,1) -> 0 | Y179: =IF(OR($F179>Y$12,AND($G179="Terminated",Y$12>=$H179)),0,1) -> 0 | Z179: =IF(OR($F179>Z$12,AND($G179="Terminated",Z$12>=$H179)),0,1) -> 0 | AA179: =IF(OR($F179>AA$12,AND($G179="Terminated",AA$12>=$H179)),0,1) -> 0 | ... BA179: =IF(OR($F179>BA$12,AND($G179="Terminated",BA$12>=$H179)),0,1) -> 1
A180: 283 | B180: Jamie | C180: Cosgrove | D180: Cosgrove, Jamie | F180: 46140 | G180: Contractor/Consultant | H180: 46140 | I180: Operations | J180: Operations | K180: Boylston | M180: No | O180: MA | P180: 100- Operations:110- G&A | Q180: {=IF($M180="Yes","Cost of Goods Sold:COGS- Travel Expenses:",IF($M180="No",XLOOKUP($P180,Key!$I:$I,Key!$J:$J),"Review Billable Status"))} -> General & Administrative:G&A- Travel Expenses: | R180: {=IF($M180="Yes","Cost of Goods Sold:COGS- Personnel Expense:",IF($M180="No",XLOOKUP($P180,Key!$I:$I,Key!$K:$K),"Review Billable Status"))} -> General & Administrative:G&A- Personnel Expenses: | S180: {=IF($G180="Paid Intern","PD Intern",IF($G180="Contractor/Consultant","Contractor",XLOOKUP(M180&P180,Key!$M:$M,Key!$L:$L)))} -> Contractor | T180: =IF(OR($F180>T$12,AND($G180="Terminated",T$12>=$H180)),0,1) -> 0 | U180: =IF(OR($F180>U$12,AND($G180="Terminated",U$12>=$H180)),0,1) -> 0 | V180: =IF(OR($F180>V$12,AND($G180="Terminated",V$12>=$H180)),0,1) -> 0 | W180: =IF(OR($F180>W$12,AND($G180="Terminated",W$12>=$H180)),0,1) -> 0 | X180: =IF(OR($F180>X$12,AND($G180="Terminated",X$12>=$H180)),0,1) -> 0 | Y180: =IF(OR($F180>Y$12,AND($G180="Terminated",Y$12>=$H180)),0,1) -> 0 | Z180: =IF(OR($F180>Z$12,AND($G180="Terminated",Z$12>=$H180)),0,1) -> 0 | AA180: =IF(OR($F180>AA$12,AND($G180="Terminated",AA$12>=$H180)),0,1) -> 0 | ... BA180: =IF(OR($F180>BA$12,AND($G180="Terminated",BA$12>=$H180)),0,1) -> 1
A181: 284 | B181: Lenny | C181: Caraballo | D181: Caraballo, Lenny | F181: 46181 | G181: Full-Time | H181: 46181 | I181: Datadog | J181: MDD | K181: Boylston | L181: Managed Datadog Engineer | M181: No | N181: L2 | O181: MA | P181: 200- Datadog:220- Engineering | Q181: {=IF($M181="Yes","Cost of Goods Sold:COGS- Travel Expenses:",IF($M181="No",XLOOKUP($P181,Key!$I:$I,Key!$J:$J),"Review Billable Status"))} -> General & Administrative:G&A- Travel Expenses: | R181: {=IF($M181="Yes","Cost of Goods Sold:COGS- Personnel Expense:",IF($M181="No",XLOOKUP($P181,Key!$I:$I,Key!$K:$K),"Review Billable Status"))} -> General & Administrative:G&A- Personnel Expenses: | S181: {=IF($G181="Paid Intern","PD Intern",IF($G181="Contractor/Consultant","Contractor",XLOOKUP(M181&P181,Key!$M:$M,Key!$L:$L)))} -> G&A | T181: =IF(OR($F181>T$12,AND($G181="Terminated",T$12>=$H181)),0,1) -> 0 | U181: =IF(OR($F181>U$12,AND($G181="Terminated",U$12>=$H181)),0,1) -> 0 | V181: =IF(OR($F181>V$12,AND($G181="Terminated",V$12>=$H181)),0,1) -> 0 | W181: =IF(OR($F181>W$12,AND($G181="Terminated",W$12>=$H181)),0,1) -> 0 | X181: =IF(OR($F181>X$12,AND($G181="Terminated",X$12>=$H181)),0,1) -> 0 | Y181: =IF(OR($F181>Y$12,AND($G181="Terminated",Y$12>=$H181)),0,1) -> 0 | Z181: =IF(OR($F181>Z$12,AND($G181="Terminated",Z$12>=$H181)),0,1) -> 0 | AA181: =IF(OR($F181>AA$12,AND($G181="Terminated",AA$12>=$H181)),0,1) -> 0 | ... BA181: =IF(OR($F181>BA$12,AND($G181="Terminated",BA$12>=$H181)),0,1) -> 1
A182: 285 | B182: Anthony | C182: Nguyen | D182: Nguyen, Anthony | F182: 46209 | I182: Datadog | J182: Engineering | M182: No | O182: VIC | P182: 200- Datadog:220- Engineering | Q182: {=IF($M182="Yes","Cost of Goods Sold:COGS- Travel Expenses:",IF($M182="No",XLOOKUP($P182,Key!$I:$I,Key!$J:$J),"Review Billable Status"))} -> General & Administrative:G&A- Travel Expenses: | R182: {=IF($M182="Yes","Cost of Goods Sold:COGS- Personnel Expense:",IF($M182="No",XLOOKUP($P182,Key!$I:$I,Key!$K:$K),"Review Billable Status"))} -> General & Administrative:G&A- Personnel Expenses: | S182: {=IF($G182="Paid Intern","PD Intern",IF($G182="Contractor/Consultant","Contractor",XLOOKUP(M182&P182,Key!$M:$M,Key!$L:$L)))} -> G&A | T182: =IF(OR($F182>T$12,AND($G182="Terminated",T$12>=$H182)),0,1) -> 0 | U182: =IF(OR($F182>U$12,AND($G182="Terminated",U$12>=$H182)),0,1) -> 0 | V182: =IF(OR($F182>V$12,AND($G182="Terminated",V$12>=$H182)),0,1) -> 0 | W182: =IF(OR($F182>W$12,AND($G182="Terminated",W$12>=$H182)),0,1) -> 0 | X182: =IF(OR($F182>X$12,AND($G182="Terminated",X$12>=$H182)),0,1) -> 0 | Y182: =IF(OR($F182>Y$12,AND($G182="Terminated",Y$12>=$H182)),0,1) -> 0 | Z182: =IF(OR($F182>Z$12,AND($G182="Terminated",Z$12>=$H182)),0,1) -> 0 | AA182: =IF(OR($F182>AA$12,AND($G182="Terminated",AA$12>=$H182)),0,1) -> 0 | ... BA182: =IF(OR($F182>BA$12,AND($G182="Terminated",BA$12>=$H182)),0,1) -> 1
A183: 286 | B183: Paulina | C183: Mateo | D183: Mateo, Paulina | F183: 46181 | G183: Full-Time | H183: 46181 | I183: ServiceNow | J183: Project Management | K183: Boylston | L183: OCM Specialist | M183: Yes | N183: L1 | O183: MA | P183: 300- ServiceNow:310- Delivery | Q183: {=IF($M183="Yes","Cost of Goods Sold:COGS- Travel Expenses:",IF($M183="No",XLOOKUP($P183,Key!$I:$I,Key!$J:$J),"Review Billable Status"))} -> Cost of Goods Sold:COGS- Travel Expenses: | R183: {=IF($M183="Yes","Cost of Goods Sold:COGS- Personnel Expense:",IF($M183="No",XLOOKUP($P183,Key!$I:$I,Key!$K:$K),"Review Billable Status"))} -> Cost of Goods Sold:COGS- Personnel Expense: | S183: {=IF($G183="Paid Intern","PD Intern",IF($G183="Contractor/Consultant","Contractor",XLOOKUP(M183&P183,Key!$M:$M,Key!$L:$L)))} -> COR | T183: =IF(OR($F183>T$12,AND($G183="Terminated",T$12>=$H183)),0,1) -> 0 | U183: =IF(OR($F183>U$12,AND($G183="Terminated",U$12>=$H183)),0,1) -> 0 | V183: =IF(OR($F183>V$12,AND($G183="Terminated",V$12>=$H183)),0,1) -> 0 | W183: =IF(OR($F183>W$12,AND($G183="Terminated",W$12>=$H183)),0,1) -> 0 | X183: =IF(OR($F183>X$12,AND($G183="Terminated",X$12>=$H183)),0,1) -> 0 | Y183: =IF(OR($F183>Y$12,AND($G183="Terminated",Y$12>=$H183)),0,1) -> 0 | Z183: =IF(OR($F183>Z$12,AND($G183="Terminated",Z$12>=$H183)),0,1) -> 0 | AA183: =IF(OR($F183>AA$12,AND($G183="Terminated",AA$12>=$H183)),0,1) -> 0 | ... BA183: =IF(OR($F183>BA$12,AND($G183="Terminated",BA$12>=$H183)),0,1) -> 1
