Workbook

Sheet Credit Card Charge
A1: Reference number | B1: CC account | C1: Line: Amount | D1: Name | E1: Type | F1: Line: Account | G1: Credit | H1: Currency | I1: Location | J1: Exchange Rate | K1: Global tax calculation | L1: Update Credit Card Charge | M1: Line: Billable status | N1: Line: Class | O1: Line: Customer | P1: Line: Tax code | Q1: Line: Description | R1: Line: Tax amount | S1: Line: Markup percent | T1: Item: Product | U1: Item: Quantity | V1: Item: Unit price | W1: Payment method | X1: Memo | Y1: Txn date | Z1: Txn source | AA1: Total tax | AB1: Transaction Location Type | AC1: Attachment: File Link | AD1: Attachment: Id | AE1: Attachment: Attach to email
B2: ='QBO Transactions'!$U4 -> Brex Credit Card | C2: ='QBO Transactions'!$S4 -> 53 | D2: ='QBO Transactions'!$R4 -> SpotHero | F2: ='QBO Transactions'!$X4 -> Cost of Goods Sold:COGS- Travel Expenses:Ground Transportation | N2: ='QBO Transactions'!$Y4 -> 200- Datadog:220- Engineering | Q2: ='QBO Transactions'!$T4 -> SPOTHERO 844-356-8054 MASTERCARD-XXXXXXPJG2AN-Logan Rohloff | X2: =Q2 -> SPOTHERO 844-356-8054 MASTERCARD-XXXXXXPJG2AN-Logan Rohloff | Y2: ='QBO Transactions'!$Q4 -> 46233
B3: ='QBO Transactions'!$U5 -> Brex Credit Card | C3: ='QBO Transactions'!$S5 -> 5207.23 | D3: ='QBO Transactions'!$R5 -> Anthropic | F3: ='QBO Transactions'!$X5 -> General & Administrative:Software Licenses | N3: ='QBO Transactions'!$Y5 -> 100- Operations:110- G&A | Q3: ='QBO Transactions'!$T5 -> ANTHROPIC MASTERCARD-XXXXXXQYD6Y9-Eric Rabkin | X3: =Q3 -> ANTHROPIC MASTERCARD-XXXXXXQYD6Y9-Eric Rabkin | Y3: ='QBO Transactions'!$Q5 -> 46233
B4: ='QBO Transactions'!$U6 -> Brex Credit Card | C4: ='QBO Transactions'!$S6 -> 78.95 | D4: ='QBO Transactions'!$R6 -> Uber | F4: ='QBO Transactions'!$X6 -> General & Administrative:G&A- Travel Expenses:Ground Transportation | N4: ='QBO Transactions'!$Y6 -> 300- ServiceNow:320- Engineering | Q4: ='QBO Transactions'!$T6 -> UBER *TRIP MASTERCARD-XXXXXX9HTP2T-Daniel Blauvelt | X4: =Q4 -> UBER *TRIP MASTERCARD-XXXXXX9HTP2T-Daniel Blauvelt | Y4: ='QBO Transactions'!$Q6 -> 46233
B5: ='QBO Transactions'!$U7 -> Brex Credit Card | C5: ='QBO Transactions'!$S7 -> 37.03 | D5: ='QBO Transactions'!$R7 -> Sweeney's | F5: ='QBO Transactions'!$X7 -> Sales & Marketing:Sales & Marketing- Travel Expenses:Meals & Entertainment | N5: ='QBO Transactions'!$Y7 -> 300- ServiceNow:330- Sales | Q5: ='QBO Transactions'!$T7 -> TST*SWEENEYS MASTERCARD-XXXXXXNQXBCA-Ryan Hale | X5: =Q5 -> TST*SWEENEYS MASTERCARD-XXXXXXNQXBCA-Ryan Hale | Y5: ='QBO Transactions'!$Q7 -> 46233
B6: ='QBO Transactions'!$U8 -> Brex Credit Card | C6: ='QBO Transactions'!$S8 -> 41.38 | D6: ='QBO Transactions'!$R8 -> Uber | F6: ='QBO Transactions'!$X8 -> Sales & Marketing:Sales & Marketing- Travel Expenses:Ground Transportation | N6: ='QBO Transactions'!$Y8 -> 200- Datadog:230- Sales | Q6: ='QBO Transactions'!$T8 -> UBER *EATS HELP.UBER.C MASTERCARD-XXXXXXFXJBXL-Jackson Donahoe | X6: =Q6 -> UBER *EATS HELP.UBER.C MASTERCARD-XXXXXXFXJBXL-Jackson Donahoe | Y6: ='QBO Transactions'!$Q8 -> 46233
B7: ='QBO Transactions'!$U9 -> Brex Credit Card | C7: ='QBO Transactions'!$S9 -> 20.99 | D7: ='QBO Transactions'!$R9 -> Uber | F7: ='QBO Transactions'!$X9 -> General & Administrative:G&A- Travel Expenses:Ground Transportation | N7: ='QBO Transactions'!$Y9 -> 100- Operations:110- G&A | Q7: ='QBO Transactions'!$T9 -> UBER *TRIP MASTERCARD-XXXXXX113XV3-Michael Button | X7: =Q7 -> UBER *TRIP MASTERCARD-XXXXXX113XV3-Michael Button | Y7: ='QBO Transactions'!$Q9 -> 46233
B8: ='QBO Transactions'!$U10 -> Brex Credit Card | C8: ='QBO Transactions'!$S10 -> 8 | D8: ='QBO Transactions'!$R10 -> Uber | F8: ='QBO Transactions'!$X10 -> Sales & Marketing:Sales & Marketing- Travel Expenses:Ground Transportation | N8: ='QBO Transactions'!$Y10 -> 100- Operations:120- Marketing | Q8: ='QBO Transactions'!$T10 -> UBER *TRIP MASTERCARD-XXXXXXPLNGVU-Leslee Brady | X8: =Q8 -> UBER *TRIP MASTERCARD-XXXXXXPLNGVU-Leslee Brady | Y8: ='QBO Transactions'!$Q10 -> 46233
B9: ='QBO Transactions'!$U11 -> Brex Credit Card | C9: ='QBO Transactions'!$S11 -> 35.98 | D9: ='QBO Transactions'!$R11 -> Uber | F9: ='QBO Transactions'!$X11 -> Cost of Goods Sold:COGS- Travel Expenses:Ground Transportation | N9: ='QBO Transactions'!$Y11 -> 300- ServiceNow:320- Engineering | Q9: ='QBO Transactions'!$T11 -> UBER *TRIP MASTERCARD-XXXXXXDU86DC-William Watson | X9: =Q9 -> UBER *TRIP MASTERCARD-XXXXXXDU86DC-William Watson | Y9: ='QBO Transactions'!$Q11 -> 46233
B10: ='QBO Transactions'!$U12 -> Brex Credit Card | C10: ='QBO Transactions'!$S12 -> 5 | D10: ='QBO Transactions'!$R12 -> Uber | F10: ='QBO Transactions'!$X12 -> Cost of Goods Sold:COGS- Travel Expenses:Ground Transportation | N10: ='QBO Transactions'!$Y12 -> 300- ServiceNow:320- Engineering | Q10: ='QBO Transactions'!$T12 -> UBER *TRIP MASTERCARD-XXXXXXRH0ON1-Jonathan Stricklin | X10: =Q10 -> UBER *TRIP MASTERCARD-XXXXXXRH0ON1-Jonathan Stricklin | Y10: ='QBO Transactions'!$Q12 -> 46233
B11: ='QBO Transactions'!$U13 -> Brex Credit Card | C11: ='QBO Transactions'!$S13 -> 47.1 | D11: ='QBO Transactions'!$R13 -> Uber | F11: ='QBO Transactions'!$X13 -> General & Administrative:G&A- Travel Expenses:Ground Transportation | N11: ='QBO Transactions'!$Y13 -> 100- Operations:110- G&A | Q11: ='QBO Transactions'!$T13 -> UBER *TRIP MASTERCARD-XXXXXXBVS4W8-Frederick Simpson | X11: =Q11 -> UBER *TRIP MASTERCARD-XXXXXXBVS4W8-Frederick Simpson | Y11: ='QBO Transactions'!$Q13 -> 46233
B12: ='QBO Transactions'!$U14 -> Brex Credit Card | C12: ='QBO Transactions'!$S14 -> 83.96 | D12: ='QBO Transactions'!$R14 -> Uber | F12: ='QBO Transactions'!$X14 -> General & Administrative:G&A- Travel Expenses:Ground Transportation | N12: ='QBO Transactions'!$Y14 -> 100- Operations:110- G&A | Q12: ='QBO Transactions'!$T14 -> UBER *TRIP MASTERCARD-XXXXXXF6IXA9-Michael Button | X12: =Q12 -> UBER *TRIP MASTERCARD-XXXXXXF6IXA9-Michael Button | Y12: ='QBO Transactions'!$Q14 -> 46233
B13: ='QBO Transactions'!$U15 -> Brex Credit Card | C13: ='QBO Transactions'!$S15 -> 20.27 | D13: ='QBO Transactions'!$R15 -> Uber | F13: ='QBO Transactions'!$X15 -> Cost of Goods Sold:COGS- Travel Expenses:Ground Transportation | N13: ='QBO Transactions'!$Y15 -> 300- ServiceNow:320- Engineering | Q13: ='QBO Transactions'!$T15 -> UBER *TRIP MASTERCARD-XXXXXXO1EQ9C-Tokuya Takahashi | X13: =Q13 -> UBER *TRIP MASTERCARD-XXXXXXO1EQ9C-Tokuya Takahashi | Y13: ='QBO Transactions'!$Q15 -> 46233
... B657: ='QBO Transactions'!$U659 | C657: ='QBO Transactions'!$S659 | D657: ='QBO Transactions'!$R659 | F657: ='QBO Transactions'!$X659 | N657: ='QBO Transactions'!$Y659 | Q657: ='QBO Transactions'!$T659 | X657: =Q657 | Y657: ='QBO Transactions'!$Q659

Sheet QBO Transactions
C1: Credit Card Account: | D1: Brex Credit Card | I1: Travel Vendor | K1: Taxi Vendor
B2: QBO Credit Card Transaction Data | I2: Food Vendor | K2: Office Vendor
B3: DATE | C3: DESCRIPTION | D3: Payee | E3: Category or Match | F3: SPENT | G3: RECEIVED | H3: xxx | I3: Payee Override | J3: Full Acct Override | K3: Parent Category Override | L3: Sub Category Override | M3: Dept Override | N3: Card # | O3: Card Name | P3: EE ID | Q3: Date | R3: Vendor | S3: Amount | T3: Updated Description | U3: Card Acct | V3: Parent Category | W3: Sub Category | X3: Line Acct | Y3: Department | Z3: Acct Check
B4: 46233 | C4: SPOTHERO 844-356-8054 MASTERCARD-XXXXXXPJG2AN-Logan Rohloff | E4: Sales & Marketing:Sales & Marketing- Travel Expenses:Ground Transportation | F4: 53 | I4: SpotHero | L4: Ground Transportation | O4: =IF(C4="", "", TRIM(RIGHT(C4, LEN(C4) - FIND("@@", SUBSTITUTE(C4, "-", "@@", LEN(C4) - LEN(SUBSTITUTE(C4, "-", ""))))))) -> Logan Rohloff | P4: =IFERROR(_xlfn.XLOOKUP(O4,'Department Listing'!$O$1:$O$395,'Department Listing'!$A$1:$A$395),IFERROR(_xlfn.XLOOKUP(O4,'Name Aliases'!$A$2:$A$1000,'Name Aliases'!$B$2:$B$1000),"")) -> 8 | Q4: =IF(ISBLANK($C4),"",$B4) -> 46233 | R4: =IF(ISBLANK($C4),"",IF(ISBLANK($I4),$D4,$I4)) -> SpotHero | S4: =IF(ISBLANK($C4),"",$F4 - $G4) -> 53 | T4: =IF(ISBLANK($C4),"",C4) -> SPOTHERO 844-356-8054 MASTERCARD-XXXXXXPJG2AN-Logan Rohloff | U4: =IF(ISBLANK($C4),"",$D$1) -> Brex Credit Card | V4: =IF(ISBLANK($B4),"",IF(ISBLANK($K4),IF(_xlfn.XLOOKUP($W4,'Category Mapping'!$C:$C,'Category Mapping'!$B:$B)="Travel",_xlfn.XLOOKUP($P4,'Department Listing'!$A:$A,'Department Listing'!$M:$M),_xlfn.XLOOKUP($W4,'Category Mapping'!$C:$C,'Category Mapping'!$D:$D)),$K4)) -> Cost of Goods Sold:COGS- Travel Expenses: | W4: =IF(ISBLANK($B4),"",IF(ISBLANK($L4),RIGHT($E4,LEN($E4) - FIND("^",SUBSTITUTE($E4,":","^",LEN($E4) - LEN(SUBSTITUTE($E4,":",""))))),$L4)) -> Ground Transportation | X4: =IF(ISBLANK($J4),$V4&$W4,$J4) -> Cost of Goods Sold:COGS- Travel Expenses:Ground Transportation | Y4: =IF(ISBLANK($M4),IFERROR(_xlfn.XLOOKUP($P4,'Department Listing'!$A:$A,'Department Listing'!$L:$L),""),$M4) -> 200- Datadog:220- Engineering | Z4: =IF(ISBLANK($B4),"",MATCH($X4,COA!$B:$B,0)) -> 124
B5: 46233 | C5: ANTHROPIC MASTERCARD-XXXXXXQYD6Y9-Eric Rabkin | E5: General & Administrative:Software Licenses | F5: 5207.23 | I5: Anthropic | L5: Software Licenses | O5: =IF(C5="", "", TRIM(RIGHT(C5, LEN(C5) - FIND("@@", SUBSTITUTE(C5, "-", "@@", LEN(C5) - LEN(SUBSTITUTE(C5, "-", ""))))))) -> Eric Rabkin | P5: =IFERROR(_xlfn.XLOOKUP(O5,'Department Listing'!$O$1:$O$395,'Department Listing'!$A$1:$A$395),IFERROR(_xlfn.XLOOKUP(O5,'Name Aliases'!$A$2:$A$1000,'Name Aliases'!$B$2:$B$1000),"")) -> 246 | Q5: =IF(ISBLANK($C5),"",$B5) -> 46233 | R5: =IF(ISBLANK($C5),"",IF(ISBLANK($I5),$D5,$I5)) -> Anthropic | S5: =IF(ISBLANK($C5),"",$F5 - $G5) -> 5207.23 | T5: =IF(ISBLANK($C5),"",C5) -> ANTHROPIC MASTERCARD-XXXXXXQYD6Y9-Eric Rabkin | U5: =IF(ISBLANK($C5),"",$D$1) -> Brex Credit Card | V5: =IF(ISBLANK($B5),"",IF(ISBLANK($K5),IF(_xlfn.XLOOKUP($W5,'Category Mapping'!$C:$C,'Category Mapping'!$B:$B)="Travel",_xlfn.XLOOKUP($P5,'Department Listing'!$A:$A,'Department Listing'!$M:$M),_xlfn.XLOOKUP($W5,'Category Mapping'!$C:$C,'Category Mapping'!$D:$D)),$K5)) -> General & Administrative: | W5: =IF(ISBLANK($B5),"",IF(ISBLANK($L5),RIGHT($E5,LEN($E5) - FIND("^",SUBSTITUTE($E5,":","^",LEN($E5) - LEN(SUBSTITUTE($E5,":",""))))),$L5)) -> Software Licenses | X5: =IF(ISBLANK($J5),$V5&$W5,$J5) -> General & Administrative:Software Licenses | Y5: =IF(ISBLANK($M5),IFERROR(_xlfn.XLOOKUP($P5,'Department Listing'!$A:$A,'Department Listing'!$L:$L),""),$M5) -> 100- Operations:110- G&A | Z5: =IF(ISBLANK($B5),"",MATCH($X5,COA!$B:$B,0)) -> 170
B6: 46233 | C6: UBER *TRIP MASTERCARD-XXXXXX9HTP2T-Daniel Blauvelt | E6: Sales & Marketing:Sales & Marketing- Travel Expenses:Ground Transportation | F6: 78.95 | I6: Uber | L6: Ground Transportation | O6: =IF(C6="", "", TRIM(RIGHT(C6, LEN(C6) - FIND("@@", SUBSTITUTE(C6, "-", "@@", LEN(C6) - LEN(SUBSTITUTE(C6, "-", ""))))))) -> Daniel Blauvelt | P6: =IFERROR(_xlfn.XLOOKUP(O6,'Department Listing'!$O$1:$O$395,'Department Listing'!$A$1:$A$395),IFERROR(_xlfn.XLOOKUP(O6,'Name Aliases'!$A$2:$A$1000,'Name Aliases'!$B$2:$B$1000),"")) -> 207 | Q6: =IF(ISBLANK($C6),"",$B6) -> 46233 | R6: =IF(ISBLANK($C6),"",IF(ISBLANK($I6),$D6,$I6)) -> Uber | S6: =IF(ISBLANK($C6),"",$F6 - $G6) -> 78.95 | T6: =IF(ISBLANK($C6),"",C6) -> UBER *TRIP MASTERCARD-XXXXXX9HTP2T-Daniel Blauvelt | U6: =IF(ISBLANK($C6),"",$D$1) -> Brex Credit Card | V6: =IF(ISBLANK($B6),"",IF(ISBLANK($K6),IF(_xlfn.XLOOKUP($W6,'Category Mapping'!$C:$C,'Category Mapping'!$B:$B)="Travel",_xlfn.XLOOKUP($P6,'Department Listing'!$A:$A,'Department Listing'!$M:$M),_xlfn.XLOOKUP($W6,'Category Mapping'!$C:$C,'Category Mapping'!$D:$D)),$K6)) -> General & Administrative:G&A- Travel Expenses: | W6: =IF(ISBLANK($B6),"",IF(ISBLANK($L6),RIGHT($E6,LEN($E6) - FIND("^",SUBSTITUTE($E6,":","^",LEN($E6) - LEN(SUBSTITUTE($E6,":",""))))),$L6)) -> Ground Transportation | X6: =IF(ISBLANK($J6),$V6&$W6,$J6) -> General & Administrative:G&A- Travel Expenses:Ground Transportation | Y6: =IF(ISBLANK($M6),IFERROR(_xlfn.XLOOKUP($P6,'Department Listing'!$A:$A,'Department Listing'!$L:$L),""),$M6) -> 300- ServiceNow:320- Engineering | Z6: =IF(ISBLANK($B6),"",MATCH($X6,COA!$B:$B,0)) -> 149
B7: 46233 | C7: TST*SWEENEYS MASTERCARD-XXXXXXNQXBCA-Ryan Hale | E7: Sales & Marketing:Sales & Marketing- Travel Expenses:Meals & Entertainment | F7: 37.03 | I7: Sweeney's | L7: Meals & Entertainment | O7: =IF(C7="", "", TRIM(RIGHT(C7, LEN(C7) - FIND("@@", SUBSTITUTE(C7, "-", "@@", LEN(C7) - LEN(SUBSTITUTE(C7, "-", ""))))))) -> Ryan Hale | P7: =IFERROR(_xlfn.XLOOKUP(O7,'Department Listing'!$O$1:$O$395,'Department Listing'!$A$1:$A$395),IFERROR(_xlfn.XLOOKUP(O7,'Name Aliases'!$A$2:$A$1000,'Name Aliases'!$B$2:$B$1000),"")) -> 222 | Q7: =IF(ISBLANK($C7),"",$B7) -> 46233 | R7: =IF(ISBLANK($C7),"",IF(ISBLANK($I7),$D7,$I7)) -> Sweeney's | S7: =IF(ISBLANK($C7),"",$F7 - $G7) -> 37.03 | T7: =IF(ISBLANK($C7),"",C7) -> TST*SWEENEYS MASTERCARD-XXXXXXNQXBCA-Ryan Hale | U7: =IF(ISBLANK($C7),"",$D$1) -> Brex Credit Card | V7: =IF(ISBLANK($B7),"",IF(ISBLANK($K7),IF(_xlfn.XLOOKUP($W7,'Category Mapping'!$C:$C,'Category Mapping'!$B:$B)="Travel",_xlfn.XLOOKUP($P7,'Department Listing'!$A:$A,'Department Listing'!$M:$M),_xlfn.XLOOKUP($W7,'Category Mapping'!$C:$C,'Category Mapping'!$D:$D)),$K7)) -> Sales & Marketing:Sales & Marketing- Travel Expenses: | W7: =IF(ISBLANK($B7),"",IF(ISBLANK($L7),RIGHT($E7,LEN($E7) - FIND("^",SUBSTITUTE($E7,":","^",LEN($E7) - LEN(SUBSTITUTE($E7,":",""))))),$L7)) -> Meals & Entertainment | X7: =IF(ISBLANK($J7),$V7&$W7,$J7) -> Sales & Marketing:Sales & Marketing- Travel Expenses:Meals & Entertainment | Y7: =IF(ISBLANK($M7),IFERROR(_xlfn.XLOOKUP($P7,'Department Listing'!$A:$A,'Department Listing'!$L:$L),""),$M7) -> 300- ServiceNow:330- Sales | Z7: =IF(ISBLANK($B7),"",MATCH($X7,COA!$B:$B,0)) -> 202
B8: 46233 | C8: UBER *EATS HELP.UBER.C MASTERCARD-XXXXXXFXJBXL-Jackson Donahoe | E8: Sales & Marketing:Sales & Marketing- Travel Expenses:Ground Transportation | F8: 41.38 | I8: Uber | L8: Ground Transportation | O8: =IF(C8="", "", TRIM(RIGHT(C8, LEN(C8) - FIND("@@", SUBSTITUTE(C8, "-", "@@", LEN(C8) - LEN(SUBSTITUTE(C8, "-", ""))))))) -> Jackson Donahoe | P8: =IFERROR(_xlfn.XLOOKUP(O8,'Department Listing'!$O$1:$O$395,'Department Listing'!$A$1:$A$395),IFERROR(_xlfn.XLOOKUP(O8,'Name Aliases'!$A$2:$A$1000,'Name Aliases'!$B$2:$B$1000),"")) -> 143 | Q8: =IF(ISBLANK($C8),"",$B8) -> 46233 | R8: =IF(ISBLANK($C8),"",IF(ISBLANK($I8),$D8,$I8)) -> Uber | S8: =IF(ISBLANK($C8),"",$F8 - $G8) -> 41.38 | T8: =IF(ISBLANK($C8),"",C8) -> UBER *EATS HELP.UBER.C MASTERCARD-XXXXXXFXJBXL-Jackson Donahoe | U8: =IF(ISBLANK($C8),"",$D$1) -> Brex Credit Card | V8: =IF(ISBLANK($B8),"",IF(ISBLANK($K8),IF(_xlfn.XLOOKUP($W8,'Category Mapping'!$C:$C,'Category Mapping'!$B:$B)="Travel",_xlfn.XLOOKUP($P8,'Department Listing'!$A:$A,'Department Listing'!$M:$M),_xlfn.XLOOKUP($W8,'Category Mapping'!$C:$C,'Category Mapping'!$D:$D)),$K8)) -> Sales & Marketing:Sales & Marketing- Travel Expenses: | W8: =IF(ISBLANK($B8),"",IF(ISBLANK($L8),RIGHT($E8,LEN($E8) - FIND("^",SUBSTITUTE($E8,":","^",LEN($E8) - LEN(SUBSTITUTE($E8,":",""))))),$L8)) -> Ground Transportation | X8: =IF(ISBLANK($J8),$V8&$W8,$J8) -> Sales & Marketing:Sales & Marketing- Travel Expenses:Ground Transportation | Y8: =IF(ISBLANK($M8),IFERROR(_xlfn.XLOOKUP($P8,'Department Listing'!$A:$A,'Department Listing'!$L:$L),""),$M8) -> 200- Datadog:230- Sales | Z8: =IF(ISBLANK($B8),"",MATCH($X8,COA!$B:$B,0)) -> 200
B9: 46233 | C9: UBER *TRIP MASTERCARD-XXXXXX113XV3-Michael Button | E9: Sales & Marketing:Sales & Marketing- Travel Expenses:Ground Transportation | F9: 20.99 | I9: Uber | L9: Ground Transportation | O9: =IF(C9="", "", TRIM(RIGHT(C9, LEN(C9) - FIND("@@", SUBSTITUTE(C9, "-", "@@", LEN(C9) - LEN(SUBSTITUTE(C9, "-", ""))))))) -> Michael Button | P9: =IFERROR(_xlfn.XLOOKUP(O9,'Department Listing'!$O$1:$O$395,'Department Listing'!$A$1:$A$395),IFERROR(_xlfn.XLOOKUP(O9,'Name Aliases'!$A$2:$A$1000,'Name Aliases'!$B$2:$B$1000),"")) -> 273 | Q9: =IF(ISBLANK($C9),"",$B9) -> 46233 | R9: =IF(ISBLANK($C9),"",IF(ISBLANK($I9),$D9,$I9)) -> Uber | S9: =IF(ISBLANK($C9),"",$F9 - $G9) -> 20.99 | T9: =IF(ISBLANK($C9),"",C9) -> UBER *TRIP MASTERCARD-XXXXXX113XV3-Michael Button | U9: =IF(ISBLANK($C9),"",$D$1) -> Brex Credit Card | V9: =IF(ISBLANK($B9),"",IF(ISBLANK($K9),IF(_xlfn.XLOOKUP($W9,'Category Mapping'!$C:$C,'Category Mapping'!$B:$B)="Travel",_xlfn.XLOOKUP($P9,'Department Listing'!$A:$A,'Department Listing'!$M:$M),_xlfn.XLOOKUP($W9,'Category Mapping'!$C:$C,'Category Mapping'!$D:$D)),$K9)) -> General & Administrative:G&A- Travel Expenses: | W9: =IF(ISBLANK($B9),"",IF(ISBLANK($L9),RIGHT($E9,LEN($E9) - FIND("^",SUBSTITUTE($E9,":","^",LEN($E9) - LEN(SUBSTITUTE($E9,":",""))))),$L9)) -> Ground Transportation | X9: =IF(ISBLANK($J9),$V9&$W9,$J9) -> General & Administrative:G&A- Travel Expenses:Ground Transportation | Y9: =IF(ISBLANK($M9),IFERROR(_xlfn.XLOOKUP($P9,'Department Listing'!$A:$A,'Department Listing'!$L:$L),""),$M9) -> 100- Operations:110- G&A | Z9: =IF(ISBLANK($B9),"",MATCH($X9,COA!$B:$B,0)) -> 149
B10: 46233 | C10: UBER *TRIP MASTERCARD-XXXXXXPLNGVU-Leslee Brady | E10: Sales & Marketing:Sales & Marketing- Travel Expenses:Ground Transportation | F10: 8 | I10: Uber | L10: Ground Transportation | O10: =IF(C10="", "", TRIM(RIGHT(C10, LEN(C10) - FIND("@@", SUBSTITUTE(C10, "-", "@@", LEN(C10) - LEN(SUBSTITUTE(C10, "-", ""))))))) -> Leslee Brady | P10: =IFERROR(_xlfn.XLOOKUP(O10,'Department Listing'!$O$1:$O$395,'Department Listing'!$A$1:$A$395),IFERROR(_xlfn.XLOOKUP(O10,'Name Aliases'!$A$2:$A$1000,'Name Aliases'!$B$2:$B$1000),"")) -> 103 | Q10: =IF(ISBLANK($C10),"",$B10) -> 46233 | R10: =IF(ISBLANK($C10),"",IF(ISBLANK($I10),$D10,$I10)) -> Uber | S10: =IF(ISBLANK($C10),"",$F10 - $G10) -> 8 | T10: =IF(ISBLANK($C10),"",C10) -> UBER *TRIP MASTERCARD-XXXXXXPLNGVU-Leslee Brady | U10: =IF(ISBLANK($C10),"",$D$1) -> Brex Credit Card | V10: =IF(ISBLANK($B10),"",IF(ISBLANK($K10),IF(_xlfn.XLOOKUP($W10,'Category Mapping'!$C:$C,'Category Mapping'!$B:$B)="Travel",_xlfn.XLOOKUP($P10,'Department Listing'!$A:$A,'Department Listing'!$M:$M),_xlfn.XLOOKUP($W10,'Category Mapping'!$C:$C,'Category Mapping'!$D:$D)),$K10)) -> Sales & Marketing:Sales & Marketing- Travel Expenses: | W10: =IF(ISBLANK($B10),"",IF(ISBLANK($L10),RIGHT($E10,LEN($E10) - FIND("^",SUBSTITUTE($E10,":","^",LEN($E10) - LEN(SUBSTITUTE($E10,":",""))))),$L10)) -> Ground Transportation | X10: =IF(ISBLANK($J10),$V10&$W10,$J10) -> Sales & Marketing:Sales & Marketing- Travel Expenses:Ground Transportation | Y10: =IF(ISBLANK($M10),IFERROR(_xlfn.XLOOKUP($P10,'Department Listing'!$A:$A,'Department Listing'!$L:$L),""),$M10) -> 100- Operations:120- Marketing | Z10: =IF(ISBLANK($B10),"",MATCH($X10,COA!$B:$B,0)) -> 200
B11: 46233 | C11: UBER *TRIP MASTERCARD-XXXXXXDU86DC-William Watson | E11: Sales & Marketing:Sales & Marketing- Travel Expenses:Ground Transportation | F11: 35.98 | I11: Uber | L11: Ground Transportation | O11: =IF(C11="", "", TRIM(RIGHT(C11, LEN(C11) - FIND("@@", SUBSTITUTE(C11, "-", "@@", LEN(C11) - LEN(SUBSTITUTE(C11, "-", ""))))))) -> William Watson | P11: =IFERROR(_xlfn.XLOOKUP(O11,'Department Listing'!$O$1:$O$395,'Department Listing'!$A$1:$A$395),IFERROR(_xlfn.XLOOKUP(O11,'Name Aliases'!$A$2:$A$1000,'Name Aliases'!$B$2:$B$1000),"")) -> 116 | Q11: =IF(ISBLANK($C11),"",$B11) -> 46233 | R11: =IF(ISBLANK($C11),"",IF(ISBLANK($I11),$D11,$I11)) -> Uber | S11: =IF(ISBLANK($C11),"",$F11 - $G11) -> 35.98 | T11: =IF(ISBLANK($C11),"",C11) -> UBER *TRIP MASTERCARD-XXXXXXDU86DC-William Watson | U11: =IF(ISBLANK($C11),"",$D$1) -> Brex Credit Card | V11: =IF(ISBLANK($B11),"",IF(ISBLANK($K11),IF(_xlfn.XLOOKUP($W11,'Category Mapping'!$C:$C,'Category Mapping'!$B:$B)="Travel",_xlfn.XLOOKUP($P11,'Department Listing'!$A:$A,'Department Listing'!$M:$M),_xlfn.XLOOKUP($W11,'Category Mapping'!$C:$C,'Category Mapping'!$D:$D)),$K11)) -> Cost of Goods Sold:COGS- Travel Expenses: | W11: =IF(ISBLANK($B11),"",IF(ISBLANK($L11),RIGHT($E11,LEN($E11) - FIND("^",SUBSTITUTE($E11,":","^",LEN($E11) - LEN(SUBSTITUTE($E11,":",""))))),$L11)) -> Ground Transportation | X11: =IF(ISBLANK($J11),$V11&$W11,$J11) -> Cost of Goods Sold:COGS- Travel Expenses:Ground Transportation | Y11: =IF(ISBLANK($M11),IFERROR(_xlfn.XLOOKUP($P11,'Department Listing'!$A:$A,'Department Listing'!$L:$L),""),$M11) -> 300- ServiceNow:320- Engineering | Z11: =IF(ISBLANK($B11),"",MATCH($X11,COA!$B:$B,0)) -> 124
B12: 46233 | C12: UBER *TRIP MASTERCARD-XXXXXXRH0ON1-Jonathan Stricklin | E12: Sales & Marketing:Sales & Marketing- Travel Expenses:Ground Transportation | F12: 5 | I12: Uber | L12: Ground Transportation | O12: =IF(C12="", "", TRIM(RIGHT(C12, LEN(C12) - FIND("@@", SUBSTITUTE(C12, "-", "@@", LEN(C12) - LEN(SUBSTITUTE(C12, "-", ""))))))) -> Jonathan Stricklin | P12: =IFERROR(_xlfn.XLOOKUP(O12,'Department Listing'!$O$1:$O$395,'Department Listing'!$A$1:$A$395),IFERROR(_xlfn.XLOOKUP(O12,'Name Aliases'!$A$2:$A$1000,'Name Aliases'!$B$2:$B$1000),"")) -> 167 | Q12: =IF(ISBLANK($C12),"",$B12) -> 46233 | R12: =IF(ISBLANK($C12),"",IF(ISBLANK($I12),$D12,$I12)) -> Uber | S12: =IF(ISBLANK($C12),"",$F12 - $G12) -> 5 | T12: =IF(ISBLANK($C12),"",C12) -> UBER *TRIP MASTERCARD-XXXXXXRH0ON1-Jonathan Stricklin | U12: =IF(ISBLANK($C12),"",$D$1) -> Brex Credit Card | V12: =IF(ISBLANK($B12),"",IF(ISBLANK($K12),IF(_xlfn.XLOOKUP($W12,'Category Mapping'!$C:$C,'Category Mapping'!$B:$B)="Travel",_xlfn.XLOOKUP($P12,'Department Listing'!$A:$A,'Department Listing'!$M:$M),_xlfn.XLOOKUP($W12,'Category Mapping'!$C:$C,'Category Mapping'!$D:$D)),$K12)) -> Cost of Goods Sold:COGS- Travel Expenses: | W12: =IF(ISBLANK($B12),"",IF(ISBLANK($L12),RIGHT($E12,LEN($E12) - FIND("^",SUBSTITUTE($E12,":","^",LEN($E12) - LEN(SUBSTITUTE($E12,":",""))))),$L12)) -> Ground Transportation | X12: =IF(ISBLANK($J12),$V12&$W12,$J12) -> Cost of Goods Sold:COGS- Travel Expenses:Ground Transportation | Y12: =IF(ISBLANK($M12),IFERROR(_xlfn.XLOOKUP($P12,'Department Listing'!$A:$A,'Department Listing'!$L:$L),""),$M12) -> 300- ServiceNow:320- Engineering | Z12: =IF(ISBLANK($B12),"",MATCH($X12,COA!$B:$B,0)) -> 124
B13: 46233 | C13: UBER *TRIP MASTERCARD-XXXXXXBVS4W8-Frederick Simpson | E13: Sales & Marketing:Sales & Marketing- Travel Expenses:Ground Transportation | F13: 47.1 | I13: Uber | L13: Ground Transportation | O13: =IF(C13="", "", TRIM(RIGHT(C13, LEN(C13) - FIND("@@", SUBSTITUTE(C13, "-", "@@", LEN(C13) - LEN(SUBSTITUTE(C13, "-", ""))))))) -> Frederick Simpson | P13: =IFERROR(_xlfn.XLOOKUP(O13,'Department Listing'!$O$1:$O$395,'Department Listing'!$A$1:$A$395),IFERROR(_xlfn.XLOOKUP(O13,'Name Aliases'!$A$2:$A$1000,'Name Aliases'!$B$2:$B$1000),"")) -> 177 | Q13: =IF(ISBLANK($C13),"",$B13) -> 46233 | R13: =IF(ISBLANK($C13),"",IF(ISBLANK($I13),$D13,$I13)) -> Uber | S13: =IF(ISBLANK($C13),"",$F13 - $G13) -> 47.1 | T13: =IF(ISBLANK($C13),"",C13) -> UBER *TRIP MASTERCARD-XXXXXXBVS4W8-Frederick Simpson | U13: =IF(ISBLANK($C13),"",$D$1) -> Brex Credit Card | V13: =IF(ISBLANK($B13),"",IF(ISBLANK($K13),IF(_xlfn.XLOOKUP($W13,'Category Mapping'!$C:$C,'Category Mapping'!$B:$B)="Travel",_xlfn.XLOOKUP($P13,'Department Listing'!$A:$A,'Department Listing'!$M:$M),_xlfn.XLOOKUP($W13,'Category Mapping'!$C:$C,'Category Mapping'!$D:$D)),$K13)) -> General & Administrative:G&A- Travel Expenses: | W13: =IF(ISBLANK($B13),"",IF(ISBLANK($L13),RIGHT($E13,LEN($E13) - FIND("^",SUBSTITUTE($E13,":","^",LEN($E13) - LEN(SUBSTITUTE($E13,":",""))))),$L13)) -> Ground Transportation | X13: =IF(ISBLANK($J13),$V13&$W13,$J13) -> General & Administrative:G&A- Travel Expenses:Ground Transportation | Y13: =IF(ISBLANK($M13),IFERROR(_xlfn.XLOOKUP($P13,'Department Listing'!$A:$A,'Department Listing'!$L:$L),""),$M13) -> 100- Operations:110- G&A | Z13: =IF(ISBLANK($B13),"",MATCH($X13,COA!$B:$B,0)) -> 149
B14: 46233 | C14: UBER *TRIP MASTERCARD-XXXXXXF6IXA9-Michael Button | E14: Sales & Marketing:Sales & Marketing- Travel Expenses:Ground Transportation | F14: 83.96 | I14: Uber | L14: Ground Transportation | O14: =IF(C14="", "", TRIM(RIGHT(C14, LEN(C14) - FIND("@@", SUBSTITUTE(C14, "-", "@@", LEN(C14) - LEN(SUBSTITUTE(C14, "-", ""))))))) -> Michael Button | P14: =IFERROR(_xlfn.XLOOKUP(O14,'Department Listing'!$O$1:$O$395,'Department Listing'!$A$1:$A$395),IFERROR(_xlfn.XLOOKUP(O14,'Name Aliases'!$A$2:$A$1000,'Name Aliases'!$B$2:$B$1000),"")) -> 273 | Q14: =IF(ISBLANK($C14),"",$B14) -> 46233 | R14: =IF(ISBLANK($C14),"",IF(ISBLANK($I14),$D14,$I14)) -> Uber | S14: =IF(ISBLANK($C14),"",$F14 - $G14) -> 83.96 | T14: =IF(ISBLANK($C14),"",C14) -> UBER *TRIP MASTERCARD-XXXXXXF6IXA9-Michael Button | U14: =IF(ISBLANK($C14),"",$D$1) -> Brex Credit Card | V14: =IF(ISBLANK($B14),"",IF(ISBLANK($K14),IF(_xlfn.XLOOKUP($W14,'Category Mapping'!$C:$C,'Category Mapping'!$B:$B)="Travel",_xlfn.XLOOKUP($P14,'Department Listing'!$A:$A,'Department Listing'!$M:$M),_xlfn.XLOOKUP($W14,'Category Mapping'!$C:$C,'Category Mapping'!$D:$D)),$K14)) -> General & Administrative:G&A- Travel Expenses: | W14: =IF(ISBLANK($B14),"",IF(ISBLANK($L14),RIGHT($E14,LEN($E14) - FIND("^",SUBSTITUTE($E14,":","^",LEN($E14) - LEN(SUBSTITUTE($E14,":",""))))),$L14)) -> Ground Transportation | X14: =IF(ISBLANK($J14),$V14&$W14,$J14) -> General & Administrative:G&A- Travel Expenses:Ground Transportation | Y14: =IF(ISBLANK($M14),IFERROR(_xlfn.XLOOKUP($P14,'Department Listing'!$A:$A,'Department Listing'!$L:$L),""),$M14) -> 100- Operations:110- G&A | Z14: =IF(ISBLANK($B14),"",MATCH($X14,COA!$B:$B,0)) -> 149
B15: 46233 | C15: UBER *TRIP MASTERCARD-XXXXXXO1EQ9C-Tokuya Takahashi | E15: Sales & Marketing:Sales & Marketing- Travel Expenses:Ground Transportation | F15: 20.27 | I15: Uber | L15: Ground Transportation | O15: =IF(C15="", "", TRIM(RIGHT(C15, LEN(C15) - FIND("@@", SUBSTITUTE(C15, "-", "@@", LEN(C15) - LEN(SUBSTITUTE(C15, "-", ""))))))) -> Tokuya Takahashi | P15: =IFERROR(_xlfn.XLOOKUP(O15,'Department Listing'!$O$1:$O$395,'Department Listing'!$A$1:$A$395),IFERROR(_xlfn.XLOOKUP(O15,'Name Aliases'!$A$2:$A$1000,'Name Aliases'!$B$2:$B$1000),"")) -> 214 | Q15: =IF(ISBLANK($C15),"",$B15) -> 46233 | R15: =IF(ISBLANK($C15),"",IF(ISBLANK($I15),$D15,$I15)) -> Uber | S15: =IF(ISBLANK($C15),"",$F15 - $G15) -> 20.27 | T15: =IF(ISBLANK($C15),"",C15) -> UBER *TRIP MASTERCARD-XXXXXXO1EQ9C-Tokuya Takahashi | U15: =IF(ISBLANK($C15),"",$D$1) -> Brex Credit Card | V15: =IF(ISBLANK($B15),"",IF(ISBLANK($K15),IF(_xlfn.XLOOKUP($W15,'Category Mapping'!$C:$C,'Category Mapping'!$B:$B)="Travel",_xlfn.XLOOKUP($P15,'Department Listing'!$A:$A,'Department Listing'!$M:$M),_xlfn.XLOOKUP($W15,'Category Mapping'!$C:$C,'Category Mapping'!$D:$D)),$K15)) -> Cost of Goods Sold:COGS- Travel Expenses: | W15: =IF(ISBLANK($B15),"",IF(ISBLANK($L15),RIGHT($E15,LEN($E15) - FIND("^",SUBSTITUTE($E15,":","^",LEN($E15) - LEN(SUBSTITUTE($E15,":",""))))),$L15)) -> Ground Transportation | X15: =IF(ISBLANK($J15),$V15&$W15,$J15) -> Cost of Goods Sold:COGS- Travel Expenses:Ground Transportation | Y15: =IF(ISBLANK($M15),IFERROR(_xlfn.XLOOKUP($P15,'Department Listing'!$A:$A,'Department Listing'!$L:$L),""),$M15) -> 300- ServiceNow:320- Engineering | Z15: =IF(ISBLANK($B15),"",MATCH($X15,COA!$B:$B,0)) -> 124
... B17: 46233 | C17: LYFT *STANDARD 07-29 MASTERCARD-XXXXXXQ5WVA4-Darshilkumar Shah | E17: Sales & Marketing:Sales & Marketing- Travel Expenses:Ground Transportation | F17: 17.94 | I17: Lyft | L17: Ground Transportation | O17: =IF(C17="", "", TRIM(RIGHT(C17, LEN(C17) - FIND("@@", SUBSTITUTE(C17, "-", "@@", LEN(C17) - LEN(SUBSTITUTE(C17, "-", ""))))))) -> Darshilkumar Shah | P17: =IFERROR(_xlfn.XLOOKUP(O17,'Department Listing'!$O$1:$O$395,'Department Listing'!$A$1:$A$395),IFERROR(_xlfn.XLOOKUP(O17,'Name Aliases'!$A$2:$A$1000,'Name Aliases'!$B$2:$B$1000),"")) -> 225 | Q17: =IF(ISBLANK($C17),"",$B17) -> 46233 | R17: =IF(ISBLANK($C17),"",IF(ISBLANK($I17),$D17,$I17)) -> Lyft | S17: =IF(ISBLANK($C17),"",$F17 - $G17) -> 17.94 | T17: =IF(ISBLANK($C17),"",C17) -> LYFT *STANDARD 07-29 MASTERCARD-XXXXXXQ5WVA4-Darshilkumar Shah | U17: =IF(ISBLANK($C17),"",$D$1) -> Brex Credit Card | V17: =IF(ISBLANK($B17),"",IF(ISBLANK($K17),IF(_xlfn.XLOOKUP($W17,'Category Mapping'!$C:$C,'Category Mapping'!$B:$B)="Travel",_xlfn.XLOOKUP($P17,'Department Listing'!$A:$A,'Department Listing'!$M:$M),_xlfn.XLOOKUP($W17,'Category Mapping'!$C:$C,'Category Mapping'!$D:$D)),$K17)) -> General & Administrative:G&A- Travel Expenses: | W17: =IF(ISBLANK($B17),"",IF(ISBLANK($L17),RIGHT($E17,LEN($E17) - FIND("^",SUBSTITUTE($E17,":","^",LEN($E17) - LEN(SUBSTITUTE($E17,":",""))))),$L17)) -> Ground Transportation | X17: =IF(ISBLANK($J17),$V17&$W17,$J17) -> General & Administrative:G&A- Travel Expenses:Ground Transportation | Y17: =IF(ISBLANK($M17),IFERROR(_xlfn.XLOOKUP($P17,'Department Listing'!$A:$A,'Department Listing'!$L:$L),""),$M17) -> 300- ServiceNow:320- Engineering | Z17: =IF(ISBLANK($B17),"",MATCH($X17,COA!$B:$B,0)) -> 149
B18: 46233 | C18: Audible*M65CI3K63 MASTERCARD-XXXXXX0V96UI-Matt Hyman | F18: 16.03 | I18: Office Vendor | L18: Dues & Subscriptions | O18: =IF(C18="", "", TRIM(RIGHT(C18, LEN(C18) - FIND("@@", SUBSTITUTE(C18, "-", "@@", LEN(C18) - LEN(SUBSTITUTE(C18, "-", ""))))))) -> Matt Hyman | P18: =IFERROR(_xlfn.XLOOKUP(O18,'Department Listing'!$O$1:$O$395,'Department Listing'!$A$1:$A$395),IFERROR(_xlfn.XLOOKUP(O18,'Name Aliases'!$A$2:$A$1000,'Name Aliases'!$B$2:$B$1000),"")) -> 24 | Q18: =IF(ISBLANK($C18),"",$B18) -> 46233 | R18: =IF(ISBLANK($C18),"",IF(ISBLANK($I18),$D18,$I18)) -> Office Vendor | S18: =IF(ISBLANK($C18),"",$F18 - $G18) -> 16.03 | T18: =IF(ISBLANK($C18),"",C18) -> Audible*M65CI3K63 MASTERCARD-XXXXXX0V96UI-Matt Hyman | U18: =IF(ISBLANK($C18),"",$D$1) -> Brex Credit Card | V18: =IF(ISBLANK($B18),"",IF(ISBLANK($K18),IF(_xlfn.XLOOKUP($W18,'Category Mapping'!$C:$C,'Category Mapping'!$B:$B)="Travel",_xlfn.XLOOKUP($P18,'Department Listing'!$A:$A,'Department Listing'!$M:$M),_xlfn.XLOOKUP($W18,'Category Mapping'!$C:$C,'Category Mapping'!$D:$D)),$K18)) -> General & Administrative:Office Expenses: | W18: =IF(ISBLANK($B18),"",IF(ISBLANK($L18),RIGHT($E18,LEN($E18) - FIND("^",SUBSTITUTE($E18,":","^",LEN($E18) - LEN(SUBSTITUTE($E18,":",""))))),$L18)) -> Dues & Subscriptions | X18: =IF(ISBLANK($J18),$V18&$W18,$J18) -> General & Administrative:Office Expenses:Dues & Subscriptions | Y18: =IF(ISBLANK($M18),IFERROR(_xlfn.XLOOKUP($P18,'Department Listing'!$A:$A,'Department Listing'!$L:$L),""),$M18) -> 300- ServiceNow:330- Sales | Z18: =IF(ISBLANK($B18),"",MATCH($X18,COA!$B:$B,0)) -> 159
B19: 46233 | C19: UBER *TRIP MASTERCARD-XXXXXXUI2GZ4-Jonathan Stricklin | E19: Sales & Marketing:Sales & Marketing- Travel Expenses:Ground Transportation | F19: 16.98 | I19: Uber | L19: Ground Transportation | O19: =IF(C19="", "", TRIM(RIGHT(C19, LEN(C19) - FIND("@@", SUBSTITUTE(C19, "-", "@@", LEN(C19) - LEN(SUBSTITUTE(C19, "-", ""))))))) -> Jonathan Stricklin | P19: =IFERROR(_xlfn.XLOOKUP(O19,'Department Listing'!$O$1:$O$395,'Department Listing'!$A$1:$A$395),IFERROR(_xlfn.XLOOKUP(O19,'Name Aliases'!$A$2:$A$1000,'Name Aliases'!$B$2:$B$1000),"")) -> 167 | Q19: =IF(ISBLANK($C19),"",$B19) -> 46233 | R19: =IF(ISBLANK($C19),"",IF(ISBLANK($I19),$D19,$I19)) -> Uber | S19: =IF(ISBLANK($C19),"",$F19 - $G19) -> 16.98 | T19: =IF(ISBLANK($C19),"",C19) -> UBER *TRIP MASTERCARD-XXXXXXUI2GZ4-Jonathan Stricklin | U19: =IF(ISBLANK($C19),"",$D$1) -> Brex Credit Card | V19: =IF(ISBLANK($B19),"",IF(ISBLANK($K19),IF(_xlfn.XLOOKUP($W19,'Category Mapping'!$C:$C,'Category Mapping'!$B:$B)="Travel",_xlfn.XLOOKUP($P19,'Department Listing'!$A:$A,'Department Listing'!$M:$M),_xlfn.XLOOKUP($W19,'Category Mapping'!$C:$C,'Category Mapping'!$D:$D)),$K19)) -> Cost of Goods Sold:COGS- Travel Expenses: | W19: =IF(ISBLANK($B19),"",IF(ISBLANK($L19),RIGHT($E19,LEN($E19) - FIND("^",SUBSTITUTE($E19,":","^",LEN($E19) - LEN(SUBSTITUTE($E19,":",""))))),$L19)) -> Ground Transportation | X19: =IF(ISBLANK($J19),$V19&$W19,$J19) -> Cost of Goods Sold:COGS- Travel Expenses:Ground Transportation | Y19: =IF(ISBLANK($M19),IFERROR(_xlfn.XLOOKUP($P19,'Department Listing'!$A:$A,'Department Listing'!$L:$L),""),$M19) -> 300- ServiceNow:320- Engineering | Z19: =IF(ISBLANK($B19),"",MATCH($X19,COA!$B:$B,0)) -> 124
B20: 46233 | C20: TST*SRV - BOSTON MASTERCARD-XXXXXXNLBUC5-Mickenzi Krpec | E20: Sales & Marketing:Sales & Marketing- Travel Expenses:Meals & Entertainment | F20: 8049.24 | I20: Food Vendor | L20: Meals & Entertainment | O20: =IF(C20="", "", TRIM(RIGHT(C20, LEN(C20) - FIND("@@", SUBSTITUTE(C20, "-", "@@", LEN(C20) - LEN(SUBSTITUTE(C20, "-", ""))))))) -> Mickenzi Krpec | P20: =IFERROR(_xlfn.XLOOKUP(O20,'Department Listing'!$O$1:$O$395,'Department Listing'!$A$1:$A$395),IFERROR(_xlfn.XLOOKUP(O20,'Name Aliases'!$A$2:$A$1000,'Name Aliases'!$B$2:$B$1000),"")) -> 170 | Q20: =IF(ISBLANK($C20),"",$B20) -> 46233 | R20: =IF(ISBLANK($C20),"",IF(ISBLANK($I20),$D20,$I20)) -> Food Vendor | S20: =IF(ISBLANK($C20),"",$F20 - $G20) -> 8049.24 | T20: =IF(ISBLANK($C20),"",C20) -> TST*SRV - BOSTON MASTERCARD-XXXXXXNLBUC5-Mickenzi Krpec | U20: =IF(ISBLANK($C20),"",$D$1) -> Brex Credit Card | V20: =IF(ISBLANK($B20),"",IF(ISBLANK($K20),IF(_xlfn.XLOOKUP($W20,'Category Mapping'!$C:$C,'Category Mapping'!$B:$B)="Travel",_xlfn.XLOOKUP($P20,'Department Listing'!$A:$A,'Department Listing'!$M:$M),_xlfn.XLOOKUP($W20,'Category Mapping'!$C:$C,'Category Mapping'!$D:$D)),$K20)) -> General & Administrative:G&A- Travel Expenses: | W20: =IF(ISBLANK($B20),"",IF(ISBLANK($L20),RIGHT($E20,LEN($E20) - FIND("^",SUBSTITUTE($E20,":","^",LEN($E20) - LEN(SUBSTITUTE($E20,":",""))))),$L20)) -> Meals & Entertainment | X20: =IF(ISBLANK($J20),$V20&$W20,$J20) -> General & Administrative:G&A- Travel Expenses:Meals & Entertainment | Y20: =IF(ISBLANK($M20),IFERROR(_xlfn.XLOOKUP($P20,'Department Listing'!$A:$A,'Department Listing'!$L:$L),""),$M20) -> 100- Operations:110- G&A | Z20: =IF(ISBLANK($B20),"",MATCH($X20,COA!$B:$B,0)) -> 151
B21: 46233 | C21: TST*SWEENEYS MASTERCARD-XXXXXX282FVU-Matt Hyman | E21: Sales & Marketing:Sales & Marketing- Travel Expenses:Meals & Entertainment | F21: 37.82 | I21: Sweeney's | L21: Meals & Entertainment | O21: =IF(C21="", "", TRIM(RIGHT(C21, LEN(C21) - FIND("@@", SUBSTITUTE(C21, "-", "@@", LEN(C21) - LEN(SUBSTITUTE(C21, "-", ""))))))) -> Matt Hyman | P21: =IFERROR(_xlfn.XLOOKUP(O21,'Department Listing'!$O$1:$O$395,'Department Listing'!$A$1:$A$395),IFERROR(_xlfn.XLOOKUP(O21,'Name Aliases'!$A$2:$A$1000,'Name Aliases'!$B$2:$B$1000),"")) -> 24 | Q21: =IF(ISBLANK($C21),"",$B21) -> 46233 | R21: =IF(ISBLANK($C21),"",IF(ISBLANK($I21),$D21,$I21)) -> Sweeney's | S21: =IF(ISBLANK($C21),"",$F21 - $G21) -> 37.82 | T21: =IF(ISBLANK($C21),"",C21) -> TST*SWEENEYS MASTERCARD-XXXXXX282FVU-Matt Hyman | U21: =IF(ISBLANK($C21),"",$D$1) -> Brex Credit Card | V21: =IF(ISBLANK($B21),"",IF(ISBLANK($K21),IF(_xlfn.XLOOKUP($W21,'Category Mapping'!$C:$C,'Category Mapping'!$B:$B)="Travel",_xlfn.XLOOKUP($P21,'Department Listing'!$A:$A,'Department Listing'!$M:$M),_xlfn.XLOOKUP($W21,'Category Mapping'!$C:$C,'Category Mapping'!$D:$D)),$K21)) -> Sales & Marketing:Sales & Marketing- Travel Expenses: | W21: =IF(ISBLANK($B21),"",IF(ISBLANK($L21),RIGHT($E21,LEN($E21) - FIND("^",SUBSTITUTE($E21,":","^",LEN($E21) - LEN(SUBSTITUTE($E21,":",""))))),$L21)) -> Meals & Entertainment | X21: =IF(ISBLANK($J21),$V21&$W21,$J21) -> Sales & Marketing:Sales & Marketing- Travel Expenses:Meals & Entertainment | Y21: =IF(ISBLANK($M21),IFERROR(_xlfn.XLOOKUP($P21,'Department Listing'!$A:$A,'Department Listing'!$L:$L),""),$M21) -> 300- ServiceNow:330- Sales | Z21: =IF(ISBLANK($B21),"",MATCH($X21,COA!$B:$B,0)) -> 202
B22: 46233 | C22: UBER *TRIP MASTERCARD-XXXXXX7O5SL0-Saurabh Premraj | E22: Sales & Marketing:Sales & Marketing- Travel Expenses:Ground Transportation | F22: 35.96 | I22: Uber | L22: Ground Transportation | O22: =IF(C22="", "", TRIM(RIGHT(C22, LEN(C22) - FIND("@@", SUBSTITUTE(C22, "-", "@@", LEN(C22) - LEN(SUBSTITUTE(C22, "-", ""))))))) -> Saurabh Premraj | P22: =IFERROR(_xlfn.XLOOKUP(O22,'Department Listing'!$O$1:$O$395,'Department Listing'!$A$1:$A$395),IFERROR(_xlfn.XLOOKUP(O22,'Name Aliases'!$A$2:$A$1000,'Name Aliases'!$B$2:$B$1000),"")) -> 199 | Q22: =IF(ISBLANK($C22),"",$B22) -> 46233 | R22: =IF(ISBLANK($C22),"",IF(ISBLANK($I22),$D22,$I22)) -> Uber | S22: =IF(ISBLANK($C22),"",$F22 - $G22) -> 35.96 | T22: =IF(ISBLANK($C22),"",C22) -> UBER *TRIP MASTERCARD-XXXXXX7O5SL0-Saurabh Premraj | U22: =IF(ISBLANK($C22),"",$D$1) -> Brex Credit Card | V22: =IF(ISBLANK($B22),"",IF(ISBLANK($K22),IF(_xlfn.XLOOKUP($W22,'Category Mapping'!$C:$C,'Category Mapping'!$B:$B)="Travel",_xlfn.XLOOKUP($P22,'Department Listing'!$A:$A,'Department Listing'!$M:$M),_xlfn.XLOOKUP($W22,'Category Mapping'!$C:$C,'Category Mapping'!$D:$D)),$K22)) -> Cost of Goods Sold:COGS- Travel Expenses: | W22: =IF(ISBLANK($B22),"",IF(ISBLANK($L22),RIGHT($E22,LEN($E22) - FIND("^",SUBSTITUTE($E22,":","^",LEN($E22) - LEN(SUBSTITUTE($E22,":",""))))),$L22)) -> Ground Transportation | X22: =IF(ISBLANK($J22),$V22&$W22,$J22) -> Cost of Goods Sold:COGS- Travel Expenses:Ground Transportation | Y22: =IF(ISBLANK($M22),IFERROR(_xlfn.XLOOKUP($P22,'Department Listing'!$A:$A,'Department Listing'!$L:$L),""),$M22) -> 200- Datadog:220- Engineering | Z22: =IF(ISBLANK($B22),"",MATCH($X22,COA!$B:$B,0)) -> 124
B23: 46233 | C23: UBER *TRIP MASTERCARD-XXXXXXQ0RO6W-Zayn Moselhy | E23: Sales & Marketing:Sales & Marketing- Travel Expenses:Ground Transportation | F23: 28.99 | I23: Uber | L23: Ground Transportation | O23: =IF(C23="", "", TRIM(RIGHT(C23, LEN(C23) - FIND("@@", SUBSTITUTE(C23, "-", "@@", LEN(C23) - LEN(SUBSTITUTE(C23, "-", ""))))))) -> Zayn Moselhy | P23: =IFERROR(_xlfn.XLOOKUP(O23,'Department Listing'!$O$1:$O$395,'Department Listing'!$A$1:$A$395),IFERROR(_xlfn.XLOOKUP(O23,'Name Aliases'!$A$2:$A$1000,'Name Aliases'!$B$2:$B$1000),"")) -> 184 | Q23: =IF(ISBLANK($C23),"",$B23) -> 46233 | R23: =IF(ISBLANK($C23),"",IF(ISBLANK($I23),$D23,$I23)) -> Uber | S23: =IF(ISBLANK($C23),"",$F23 - $G23) -> 28.99 | T23: =IF(ISBLANK($C23),"",C23) -> UBER *TRIP MASTERCARD-XXXXXXQ0RO6W-Zayn Moselhy | U23: =IF(ISBLANK($C23),"",$D$1) -> Brex Credit Card | V23: =IF(ISBLANK($B23),"",IF(ISBLANK($K23),IF(_xlfn.XLOOKUP($W23,'Category Mapping'!$C:$C,'Category Mapping'!$B:$B)="Travel",_xlfn.XLOOKUP($P23,'Department Listing'!$A:$A,'Department Listing'!$M:$M),_xlfn.XLOOKUP($W23,'Category Mapping'!$C:$C,'Category Mapping'!$D:$D)),$K23)) -> General & Administrative:G&A- Travel Expenses: | W23: =IF(ISBLANK($B23),"",IF(ISBLANK($L23),RIGHT($E23,LEN($E23) - FIND("^",SUBSTITUTE($E23,":","^",LEN($E23) - LEN(SUBSTITUTE($E23,":",""))))),$L23)) -> Ground Transportation | X23: =IF(ISBLANK($J23),$V23&$W23,$J23) -> General & Administrative:G&A- Travel Expenses:Ground Transportation | Y23: =IF(ISBLANK($M23),IFERROR(_xlfn.XLOOKUP($P23,'Department Listing'!$A:$A,'Department Listing'!$L:$L),""),$M23) -> 100- Operations:110- G&A | Z23: =IF(ISBLANK($B23),"",MATCH($X23,COA!$B:$B,0)) -> 149
B24: 46233 | C24: LYFT *SCHD STD 07-29 MASTERCARD-XXXXXX1Y2IYE-Patrick Donovan | E24: Sales & Marketing:Sales & Marketing- Travel Expenses:Ground Transportation | F24: 55.91 | I24: Lyft | L24: Ground Transportation | O24: =IF(C24="", "", TRIM(RIGHT(C24, LEN(C24) - FIND("@@", SUBSTITUTE(C24, "-", "@@", LEN(C24) - LEN(SUBSTITUTE(C24, "-", ""))))))) -> Patrick Donovan | P24: =IFERROR(_xlfn.XLOOKUP(O24,'Department Listing'!$O$1:$O$395,'Department Listing'!$A$1:$A$395),IFERROR(_xlfn.XLOOKUP(O24,'Name Aliases'!$A$2:$A$1000,'Name Aliases'!$B$2:$B$1000),"")) -> 137 | Q24: =IF(ISBLANK($C24),"",$B24) -> 46233 | R24: =IF(ISBLANK($C24),"",IF(ISBLANK($I24),$D24,$I24)) -> Lyft | S24: =IF(ISBLANK($C24),"",$F24 - $G24) -> 55.91 | T24: =IF(ISBLANK($C24),"",C24) -> LYFT *SCHD STD 07-29 MASTERCARD-XXXXXX1Y2IYE-Patrick Donovan | U24: =IF(ISBLANK($C24),"",$D$1) -> Brex Credit Card | V24: =IF(ISBLANK($B24),"",IF(ISBLANK($K24),IF(_xlfn.XLOOKUP($W24,'Category Mapping'!$C:$C,'Category Mapping'!$B:$B)="Travel",_xlfn.XLOOKUP($P24,'Department Listing'!$A:$A,'Department Listing'!$M:$M),_xlfn.XLOOKUP($W24,'Category Mapping'!$C:$C,'Category Mapping'!$D:$D)),$K24)) -> Cost of Goods Sold:COGS- Travel Expenses: | W24: =IF(ISBLANK($B24),"",IF(ISBLANK($L24),RIGHT($E24,LEN($E24) - FIND("^",SUBSTITUTE($E24,":","^",LEN($E24) - LEN(SUBSTITUTE($E24,":",""))))),$L24)) -> Ground Transportation | X24: =IF(ISBLANK($J24),$V24&$W24,$J24) -> Cost of Goods Sold:COGS- Travel Expenses:Ground Transportation | Y24: =IF(ISBLANK($M24),IFERROR(_xlfn.XLOOKUP($P24,'Department Listing'!$A:$A,'Department Listing'!$L:$L),""),$M24) -> 200- Datadog:210- Delivery | Z24: =IF(ISBLANK($B24),"",MATCH($X24,COA!$B:$B,0)) -> 124
B25: 46233 | C25: UBER *TRIP MASTERCARD-XXXXXXG5H8YM-Frederick Simpson | E25: Sales & Marketing:Sales & Marketing- Travel Expenses:Ground Transportation | F25: 25.81 | I25: Uber | L25: Ground Transportation | O25: =IF(C25="", "", TRIM(RIGHT(C25, LEN(C25) - FIND("@@", SUBSTITUTE(C25, "-", "@@", LEN(C25) - LEN(SUBSTITUTE(C25, "-", ""))))))) -> Frederick Simpson | P25: =IFERROR(_xlfn.XLOOKUP(O25,'Department Listing'!$O$1:$O$395,'Department Listing'!$A$1:$A$395),IFERROR(_xlfn.XLOOKUP(O25,'Name Aliases'!$A$2:$A$1000,'Name Aliases'!$B$2:$B$1000),"")) -> 177 | Q25: =IF(ISBLANK($C25),"",$B25) -> 46233 | R25: =IF(ISBLANK($C25),"",IF(ISBLANK($I25),$D25,$I25)) -> Uber | S25: =IF(ISBLANK($C25),"",$F25 - $G25) -> 25.81 | T25: =IF(ISBLANK($C25),"",C25) -> UBER *TRIP MASTERCARD-XXXXXXG5H8YM-Frederick Simpson | U25: =IF(ISBLANK($C25),"",$D$1) -> Brex Credit Card | V25: =IF(ISBLANK($B25),"",IF(ISBLANK($K25),IF(_xlfn.XLOOKUP($W25,'Category Mapping'!$C:$C,'Category Mapping'!$B:$B)="Travel",_xlfn.XLOOKUP($P25,'Department Listing'!$A:$A,'Department Listing'!$M:$M),_xlfn.XLOOKUP($W25,'Category Mapping'!$C:$C,'Category Mapping'!$D:$D)),$K25)) -> General & Administrative:G&A- Travel Expenses: | W25: =IF(ISBLANK($B25),"",IF(ISBLANK($L25),RIGHT($E25,LEN($E25) - FIND("^",SUBSTITUTE($E25,":","^",LEN($E25) - LEN(SUBSTITUTE($E25,":",""))))),$L25)) -> Ground Transportation | X25: =IF(ISBLANK($J25),$V25&$W25,$J25) -> General & Administrative:G&A- Travel Expenses:Ground Transportation | Y25: =IF(ISBLANK($M25),IFERROR(_xlfn.XLOOKUP($P25,'Department Listing'!$A:$A,'Department Listing'!$L:$L),""),$M25) -> 100- Operations:110- G&A | Z25: =IF(ISBLANK($B25),"",MATCH($X25,COA!$B:$B,0)) -> 149
B26: 46233 | C26: UBER *TRIP MASTERCARD-XXXXXXEGMHWC-Tyler Grimshaw | E26: Sales & Marketing:Sales & Marketing- Travel Expenses:Ground Transportation | F26: 31.99 | I26: Uber | L26: Ground Transportation | O26: =IF(C26="", "", TRIM(RIGHT(C26, LEN(C26) - FIND("@@", SUBSTITUTE(C26, "-", "@@", LEN(C26) - LEN(SUBSTITUTE(C26, "-", ""))))))) -> Tyler Grimshaw | P26: =IFERROR(_xlfn.XLOOKUP(O26,'Department Listing'!$O$1:$O$395,'Department Listing'!$A$1:$A$395),IFERROR(_xlfn.XLOOKUP(O26,'Name Aliases'!$A$2:$A$1000,'Name Aliases'!$B$2:$B$1000),"")) -> 264 | Q26: =IF(ISBLANK($C26),"",$B26) -> 46233 | R26: =IF(ISBLANK($C26),"",IF(ISBLANK($I26),$D26,$I26)) -> Uber | S26: =IF(ISBLANK($C26),"",$F26 - $G26) -> 31.99 | T26: =IF(ISBLANK($C26),"",C26) -> UBER *TRIP MASTERCARD-XXXXXXEGMHWC-Tyler Grimshaw | U26: =IF(ISBLANK($C26),"",$D$1) -> Brex Credit Card | V26: =IF(ISBLANK($B26),"",IF(ISBLANK($K26),IF(_xlfn.XLOOKUP($W26,'Category Mapping'!$C:$C,'Category Mapping'!$B:$B)="Travel",_xlfn.XLOOKUP($P26,'Department Listing'!$A:$A,'Department Listing'!$M:$M),_xlfn.XLOOKUP($W26,'Category Mapping'!$C:$C,'Category Mapping'!$D:$D)),$K26)) -> Sales & Marketing:Sales & Marketing- Travel Expenses: | W26: =IF(ISBLANK($B26),"",IF(ISBLANK($L26),RIGHT($E26,LEN($E26) - FIND("^",SUBSTITUTE($E26,":","^",LEN($E26) - LEN(SUBSTITUTE($E26,":",""))))),$L26)) -> Ground Transportation | X26: =IF(ISBLANK($J26),$V26&$W26,$J26) -> Sales & Marketing:Sales & Marketing- Travel Expenses:Ground Transportation | Y26: =IF(ISBLANK($M26),IFERROR(_xlfn.XLOOKUP($P26,'Department Listing'!$A:$A,'Department Listing'!$L:$L),""),$M26) -> 200- Datadog:230- Sales | Z26: =IF(ISBLANK($B26),"",MATCH($X26,COA!$B:$B,0)) -> 200
B27: 46233 | C27: UBER *TRIP MASTERCARD-XXXXXXR1SOS6-Toni Manning | E27: Sales & Marketing:Sales & Marketing- Travel Expenses:Ground Transportation | F27: 3 | I27: Uber | L27: Ground Transportation | O27: =IF(C27="", "", TRIM(RIGHT(C27, LEN(C27) - FIND("@@", SUBSTITUTE(C27, "-", "@@", LEN(C27) - LEN(SUBSTITUTE(C27, "-", ""))))))) -> Toni Manning | P27: =IFERROR(_xlfn.XLOOKUP(O27,'Department Listing'!$O$1:$O$395,'Department Listing'!$A$1:$A$395),IFERROR(_xlfn.XLOOKUP(O27,'Name Aliases'!$A$2:$A$1000,'Name Aliases'!$B$2:$B$1000),"")) -> 121 | Q27: =IF(ISBLANK($C27),"",$B27) -> 46233 | R27: =IF(ISBLANK($C27),"",IF(ISBLANK($I27),$D27,$I27)) -> Uber | S27: =IF(ISBLANK($C27),"",$F27 - $G27) -> 3 | T27: =IF(ISBLANK($C27),"",C27) -> UBER *TRIP MASTERCARD-XXXXXXR1SOS6-Toni Manning | U27: =IF(ISBLANK($C27),"",$D$1) -> Brex Credit Card | V27: =IF(ISBLANK($B27),"",IF(ISBLANK($K27),IF(_xlfn.XLOOKUP($W27,'Category Mapping'!$C:$C,'Category Mapping'!$B:$B)="Travel",_xlfn.XLOOKUP($P27,'Department Listing'!$A:$A,'Department Listing'!$M:$M),_xlfn.XLOOKUP($W27,'Category Mapping'!$C:$C,'Category Mapping'!$D:$D)),$K27)) -> Sales & Marketing:Sales & Marketing- Travel Expenses: | W27: =IF(ISBLANK($B27),"",IF(ISBLANK($L27),RIGHT($E27,LEN($E27) - FIND("^",SUBSTITUTE($E27,":","^",LEN($E27) - LEN(SUBSTITUTE($E27,":",""))))),$L27)) -> Ground Transportation | X27: =IF(ISBLANK($J27),$V27&$W27,$J27) -> Sales & Marketing:Sales & Marketing- Travel Expenses:Ground Transportation | Y27: =IF(ISBLANK($M27),IFERROR(_xlfn.XLOOKUP($P27,'Department Listing'!$A:$A,'Department Listing'!$L:$L),""),$M27) -> 100- Operations:120- Marketing | Z27: =IF(ISBLANK($B27),"",MATCH($X27,COA!$B:$B,0)) -> 200
B28: 46233 | C28: UBER *TRIP MASTERCARD-XXXXXXXR4LXN-Jackson Donahoe | E28: Sales & Marketing:Sales & Marketing- Travel Expenses:Ground Transportation | F28: 12.99 | I28: Uber | L28: Ground Transportation | O28: =IF(C28="", "", TRIM(RIGHT(C28, LEN(C28) - FIND("@@", SUBSTITUTE(C28, "-", "@@", LEN(C28) - LEN(SUBSTITUTE(C28, "-", ""))))))) -> Jackson Donahoe | P28: =IFERROR(_xlfn.XLOOKUP(O28,'Department Listing'!$O$1:$O$395,'Department Listing'!$A$1:$A$395),IFERROR(_xlfn.XLOOKUP(O28,'Name Aliases'!$A$2:$A$1000,'Name Aliases'!$B$2:$B$1000),"")) -> 143 | Q28: =IF(ISBLANK($C28),"",$B28) -> 46233 | R28: =IF(ISBLANK($C28),"",IF(ISBLANK($I28),$D28,$I28)) -> Uber | S28: =IF(ISBLANK($C28),"",$F28 - $G28) -> 12.99 | T28: =IF(ISBLANK($C28),"",C28) -> UBER *TRIP MASTERCARD-XXXXXXXR4LXN-Jackson Donahoe | U28: =IF(ISBLANK($C28),"",$D$1) -> Brex Credit Card | V28: =IF(ISBLANK($B28),"",IF(ISBLANK($K28),IF(_xlfn.XLOOKUP($W28,'Category Mapping'!$C:$C,'Category Mapping'!$B:$B)="Travel",_xlfn.XLOOKUP($P28,'Department Listing'!$A:$A,'Department Listing'!$M:$M),_xlfn.XLOOKUP($W28,'Category Mapping'!$C:$C,'Category Mapping'!$D:$D)),$K28)) -> Sales & Marketing:Sales & Marketing- Travel Expenses: | W28: =IF(ISBLANK($B28),"",IF(ISBLANK($L28),RIGHT($E28,LEN($E28) - FIND("^",SUBSTITUTE($E28,":","^",LEN($E28) - LEN(SUBSTITUTE($E28,":",""))))),$L28)) -> Ground Transportation | X28: =IF(ISBLANK($J28),$V28&$W28,$J28) -> Sales & Marketing:Sales & Marketing- Travel Expenses:Ground Transportation | Y28: =IF(ISBLANK($M28),IFERROR(_xlfn.XLOOKUP($P28,'Department Listing'!$A:$A,'Department Listing'!$L:$L),""),$M28) -> 200- Datadog:230- Sales | Z28: =IF(ISBLANK($B28),"",MATCH($X28,COA!$B:$B,0)) -> 200
B29: 46233 | C29: UBER *TRIP MASTERCARD-XXXXXXWBKXK9-Robert Kolosky | E29: Sales & Marketing:Sales & Marketing- Travel Expenses:Ground Transportation | F29: 24.97 | I29: Uber | L29: Ground Transportation | O29: =IF(C29="", "", TRIM(RIGHT(C29, LEN(C29) - FIND("@@", SUBSTITUTE(C29, "-", "@@", LEN(C29) - LEN(SUBSTITUTE(C29, "-", ""))))))) -> Robert Kolosky | P29: =IFERROR(_xlfn.XLOOKUP(O29,'Department Listing'!$O$1:$O$395,'Department Listing'!$A$1:$A$395),IFERROR(_xlfn.XLOOKUP(O29,'Name Aliases'!$A$2:$A$1000,'Name Aliases'!$B$2:$B$1000),"")) -> 91 | Q29: =IF(ISBLANK($C29),"",$B29) -> 46233 | R29: =IF(ISBLANK($C29),"",IF(ISBLANK($I29),$D29,$I29)) -> Uber | S29: =IF(ISBLANK($C29),"",$F29 - $G29) -> 24.97 | T29: =IF(ISBLANK($C29),"",C29) -> UBER *TRIP MASTERCARD-XXXXXXWBKXK9-Robert Kolosky | U29: =IF(ISBLANK($C29),"",$D$1) -> Brex Credit Card | V29: =IF(ISBLANK($B29),"",IF(ISBLANK($K29),IF(_xlfn.XLOOKUP($W29,'Category Mapping'!$C:$C,'Category Mapping'!$B:$B)="Travel",_xlfn.XLOOKUP($P29,'Department Listing'!$A:$A,'Department Listing'!$M:$M),_xlfn.XLOOKUP($W29,'Category Mapping'!$C:$C,'Category Mapping'!$D:$D)),$K29)) -> Cost of Goods Sold:COGS- Travel Expenses: | W29: =IF(ISBLANK($B29),"",IF(ISBLANK($L29),RIGHT($E29,LEN($E29) - FIND("^",SUBSTITUTE($E29,":","^",LEN($E29) - LEN(SUBSTITUTE($E29,":",""))))),$L29)) -> Ground Transportation | X29: =IF(ISBLANK($J29),$V29&$W29,$J29) -> Cost of Goods Sold:COGS- Travel Expenses:Ground Transportation | Y29: =IF(ISBLANK($M29),IFERROR(_xlfn.XLOOKUP($P29,'Department Listing'!$A:$A,'Department Listing'!$L:$L),""),$M29) -> 300- ServiceNow:320- Engineering | Z29: =IF(ISBLANK($B29),"",MATCH($X29,COA!$B:$B,0)) -> 124
B30: 46233 | C30: UBER *TRIP MASTERCARD-XXXXXXLK316L-Jonathan Stricklin | E30: Sales & Marketing:Sales & Marketing- Travel Expenses:Ground Transportation | F30: 28.98 | I30: Uber | L30: Ground Transportation | O30: =IF(C30="", "", TRIM(RIGHT(C30, LEN(C30) - FIND("@@", SUBSTITUTE(C30, "-", "@@", LEN(C30) - LEN(SUBSTITUTE(C30, "-", ""))))))) -> Jonathan Stricklin | P30: =IFERROR(_xlfn.XLOOKUP(O30,'Department Listing'!$O$1:$O$395,'Department Listing'!$A$1:$A$395),IFERROR(_xlfn.XLOOKUP(O30,'Name Aliases'!$A$2:$A$1000,'Name Aliases'!$B$2:$B$1000),"")) -> 167 | Q30: =IF(ISBLANK($C30),"",$B30) -> 46233 | R30: =IF(ISBLANK($C30),"",IF(ISBLANK($I30),$D30,$I30)) -> Uber | S30: =IF(ISBLANK($C30),"",$F30 - $G30) -> 28.98 | T30: =IF(ISBLANK($C30),"",C30) -> UBER *TRIP MASTERCARD-XXXXXXLK316L-Jonathan Stricklin | U30: =IF(ISBLANK($C30),"",$D$1) -> Brex Credit Card | V30: =IF(ISBLANK($B30),"",IF(ISBLANK($K30),IF(_xlfn.XLOOKUP($W30,'Category Mapping'!$C:$C,'Category Mapping'!$B:$B)="Travel",_xlfn.XLOOKUP($P30,'Department Listing'!$A:$A,'Department Listing'!$M:$M),_xlfn.XLOOKUP($W30,'Category Mapping'!$C:$C,'Category Mapping'!$D:$D)),$K30)) -> Cost of Goods Sold:COGS- Travel Expenses: | W30: =IF(ISBLANK($B30),"",IF(ISBLANK($L30),RIGHT($E30,LEN($E30) - FIND("^",SUBSTITUTE($E30,":","^",LEN($E30) - LEN(SUBSTITUTE($E30,":",""))))),$L30)) -> Ground Transportation | X30: =IF(ISBLANK($J30),$V30&$W30,$J30) -> Cost of Goods Sold:COGS- Travel Expenses:Ground Transportation | Y30: =IF(ISBLANK($M30),IFERROR(_xlfn.XLOOKUP($P30,'Department Listing'!$A:$A,'Department Listing'!$L:$L),""),$M30) -> 300- ServiceNow:320- Engineering | Z30: =IF(ISBLANK($B30),"",MATCH($X30,COA!$B:$B,0)) -> 124
... B35: 46233 | C35: UBER *TRIP MASTERCARD-XXXXXXPOW1YO-Israel Baral | E35: Sales & Marketing:Sales & Marketing- Travel Expenses:Ground Transportation | F35: 12.94 | I35: Uber | L35: Ground Transportation | O35: =IF(C35="", "", TRIM(RIGHT(C35, LEN(C35) - FIND("@@", SUBSTITUTE(C35, "-", "@@", LEN(C35) - LEN(SUBSTITUTE(C35, "-", ""))))))) -> Israel Baral | P35: =IFERROR(_xlfn.XLOOKUP(O35,'Department Listing'!$O$1:$O$395,'Department Listing'!$A$1:$A$395),IFERROR(_xlfn.XLOOKUP(O35,'Name Aliases'!$A$2:$A$1000,'Name Aliases'!$B$2:$B$1000),"")) -> 215 | Q35: =IF(ISBLANK($C35),"",$B35) -> 46233 | R35: =IF(ISBLANK($C35),"",IF(ISBLANK($I35),$D35,$I35)) -> Uber | S35: =IF(ISBLANK($C35),"",$F35 - $G35) -> 12.94 | T35: =IF(ISBLANK($C35),"",C35) -> UBER *TRIP MASTERCARD-XXXXXXPOW1YO-Israel Baral | U35: =IF(ISBLANK($C35),"",$D$1) -> Brex Credit Card | V35: =IF(ISBLANK($B35),"",IF(ISBLANK($K35),IF(_xlfn.XLOOKUP($W35,'Category Mapping'!$C:$C,'Category Mapping'!$B:$B)="Travel",_xlfn.XLOOKUP($P35,'Department Listing'!$A:$A,'Department Listing'!$M:$M),_xlfn.XLOOKUP($W35,'Category Mapping'!$C:$C,'Category Mapping'!$D:$D)),$K35)) -> Cost of Goods Sold:COGS- Travel Expenses: | W35: =IF(ISBLANK($B35),"",IF(ISBLANK($L35),RIGHT($E35,LEN($E35) - FIND("^",SUBSTITUTE($E35,":","^",LEN($E35) - LEN(SUBSTITUTE($E35,":",""))))),$L35)) -> Ground Transportation | X35: =IF(ISBLANK($J35),$V35&$W35,$J35) -> Cost of Goods Sold:COGS- Travel Expenses:Ground Transportation | Y35: =IF(ISBLANK($M35),IFERROR(_xlfn.XLOOKUP($P35,'Department Listing'!$A:$A,'Department Listing'!$L:$L),""),$M35) -> 300- ServiceNow:320- Engineering | Z35: =IF(ISBLANK($B35),"",MATCH($X35,COA!$B:$B,0)) -> 124
B36: 46233 | C36: VPNE BackBayGarage MASTERCARD-XXXXXXYNKQQQ-Kevin Ebert | F36: 45 | I36: Back Bay Garage | L36: Ground Transportation | O36: =IF(C36="", "", TRIM(RIGHT(C36, LEN(C36) - FIND("@@", SUBSTITUTE(C36, "-", "@@", LEN(C36) - LEN(SUBSTITUTE(C36, "-", ""))))))) -> Kevin Ebert | P36: =IFERROR(_xlfn.XLOOKUP(O36,'Department Listing'!$O$1:$O$395,'Department Listing'!$A$1:$A$395),IFERROR(_xlfn.XLOOKUP(O36,'Name Aliases'!$A$2:$A$1000,'Name Aliases'!$B$2:$B$1000),"")) -> 187 | Q36: =IF(ISBLANK($C36),"",$B36) -> 46233 | R36: =IF(ISBLANK($C36),"",IF(ISBLANK($I36),$D36,$I36)) -> Back Bay Garage | S36: =IF(ISBLANK($C36),"",$F36 - $G36) -> 45 | T36: =IF(ISBLANK($C36),"",C36) -> VPNE BackBayGarage MASTERCARD-XXXXXXYNKQQQ-Kevin Ebert | U36: =IF(ISBLANK($C36),"",$D$1) -> Brex Credit Card | V36: =IF(ISBLANK($B36),"",IF(ISBLANK($K36),IF(_xlfn.XLOOKUP($W36,'Category Mapping'!$C:$C,'Category Mapping'!$B:$B)="Travel",_xlfn.XLOOKUP($P36,'Department Listing'!$A:$A,'Department Listing'!$M:$M),_xlfn.XLOOKUP($W36,'Category Mapping'!$C:$C,'Category Mapping'!$D:$D)),$K36)) -> General & Administrative:G&A- Travel Expenses: | W36: =IF(ISBLANK($B36),"",IF(ISBLANK($L36),RIGHT($E36,LEN($E36) - FIND("^",SUBSTITUTE($E36,":","^",LEN($E36) - LEN(SUBSTITUTE($E36,":",""))))),$L36)) -> Ground Transportation | X36: =IF(ISBLANK($J36),$V36&$W36,$J36) -> General & Administrative:G&A- Travel Expenses:Ground Transportation | Y36: =IF(ISBLANK($M36),IFERROR(_xlfn.XLOOKUP($P36,'Department Listing'!$A:$A,'Department Listing'!$L:$L),""),$M36) -> 100- Operations:110- G&A | Z36: =IF(ISBLANK($B36),"",MATCH($X36,COA!$B:$B,0)) -> 149
B37: 46233 | C37: UBER *TRIP MASTERCARD-XXXXXXJ2BIB9-Dor Vaknin | E37: Sales & Marketing:Sales & Marketing- Travel Expenses:Ground Transportation | F37: 50.48 | I37: Uber | L37: Ground Transportation | O37: =IF(C37="", "", TRIM(RIGHT(C37, LEN(C37) - FIND("@@", SUBSTITUTE(C37, "-", "@@", LEN(C37) - LEN(SUBSTITUTE(C37, "-", ""))))))) -> Dor Vaknin | P37: =IFERROR(_xlfn.XLOOKUP(O37,'Department Listing'!$O$1:$O$395,'Department Listing'!$A$1:$A$395),IFERROR(_xlfn.XLOOKUP(O37,'Name Aliases'!$A$2:$A$1000,'Name Aliases'!$B$2:$B$1000),"")) -> 28 | Q37: =IF(ISBLANK($C37),"",$B37) -> 46233 | R37: =IF(ISBLANK($C37),"",IF(ISBLANK($I37),$D37,$I37)) -> Uber | S37: =IF(ISBLANK($C37),"",$F37 - $G37) -> 50.48 | T37: =IF(ISBLANK($C37),"",C37) -> UBER *TRIP MASTERCARD-XXXXXXJ2BIB9-Dor Vaknin | U37: =IF(ISBLANK($C37),"",$D$1) -> Brex Credit Card | V37: =IF(ISBLANK($B37),"",IF(ISBLANK($K37),IF(_xlfn.XLOOKUP($W37,'Category Mapping'!$C:$C,'Category Mapping'!$B:$B)="Travel",_xlfn.XLOOKUP($P37,'Department Listing'!$A:$A,'Department Listing'!$M:$M),_xlfn.XLOOKUP($W37,'Category Mapping'!$C:$C,'Category Mapping'!$D:$D)),$K37)) -> Cost of Goods Sold:COGS- Travel Expenses: | W37: =IF(ISBLANK($B37),"",IF(ISBLANK($L37),RIGHT($E37,LEN($E37) - FIND("^",SUBSTITUTE($E37,":","^",LEN($E37) - LEN(SUBSTITUTE($E37,":",""))))),$L37)) -> Ground Transportation | X37: =IF(ISBLANK($J37),$V37&$W37,$J37) -> Cost of Goods Sold:COGS- Travel Expenses:Ground Transportation | Y37: =IF(ISBLANK($M37),IFERROR(_xlfn.XLOOKUP($P37,'Department Listing'!$A:$A,'Department Listing'!$L:$L),""),$M37) -> 300- ServiceNow:320- Engineering | Z37: =IF(ISBLANK($B37),"",MATCH($X37,COA!$B:$B,0)) -> 124
B38: 46233 | C38: UBER *TRIP MASTERCARD-XXXXXXFKYF9Q-Ryan Henrich | E38: Sales & Marketing:Sales & Marketing- Travel Expenses:Ground Transportation | F38: 47.98 | I38: Uber | L38: Ground Transportation | O38: =IF(C38="", "", TRIM(RIGHT(C38, LEN(C38) - FIND("@@", SUBSTITUTE(C38, "-", "@@", LEN(C38) - LEN(SUBSTITUTE(C38, "-", ""))))))) -> Ryan Henrich | P38: =IFERROR(_xlfn.XLOOKUP(O38,'Department Listing'!$O$1:$O$395,'Department Listing'!$A$1:$A$395),IFERROR(_xlfn.XLOOKUP(O38,'Name Aliases'!$A$2:$A$1000,'Name Aliases'!$B$2:$B$1000),"")) -> 154 | Q38: =IF(ISBLANK($C38),"",$B38) -> 46233 | R38: =IF(ISBLANK($C38),"",IF(ISBLANK($I38),$D38,$I38)) -> Uber | S38: =IF(ISBLANK($C38),"",$F38 - $G38) -> 47.98 | T38: =IF(ISBLANK($C38),"",C38) -> UBER *TRIP MASTERCARD-XXXXXXFKYF9Q-Ryan Henrich | U38: =IF(ISBLANK($C38),"",$D$1) -> Brex Credit Card | V38: =IF(ISBLANK($B38),"",IF(ISBLANK($K38),IF(_xlfn.XLOOKUP($W38,'Category Mapping'!$C:$C,'Category Mapping'!$B:$B)="Travel",_xlfn.XLOOKUP($P38,'Department Listing'!$A:$A,'Department Listing'!$M:$M),_xlfn.XLOOKUP($W38,'Category Mapping'!$C:$C,'Category Mapping'!$D:$D)),$K38)) -> Sales & Marketing:Sales & Marketing- Travel Expenses: | W38: =IF(ISBLANK($B38),"",IF(ISBLANK($L38),RIGHT($E38,LEN($E38) - FIND("^",SUBSTITUTE($E38,":","^",LEN($E38) - LEN(SUBSTITUTE($E38,":",""))))),$L38)) -> Ground Transportation | X38: =IF(ISBLANK($J38),$V38&$W38,$J38) -> Sales & Marketing:Sales & Marketing- Travel Expenses:Ground Transportation | Y38: =IF(ISBLANK($M38),IFERROR(_xlfn.XLOOKUP($P38,'Department Listing'!$A:$A,'Department Listing'!$L:$L),""),$M38) -> 200- Datadog:230- Sales | Z38: =IF(ISBLANK($B38),"",MATCH($X38,COA!$B:$B,0)) -> 200
B39: 46233 | C39: TST* YELLOW DOOR TAQUE MASTERCARD-XXXXXXN730G8-Mickenzi Krpec | E39: Sales & Marketing:Sales & Marketing- Travel Expenses:Meals & Entertainment | F39: 3500 | I39: Food Vendor | L39: Meals & Entertainment | O39: =IF(C39="", "", TRIM(RIGHT(C39, LEN(C39) - FIND("@@", SUBSTITUTE(C39, "-", "@@", LEN(C39) - LEN(SUBSTITUTE(C39, "-", ""))))))) -> Mickenzi Krpec | P39: =IFERROR(_xlfn.XLOOKUP(O39,'Department Listing'!$O$1:$O$395,'Department Listing'!$A$1:$A$395),IFERROR(_xlfn.XLOOKUP(O39,'Name Aliases'!$A$2:$A$1000,'Name Aliases'!$B$2:$B$1000),"")) -> 170 | Q39: =IF(ISBLANK($C39),"",$B39) -> 46233 | R39: =IF(ISBLANK($C39),"",IF(ISBLANK($I39),$D39,$I39)) -> Food Vendor | S39: =IF(ISBLANK($C39),"",$F39 - $G39) -> 3500 | T39: =IF(ISBLANK($C39),"",C39) -> TST* YELLOW DOOR TAQUE MASTERCARD-XXXXXXN730G8-Mickenzi Krpec | U39: =IF(ISBLANK($C39),"",$D$1) -> Brex Credit Card | V39: =IF(ISBLANK($B39),"",IF(ISBLANK($K39),IF(_xlfn.XLOOKUP($W39,'Category Mapping'!$C:$C,'Category Mapping'!$B:$B)="Travel",_xlfn.XLOOKUP($P39,'Department Listing'!$A:$A,'Department Listing'!$M:$M),_xlfn.XLOOKUP($W39,'Category Mapping'!$C:$C,'Category Mapping'!$D:$D)),$K39)) -> General & Administrative:G&A- Travel Expenses: | W39: =IF(ISBLANK($B39),"",IF(ISBLANK($L39),RIGHT($E39,LEN($E39) - FIND("^",SUBSTITUTE($E39,":","^",LEN($E39) - LEN(SUBSTITUTE($E39,":",""))))),$L39)) -> Meals & Entertainment | X39: =IF(ISBLANK($J39),$V39&$W39,$J39) -> General & Administrative:G&A- Travel Expenses:Meals & Entertainment | Y39: =IF(ISBLANK($M39),IFERROR(_xlfn.XLOOKUP($P39,'Department Listing'!$A:$A,'Department Listing'!$L:$L),""),$M39) -> 100- Operations:110- G&A | Z39: =IF(ISBLANK($B39),"",MATCH($X39,COA!$B:$B,0)) -> 151
