Workbook

Sheet GAAP Summary
B1: GAAP Management Reporting
B2: 46174
B4: Q4 - OPERATING GOALS
B6: millions | C6: Actuals - 4Q22 | D6: Actuals - 4Q23 | E6: Target | G6: Operating Goals | J6: Achievement | Q6: Inputs
B7: Revenue | C7: ='GAAP Analysis'!DN13 -> 4885562 | D7: ='GAAP Analysis'!DH13 -> 5095749 | E7: =6700000/1000/1000 -> 6.7 | G7: =(E7-E8)*1000000/R10/R9/3 -> 134.41358 | H7: monthly billable hours per resource | Q7: Deposit % of revenue | R7: 0.22
B8: from deposits | E8: =E7*R7 -> 1.474 | Q8: Avg deposit amount | R8: 0.2
B9: from billable work | E9: =E7-E8 -> 5.226 | Q9: Rate | R9: 270
B10: Bookings | C10: ='GAAP Analysis'!DN7 -> 7894608.2 | D10: ='GAAP Analysis'!DH7 -> 8144285.3 | E10: =E8/R8 -> 7.37 | G10: =E10/R11*1000000/3 -> 223333.33 | H10: monthly bookings per AE | Q10: Billable HC | R10: 48
Q11: AE HC | R11: 11
B14: Bookings / Revenue / EBITDA - Monthly
B44: Bookings - FY25 vs. FY24 vs. FY23 vs. FY22
B68: YoY Revenue - FY25 vs. FY24 vs. FY23 vs. FY22
B92: YoY Performance by Quarter
B138: TTM Bookings, Revenue & EBITDA as of Date
B188: Bookings Composition - SN vs DD
AD189: GP + 15%
AC190: 65 | AD190: =AC190*1.15 -> 74.75 | AE190: 74.75
AC191: 61 | AD191: =AC191*1.15 -> 70.15 | AE191: 70.15
AC192: 67 | AD192: =AC192*1.15 -> 77.05 | AE192: 77.05
AC193: 62 | AD193: =AC193*1.15 -> 71.3 | AE193: 71.3
AC194: 57 | AD194: =AC194*1.15 -> 65.55 | AE194: 65.55
AC195: 57 | AD195: =AC195*1.15 -> 65.55 | AE195: 65.55
AC196: 58 | AD196: =AC196*1.15 -> 66.7 | AE196: 66.7
AC197: 57 | AD197: =AC197*1.15 -> 65.55 | AE197: 65.55
AC198: 62 | AD198: =AC198*1.15 -> 71.3 | AE198: 71.3
AC199: 58 | AD199: =AC199*1.15 -> 66.7 | AE199: 66.7
AC200: 59 | AD200: =AC200*1.15 -> 67.85 | AE200: 67.85
AC201: 61 | AD201: =AC201*1.15 -> 70.15 | AE201: 70.15
AC202: =AC203/100 -> 0.007475 | AD202: =AD203/100 -> 0.007015 | AE202: =AE203/100 -> 0.007705 | AF202: =AF203/100 -> 0.00713 | AG202: =AG203/100 -> 0.006555 | AH202: =AH203/100 -> 0.006555 | AI202: =AI203/100 -> 0.00667 | AJ202: =AJ203/100 -> 0.006555 | ... AN202: =AN203/100 -> 0.007015
AC203: 0.7475 | AD203: 0.7015 | AE203: 0.7705 | AF203: 0.713 | AG203: 0.6555 | AH203: 0.6555 | AI203: 0.667 | AJ203: 0.6555 | AK203: 0.713 | AL203: 0.667 | AM203: 0.6785 | AN203: 0.7015
B210: Revenue & Gross Profit
B234: Monthly Expenses
B256: Forecast vs. Actuals- Calendar Year 2026
B297: Billable vs Non-Billable Headcount
B318: Hours billed per head & Padding
B340: Real Rate vs. Net Income

Sheet GAAP Analysis
C2: 2020 | O2: 2021 | AA2: 2022 | AM2: 2023 | DS2: TTM As Of:
C3: 43831 | D3: 43862 | E3: 43891 | F3: 43922 | G3: 43952 | H3: 43983 | I3: 44013 | J3: 44044 | K3: 44075 | L3: 44105 | M3: 44136 | N3: 44166 | O3: 44197 | P3: 44228 | Q3: 44256 | R3: 44287 | S3: 44317 | T3: 44348 | U3: 44378 | V3: 44409 | W3: 44440 | X3: 44470 | Y3: 44501 | Z3: 44531 | AA3: 44562 | AB3: 44593 | AC3: 44621 | AD3: 44652 | AE3: 44682 | AF3: 44713 | AG3: 44743 | AH3: 44774 | AI3: 44805 | AJ3: 44835 | AK3: 44866 | AL3: 44896 | AM3: 44927 | AN3: 44958 | AO3: 44986 | AP3: 45017 | AQ3: 45047 | AR3: 45078 | AS3: 45108 | AT3: 45139 | AU3: 45170 | AV3: 45200 | AW3: 45231 | AX3: 45261 | AY3: 45292 | AZ3: 45323 | BA3: 45352 | BB3: 45383 | BC3: 45413 | BD3: 45444 | BE3: 45474 | BF3: 45505 | BG3: 45536 | BH3: 45566 | BI3: 45597 | BJ3: 45627 | BK3: 45658 | BL3: 45689 | BM3: 45717 | BN3: 45748 | BO3: 45778 | BP3: 45809 | BQ3: 45839 | BR3: 45870 | BS3: 45901 | BT3: 45931 | BU3: 45962 | BV3: 45992 | BW3: 46023 | BX3: 46054 | BY3: 46082 | BZ3: 46113 | CA3: 46143 | CB3: 46174 | CC3: 46204 | CD3: 46235 | CE3: 46266 | CF3: 46296 | CG3: 46327 | CH3: 46357 | CK3: ="TTM as of "&TEXT('GAAP Summary'!B2,"MMM 'YY") -> TTM as of Jun '26 | CM3: 4Q25 | CN3: 1Q26 | CO3: 2Q26 | CP3: 3Q26 | CQ3: CY26 | CS3: 4Q24 | CT3: 1Q25 | CU3: 2Q25 | CV3: 3Q25 | CW3: CY25 | CY3: 4Q23 | CZ3: 1Q24 | DA3: 2Q24 | DB3: 3Q24 | DC3: FY24 | DE3: 4Q22 | DF3: 1Q23 | DG3: 2Q23 | DH3: 3Q23 | DI3: FY23 | DK3: 4Q21 | DL3: 1Q22 | DM3: 2Q22 | DN3: 3Q22 | DO3: FY22 | DQ3: FY21 | DS3: 44197 | DT3: 44228 | DU3: 44256 | DV3: 44287 | DW3: 44317 | DX3: 44348 | DY3: 44378 | DZ3: 44409 | EA3: 44440 | EB3: 44470 | EC3: 44501 | ED3: 44531 | EE3: 44562 | EF3: 44593 | EG3: 44621 | EH3: 44652 | EI3: 44682 | EJ3: 44713 | EK3: 44743 | EL3: 44774 | EM3: 44805 | EN3: 44835 | EO3: 44866 | EP3: 44896 | EQ3: 44927 | ER3: 44958 | ES3: 44986 | ET3: 45017 | EU3: 45047 | EV3: 45078 | EW3: 45108 | EX3: 45139 | EY3: 45170 | EZ3: 45200 | FA3: 45231 | FB3: 45261 | FC3: 45292 | FD3: 45323 | FE3: 45352 | FF3: 45383 | FG3: 45413 | FH3: 45444 | FI3: 45474 | FJ3: 45505 | FK3: 45536 | FL3: 45566 | FM3: 45597 | FN3: 45627 | FO3: 45658 | FP3: 45689 | FQ3: 45717 | FR3: 45748 | FS3: 45778 | FT3: 45809 | FU3: 45839 | FV3: 45870 | FW3: 45901 | FX3: 45931 | FY3: 45962 | FZ3: 45992 | GA3: 46023 | GB3: 46054 | GC3: 46082 | GD3: 46113 | GE3: 46143 | GF3: 46174 | GG3: 46204 | GH3: 46235 | GI3: 46266 | GJ3: 46296 | GK3: 46327 | GL3: 46357
B5: Actuals
CM6: =CM7/CM13 -> 1.1303556 | CS6: =CS7/CS13 -> 1.1307252 | CT6: =CT7/CT13 -> 1.5391623 | CU6: =CU7/CU13 -> 1.3006619 | CV6: =CV7/CV13 -> 1.6265529 | CY6: =CY7/CY13 -> 1.0765554 | CZ6: =CZ7/CZ13 -> 1.1380873 | DA6: =DA7/DA13 -> 0.96709459 | DB6: =DB7/DB13 -> 1.2340552 | DE6: =DE7/DE13 -> 0.44561878 | DF6: =DF7/DF13 -> 0.67674018 | DG6: =DG7/DG13 -> 0.83586857 | DH6: =DH7/DH13 -> 1.5982509
B7: Bookings | C7: =sum(C8:C11) -> 0 | D7: =sum(D8:D11) -> 0 | E7: =sum(E8:E11) -> 0 | F7: =sum(F8:F11) -> 0 | G7: =sum(G8:G11) -> 0 | H7: =sum(H8:H11) -> 0 | I7: =sum(I8:I11) -> 0 | J7: =sum(J8:J11) -> 0 | ... CH7: =sum(CH8:CH11) -> 0 | CK7: {=SUM(INDIRECT(XLOOKUP('GAAP Summary'!$B$2,'TTM Dates'!$B:$B,'TTM Dates'!$E:$E)&ROW($CJ7)&":"&XLOOKUP('GAAP Summary'!$B$2,'TTM Dates'!$B:$B,'TTM Dates'!$C:$C)&ROW($CJ7)))} -> 53144206 | CM7: =sum(BW7:BY7) -> 14213363 | CN7: =sum(BZ7:CB7) -> 8764995.3 | CO7: 0 | CP7: 0 | CQ7: =sum(CM7:CP7) -> 22978358 | CS7: =sum(BK7:BM7) -> 8394063.9 | CT7: =sum(BN7:BP7) -> 12379014 | CU7: =sum(BQ7:BS7) -> 12354635 | CV7: =sum(BT7:BV7) -> 17811213 | CW7: =sum(BK7:BV7) -> 50938925 | CX7: =sum(CT7:CV7)/sum(CZ7:DB7)-1 -> 0.90927214 | CY7: =sum(AY7:BA7) -> 5881823 | CZ7: =sum(BB7:BD7) -> 6544902 | DA7: =sum(BE7:BG7) -> 6201507 | DB7: =sum(BH7:BJ7) -> 9536879.1 | DC7: =sum(AY7:BJ7) -> 28165111 | DE7: =sum(AM7:AO7) -> 2808888 | DF7: =sum(AP7:AR7) -> 3780640.8 | DG7: =sum(AS7:AU7) -> 4345506 | DH7: =sum(AV7:AX7) -> 8144285.3 | DI7: =sum(DE8:DH10) -> 19079320 | DK7: =sum(AA7:AC7) -> 3491390 | DL7: =sum(AD7:AF7) -> 7507668 | DM7: =sum(AG7:AI7) -> 5709804.4 | DN7: =sum(AJ7:AL7) -> 7894608.2 | DO7: =sum(AA7:AL7) -> 24603471 | DQ7: =sum(O7:Z7) -> 0 | DS7: {=IF(DS$3>'GAAP Summary'!$B$2,0,SUM(INDIRECT(XLOOKUP(DS$3,'TTM Dates'!$B:$B,'TTM Dates'!$E:$E)&ROW($CJ7)&":"&XLOOKUP(DS$3,'TTM Dates'!$B:$B,'TTM Dates'!$C:$C)&ROW($CJ7))))} -> 0 | DT7: {=IF(DT$3>'GAAP Summary'!$B$2,0,SUM(INDIRECT(XLOOKUP(DT$3,'TTM Dates'!$B:$B,'TTM Dates'!$E:$E)&ROW($CJ7)&":"&XLOOKUP(DT$3,'TTM Dates'!$B:$B,'TTM Dates'!$C:$C)&ROW($CJ7))))} -> 0 | DU7: {=IF(DU$3>'GAAP Summary'!$B$2,0,SUM(INDIRECT(XLOOKUP(DU$3,'TTM Dates'!$B:$B,'TTM Dates'!$E:$E)&ROW($CJ7)&":"&XLOOKUP(DU$3,'TTM Dates'!$B:$B,'TTM Dates'!$C:$C)&ROW($CJ7))))} -> 0 | DV7: {=IF(DV$3>'GAAP Summary'!$B$2,0,SUM(INDIRECT(XLOOKUP(DV$3,'TTM Dates'!$B:$B,'TTM Dates'!$E:$E)&ROW($CJ7)&":"&XLOOKUP(DV$3,'TTM Dates'!$B:$B,'TTM Dates'!$C:$C)&ROW($CJ7))))} -> 0 | DW7: {=IF(DW$3>'GAAP Summary'!$B$2,0,SUM(INDIRECT(XLOOKUP(DW$3,'TTM Dates'!$B:$B,'TTM Dates'!$E:$E)&ROW($CJ7)&":"&XLOOKUP(DW$3,'TTM Dates'!$B:$B,'TTM Dates'!$C:$C)&ROW($CJ7))))} -> 0 | DX7: {=IF(DX$3>'GAAP Summary'!$B$2,0,SUM(INDIRECT(XLOOKUP(DX$3,'TTM Dates'!$B:$B,'TTM Dates'!$E:$E)&ROW($CJ7)&":"&XLOOKUP(DX$3,'TTM Dates'!$B:$B,'TTM Dates'!$C:$C)&ROW($CJ7))))} -> 0 | DY7: {=IF(DY$3>'GAAP Summary'!$B$2,0,SUM(INDIRECT(XLOOKUP(DY$3,'TTM Dates'!$B:$B,'TTM Dates'!$E:$E)&ROW($CJ7)&":"&XLOOKUP(DY$3,'TTM Dates'!$B:$B,'TTM Dates'!$C:$C)&ROW($CJ7))))} -> 0 | DZ7: {=IF(DZ$3>'GAAP Summary'!$B$2,0,SUM(INDIRECT(XLOOKUP(DZ$3,'TTM Dates'!$B:$B,'TTM Dates'!$E:$E)&ROW($CJ7)&":"&XLOOKUP(DZ$3,'TTM Dates'!$B:$B,'TTM Dates'!$C:$C)&ROW($CJ7))))} -> 0 | ... GL7: {=IF(GL$3>'GAAP Summary'!$B$2,0,SUM(INDIRECT(XLOOKUP(GL$3,'TTM Dates'!$B:$B,'TTM Dates'!$E:$E)&ROW($CJ7)&":"&XLOOKUP(GL$3,'TTM Dates'!$B:$B,'TTM Dates'!$C:$C)&ROW($CJ7))))} -> 0
B8: DD | AA8: 99720 | AB8: 80640 | AC8: 204640 | AD8: 415440 | AE8: 586400 | AF8: 1074960 | AG8: 1328420 | AH8: 79040 | AI8: 922672 | AJ8: 1649000 | AK8: 427800 | AL8: 813970 | AM8: 134400 | AN8: 349104 | AO8: 801544 | AP8: 331413.01 | AQ8: 732202 | AR8: 985245 | AS8: 111000 | AT8: 1120200 | AU8: 293440 | AV8: =57600+216000+87680+106880+25000+345900 -> 839060 | AW8: 2468100 | AX8: 1607072 | AY8: 0 | AZ8: =60700+34560 -> 95260 | BA8: 664160 | BB8: 245840 | BC8: 1070080 | BD8: 595296 | BE8: 710760 | BF8: 1387561 | BG8: 286700 | BH8: 436906 | BI8: 2447618 | BJ8: 1341556 | BK8: 119460 | BL8: 115760 | BM8: 404780 | BN8: 1148000 | BO8: 433500 | BP8: 1071080 | BQ8: 825056 | BR8: 951820 | BS8: 610240 | BT8: 555824 | BU8: 2429600 | BV8: 2964830 | BW8: 109440 | BX8: 718652 | BY8: 2704916 | BZ8: 106832 | CA8: 551080 | CB8: 328016 | CK8: {=SUM(INDIRECT(XLOOKUP('GAAP Summary'!$B$2,'TTM Dates'!$B:$B,'TTM Dates'!$E:$E)&ROW($CJ8)&":"&XLOOKUP('GAAP Summary'!$B$2,'TTM Dates'!$B:$B,'TTM Dates'!$C:$C)&ROW($CJ8)))} -> 12856306 | CM8: =sum(BW8:BY8) -> 3533008 | CN8: =sum(BZ8:CB8) -> 985928 | CO8: =sum(CC8:CE8) -> 0 | CP8: =sum(CF8:CH8) -> 0 | CQ8: =sum(BW8:CH8) -> 4518936 | CS8: =sum(BK8:BM8) -> 640000 | CT8: =sum(BN8:BP8) -> 2652580 | CU8: =sum(BQ8:BS8) -> 2387116 | CV8: =sum(BT8:BV8) -> 5950254 | CW8: =sum(BK8:BV8) -> 11629950 | CX8: =sum(CT8:CV8)/sum(CZ8:DB8)-1 -> 0.28954954 | CY8: =sum(AY8:BA8) -> 759420 | CZ8: =sum(BB8:BD8) -> 1911216 | DA8: =sum(BE8:BG8) -> 2385021 | DB8: =sum(BH8:BJ8) -> 4226080 | DC8: =sum(AY8:BJ8) -> 9281737 | DE8: =sum(AM8:AO8) -> 1285048 | DF8: =sum(AP8:AR8) -> 2048860 | DG8: =sum(AS8:AU8) -> 1524640 | DH8: =sum(AV8:AX8) -> 4914232 | DI8: =sum(AM8:AX8) -> 9772780 | DK8: =sum(AA8:AC8) -> 385000 | DL8: =sum(AD8:AF8) -> 2076800 | DM8: =sum(AG8:AI8) -> 2330132 | DN8: =sum(AJ8:AL8) -> 2890770 | DO8: =sum(AA8:AL8) -> 7682702 | DQ8: =SUM(O8:Z8) -> 0 | DS8: {=IF(DS$3>'GAAP Summary'!$B$2,0,SUM(INDIRECT(XLOOKUP(DS$3,'TTM Dates'!$B:$B,'TTM Dates'!$E:$E)&ROW($CJ8)&":"&XLOOKUP(DS$3,'TTM Dates'!$B:$B,'TTM Dates'!$C:$C)&ROW($CJ8))))} -> 0 | DT8: {=IF(DT$3>'GAAP Summary'!$B$2,0,SUM(INDIRECT(XLOOKUP(DT$3,'TTM Dates'!$B:$B,'TTM Dates'!$E:$E)&ROW($CJ8)&":"&XLOOKUP(DT$3,'TTM Dates'!$B:$B,'TTM Dates'!$C:$C)&ROW($CJ8))))} -> 0 | DU8: {=IF(DU$3>'GAAP Summary'!$B$2,0,SUM(INDIRECT(XLOOKUP(DU$3,'TTM Dates'!$B:$B,'TTM Dates'!$E:$E)&ROW($CJ8)&":"&XLOOKUP(DU$3,'TTM Dates'!$B:$B,'TTM Dates'!$C:$C)&ROW($CJ8))))} -> 0 | DV8: {=IF(DV$3>'GAAP Summary'!$B$2,0,SUM(INDIRECT(XLOOKUP(DV$3,'TTM Dates'!$B:$B,'TTM Dates'!$E:$E)&ROW($CJ8)&":"&XLOOKUP(DV$3,'TTM Dates'!$B:$B,'TTM Dates'!$C:$C)&ROW($CJ8))))} -> 0 | DW8: {=IF(DW$3>'GAAP Summary'!$B$2,0,SUM(INDIRECT(XLOOKUP(DW$3,'TTM Dates'!$B:$B,'TTM Dates'!$E:$E)&ROW($CJ8)&":"&XLOOKUP(DW$3,'TTM Dates'!$B:$B,'TTM Dates'!$C:$C)&ROW($CJ8))))} -> 0 | DX8: {=IF(DX$3>'GAAP Summary'!$B$2,0,SUM(INDIRECT(XLOOKUP(DX$3,'TTM Dates'!$B:$B,'TTM Dates'!$E:$E)&ROW($CJ8)&":"&XLOOKUP(DX$3,'TTM Dates'!$B:$B,'TTM Dates'!$C:$C)&ROW($CJ8))))} -> 0 | DY8: {=IF(DY$3>'GAAP Summary'!$B$2,0,SUM(INDIRECT(XLOOKUP(DY$3,'TTM Dates'!$B:$B,'TTM Dates'!$E:$E)&ROW($CJ8)&":"&XLOOKUP(DY$3,'TTM Dates'!$B:$B,'TTM Dates'!$C:$C)&ROW($CJ8))))} -> 0 | DZ8: {=IF(DZ$3>'GAAP Summary'!$B$2,0,SUM(INDIRECT(XLOOKUP(DZ$3,'TTM Dates'!$B:$B,'TTM Dates'!$E:$E)&ROW($CJ8)&":"&XLOOKUP(DZ$3,'TTM Dates'!$B:$B,'TTM Dates'!$C:$C)&ROW($CJ8))))} -> 0 | ... GL8: {=IF(GL$3>'GAAP Summary'!$B$2,0,SUM(INDIRECT(XLOOKUP(GL$3,'TTM Dates'!$B:$B,'TTM Dates'!$E:$E)&ROW($CJ8)&":"&XLOOKUP(GL$3,'TTM Dates'!$B:$B,'TTM Dates'!$C:$C)&ROW($CJ8))))} -> 0
B9: SN | AA9: 45100 | AB9: 34560 | AC9: 2906490 | AD9: 240400 | AE9: 3445490 | AF9: 1705200 | AG9: 1642900 | AH9: 240000 | AI9: 1323460 | AJ9: 977400 | AK9: 459420 | AL9: 3326280 | AM9: 0 | AN9: 245760 | AO9: 1007040 | AP9: 220200 | AQ9: 103200 | AR9: 1237328 | AS9: 796400 | AT9: 968070 | AU9: 929178 | AV9: =249600+81000+40500+20025+103200 -> 494325 | AW9: 874546 | AX9: 1259600 | AY9: 57000 | AZ9: 235790 | BA9: 4709700 | BB9: 1366812 | BC9: 2795784 | BD9: 395700 | BE9: 689600 | BF9: 685920 | BG9: 2020630 | BH9: 2156205.2 | BI9: 479693.52 | BJ9: 2235526.2 | BK9: 919568.5 | BL9: 2372860 | BM9: 3187678 | BN9: 4195676 | BO9: 2326386 | BP9: 2388176.5 | BQ9: 3882712 | BR9: 1782484 | BS9: 3813550 | BT9: 5355617 | BU9: 947810 | BV9: 4188499 | BW9: 888340 | BX9: 3672409 | BY9: 5681048 | BZ9: 1330840 | CA9: 3464011 | CB9: 2354221 | CK9: {=SUM(INDIRECT(XLOOKUP('GAAP Summary'!$B$2,'TTM Dates'!$B:$B,'TTM Dates'!$E:$E)&ROW($CJ9)&":"&XLOOKUP('GAAP Summary'!$B$2,'TTM Dates'!$B:$B,'TTM Dates'!$C:$C)&ROW($CJ9)))} -> 37361541 | CM9: =sum(BW9:BY9) -> 10241797 | CN9: =sum(BZ9:CB9) -> 7149072 | CO9: =sum(CC9:CE9) -> 0 | CP9: =sum(CF9:CH9) -> 0 | CQ9: =sum(BW9:CH9) -> 17390869 | CS9: =sum(BK9:BM9) -> 6480106.5 | CT9: =sum(BN9:BP9) -> 8910238.5 | CU9: =sum(BQ9:BS9) -> 9478746 | CV9: =sum(BT9:BV9) -> 10491926 | CW9: =sum(BK9:BV9) -> 35361017 | CX9: =sum(CT9:CV9)/sum(CZ9:DB9)-1 -> 1.2517699 | CY9: =sum(AY9:BA9) -> 5002490 | CZ9: =sum(BB9:BD9) -> 4558296 | DA9: =sum(BE9:BG9) -> 3396150 | DB9: =sum(BH9:BJ9) -> 4871424.9 | DC9: =sum(AY9:BJ9) -> 17828361 | DE9: =sum(AM9:AO9) -> 1252800 | DF9: =sum(AP9:AR9) -> 1560728 | DG9: =sum(AS9:AU9) -> 2693648 | DH9: =sum(AV9:AX9) -> 2628471 | DI9: =sum(AM9:AX9) -> 8135647 | DK9: =sum(AA9:AC9) -> 2986150 | DL9: =sum(AD9:AF9) -> 5391090 | DM9: =sum(AG9:AI9) -> 3206360 | DN9: =sum(AJ9:AL9) -> 4763100 | DO9: =sum(AA9:AL9) -> 16346700 | DQ9: =SUM(O9:Z9) -> 0 | DS9: {=IF(DS$3>'GAAP Summary'!$B$2,0,SUM(INDIRECT(XLOOKUP(DS$3,'TTM Dates'!$B:$B,'TTM Dates'!$E:$E)&ROW($CJ9)&":"&XLOOKUP(DS$3,'TTM Dates'!$B:$B,'TTM Dates'!$C:$C)&ROW($CJ9))))} -> 0 | DT9: {=IF(DT$3>'GAAP Summary'!$B$2,0,SUM(INDIRECT(XLOOKUP(DT$3,'TTM Dates'!$B:$B,'TTM Dates'!$E:$E)&ROW($CJ9)&":"&XLOOKUP(DT$3,'TTM Dates'!$B:$B,'TTM Dates'!$C:$C)&ROW($CJ9))))} -> 0 | DU9: {=IF(DU$3>'GAAP Summary'!$B$2,0,SUM(INDIRECT(XLOOKUP(DU$3,'TTM Dates'!$B:$B,'TTM Dates'!$E:$E)&ROW($CJ9)&":"&XLOOKUP(DU$3,'TTM Dates'!$B:$B,'TTM Dates'!$C:$C)&ROW($CJ9))))} -> 0 | DV9: {=IF(DV$3>'GAAP Summary'!$B$2,0,SUM(INDIRECT(XLOOKUP(DV$3,'TTM Dates'!$B:$B,'TTM Dates'!$E:$E)&ROW($CJ9)&":"&XLOOKUP(DV$3,'TTM Dates'!$B:$B,'TTM Dates'!$C:$C)&ROW($CJ9))))} -> 0 | DW9: {=IF(DW$3>'GAAP Summary'!$B$2,0,SUM(INDIRECT(XLOOKUP(DW$3,'TTM Dates'!$B:$B,'TTM Dates'!$E:$E)&ROW($CJ9)&":"&XLOOKUP(DW$3,'TTM Dates'!$B:$B,'TTM Dates'!$C:$C)&ROW($CJ9))))} -> 0 | DX9: {=IF(DX$3>'GAAP Summary'!$B$2,0,SUM(INDIRECT(XLOOKUP(DX$3,'TTM Dates'!$B:$B,'TTM Dates'!$E:$E)&ROW($CJ9)&":"&XLOOKUP(DX$3,'TTM Dates'!$B:$B,'TTM Dates'!$C:$C)&ROW($CJ9))))} -> 0 | DY9: {=IF(DY$3>'GAAP Summary'!$B$2,0,SUM(INDIRECT(XLOOKUP(DY$3,'TTM Dates'!$B:$B,'TTM Dates'!$E:$E)&ROW($CJ9)&":"&XLOOKUP(DY$3,'TTM Dates'!$B:$B,'TTM Dates'!$C:$C)&ROW($CJ9))))} -> 0 | DZ9: {=IF(DZ$3>'GAAP Summary'!$B$2,0,SUM(INDIRECT(XLOOKUP(DZ$3,'TTM Dates'!$B:$B,'TTM Dates'!$E:$E)&ROW($CJ9)&":"&XLOOKUP(DZ$3,'TTM Dates'!$B:$B,'TTM Dates'!$C:$C)&ROW($CJ9))))} -> 0 | ... GL9: {=IF(GL$3>'GAAP Summary'!$B$2,0,SUM(INDIRECT(XLOOKUP(GL$3,'TTM Dates'!$B:$B,'TTM Dates'!$E:$E)&ROW($CJ9)&":"&XLOOKUP(GL$3,'TTM Dates'!$B:$B,'TTM Dates'!$C:$C)&ROW($CJ9))))} -> 0
B10: SW | AA10: 0 | AB10: 120240 | AC10: 0 | AD10: 9120 | AE10: 11375 | AF10: 19283 | AG10: 164022 | AH10: 7980 | AI10: 1310.4 | AJ10: 14208 | AK10: 104678.8 | AL10: 121851.36 | AM10: 0 | AN10: 252000 | AO10: 19040 | AP10: 1310.4 | AQ10: 22188 | AR10: 147554.4 | AS10: 108510 | AT10: 14208 | AU10: 4500 | AV10: 92818 | AW10: 56866.32 | AX10: 451898 | AY10: 0 | AZ10: 52800 | BA10: 67113 | BC10: 1890 | BD10: 73500 | BE10: 5860 | BF10: 47660 | BH10: 3931.2 | BI10: 84511.25 | BJ10: 229832.7 | BK10: 92097.6 | BL10: 0 | BN10: 11088 | BP10: 73500 | BQ10: 0 | BS10: 258006 | BT10: 29269.17 | BU10: 80732 | BV10: 289031.47 | BW10: 7426 | BX10: 81692 | BY10: 19440 | BZ10: 0 | CB10: 64800 | CK10: {=SUM(INDIRECT(XLOOKUP('GAAP Summary'!$B$2,'TTM Dates'!$B:$B,'TTM Dates'!$E:$E)&ROW($CJ10)&":"&XLOOKUP('GAAP Summary'!$B$2,'TTM Dates'!$B:$B,'TTM Dates'!$C:$C)&ROW($CJ10)))} -> 830396.64 | CM10: =sum(BW10:BY10) -> 108558 | CN10: =sum(BZ10:CB10) -> 64800 | CO10: =sum(CC10:CE10) -> 0 | CP10: =sum(CF10:CH10) -> 0 | CQ10: =sum(BW10:CH10) -> 173358 | CS10: =sum(BK10:BM10) -> 92097.6 | CT10: =sum(BN10:BP10) -> 84588 | CU10: =sum(BQ10:BS10) -> 258006 | CV10: =sum(BT10:BV10) -> 399032.64 | CW10: =sum(BK10:BV10) -> 833724.24 | CX10: =sum(CT10:CV10)/sum(CZ10:DB10)-1 -> 0.65843307 | CY10: =sum(AY10:BA10) -> 119913 | CZ10: =sum(BB10:BD10) -> 75390 | DA10: =sum(BE10:BG10) -> 53520 | DB10: =sum(BH10:BJ10) -> 318275.15 | DC10: =sum(AY10:BJ10) -> 567098.15 | DE10: =sum(AM10:AO10) -> 271040 | DF10: =sum(AP10:AR10) -> 171052.8 | DG10: =sum(AS10:AU10) -> 127218 | DH10: =sum(AV10:AX10) -> 601582.32 | DI10: =sum(AM10:AX10) -> 1170893.1 | DK10: =sum(AA10:AC10) -> 120240 | DL10: =sum(AD10:AF10) -> 39778 | DM10: =sum(AG10:AI10) -> 173312.4 | DN10: =sum(AJ10:AL10) -> 240738.16 | DO10: =sum(AA10:AL10) -> 574068.56 | DS10: {=IF(DS$3>'GAAP Summary'!$B$2,0,SUM(INDIRECT(XLOOKUP(DS$3,'TTM Dates'!$B:$B,'TTM Dates'!$E:$E)&ROW($CJ10)&":"&XLOOKUP(DS$3,'TTM Dates'!$B:$B,'TTM Dates'!$C:$C)&ROW($CJ10))))} -> 0 | DT10: {=IF(DT$3>'GAAP Summary'!$B$2,0,SUM(INDIRECT(XLOOKUP(DT$3,'TTM Dates'!$B:$B,'TTM Dates'!$E:$E)&ROW($CJ10)&":"&XLOOKUP(DT$3,'TTM Dates'!$B:$B,'TTM Dates'!$C:$C)&ROW($CJ10))))} -> 0 | DU10: {=IF(DU$3>'GAAP Summary'!$B$2,0,SUM(INDIRECT(XLOOKUP(DU$3,'TTM Dates'!$B:$B,'TTM Dates'!$E:$E)&ROW($CJ10)&":"&XLOOKUP(DU$3,'TTM Dates'!$B:$B,'TTM Dates'!$C:$C)&ROW($CJ10))))} -> 0 | DV10: {=IF(DV$3>'GAAP Summary'!$B$2,0,SUM(INDIRECT(XLOOKUP(DV$3,'TTM Dates'!$B:$B,'TTM Dates'!$E:$E)&ROW($CJ10)&":"&XLOOKUP(DV$3,'TTM Dates'!$B:$B,'TTM Dates'!$C:$C)&ROW($CJ10))))} -> 0 | DW10: {=IF(DW$3>'GAAP Summary'!$B$2,0,SUM(INDIRECT(XLOOKUP(DW$3,'TTM Dates'!$B:$B,'TTM Dates'!$E:$E)&ROW($CJ10)&":"&XLOOKUP(DW$3,'TTM Dates'!$B:$B,'TTM Dates'!$C:$C)&ROW($CJ10))))} -> 0 | DX10: {=IF(DX$3>'GAAP Summary'!$B$2,0,SUM(INDIRECT(XLOOKUP(DX$3,'TTM Dates'!$B:$B,'TTM Dates'!$E:$E)&ROW($CJ10)&":"&XLOOKUP(DX$3,'TTM Dates'!$B:$B,'TTM Dates'!$C:$C)&ROW($CJ10))))} -> 0 | DY10: {=IF(DY$3>'GAAP Summary'!$B$2,0,SUM(INDIRECT(XLOOKUP(DY$3,'TTM Dates'!$B:$B,'TTM Dates'!$E:$E)&ROW($CJ10)&":"&XLOOKUP(DY$3,'TTM Dates'!$B:$B,'TTM Dates'!$C:$C)&ROW($CJ10))))} -> 0 | DZ10: {=IF(DZ$3>'GAAP Summary'!$B$2,0,SUM(INDIRECT(XLOOKUP(DZ$3,'TTM Dates'!$B:$B,'TTM Dates'!$E:$E)&ROW($CJ10)&":"&XLOOKUP(DZ$3,'TTM Dates'!$B:$B,'TTM Dates'!$C:$C)&ROW($CJ10))))} -> 0 | ... GL10: {=IF(GL$3>'GAAP Summary'!$B$2,0,SUM(INDIRECT(XLOOKUP(GL$3,'TTM Dates'!$B:$B,'TTM Dates'!$E:$E)&ROW($CJ10)&":"&XLOOKUP(GL$3,'TTM Dates'!$B:$B,'TTM Dates'!$C:$C)&ROW($CJ10))))} -> 0
B11: MSP | BF11: 366816 | BH11: 21117 | BI11: 79982 | BJ11: 20000 | BL11: 900000 | BM11: 281859.85 | BN11: 303607 | BO11: 180000 | BP11: 248000 | BQ11: 0 | BR11: 75000 | BS11: =148962.96+6804 -> 155766.96 | BT11: 435000 | BU11: 535000 | BV11: 0 | BY11: 330000 | BZ11: 0 | CA11: 465195.32 | CB11: 100000 | CK11: {=SUM(INDIRECT(XLOOKUP('GAAP Summary'!$B$2,'TTM Dates'!$B:$B,'TTM Dates'!$E:$E)&ROW($CJ11)&":"&XLOOKUP('GAAP Summary'!$B$2,'TTM Dates'!$B:$B,'TTM Dates'!$C:$C)&ROW($CJ11)))} -> 2095962.3 | CM11: =sum(BW11:BY11) -> 330000 | CN11: =sum(BZ11:CB11) -> 565195.32 | CO11: =sum(CC11:CE11) -> 0 | CP11: =sum(CF11:CH11) -> 0 | CQ11: =sum(BW11:CH11) -> 895195.32 | CS11: =sum(BK11:BM11) -> 1181859.9 | CT11: =sum(BN11:BP11) -> 731607 | CU11: =sum(BQ11:BS11) -> 230766.96 | CV11: =sum(BT11:BV11) -> 970000 | CW11: =sum(BK11:BV11) -> 3114233.8 | CX11: =sum(CT11:CV11)/sum(CZ11:DB11)-1 -> 2.9604725 | CY11: =sum(AY11:BA11) -> 0 | CZ11: =sum(BB11:BD11) -> 0 | DA11: =sum(BE11:BG11) -> 366816 | DB11: =sum(BH11:BJ11) -> 121099 | DC11: =sum(AY11:BJ11) -> 487915 | DK11: =sum(AA11:AC11) -> 0 | DL11: =sum(AD11:AF11) -> 0 | DM11: =sum(AG11:AI11) -> 0 | DN11: =sum(AJ11:AL11) -> 0 | DO11: =sum(AA11:AL11) -> 0 | EE11: {=IF(EE$3>'GAAP Summary'!$B$2,0,SUM(INDIRECT(XLOOKUP(EE$3,'TTM Dates'!$B:$B,'TTM Dates'!$E:$E)&ROW($CJ11)&":"&XLOOKUP(EE$3,'TTM Dates'!$B:$B,'TTM Dates'!$C:$C)&ROW($CJ11))))} -> 0 | EF11: {=IF(EF$3>'GAAP Summary'!$B$2,0,SUM(INDIRECT(XLOOKUP(EF$3,'TTM Dates'!$B:$B,'TTM Dates'!$E:$E)&ROW($CJ11)&":"&XLOOKUP(EF$3,'TTM Dates'!$B:$B,'TTM Dates'!$C:$C)&ROW($CJ11))))} -> 0 | EG11: {=IF(EG$3>'GAAP Summary'!$B$2,0,SUM(INDIRECT(XLOOKUP(EG$3,'TTM Dates'!$B:$B,'TTM Dates'!$E:$E)&ROW($CJ11)&":"&XLOOKUP(EG$3,'TTM Dates'!$B:$B,'TTM Dates'!$C:$C)&ROW($CJ11))))} -> 0 | EH11: {=IF(EH$3>'GAAP Summary'!$B$2,0,SUM(INDIRECT(XLOOKUP(EH$3,'TTM Dates'!$B:$B,'TTM Dates'!$E:$E)&ROW($CJ11)&":"&XLOOKUP(EH$3,'TTM Dates'!$B:$B,'TTM Dates'!$C:$C)&ROW($CJ11))))} -> 0 | EI11: {=IF(EI$3>'GAAP Summary'!$B$2,0,SUM(INDIRECT(XLOOKUP(EI$3,'TTM Dates'!$B:$B,'TTM Dates'!$E:$E)&ROW($CJ11)&":"&XLOOKUP(EI$3,'TTM Dates'!$B:$B,'TTM Dates'!$C:$C)&ROW($CJ11))))} -> 0 | EJ11: {=IF(EJ$3>'GAAP Summary'!$B$2,0,SUM(INDIRECT(XLOOKUP(EJ$3,'TTM Dates'!$B:$B,'TTM Dates'!$E:$E)&ROW($CJ11)&":"&XLOOKUP(EJ$3,'TTM Dates'!$B:$B,'TTM Dates'!$C:$C)&ROW($CJ11))))} -> 0 | EK11: {=IF(EK$3>'GAAP Summary'!$B$2,0,SUM(INDIRECT(XLOOKUP(EK$3,'TTM Dates'!$B:$B,'TTM Dates'!$E:$E)&ROW($CJ11)&":"&XLOOKUP(EK$3,'TTM Dates'!$B:$B,'TTM Dates'!$C:$C)&ROW($CJ11))))} -> 0 | EL11: {=IF(EL$3>'GAAP Summary'!$B$2,0,SUM(INDIRECT(XLOOKUP(EL$3,'TTM Dates'!$B:$B,'TTM Dates'!$E:$E)&ROW($CJ11)&":"&XLOOKUP(EL$3,'TTM Dates'!$B:$B,'TTM Dates'!$C:$C)&ROW($CJ11))))} -> 0 | ... GL11: {=IF(GL$3>'GAAP Summary'!$B$2,0,SUM(INDIRECT(XLOOKUP(GL$3,'TTM Dates'!$B:$B,'TTM Dates'!$E:$E)&ROW($CJ11)&":"&XLOOKUP(GL$3,'TTM Dates'!$B:$B,'TTM Dates'!$C:$C)&ROW($CJ11))))} -> 0
B12: Data Label | AM12: =IF(AM7=0,"", TEXT(AM7,"0,000")&" "&"("&TEXT((AM7-AA7)/AA7,"0%")&" YoY)") -> 134,400 (-7% YoY) | AN12: =IF(AN7=0,"", TEXT(AN7,"0,000")&" "&"("&TEXT((AN7-AB7)/AB7,"0%")&" YoY)") -> 846,864 (260% YoY) | AO12: =IF(AO7=0,"", TEXT(AO7,"0,000")&" "&"("&TEXT((AO7-AC7)/AC7,"0%")&" YoY)") -> 1,827,624 (-41% YoY) | AP12: =IF(AP7=0,"", TEXT(AP7,"0,000")&" "&"("&TEXT((AP7-AD7)/AD7,"0%")&" YoY)") -> 552,923 (-17% YoY) | AQ12: =IF(AQ7=0,"", TEXT(AQ7,"0,000")&" "&"("&TEXT((AQ7-AE7)/AE7,"0%")&" YoY)") -> 857,590 (-79% YoY) | AR12: =IF(AR7=0,"", TEXT(AR7,"0,000")&" "&"("&TEXT((AR7-AF7)/AF7,"0%")&" YoY)") -> 2,370,127 (-15% YoY) | AS12: =IF(AS7=0,"", TEXT(AS7,"0,000")&" "&"("&TEXT((AS7-AG7)/AG7,"0%")&" YoY)") -> 1,015,910 (-68% YoY) | AT12: =IF(AT7=0,"", TEXT(AT7,"0,000")&" "&"("&TEXT((AT7-AH7)/AH7,"0%")&" YoY)") -> 2,102,478 (543% YoY) | ... CH12: =IF(CH7=0,"", TEXT(CH7,"0,000")&" "&"("&TEXT((CH7-BV7)/BV7,"0%")&" YoY)") | CM12: =IF(CM7=0,"", TEXT(CM7,"0,000")&" "&"("&TEXT((CM7-CS7)/CS7,"0%")&" YoY)") -> 14,213,363 (69% YoY) | CN12: =IF(CN7=0,"", TEXT(CN7,"0,000")&" "&"("&TEXT((CN7-CT7)/CT7,"0%")&" YoY)") -> 8,764,995 (-29% YoY) | CS12: =IF(CS7=0,"", TEXT(CS7,"0,000")&" "&"("&TEXT((CS7-CY7)/CY7,"0%")&" YoY)") -> 8,394,064 (43% YoY) | CT12: =IF(CT7=0,"", TEXT(CT7,"0,000")&" "&"("&TEXT((CT7-CZ7)/CZ7,"0%")&" YoY)") -> 12,379,014 (89% YoY) | CU12: =IF(CU7=0,"", TEXT(CU7,"0,000")&" "&"("&TEXT((CU7-DA7)/DA7,"0%")&" YoY)") -> 12,354,635 (99% YoY) | CV12: =IF(CV7=0,"", TEXT(CV7,"0,000")&" "&"("&TEXT((CV7-DB7)/DB7,"0%")&" YoY)") -> 17,811,213 (87% YoY) | CY12: =IF(CY7=0,"", TEXT(CY7,"0,000")&" "&"("&TEXT((CY7-DE7)/DE7,"0%")&" YoY)") -> 5,881,823 (109% YoY) | CZ12: =IF(CZ7=0,"", TEXT(CZ7,"0,000")&" "&"("&TEXT((CZ7-DF7)/DF7,"0%")&" YoY)") -> 6,544,902 (73% YoY) | DA12: =IF(DA7=0,"", TEXT(DA7,"0,000")&" "&"("&TEXT((DA7-DG7)/DG7,"0%")&" YoY)") -> 6,201,507 (43% YoY) | DB12: =IF(DB7=0,"", TEXT(DB7,"0,000")&" "&"("&TEXT((DB7-DH7)/DH7,"0%")&" YoY)") -> 9,536,879 (17% YoY) | DF12: =DF13*1.25 -> 6983183.8 | DG12: =DG13*1.35 -> 7018367.8 | DH12: =DH13*1.25 -> 6369686.2
B13: Revenue | C13: =C14+C19 -> 0 | D13: =D14+D19 -> 0 | E13: =E14+E19 -> 0 | F13: =F14+F19 -> 0 | G13: =G14+G19 -> 0 | H13: =H14+H19 -> 0 | I13: =I14+I19 -> 0 | J13: =J14+J19 -> 0 | ... Z13: =Z14+Z19 -> 0 | AA13: 1174821 | AB13: 1058642 | AC13: 1382675 | AD13: 1197302 | AE13: 1277152 | AF13: 1539826 | AG13: 1326478 | AH13: 1933412 | AI13: 1626732 | AJ13: 1863172 | AK13: 1785275 | AL13: 1237115 | AM13: 2132202 | AN13: 1943840 | AO13: 2227301 | AP13: 1844526 | AQ13: 1900795 | AR13: 1841226 | AS13: 1634207 | AT13: 1985443 | AU13: 1579141 | AV13: 1868299 | AW13: 1657348 | AX13: 1570102 | AY13: =AY14+AY19 -> 1682341.9 | AZ13: =AZ14+AZ19 -> 1868928.9 | BA13: =BA14+BA19 -> 1912287.5 | BB13: =BB14+BB19 -> 2003722.6 | BC13: =BC14+BC19 -> 1916051.2 | BD13: =BD14+BD19 -> 1831016.7 | BE13: =BE14+BE19 -> 2080921.4 | BF13: =BF14+BF19 -> 2167206.4 | ... CH13: =CH14+CH19 -> 0 | CK13: {=SUM(INDIRECT(XLOOKUP('GAAP Summary'!$B$2,'TTM Dates'!$B:$B,'TTM Dates'!$E:$E)&ROW($CJ13)&":"&XLOOKUP('GAAP Summary'!$B$2,'TTM Dates'!$B:$B,'TTM Dates'!$C:$C)&ROW($CJ13)))} -> 46667706 | CM13: =sum(BW13:BY13) -> 12574241 | CN13: =sum(BZ13:CB13) -> 13644454 | CO13: =sum(CC13:CE13) -> 0 | CP13: =sum(CF13:CH13) -> 0 | CQ13: =sum(BW13:CH13) -> 26218695 | CS13: =sum(BK13:BM13) -> 7423611 | CT13: =sum(BN13:BP13) -> 8042695.1 | CU13: =sum(BQ13:BS13) -> 9498729.3 | CV13: =sum(BT13:BV13) -> 10950282 | CW13: =sum(BK13:BV13) -> 35915317 | CY13: =sum(AY13:BA13) -> 5463558.3 | CZ13: =sum(BB13:BD13) -> 5750790.6 | DA13: =sum(BE13:BG13) -> 6412513.4 | DB13: =sum(BH13:BJ13) -> 7728081.2 | DC13: =sum(AY13:BJ13) -> 25354944 | DE13: =sum(AM13:AO13) -> 6303343 | DF13: =sum(AP13:AR13) -> 5586547 | DG13: =sum(AS13:AU13) -> 5198791 | DH13: =sum(AV13:AX13) -> 5095749 | DI13: =sum(AM13:AX13) -> 22184430 | DK13: =sum(AA13:AC13) -> 3616138 | DL13: =sum(AD13:AF13) -> 4014280 | DM13: =sum(AG13:AI13) -> 4886622 | DN13: =sum(AJ13:AL13) -> 4885562 | DO13: =sum(AA13:AL13) -> 17402602 | DQ13: =SUM(O13:Z13) -> 0 | DS13: {=IF(DS$3>'GAAP Summary'!$B$2,0,SUM(INDIRECT(XLOOKUP(DS$3,'TTM Dates'!$B:$B,'TTM Dates'!$E:$E)&ROW($CJ13)&":"&XLOOKUP(DS$3,'TTM Dates'!$B:$B,'TTM Dates'!$C:$C)&ROW($CJ13))))} -> 0 | DT13: {=IF(DT$3>'GAAP Summary'!$B$2,0,SUM(INDIRECT(XLOOKUP(DT$3,'TTM Dates'!$B:$B,'TTM Dates'!$E:$E)&ROW($CJ13)&":"&XLOOKUP(DT$3,'TTM Dates'!$B:$B,'TTM Dates'!$C:$C)&ROW($CJ13))))} -> 0 | DU13: {=IF(DU$3>'GAAP Summary'!$B$2,0,SUM(INDIRECT(XLOOKUP(DU$3,'TTM Dates'!$B:$B,'TTM Dates'!$E:$E)&ROW($CJ13)&":"&XLOOKUP(DU$3,'TTM Dates'!$B:$B,'TTM Dates'!$C:$C)&ROW($CJ13))))} -> 0 | DV13: {=IF(DV$3>'GAAP Summary'!$B$2,0,SUM(INDIRECT(XLOOKUP(DV$3,'TTM Dates'!$B:$B,'TTM Dates'!$E:$E)&ROW($CJ13)&":"&XLOOKUP(DV$3,'TTM Dates'!$B:$B,'TTM Dates'!$C:$C)&ROW($CJ13))))} -> 0 | DW13: {=IF(DW$3>'GAAP Summary'!$B$2,0,SUM(INDIRECT(XLOOKUP(DW$3,'TTM Dates'!$B:$B,'TTM Dates'!$E:$E)&ROW($CJ13)&":"&XLOOKUP(DW$3,'TTM Dates'!$B:$B,'TTM Dates'!$C:$C)&ROW($CJ13))))} -> 0 | DX13: {=IF(DX$3>'GAAP Summary'!$B$2,0,SUM(INDIRECT(XLOOKUP(DX$3,'TTM Dates'!$B:$B,'TTM Dates'!$E:$E)&ROW($CJ13)&":"&XLOOKUP(DX$3,'TTM Dates'!$B:$B,'TTM Dates'!$C:$C)&ROW($CJ13))))} -> 0 | DY13: {=IF(DY$3>'GAAP Summary'!$B$2,0,SUM(INDIRECT(XLOOKUP(DY$3,'TTM Dates'!$B:$B,'TTM Dates'!$E:$E)&ROW($CJ13)&":"&XLOOKUP(DY$3,'TTM Dates'!$B:$B,'TTM Dates'!$C:$C)&ROW($CJ13))))} -> 0 | DZ13: {=IF(DZ$3>'GAAP Summary'!$B$2,0,SUM(INDIRECT(XLOOKUP(DZ$3,'TTM Dates'!$B:$B,'TTM Dates'!$E:$E)&ROW($CJ13)&":"&XLOOKUP(DZ$3,'TTM Dates'!$B:$B,'TTM Dates'!$C:$C)&ROW($CJ13))))} -> 0 | ... GL13: {=IF(GL$3>'GAAP Summary'!$B$2,0,SUM(INDIRECT(XLOOKUP(GL$3,'TTM Dates'!$B:$B,'TTM Dates'!$E:$E)&ROW($CJ13)&":"&XLOOKUP(GL$3,'TTM Dates'!$B:$B,'TTM Dates'!$C:$C)&ROW($CJ13))))} -> 0
B14: DD | C14: =SUM(C15:C18) -> 0 | D14: =SUM(D15:D18) -> 0 | E14: =SUM(E15:E18) -> 0 | F14: =SUM(F15:F18) -> 0 | G14: =SUM(G15:G18) -> 0 | H14: =SUM(H15:H18) -> 0 | I14: =SUM(I15:I18) -> 0 | J14: =SUM(J15:J18) -> 0 | ... CH14: =SUM(CH15:CH18) -> 0 | CK14: {=SUM(INDIRECT(XLOOKUP('GAAP Summary'!$B$2,'TTM Dates'!$B:$B,'TTM Dates'!$E:$E)&ROW($CJ14)&":"&XLOOKUP('GAAP Summary'!$B$2,'TTM Dates'!$B:$B,'TTM Dates'!$C:$C)&ROW($CJ14)))} -> 13577110 | CM14: =sum(BW14:BY14) -> 3468495.1 | CN14: =sum(BZ14:CB14) -> 4388143.9 | CO14: =sum(CC14:CE14) -> 0 | CP14: =sum(CF14:CH14) -> 0 | CQ14: =sum(BW14:CH14) -> 7856639.1 | CS14: =sum(BK14:BM14) -> 2653528 | CT14: =sum(BN14:BP14) -> 2590280.1 | CU14: =sum(BQ14:BS14) -> 2722537 | CV14: =sum(BT14:BV14) -> 2997934 | CW14: =sum(BK14:BV14) -> 10964279 | CY14: =sum(AY14:BA14) -> 3062767 | CZ14: =sum(BB14:BD14) -> 2411844.2 | DA14: =sum(BE14:BG14) -> 2484964.8 | DB14: =sum(BH14:BJ14) -> 3157902.1 | DC14: =sum(AY14:BJ14) -> 11117478 | DE14: =sum(AM14:AO14) -> 0 | DF14: =sum(AP14:AR14) -> 0 | DG14: =sum(AS14:AU14) -> 0 | DH14: =sum(AV14:AX14) -> 0 | DI14: =sum(AM14:AX14) -> 0 | DK14: =sum(AA14:AC14) -> 0 | DL14: =sum(AD14:AF14) -> 0 | DM14: =sum(AG14:AI14) -> 0 | DN14: =sum(AJ14:AL14) -> 0 | DO14: =sum(AA14:AL14) -> 0 | DS14: {=IF(DS$3>'GAAP Summary'!$B$2,0,SUM(INDIRECT(XLOOKUP(DS$3,'TTM Dates'!$B:$B,'TTM Dates'!$E:$E)&ROW($CJ14)&":"&XLOOKUP(DS$3,'TTM Dates'!$B:$B,'TTM Dates'!$C:$C)&ROW($CJ14))))} -> 0 | DT14: {=IF(DT$3>'GAAP Summary'!$B$2,0,SUM(INDIRECT(XLOOKUP(DT$3,'TTM Dates'!$B:$B,'TTM Dates'!$E:$E)&ROW($CJ14)&":"&XLOOKUP(DT$3,'TTM Dates'!$B:$B,'TTM Dates'!$C:$C)&ROW($CJ14))))} -> 0 | DU14: {=IF(DU$3>'GAAP Summary'!$B$2,0,SUM(INDIRECT(XLOOKUP(DU$3,'TTM Dates'!$B:$B,'TTM Dates'!$E:$E)&ROW($CJ14)&":"&XLOOKUP(DU$3,'TTM Dates'!$B:$B,'TTM Dates'!$C:$C)&ROW($CJ14))))} -> 0 | DV14: {=IF(DV$3>'GAAP Summary'!$B$2,0,SUM(INDIRECT(XLOOKUP(DV$3,'TTM Dates'!$B:$B,'TTM Dates'!$E:$E)&ROW($CJ14)&":"&XLOOKUP(DV$3,'TTM Dates'!$B:$B,'TTM Dates'!$C:$C)&ROW($CJ14))))} -> 0 | DW14: {=IF(DW$3>'GAAP Summary'!$B$2,0,SUM(INDIRECT(XLOOKUP(DW$3,'TTM Dates'!$B:$B,'TTM Dates'!$E:$E)&ROW($CJ14)&":"&XLOOKUP(DW$3,'TTM Dates'!$B:$B,'TTM Dates'!$C:$C)&ROW($CJ14))))} -> 0 | DX14: {=IF(DX$3>'GAAP Summary'!$B$2,0,SUM(INDIRECT(XLOOKUP(DX$3,'TTM Dates'!$B:$B,'TTM Dates'!$E:$E)&ROW($CJ14)&":"&XLOOKUP(DX$3,'TTM Dates'!$B:$B,'TTM Dates'!$C:$C)&ROW($CJ14))))} -> 0 | DY14: {=IF(DY$3>'GAAP Summary'!$B$2,0,SUM(INDIRECT(XLOOKUP(DY$3,'TTM Dates'!$B:$B,'TTM Dates'!$E:$E)&ROW($CJ14)&":"&XLOOKUP(DY$3,'TTM Dates'!$B:$B,'TTM Dates'!$C:$C)&ROW($CJ14))))} -> 0 | DZ14: {=IF(DZ$3>'GAAP Summary'!$B$2,0,SUM(INDIRECT(XLOOKUP(DZ$3,'TTM Dates'!$B:$B,'TTM Dates'!$E:$E)&ROW($CJ14)&":"&XLOOKUP(DZ$3,'TTM Dates'!$B:$B,'TTM Dates'!$C:$C)&ROW($CJ14))))} -> 0 | ... GL14: {=IF(GL$3>'GAAP Summary'!$B$2,0,SUM(INDIRECT(XLOOKUP(GL$3,'TTM Dates'!$B:$B,'TTM Dates'!$E:$E)&ROW($CJ14)&":"&XLOOKUP(GL$3,'TTM Dates'!$B:$B,'TTM Dates'!$C:$C)&ROW($CJ14))))} -> 0
B15: Services | AY15: 830517.09 | AZ15: 966762.28 | BA15: 1023745.7 | BB15: 879742.33 | BC15: 672022.87 | BD15: 621978.96 | BE15: 736704.73 | BF15: 730984.54 | BG15: 781523.54 | BH15: 1033979.3 | BI15: 839033.27 | BJ15: 753392.62 | BK15: 875394 | BL15: 757328 | BM15: 612975 | BN15: 779274 | BO15: 723585 | BP15: 690883 | BQ15: 696347 | BR15: 724050 | BS15: 827944.01 | BT15: 758558.2 | BU15: 715157.84 | BV15: 775176.62 | BW15: 876689.99 | BX15: 930965.7 | BY15: 934939.53 | BZ15: =1178761.51+28660.75 -> 1207422.3 | CA15: =1398699.17-10982.96+36137.21 -> 1423853.4 | CB15: =972695.35+36035.57 -> 1008730.9 | CK15: {=SUM(INDIRECT(XLOOKUP('GAAP Summary'!$B$2,'TTM Dates'!$B:$B,'TTM Dates'!$E:$E)&ROW($CJ15)&":"&XLOOKUP('GAAP Summary'!$B$2,'TTM Dates'!$B:$B,'TTM Dates'!$C:$C)&ROW($CJ15)))} -> 10879835 | CM15: =sum(BW15:BY15) -> 2742595.2 | CN15: =sum(BZ15:CB15) -> 3640006.6 | CO15: =sum(CC15:CE15) -> 0 | CP15: =sum(CF15:CH15) -> 0 | CQ15: =sum(BW15:CH15) -> 6382601.8 | CS15: =sum(BK15:BM15) -> 2245697 | CT15: =sum(BN15:BP15) -> 2193742 | CU15: =sum(BQ15:BS15) -> 2248341 | CV15: =sum(BT15:BV15) -> 2248892.7 | CW15: =sum(BK15:BV15) -> 8936672.7 | CY15: =sum(AY15:BA15) -> 2821025 | CZ15: =sum(BB15:BD15) -> 2173744.2 | DA15: =sum(BE15:BG15) -> 2249212.8 | DB15: =sum(BH15:BJ15) -> 2626405.1 | DC15: =sum(AY15:BJ15) -> 9870387.2 | DE15: =sum(AM15:AO15) -> 0 | DF15: =sum(AP15:AR15) -> 0 | DG15: =sum(AS15:AU15) -> 0 | DH15: =sum(AV15:AX15) -> 0 | DI15: =sum(AM15:AX15) -> 0 | DK15: =sum(AA15:AC15) -> 0 | DL15: =sum(AD15:AF15) -> 0 | DM15: =sum(AG15:AI15) -> 0 | DN15: =sum(AJ15:AL15) -> 0 | DO15: =sum(AA15:AL15) -> 0 | DS15: {=IF(DS$3>'GAAP Summary'!$B$2,0,SUM(INDIRECT(XLOOKUP(DS$3,'TTM Dates'!$B:$B,'TTM Dates'!$E:$E)&ROW($CJ15)&":"&XLOOKUP(DS$3,'TTM Dates'!$B:$B,'TTM Dates'!$C:$C)&ROW($CJ15))))} -> 0 | DT15: {=IF(DT$3>'GAAP Summary'!$B$2,0,SUM(INDIRECT(XLOOKUP(DT$3,'TTM Dates'!$B:$B,'TTM Dates'!$E:$E)&ROW($CJ15)&":"&XLOOKUP(DT$3,'TTM Dates'!$B:$B,'TTM Dates'!$C:$C)&ROW($CJ15))))} -> 0 | DU15: {=IF(DU$3>'GAAP Summary'!$B$2,0,SUM(INDIRECT(XLOOKUP(DU$3,'TTM Dates'!$B:$B,'TTM Dates'!$E:$E)&ROW($CJ15)&":"&XLOOKUP(DU$3,'TTM Dates'!$B:$B,'TTM Dates'!$C:$C)&ROW($CJ15))))} -> 0 | DV15: {=IF(DV$3>'GAAP Summary'!$B$2,0,SUM(INDIRECT(XLOOKUP(DV$3,'TTM Dates'!$B:$B,'TTM Dates'!$E:$E)&ROW($CJ15)&":"&XLOOKUP(DV$3,'TTM Dates'!$B:$B,'TTM Dates'!$C:$C)&ROW($CJ15))))} -> 0 | DW15: {=IF(DW$3>'GAAP Summary'!$B$2,0,SUM(INDIRECT(XLOOKUP(DW$3,'TTM Dates'!$B:$B,'TTM Dates'!$E:$E)&ROW($CJ15)&":"&XLOOKUP(DW$3,'TTM Dates'!$B:$B,'TTM Dates'!$C:$C)&ROW($CJ15))))} -> 0 | DX15: {=IF(DX$3>'GAAP Summary'!$B$2,0,SUM(INDIRECT(XLOOKUP(DX$3,'TTM Dates'!$B:$B,'TTM Dates'!$E:$E)&ROW($CJ15)&":"&XLOOKUP(DX$3,'TTM Dates'!$B:$B,'TTM Dates'!$C:$C)&ROW($CJ15))))} -> 0 | DY15: {=IF(DY$3>'GAAP Summary'!$B$2,0,SUM(INDIRECT(XLOOKUP(DY$3,'TTM Dates'!$B:$B,'TTM Dates'!$E:$E)&ROW($CJ15)&":"&XLOOKUP(DY$3,'TTM Dates'!$B:$B,'TTM Dates'!$C:$C)&ROW($CJ15))))} -> 0 | DZ15: {=IF(DZ$3>'GAAP Summary'!$B$2,0,SUM(INDIRECT(XLOOKUP(DZ$3,'TTM Dates'!$B:$B,'TTM Dates'!$E:$E)&ROW($CJ15)&":"&XLOOKUP(DZ$3,'TTM Dates'!$B:$B,'TTM Dates'!$C:$C)&ROW($CJ15))))} -> 0 | ... GL15: {=IF(GL$3>'GAAP Summary'!$B$2,0,SUM(INDIRECT(XLOOKUP(GL$3,'TTM Dates'!$B:$B,'TTM Dates'!$E:$E)&ROW($CJ15)&":"&XLOOKUP(GL$3,'TTM Dates'!$B:$B,'TTM Dates'!$C:$C)&ROW($CJ15))))} -> 0
B16: Software | AY16: 80743 | AZ16: 79623 | BA16: 81376 | BB16: 72606 | BC16: 79646 | BD16: 72514 | BE16: 74182 | BF16: 74307 | BG16: 75211 | BH16: 87133 | BI16: 86683 | BJ16: 86797 | BK16: 127809 | BL16: 84064 | BM16: 93790 | BN16: 77607 | BO16: 48652 | BP16: 45404 | BQ16: 50745.93 | BR16: 66270.69 | BS16: 69253.69 | BT16: 69413.5 | BU16: 95773.09 | BV16: 70032.69 | BW16: 84906.83 | BX16: 89329.83 | BY16: 87046.32 | BZ16: 81991.83 | CA16: 86060.79 | CB16: 78619.8 | CK16: {=SUM(INDIRECT(XLOOKUP('GAAP Summary'!$B$2,'TTM Dates'!$B:$B,'TTM Dates'!$E:$E)&ROW($CJ16)&":"&XLOOKUP('GAAP Summary'!$B$2,'TTM Dates'!$B:$B,'TTM Dates'!$C:$C)&ROW($CJ16)))} -> 929444.99 | CM16: =sum(BW16:BY16) -> 261282.98 | CN16: =sum(BZ16:CB16) -> 246672.42 | CO16: =sum(CC16:CE16) -> 0 | CP16: =sum(CF16:CH16) -> 0 | CQ16: =sum(BW16:CH16) -> 507955.4 | CS16: =sum(BK16:BM16) -> 305663 | CT16: =sum(BN16:BP16) -> 171663 | CU16: =sum(BQ16:BS16) -> 186270.31 | CV16: =sum(BT16:BV16) -> 235219.28 | CW16: =sum(BK16:BV16) -> 898815.59 | CY16: =sum(AY16:BA16) -> 241742 | CZ16: =sum(BB16:BD16) -> 224766 | DA16: =sum(BE16:BG16) -> 223700 | DB16: =sum(BH16:BJ16) -> 260613 | DC16: =sum(AY16:BJ16) -> 950821 | DE16: =sum(AM16:AO16) -> 0 | DF16: =sum(AP16:AR16) -> 0 | DG16: =sum(AS16:AU16) -> 0 | DH16: =sum(AV16:AX16) -> 0 | DI16: =sum(AM16:AX16) -> 0 | DK16: =sum(AA16:AC16) -> 0 | DL16: =sum(AD16:AF16) -> 0 | DM16: =sum(AG16:AI16) -> 0 | DN16: =sum(AJ16:AL16) -> 0 | DO16: =sum(AA16:AL16) -> 0 | DS16: {=IF(DS$3>'GAAP Summary'!$B$2,0,SUM(INDIRECT(XLOOKUP(DS$3,'TTM Dates'!$B:$B,'TTM Dates'!$E:$E)&ROW($CJ16)&":"&XLOOKUP(DS$3,'TTM Dates'!$B:$B,'TTM Dates'!$C:$C)&ROW($CJ16))))} -> 0 | DT16: {=IF(DT$3>'GAAP Summary'!$B$2,0,SUM(INDIRECT(XLOOKUP(DT$3,'TTM Dates'!$B:$B,'TTM Dates'!$E:$E)&ROW($CJ16)&":"&XLOOKUP(DT$3,'TTM Dates'!$B:$B,'TTM Dates'!$C:$C)&ROW($CJ16))))} -> 0 | DU16: {=IF(DU$3>'GAAP Summary'!$B$2,0,SUM(INDIRECT(XLOOKUP(DU$3,'TTM Dates'!$B:$B,'TTM Dates'!$E:$E)&ROW($CJ16)&":"&XLOOKUP(DU$3,'TTM Dates'!$B:$B,'TTM Dates'!$C:$C)&ROW($CJ16))))} -> 0 | DV16: {=IF(DV$3>'GAAP Summary'!$B$2,0,SUM(INDIRECT(XLOOKUP(DV$3,'TTM Dates'!$B:$B,'TTM Dates'!$E:$E)&ROW($CJ16)&":"&XLOOKUP(DV$3,'TTM Dates'!$B:$B,'TTM Dates'!$C:$C)&ROW($CJ16))))} -> 0 | DW16: {=IF(DW$3>'GAAP Summary'!$B$2,0,SUM(INDIRECT(XLOOKUP(DW$3,'TTM Dates'!$B:$B,'TTM Dates'!$E:$E)&ROW($CJ16)&":"&XLOOKUP(DW$3,'TTM Dates'!$B:$B,'TTM Dates'!$C:$C)&ROW($CJ16))))} -> 0 | DX16: {=IF(DX$3>'GAAP Summary'!$B$2,0,SUM(INDIRECT(XLOOKUP(DX$3,'TTM Dates'!$B:$B,'TTM Dates'!$E:$E)&ROW($CJ16)&":"&XLOOKUP(DX$3,'TTM Dates'!$B:$B,'TTM Dates'!$C:$C)&ROW($CJ16))))} -> 0 | DY16: {=IF(DY$3>'GAAP Summary'!$B$2,0,SUM(INDIRECT(XLOOKUP(DY$3,'TTM Dates'!$B:$B,'TTM Dates'!$E:$E)&ROW($CJ16)&":"&XLOOKUP(DY$3,'TTM Dates'!$B:$B,'TTM Dates'!$C:$C)&ROW($CJ16))))} -> 0 | DZ16: {=IF(DZ$3>'GAAP Summary'!$B$2,0,SUM(INDIRECT(XLOOKUP(DZ$3,'TTM Dates'!$B:$B,'TTM Dates'!$E:$E)&ROW($CJ16)&":"&XLOOKUP(DZ$3,'TTM Dates'!$B:$B,'TTM Dates'!$C:$C)&ROW($CJ16))))} -> 0 | ... GL16: {=IF(GL$3>'GAAP Summary'!$B$2,0,SUM(INDIRECT(XLOOKUP(GL$3,'TTM Dates'!$B:$B,'TTM Dates'!$E:$E)&ROW($CJ16)&":"&XLOOKUP(GL$3,'TTM Dates'!$B:$B,'TTM Dates'!$C:$C)&ROW($CJ16))))} -> 0
B17: Managed DD | AY17: 0 | AZ17: 0 | BA17: 0 | BB17: 0 | BC17: 6667 | BD17: 6667 | BE17: 6667 | BF17: 0 | BG17: 5385 | BH17: 88580 | BI17: 88580 | BJ17: 93724 | BK17: 35588 | BL17: 33290 | BM17: 33290 | BN17: 33290.15 | BO17: 48290.15 | BP17: 48290.15 | BQ17: 48290.15 | BR17: 48290.15 | BS17: 54540.12 | BT17: 92612.38 | BU17: 103862.28 | BV17: 98718.08 | BW17: 98718.08 | BX17: 57884.79 | BY17: 58718.08 | BZ17: 64968.08 | CA17: 72468.07 | CB17: 72468.07 | CK17: {=SUM(INDIRECT(XLOOKUP('GAAP Summary'!$B$2,'TTM Dates'!$B:$B,'TTM Dates'!$E:$E)&ROW($CJ17)&":"&XLOOKUP('GAAP Summary'!$B$2,'TTM Dates'!$B:$B,'TTM Dates'!$C:$C)&ROW($CJ17)))} -> 871538.33 | CM17: =sum(BW17:BY17) -> 215320.95 | CN17: =sum(BZ17:CB17) -> 209904.22 | CO17: =sum(CC17:CE17) -> 0 | CP17: =sum(CF17:CH17) -> 0 | CQ17: =sum(BW17:CH17) -> 425225.17 | CS17: =sum(BK17:BM17) -> 102168 | CT17: =sum(BN17:BP17) -> 129870.45 | CU17: =sum(BQ17:BS17) -> 151120.42 | CV17: =sum(BT17:BV17) -> 295192.74 | CW17: =sum(BK17:BV17) -> 678351.61 | CY17: =sum(AY17:BA17) -> 0 | CZ17: =sum(BB17:BD17) -> 13334 | DA17: =sum(BE17:BG17) -> 12052 | DB17: =sum(BH17:BJ17) -> 270884 | DC17: =sum(AY17:BJ17) -> 296270 | DE17: =sum(AM17:AO17) -> 0 | DF17: =sum(AP17:AR17) -> 0 | DG17: =sum(AS17:AU17) -> 0 | DH17: =sum(AV17:AX17) -> 0 | DI17: =sum(AM17:AX17) -> 0 | DK17: =sum(AA17:AC17) -> 0 | DL17: =sum(AD17:AF17) -> 0 | DM17: =sum(AG17:AI17) -> 0 | DN17: =sum(AJ17:AL17) -> 0 | DO17: =sum(AA17:AL17) -> 0 | DS17: {=IF(DS$3>'GAAP Summary'!$B$2,0,SUM(INDIRECT(XLOOKUP(DS$3,'TTM Dates'!$B:$B,'TTM Dates'!$E:$E)&ROW($CJ17)&":"&XLOOKUP(DS$3,'TTM Dates'!$B:$B,'TTM Dates'!$C:$C)&ROW($CJ17))))} -> 0 | DT17: {=IF(DT$3>'GAAP Summary'!$B$2,0,SUM(INDIRECT(XLOOKUP(DT$3,'TTM Dates'!$B:$B,'TTM Dates'!$E:$E)&ROW($CJ17)&":"&XLOOKUP(DT$3,'TTM Dates'!$B:$B,'TTM Dates'!$C:$C)&ROW($CJ17))))} -> 0 | DU17: {=IF(DU$3>'GAAP Summary'!$B$2,0,SUM(INDIRECT(XLOOKUP(DU$3,'TTM Dates'!$B:$B,'TTM Dates'!$E:$E)&ROW($CJ17)&":"&XLOOKUP(DU$3,'TTM Dates'!$B:$B,'TTM Dates'!$C:$C)&ROW($CJ17))))} -> 0 | DV17: {=IF(DV$3>'GAAP Summary'!$B$2,0,SUM(INDIRECT(XLOOKUP(DV$3,'TTM Dates'!$B:$B,'TTM Dates'!$E:$E)&ROW($CJ17)&":"&XLOOKUP(DV$3,'TTM Dates'!$B:$B,'TTM Dates'!$C:$C)&ROW($CJ17))))} -> 0 | DW17: {=IF(DW$3>'GAAP Summary'!$B$2,0,SUM(INDIRECT(XLOOKUP(DW$3,'TTM Dates'!$B:$B,'TTM Dates'!$E:$E)&ROW($CJ17)&":"&XLOOKUP(DW$3,'TTM Dates'!$B:$B,'TTM Dates'!$C:$C)&ROW($CJ17))))} -> 0 | DX17: {=IF(DX$3>'GAAP Summary'!$B$2,0,SUM(INDIRECT(XLOOKUP(DX$3,'TTM Dates'!$B:$B,'TTM Dates'!$E:$E)&ROW($CJ17)&":"&XLOOKUP(DX$3,'TTM Dates'!$B:$B,'TTM Dates'!$C:$C)&ROW($CJ17))))} -> 0 | DY17: {=IF(DY$3>'GAAP Summary'!$B$2,0,SUM(INDIRECT(XLOOKUP(DY$3,'TTM Dates'!$B:$B,'TTM Dates'!$E:$E)&ROW($CJ17)&":"&XLOOKUP(DY$3,'TTM Dates'!$B:$B,'TTM Dates'!$C:$C)&ROW($CJ17))))} -> 0 | DZ17: {=IF(DZ$3>'GAAP Summary'!$B$2,0,SUM(INDIRECT(XLOOKUP(DZ$3,'TTM Dates'!$B:$B,'TTM Dates'!$E:$E)&ROW($CJ17)&":"&XLOOKUP(DZ$3,'TTM Dates'!$B:$B,'TTM Dates'!$C:$C)&ROW($CJ17))))} -> 0 | ... GL17: {=IF(GL$3>'GAAP Summary'!$B$2,0,SUM(INDIRECT(XLOOKUP(GL$3,'TTM Dates'!$B:$B,'TTM Dates'!$E:$E)&ROW($CJ17)&":"&XLOOKUP(GL$3,'TTM Dates'!$B:$B,'TTM Dates'!$C:$C)&ROW($CJ17))))} -> 0
B18: Managed SOC | BN18: 14801.17 | BO18: 40101.75 | BP18: 40101.75 | BQ18: 45601.75 | BR18: 45601.75 | BS18: 45601.75 | BT18: 70098.66 | BU18: 70098.66 | BV18: 78431.99 | BW18: 78431.99 | BX18: 85431.99 | BY18: 85431.99 | BZ18: 85431.99 | CA18: 98897.69 | CB18: 107231.02 | CK18: {=SUM(INDIRECT(XLOOKUP('GAAP Summary'!$B$2,'TTM Dates'!$B:$B,'TTM Dates'!$E:$E)&ROW($CJ18)&":"&XLOOKUP('GAAP Summary'!$B$2,'TTM Dates'!$B:$B,'TTM Dates'!$C:$C)&ROW($CJ18)))} -> 896291.23 | CM18: =sum(BW18:BY18) -> 249295.97 | CN18: =sum(BZ18:CB18) -> 291560.7 | CO18: =sum(CC18:CE18) -> 0 | CP18: =sum(CF18:CH18) -> 0 | CQ18: =sum(BW18:CH18) -> 540856.67 | CS18: =sum(BK18:BM18) -> 0 | CT18: =sum(BN18:BP18) -> 95004.67 | CU18: =sum(BQ18:BS18) -> 136805.25 | CV18: =sum(BT18:BV18) -> 218629.31 | CW18: =sum(BK18:BV18) -> 450439.23 | CY18: =sum(AY18:BA18) -> 0 | CZ18: =sum(BB18:BD18) -> 0 | DA18: =sum(BE18:BG18) -> 0 | DB18: =sum(BH18:BJ18) -> 0 | DC18: =sum(AY18:BJ18) -> 0 | DE18: =sum(AM18:AO18) -> 0 | DF18: =sum(AP18:AR18) -> 0 | DG18: =sum(AS18:AU18) -> 0 | DH18: =sum(AV18:AX18) -> 0 | DI18: =sum(AM18:AX18) -> 0 | DK18: =sum(AA18:AC18) -> 0 | DL18: =sum(AD18:AF18) -> 0 | DM18: =sum(AG18:AI18) -> 0 | DN18: =sum(AJ18:AL18) -> 0 | DO18: =sum(AA18:AL18) -> 0
B19: SN | C19: =SUM(C20:C22) -> 0 | D19: =SUM(D20:D22) -> 0 | E19: =SUM(E20:E22) -> 0 | F19: =SUM(F20:F22) -> 0 | G19: =SUM(G20:G22) -> 0 | H19: =SUM(H20:H22) -> 0 | I19: =SUM(I20:I22) -> 0 | J19: =SUM(J20:J22) -> 0 | ... CH19: =SUM(CH20:CH22) -> 0 | CK19: {=SUM(INDIRECT(XLOOKUP('GAAP Summary'!$B$2,'TTM Dates'!$B:$B,'TTM Dates'!$E:$E)&ROW($CJ19)&":"&XLOOKUP('GAAP Summary'!$B$2,'TTM Dates'!$B:$B,'TTM Dates'!$C:$C)&ROW($CJ19)))} -> 33090596 | CM19: =sum(BW19:BY19) -> 9105745.6 | CN19: =sum(BZ19:CB19) -> 9256310 | CO19: =sum(CC19:CE19) -> 0 | CP19: =sum(CF19:CH19) -> 0 | CQ19: =sum(BW19:CH19) -> 18362056 | CS19: =sum(BK19:BM19) -> 4770083 | CT19: =sum(BN19:BP19) -> 5452415 | CU19: =sum(BQ19:BS19) -> 6776192.3 | CV19: =sum(BT19:BV19) -> 7952347.7 | CW19: =sum(BK19:BV19) -> 24951038 | CY19: =sum(AY19:BA19) -> 2400791.3 | CZ19: =sum(BB19:BD19) -> 3338946.4 | DA19: =sum(BE19:BG19) -> 3927548.6 | DB19: =sum(BH19:BJ19) -> 4570179.1 | DC19: =sum(AY19:BJ19) -> 14237465 | DE19: =sum(AM19:AO19) -> 0 | DF19: =sum(AP19:AR19) -> 0 | DG19: =sum(AS19:AU19) -> 0 | DH19: =sum(AV19:AX19) -> 0 | DI19: =sum(AM19:AX19) -> 0 | DS19: {=IF(DS$3>'GAAP Summary'!$B$2,0,SUM(INDIRECT(XLOOKUP(DS$3,'TTM Dates'!$B:$B,'TTM Dates'!$E:$E)&ROW($CJ19)&":"&XLOOKUP(DS$3,'TTM Dates'!$B:$B,'TTM Dates'!$C:$C)&ROW($CJ19))))} -> 0 | DT19: {=IF(DT$3>'GAAP Summary'!$B$2,0,SUM(INDIRECT(XLOOKUP(DT$3,'TTM Dates'!$B:$B,'TTM Dates'!$E:$E)&ROW($CJ19)&":"&XLOOKUP(DT$3,'TTM Dates'!$B:$B,'TTM Dates'!$C:$C)&ROW($CJ19))))} -> 0 | DU19: {=IF(DU$3>'GAAP Summary'!$B$2,0,SUM(INDIRECT(XLOOKUP(DU$3,'TTM Dates'!$B:$B,'TTM Dates'!$E:$E)&ROW($CJ19)&":"&XLOOKUP(DU$3,'TTM Dates'!$B:$B,'TTM Dates'!$C:$C)&ROW($CJ19))))} -> 0 | DV19: {=IF(DV$3>'GAAP Summary'!$B$2,0,SUM(INDIRECT(XLOOKUP(DV$3,'TTM Dates'!$B:$B,'TTM Dates'!$E:$E)&ROW($CJ19)&":"&XLOOKUP(DV$3,'TTM Dates'!$B:$B,'TTM Dates'!$C:$C)&ROW($CJ19))))} -> 0 | DW19: {=IF(DW$3>'GAAP Summary'!$B$2,0,SUM(INDIRECT(XLOOKUP(DW$3,'TTM Dates'!$B:$B,'TTM Dates'!$E:$E)&ROW($CJ19)&":"&XLOOKUP(DW$3,'TTM Dates'!$B:$B,'TTM Dates'!$C:$C)&ROW($CJ19))))} -> 0 | DX19: {=IF(DX$3>'GAAP Summary'!$B$2,0,SUM(INDIRECT(XLOOKUP(DX$3,'TTM Dates'!$B:$B,'TTM Dates'!$E:$E)&ROW($CJ19)&":"&XLOOKUP(DX$3,'TTM Dates'!$B:$B,'TTM Dates'!$C:$C)&ROW($CJ19))))} -> 0 | DY19: {=IF(DY$3>'GAAP Summary'!$B$2,0,SUM(INDIRECT(XLOOKUP(DY$3,'TTM Dates'!$B:$B,'TTM Dates'!$E:$E)&ROW($CJ19)&":"&XLOOKUP(DY$3,'TTM Dates'!$B:$B,'TTM Dates'!$C:$C)&ROW($CJ19))))} -> 0 | DZ19: {=IF(DZ$3>'GAAP Summary'!$B$2,0,SUM(INDIRECT(XLOOKUP(DZ$3,'TTM Dates'!$B:$B,'TTM Dates'!$E:$E)&ROW($CJ19)&":"&XLOOKUP(DZ$3,'TTM Dates'!$B:$B,'TTM Dates'!$C:$C)&ROW($CJ19))))} -> 0 | ... GL19: {=IF(GL$3>'GAAP Summary'!$B$2,0,SUM(INDIRECT(XLOOKUP(GL$3,'TTM Dates'!$B:$B,'TTM Dates'!$E:$E)&ROW($CJ19)&":"&XLOOKUP(GL$3,'TTM Dates'!$B:$B,'TTM Dates'!$C:$C)&ROW($CJ19))))} -> 0
B20: Services | AY20: 771081.83 | AZ20: 769743.59 | BA20: 807165.84 | BB20: 1051374.3 | BC20: 1157715.4 | BD20: 1129856.8 | BE20: 1257534.6 | BF20: 1356081.8 | BG20: 1296433.1 | BH20: 1615619.4 | BI20: 1448123.6 | BJ20: 1488937.1 | BK20: 1533472 | BL20: 1536951 | BM20: 1682161 | BN20: 1798995 | BO20: 1781972 | BP20: 1853949 | BQ20: 2268372 | BR20: 2040001 | BS20: 2467819.4 | BT20: 3001139.8 | BU20: 2302939.9 | BV20: 2467373.7 | BW20: 2942831.8 | BX20: 2880949.1 | BY20: 3280298 | BZ20: =2585543.06+560383.68 -> 3145926.7 | CA20: =2457304.79+216386.75 -> 2673691.5 | CB20: =3393716.51+29780.3+9861.58 -> 3433358.4 | CK20: {=SUM(INDIRECT(XLOOKUP('GAAP Summary'!$B$2,'TTM Dates'!$B:$B,'TTM Dates'!$E:$E)&ROW($CJ20)&":"&XLOOKUP('GAAP Summary'!$B$2,'TTM Dates'!$B:$B,'TTM Dates'!$C:$C)&ROW($CJ20)))} -> 32904701 | CM20: =sum(BW20:BY20) -> 9104079 | CN20: =sum(BZ20:CB20) -> 9252976.7 | CO20: =sum(CC20:CE20) -> 0 | CP20: =sum(CF20:CH20) -> 0 | CQ20: =sum(BW20:CH20) -> 18357056 | CS20: =sum(BK20:BM20) -> 4752584 | CT20: =sum(BN20:BP20) -> 5434916 | CU20: =sum(BQ20:BS20) -> 6776192.3 | CV20: =sum(BT20:BV20) -> 7771453.4 | CW20: =sum(BK20:BV20) -> 24735146 | CY20: =sum(AY20:BA20) -> 2347991.3 | CZ20: =sum(BB20:BD20) -> 3338946.4 | DA20: =sum(BE20:BG20) -> 3910049.6 | DB20: =sum(BH20:BJ20) -> 4552680.1 | DC20: =sum(AY20:BJ20) -> 14149667 | DE20: =sum(AM20:AO20) -> 0 | DF20: =sum(AP20:AR20) -> 0 | DG20: =sum(AS20:AU20) -> 0 | DH20: =sum(AV20:AX20) -> 0 | DI20: =sum(AM20:AX20) -> 0 | DK20: =sum(AA20:AC20) -> 0 | DL20: =sum(AD20:AF20) -> 0 | DM20: =sum(AG20:AI20) -> 0 | DN20: =sum(AJ20:AL20) -> 0 | DO20: =sum(AA20:AL20) -> 0 | DS20: {=IF(DS$3>'GAAP Summary'!$B$2,0,SUM(INDIRECT(XLOOKUP(DS$3,'TTM Dates'!$B:$B,'TTM Dates'!$E:$E)&ROW($CJ20)&":"&XLOOKUP(DS$3,'TTM Dates'!$B:$B,'TTM Dates'!$C:$C)&ROW($CJ20))))} -> 0 | DT20: {=IF(DT$3>'GAAP Summary'!$B$2,0,SUM(INDIRECT(XLOOKUP(DT$3,'TTM Dates'!$B:$B,'TTM Dates'!$E:$E)&ROW($CJ20)&":"&XLOOKUP(DT$3,'TTM Dates'!$B:$B,'TTM Dates'!$C:$C)&ROW($CJ20))))} -> 0 | DU20: {=IF(DU$3>'GAAP Summary'!$B$2,0,SUM(INDIRECT(XLOOKUP(DU$3,'TTM Dates'!$B:$B,'TTM Dates'!$E:$E)&ROW($CJ20)&":"&XLOOKUP(DU$3,'TTM Dates'!$B:$B,'TTM Dates'!$C:$C)&ROW($CJ20))))} -> 0 | DV20: {=IF(DV$3>'GAAP Summary'!$B$2,0,SUM(INDIRECT(XLOOKUP(DV$3,'TTM Dates'!$B:$B,'TTM Dates'!$E:$E)&ROW($CJ20)&":"&XLOOKUP(DV$3,'TTM Dates'!$B:$B,'TTM Dates'!$C:$C)&ROW($CJ20))))} -> 0 | DW20: {=IF(DW$3>'GAAP Summary'!$B$2,0,SUM(INDIRECT(XLOOKUP(DW$3,'TTM Dates'!$B:$B,'TTM Dates'!$E:$E)&ROW($CJ20)&":"&XLOOKUP(DW$3,'TTM Dates'!$B:$B,'TTM Dates'!$C:$C)&ROW($CJ20))))} -> 0 | DX20: {=IF(DX$3>'GAAP Summary'!$B$2,0,SUM(INDIRECT(XLOOKUP(DX$3,'TTM Dates'!$B:$B,'TTM Dates'!$E:$E)&ROW($CJ20)&":"&XLOOKUP(DX$3,'TTM Dates'!$B:$B,'TTM Dates'!$C:$C)&ROW($CJ20))))} -> 0 | DY20: {=IF(DY$3>'GAAP Summary'!$B$2,0,SUM(INDIRECT(XLOOKUP(DY$3,'TTM Dates'!$B:$B,'TTM Dates'!$E:$E)&ROW($CJ20)&":"&XLOOKUP(DY$3,'TTM Dates'!$B:$B,'TTM Dates'!$C:$C)&ROW($CJ20))))} -> 0 | DZ20: {=IF(DZ$3>'GAAP Summary'!$B$2,0,SUM(INDIRECT(XLOOKUP(DZ$3,'TTM Dates'!$B:$B,'TTM Dates'!$E:$E)&ROW($CJ20)&":"&XLOOKUP(DZ$3,'TTM Dates'!$B:$B,'TTM Dates'!$C:$C)&ROW($CJ20))))} -> 0 | ... GL20: {=IF(GL$3>'GAAP Summary'!$B$2,0,SUM(INDIRECT(XLOOKUP(GL$3,'TTM Dates'!$B:$B,'TTM Dates'!$E:$E)&ROW($CJ20)&":"&XLOOKUP(GL$3,'TTM Dates'!$B:$B,'TTM Dates'!$C:$C)&ROW($CJ20))))} -> 0
B21: Software | AY21: 0 | AZ21: 52800 | BA21: 0 | BB21: 0 | BC21: 0 | BD21: 0 | BE21: 5833 | BF21: 5833 | BG21: 5833 | BH21: 5833 | BI21: 5833 | BJ21: 5833 | BK21: 5833 | BL21: 5833 | BM21: 5833 | BN21: 5833 | BO21: 5833 | BP21: 5833 | BQ21: 0 | BS21: 0 | BT21: 29269.17 | BV21: 151625.04 | BY21: 1666.67 | BZ21: 1666.67 | CB21: 1666.67 | CK21: {=SUM(INDIRECT(XLOOKUP('GAAP Summary'!$B$2,'TTM Dates'!$B:$B,'TTM Dates'!$E:$E)&ROW($CJ21)&":"&XLOOKUP('GAAP Summary'!$B$2,'TTM Dates'!$B:$B,'TTM Dates'!$C:$C)&ROW($CJ21)))} -> 185894.22 | CM21: =sum(BW21:BY21) -> 1666.67 | CN21: =sum(BZ21:CB21) -> 3333.34 | CO21: =sum(CC21:CE21) -> 0 | CP21: =sum(CF21:CH21) -> 0 | CQ21: =sum(BW21:CH21) -> 5000.01 | CS21: =sum(BK21:BM21) -> 17499 | CT21: =sum(BN21:BP21) -> 17499 | CU21: =sum(BQ21:BS21) -> 0 | CV21: =sum(BT21:BV21) -> 180894.21 | CW21: =sum(BK21:BV21) -> 215892.21 | CY21: =sum(AY21:BA21) -> 52800 | CZ21: =sum(BB21:BD21) -> 0 | DA21: =sum(BE21:BG21) -> 17499 | DB21: =sum(BH21:BJ21) -> 17499 | DC21: =sum(AY21:BJ21) -> 87798 | DE21: =sum(AM21:AO21) -> 0 | DF21: =sum(AP21:AR21) -> 0 | DG21: =sum(AS21:AU21) -> 0 | DH21: =sum(AV21:AX21) -> 0 | DI21: =sum(AM21:AX21) -> 0 | DK21: =sum(AA21:AC21) -> 0 | DL21: =sum(AD21:AF21) -> 0 | DM21: =sum(AG21:AI21) -> 0 | DN21: =sum(AJ21:AL21) -> 0 | DO21: =sum(AA21:AL21) -> 0 | DS21: {=IF(DS$3>'GAAP Summary'!$B$2,0,SUM(INDIRECT(XLOOKUP(DS$3,'TTM Dates'!$B:$B,'TTM Dates'!$E:$E)&ROW($CJ21)&":"&XLOOKUP(DS$3,'TTM Dates'!$B:$B,'TTM Dates'!$C:$C)&ROW($CJ21))))} -> 0 | DT21: {=IF(DT$3>'GAAP Summary'!$B$2,0,SUM(INDIRECT(XLOOKUP(DT$3,'TTM Dates'!$B:$B,'TTM Dates'!$E:$E)&ROW($CJ21)&":"&XLOOKUP(DT$3,'TTM Dates'!$B:$B,'TTM Dates'!$C:$C)&ROW($CJ21))))} -> 0 | DU21: {=IF(DU$3>'GAAP Summary'!$B$2,0,SUM(INDIRECT(XLOOKUP(DU$3,'TTM Dates'!$B:$B,'TTM Dates'!$E:$E)&ROW($CJ21)&":"&XLOOKUP(DU$3,'TTM Dates'!$B:$B,'TTM Dates'!$C:$C)&ROW($CJ21))))} -> 0 | DV21: {=IF(DV$3>'GAAP Summary'!$B$2,0,SUM(INDIRECT(XLOOKUP(DV$3,'TTM Dates'!$B:$B,'TTM Dates'!$E:$E)&ROW($CJ21)&":"&XLOOKUP(DV$3,'TTM Dates'!$B:$B,'TTM Dates'!$C:$C)&ROW($CJ21))))} -> 0 | DW21: {=IF(DW$3>'GAAP Summary'!$B$2,0,SUM(INDIRECT(XLOOKUP(DW$3,'TTM Dates'!$B:$B,'TTM Dates'!$E:$E)&ROW($CJ21)&":"&XLOOKUP(DW$3,'TTM Dates'!$B:$B,'TTM Dates'!$C:$C)&ROW($CJ21))))} -> 0 | DX21: {=IF(DX$3>'GAAP Summary'!$B$2,0,SUM(INDIRECT(XLOOKUP(DX$3,'TTM Dates'!$B:$B,'TTM Dates'!$E:$E)&ROW($CJ21)&":"&XLOOKUP(DX$3,'TTM Dates'!$B:$B,'TTM Dates'!$C:$C)&ROW($CJ21))))} -> 0 | DY21: {=IF(DY$3>'GAAP Summary'!$B$2,0,SUM(INDIRECT(XLOOKUP(DY$3,'TTM Dates'!$B:$B,'TTM Dates'!$E:$E)&ROW($CJ21)&":"&XLOOKUP(DY$3,'TTM Dates'!$B:$B,'TTM Dates'!$C:$C)&ROW($CJ21))))} -> 0 | DZ21: {=IF(DZ$3>'GAAP Summary'!$B$2,0,SUM(INDIRECT(XLOOKUP(DZ$3,'TTM Dates'!$B:$B,'TTM Dates'!$E:$E)&ROW($CJ21)&":"&XLOOKUP(DZ$3,'TTM Dates'!$B:$B,'TTM Dates'!$C:$C)&ROW($CJ21))))} -> 0 | ... GL21: {=IF(GL$3>'GAAP Summary'!$B$2,0,SUM(INDIRECT(XLOOKUP(GL$3,'TTM Dates'!$B:$B,'TTM Dates'!$E:$E)&ROW($CJ21)&":"&XLOOKUP(GL$3,'TTM Dates'!$B:$B,'TTM Dates'!$C:$C)&ROW($CJ21))))} -> 0
B22: MSP | BS22: 0 | CK22: {=SUM(INDIRECT(XLOOKUP('GAAP Summary'!$B$2,'TTM Dates'!$B:$B,'TTM Dates'!$E:$E)&ROW($CJ22)&":"&XLOOKUP('GAAP Summary'!$B$2,'TTM Dates'!$B:$B,'TTM Dates'!$C:$C)&ROW($CJ22)))} -> 0 | CM22: =sum(BW22:BY22) -> 0 | CN22: =sum(BZ22:CB22) -> 0 | CO22: =sum(CC22:CE22) -> 0 | CP22: =sum(CF22:CH22) -> 0 | CQ22: =sum(BW22:CH22) -> 0 | CS22: =sum(BK22:BM22) -> 0 | CT22: =sum(BN22:BP22) -> 0 | CU22: =sum(BQ22:BS22) -> 0 | CV22: =sum(BT22:BV22) -> 0 | CW22: =sum(BK22:BV22) -> 0 | CY22: =sum(AY22:BA22) -> 0 | CZ22: =sum(BB22:BD22) -> 0 | DA22: =sum(BE22:BG22) -> 0 | DB22: =sum(BH22:BJ22) -> 0 | DC22: =sum(AY22:BJ22) -> 0 | DE22: =sum(AM22:AO22) -> 0 | DF22: =sum(AP22:AR22) -> 0 | DG22: =sum(AS22:AU22) -> 0 | DH22: =sum(AV22:AX22) -> 0 | DI22: =sum(AM22:AX22) -> 0 | DK22: =sum(AA22:AC22) -> 0 | DL22: =sum(AD22:AF22) -> 0 | DM22: =sum(AG22:AI22) -> 0 | DN22: =sum(AJ22:AL22) -> 0 | DO22: =sum(AA22:AL22) -> 0 | DS22: {=IF(DS$3>'GAAP Summary'!$B$2,0,SUM(INDIRECT(XLOOKUP(DS$3,'TTM Dates'!$B:$B,'TTM Dates'!$E:$E)&ROW($CJ22)&":"&XLOOKUP(DS$3,'TTM Dates'!$B:$B,'TTM Dates'!$C:$C)&ROW($CJ22))))} -> 0 | DT22: {=IF(DT$3>'GAAP Summary'!$B$2,0,SUM(INDIRECT(XLOOKUP(DT$3,'TTM Dates'!$B:$B,'TTM Dates'!$E:$E)&ROW($CJ22)&":"&XLOOKUP(DT$3,'TTM Dates'!$B:$B,'TTM Dates'!$C:$C)&ROW($CJ22))))} -> 0 | DU22: {=IF(DU$3>'GAAP Summary'!$B$2,0,SUM(INDIRECT(XLOOKUP(DU$3,'TTM Dates'!$B:$B,'TTM Dates'!$E:$E)&ROW($CJ22)&":"&XLOOKUP(DU$3,'TTM Dates'!$B:$B,'TTM Dates'!$C:$C)&ROW($CJ22))))} -> 0 | DV22: {=IF(DV$3>'GAAP Summary'!$B$2,0,SUM(INDIRECT(XLOOKUP(DV$3,'TTM Dates'!$B:$B,'TTM Dates'!$E:$E)&ROW($CJ22)&":"&XLOOKUP(DV$3,'TTM Dates'!$B:$B,'TTM Dates'!$C:$C)&ROW($CJ22))))} -> 0 | DW22: {=IF(DW$3>'GAAP Summary'!$B$2,0,SUM(INDIRECT(XLOOKUP(DW$3,'TTM Dates'!$B:$B,'TTM Dates'!$E:$E)&ROW($CJ22)&":"&XLOOKUP(DW$3,'TTM Dates'!$B:$B,'TTM Dates'!$C:$C)&ROW($CJ22))))} -> 0 | DX22: {=IF(DX$3>'GAAP Summary'!$B$2,0,SUM(INDIRECT(XLOOKUP(DX$3,'TTM Dates'!$B:$B,'TTM Dates'!$E:$E)&ROW($CJ22)&":"&XLOOKUP(DX$3,'TTM Dates'!$B:$B,'TTM Dates'!$C:$C)&ROW($CJ22))))} -> 0 | DY22: {=IF(DY$3>'GAAP Summary'!$B$2,0,SUM(INDIRECT(XLOOKUP(DY$3,'TTM Dates'!$B:$B,'TTM Dates'!$E:$E)&ROW($CJ22)&":"&XLOOKUP(DY$3,'TTM Dates'!$B:$B,'TTM Dates'!$C:$C)&ROW($CJ22))))} -> 0 | DZ22: {=IF(DZ$3>'GAAP Summary'!$B$2,0,SUM(INDIRECT(XLOOKUP(DZ$3,'TTM Dates'!$B:$B,'TTM Dates'!$E:$E)&ROW($CJ22)&":"&XLOOKUP(DZ$3,'TTM Dates'!$B:$B,'TTM Dates'!$C:$C)&ROW($CJ22))))} -> 0 | ... GL22: {=IF(GL$3>'GAAP Summary'!$B$2,0,SUM(INDIRECT(XLOOKUP(GL$3,'TTM Dates'!$B:$B,'TTM Dates'!$E:$E)&ROW($CJ22)&":"&XLOOKUP(GL$3,'TTM Dates'!$B:$B,'TTM Dates'!$C:$C)&ROW($CJ22))))} -> 0
B23: Total Services | AA23: 1143669 | AB23: 1028683 | AC23: 1352064 | AD23: 1147004 | AE23: 1244549 | AF23: 1491129 | AG23: 1287410 | AH23: 1888401 | AI23: 1579699 | AJ23: 1828195 | AK23: 1724117 | AL23: 1178549 | AM23: 2070143 | AN23: 1837048 | AO23: 2158000 | AP23: 1764880 | AQ23: 1839846 | AR23: 1763751 | AS23: 1526951 | AT23: 1895072 | AU23: 1506266 | AV23: 1727134 | AW23: 1582123 | AX23: 1495367 | AY23: =AY15+AY20 -> 1601598.9 | AZ23: =AZ15+AZ20 -> 1736505.9 | BA23: =BA15+BA20 -> 1830911.5 | BB23: =BB15+BB20 -> 1931116.6 | BC23: =BC15+BC20 -> 1829738.2 | BD23: =BD15+BD20 -> 1751835.7 | BE23: =BE15+BE20 -> 1994239.4 | BF23: =BF15+BF20 -> 2087066.4 | ... CH23: =CH15+CH20 -> 0 | CK23: {=SUM(INDIRECT(XLOOKUP('GAAP Summary'!$B$2,'TTM Dates'!$B:$B,'TTM Dates'!$E:$E)&ROW($CJ23)&":"&XLOOKUP('GAAP Summary'!$B$2,'TTM Dates'!$B:$B,'TTM Dates'!$C:$C)&ROW($CJ23)))} -> 43784537 | CM23: =sum(BW23:BY23) -> 11846674 | CN23: =sum(BZ23:CB23) -> 12892983 | CO23: =sum(CC23:CE23) -> 0 | CP23: =sum(CF23:CH23) -> 0 | CQ23: =sum(BW23:CH23) -> 24739657 | CS23: =sum(BK23:BM23) -> 6998281 | CT23: =sum(BN23:BP23) -> 7628658 | CU23: =sum(BQ23:BS23) -> 9024533.4 | CV23: =sum(BT23:BV23) -> 10020346 | CW23: =sum(BK23:BV23) -> 33671818 | CY23: =sum(AY23:BA23) -> 5169016.3 | CZ23: =sum(BB23:BD23) -> 5512690.6 | DA23: =sum(BE23:BG23) -> 6159262.4 | DB23: =sum(BH23:BJ23) -> 7179085.2 | DC23: =sum(AY23:BJ23) -> 24020055 | DE23: =sum(AM23:AO23) -> 6065191 | DF23: =sum(AP23:AR23) -> 5368477 | DG23: =sum(AS23:AU23) -> 4928289 | DH23: =sum(AV23:AX23) -> 4804624 | DI23: =sum(AM23:AX23) -> 21166581 | DK23: =sum(AA23:AC23) -> 3524416 | DL23: =sum(AD23:AF23) -> 3882682 | DM23: =sum(AG23:AI23) -> 4755510 | DN23: =sum(AJ23:AL23) -> 4730861 | DO23: =sum(AA23:AL23) -> 16893469 | DS23: {=IF(DS$3>'GAAP Summary'!$B$2,0,SUM(INDIRECT(XLOOKUP(DS$3,'TTM Dates'!$B:$B,'TTM Dates'!$E:$E)&ROW($CJ23)&":"&XLOOKUP(DS$3,'TTM Dates'!$B:$B,'TTM Dates'!$C:$C)&ROW($CJ23))))} -> 0 | DT23: {=IF(DT$3>'GAAP Summary'!$B$2,0,SUM(INDIRECT(XLOOKUP(DT$3,'TTM Dates'!$B:$B,'TTM Dates'!$E:$E)&ROW($CJ23)&":"&XLOOKUP(DT$3,'TTM Dates'!$B:$B,'TTM Dates'!$C:$C)&ROW($CJ23))))} -> 0 | DU23: {=IF(DU$3>'GAAP Summary'!$B$2,0,SUM(INDIRECT(XLOOKUP(DU$3,'TTM Dates'!$B:$B,'TTM Dates'!$E:$E)&ROW($CJ23)&":"&XLOOKUP(DU$3,'TTM Dates'!$B:$B,'TTM Dates'!$C:$C)&ROW($CJ23))))} -> 0 | DV23: {=IF(DV$3>'GAAP Summary'!$B$2,0,SUM(INDIRECT(XLOOKUP(DV$3,'TTM Dates'!$B:$B,'TTM Dates'!$E:$E)&ROW($CJ23)&":"&XLOOKUP(DV$3,'TTM Dates'!$B:$B,'TTM Dates'!$C:$C)&ROW($CJ23))))} -> 0 | DW23: {=IF(DW$3>'GAAP Summary'!$B$2,0,SUM(INDIRECT(XLOOKUP(DW$3,'TTM Dates'!$B:$B,'TTM Dates'!$E:$E)&ROW($CJ23)&":"&XLOOKUP(DW$3,'TTM Dates'!$B:$B,'TTM Dates'!$C:$C)&ROW($CJ23))))} -> 0 | DX23: {=IF(DX$3>'GAAP Summary'!$B$2,0,SUM(INDIRECT(XLOOKUP(DX$3,'TTM Dates'!$B:$B,'TTM Dates'!$E:$E)&ROW($CJ23)&":"&XLOOKUP(DX$3,'TTM Dates'!$B:$B,'TTM Dates'!$C:$C)&ROW($CJ23))))} -> 0 | DY23: {=IF(DY$3>'GAAP Summary'!$B$2,0,SUM(INDIRECT(XLOOKUP(DY$3,'TTM Dates'!$B:$B,'TTM Dates'!$E:$E)&ROW($CJ23)&":"&XLOOKUP(DY$3,'TTM Dates'!$B:$B,'TTM Dates'!$C:$C)&ROW($CJ23))))} -> 0 | DZ23: {=IF(DZ$3>'GAAP Summary'!$B$2,0,SUM(INDIRECT(XLOOKUP(DZ$3,'TTM Dates'!$B:$B,'TTM Dates'!$E:$E)&ROW($CJ23)&":"&XLOOKUP(DZ$3,'TTM Dates'!$B:$B,'TTM Dates'!$C:$C)&ROW($CJ23))))} -> 0 | ... GL23: {=IF(GL$3>'GAAP Summary'!$B$2,0,SUM(INDIRECT(XLOOKUP(GL$3,'TTM Dates'!$B:$B,'TTM Dates'!$E:$E)&ROW($CJ23)&":"&XLOOKUP(GL$3,'TTM Dates'!$B:$B,'TTM Dates'!$C:$C)&ROW($CJ23))))} -> 0
B24: Total SW | AA24: 31151 | AB24: 29959 | AC24: 30610 | AD24: 50298 | AE24: 32603 | AF24: 48697 | AG24: 39067 | AH24: 45011 | AI24: 47033 | AJ24: 34977 | AK24: 61158 | AL24: 58566 | AM24: 62059 | AN24: 106792 | AO24: 69301 | AP24: 79646 | AQ24: 60949 | AR24: 77475 | AS24: 107256 | AT24: 90370 | AU24: 72875 | AV24: 141165 | AW24: 75225 | AX24: 74735 | AY24: =AY16+AY21 -> 80743 | AZ24: =AZ16+AZ21 -> 132423 | BA24: =BA16+BA21 -> 81376 | BB24: =BB16+BB21 -> 72606 | BC24: =BC16+BC21 -> 79646 | BD24: =BD16+BD21 -> 72514 | BE24: =BE16+BE21 -> 80015 | BF24: =BF16+BF21 -> 80140 | ... CH24: =CH16+CH21 -> 0 | CK24: {=SUM(INDIRECT(XLOOKUP('GAAP Summary'!$B$2,'TTM Dates'!$B:$B,'TTM Dates'!$E:$E)&ROW($CJ24)&":"&XLOOKUP('GAAP Summary'!$B$2,'TTM Dates'!$B:$B,'TTM Dates'!$C:$C)&ROW($CJ24)))} -> 1115339.2 | CM24: =sum(BW24:BY24) -> 262949.65 | CN24: =sum(BZ24:CB24) -> 250005.76 | CO24: =sum(CC24:CE24) -> 0 | CP24: =sum(CF24:CH24) -> 0 | CQ24: =sum(BW24:CH24) -> 512955.41 | CS24: =sum(BK24:BM24) -> 323162 | CT24: =sum(BN24:BP24) -> 189162 | CU24: =sum(BQ24:BS24) -> 186270.31 | CV24: =sum(BT24:BV24) -> 416113.49 | CW24: =sum(BK24:BV24) -> 1114707.8 | CY24: =sum(AY24:BA24) -> 294542 | CZ24: =sum(BB24:BD24) -> 224766 | DA24: =sum(BE24:BG24) -> 241199 | DB24: =sum(BH24:BJ24) -> 278112 | DC24: =sum(AY24:BJ24) -> 1038619 | DE24: =sum(AM24:AO24) -> 238152 | DF24: =sum(AP24:AR24) -> 218070 | DG24: =sum(AS24:AU24) -> 270501 | DH24: =sum(AV24:AX24) -> 291125 | DI24: =sum(AM24:AX24) -> 1017848 | DK24: =sum(AA24:AC24) -> 91720 | DL24: =sum(AD24:AF24) -> 131598 | DM24: =sum(AG24:AI24) -> 131111 | DN24: =sum(AJ24:AL24) -> 154701 | DO24: =sum(AA24:AL24) -> 509130 | DS24: {=IF(DS$3>'GAAP Summary'!$B$2,0,SUM(INDIRECT(XLOOKUP(DS$3,'TTM Dates'!$B:$B,'TTM Dates'!$E:$E)&ROW($CJ24)&":"&XLOOKUP(DS$3,'TTM Dates'!$B:$B,'TTM Dates'!$C:$C)&ROW($CJ24))))} -> 0 | DT24: {=IF(DT$3>'GAAP Summary'!$B$2,0,SUM(INDIRECT(XLOOKUP(DT$3,'TTM Dates'!$B:$B,'TTM Dates'!$E:$E)&ROW($CJ24)&":"&XLOOKUP(DT$3,'TTM Dates'!$B:$B,'TTM Dates'!$C:$C)&ROW($CJ24))))} -> 0 | DU24: {=IF(DU$3>'GAAP Summary'!$B$2,0,SUM(INDIRECT(XLOOKUP(DU$3,'TTM Dates'!$B:$B,'TTM Dates'!$E:$E)&ROW($CJ24)&":"&XLOOKUP(DU$3,'TTM Dates'!$B:$B,'TTM Dates'!$C:$C)&ROW($CJ24))))} -> 0 | DV24: {=IF(DV$3>'GAAP Summary'!$B$2,0,SUM(INDIRECT(XLOOKUP(DV$3,'TTM Dates'!$B:$B,'TTM Dates'!$E:$E)&ROW($CJ24)&":"&XLOOKUP(DV$3,'TTM Dates'!$B:$B,'TTM Dates'!$C:$C)&ROW($CJ24))))} -> 0 | DW24: {=IF(DW$3>'GAAP Summary'!$B$2,0,SUM(INDIRECT(XLOOKUP(DW$3,'TTM Dates'!$B:$B,'TTM Dates'!$E:$E)&ROW($CJ24)&":"&XLOOKUP(DW$3,'TTM Dates'!$B:$B,'TTM Dates'!$C:$C)&ROW($CJ24))))} -> 0 | DX24: {=IF(DX$3>'GAAP Summary'!$B$2,0,SUM(INDIRECT(XLOOKUP(DX$3,'TTM Dates'!$B:$B,'TTM Dates'!$E:$E)&ROW($CJ24)&":"&XLOOKUP(DX$3,'TTM Dates'!$B:$B,'TTM Dates'!$C:$C)&ROW($CJ24))))} -> 0 | DY24: {=IF(DY$3>'GAAP Summary'!$B$2,0,SUM(INDIRECT(XLOOKUP(DY$3,'TTM Dates'!$B:$B,'TTM Dates'!$E:$E)&ROW($CJ24)&":"&XLOOKUP(DY$3,'TTM Dates'!$B:$B,'TTM Dates'!$C:$C)&ROW($CJ24))))} -> 0 | DZ24: {=IF(DZ$3>'GAAP Summary'!$B$2,0,SUM(INDIRECT(XLOOKUP(DZ$3,'TTM Dates'!$B:$B,'TTM Dates'!$E:$E)&ROW($CJ24)&":"&XLOOKUP(DZ$3,'TTM Dates'!$B:$B,'TTM Dates'!$C:$C)&ROW($CJ24))))} -> 0 | ... GL24: {=IF(GL$3>'GAAP Summary'!$B$2,0,SUM(INDIRECT(XLOOKUP(GL$3,'TTM Dates'!$B:$B,'TTM Dates'!$E:$E)&ROW($CJ24)&":"&XLOOKUP(GL$3,'TTM Dates'!$B:$B,'TTM Dates'!$C:$C)&ROW($CJ24))))} -> 0
