Workbook

Sheet Wkly Cash Flow
B1: Week Number | AC1: 31 | AD1: 32 | AE1: 33 | AF1: 34 | AG1: 35 | AH1: 36 | AI1: 37 | AJ1: 38 | AK1: 39 | AL1: 40 | AM1: 41 | AN1: 42 | AO1: 43 | AP1: 44 | AQ1: 45 | AR1: 46 | AS1: 47 | AT1: 48 | AU1: 49 | AV1: 50 | AW1: 51 | AX1: 52 | AY1: 1 | AZ1: 2 | BA1: 3 | BB1: 4 | BC1: 5 | BD1: 6 | BE1: 7 | BF1: 8 | BG1: 9 | BH1: 10 | BI1: 11 | BJ1: 12 | BK1: 13 | BL1: 14 | BM1: 15 | BN1: 16 | BO1: 17 | BP1: 18 | BQ1: 19 | BR1: 20 | BS1: 21 | BT1: 22 | BU1: 23 | BV1: 24 | BW1: 25 | BX1: 26 | BY1: 27 | BZ1: 28 | CA1: 29 | CB1: 30 | CC1: 31 | CD1: 32 | CE1: 33 | CF1: 34 | CG1: 35 | CH1: 36 | CI1: 37 | CJ1: 38 | CK1: 39 | CL1: 40 | CM1: 41 | CN1: 42 | CO1: 43 | CP1: 44 | CQ1: 45 | CR1: 46 | CS1: 47 | CT1: 48 | CU1: 49 | CV1: 50 | CW1: 51 | CX1: 52 | CY1: 1 | CZ1: 2 | DA1: 3 | DB1: 4 | DC1: 5 | DD1: 6 | DE1: 7 | DF1: 8 | DG1: 9 | DH1: 10 | DI1: 11 | DJ1: 12 | DK1: 13 | DL1: 14 | DM1: 15 | DN1: 16 | DO1: 17 | DP1: 18 | DQ1: 19 | DR1: 20 | DS1: 21 | DT1: 22 | DU1: 23 | DV1: 24 | DW1: 25 | DX1: 26 | DY1: 27 | DZ1: 28 | EA1: 29 | EB1: 30 | EC1: 31 | ED1: 32 | EE1: 33 | EF1: 34 | EG1: 35 | EH1: 36 | EI1: 37 | EJ1: 38 | EK1: 39 | EL1: 40
B2: Week Ending | C2: 45324 | D2: =C2+7 -> 45331 | E2: =D2+7 -> 45338 | F2: =E2+7 -> 45345 | G2: =F2+7 -> 45352 | H2: =G2+7 -> 45359 | I2: =H2+7 -> 45366 | J2: =I2+7 -> 45373 | K2: =J2+7 -> 45380 | ... AC2: =AB2+7 -> 45506 | AD2: 45513 | AE2: 45520 | AF2: 45527 | AG2: 45534 | AH2: 45541 | AI2: 45548 | AJ2: 45555 | AK2: 45562 | AL2: 45569 | AM2: 45576 | AN2: 45583 | AO2: 45590 | AP2: 45597 | AQ2: 45604 | AR2: 45611 | AS2: 45618 | AT2: 45625 | AU2: 45632 | AV2: 45639 | AW2: 45646 | AX2: 45653 | AY2: 45660 | AZ2: 45667 | BA2: 45674 | BB2: 45681 | BC2: 45688 | BD2: 45695 | BE2: 45702 | BF2: 45709 | BG2: 45716 | BH2: 45723 | BI2: 45730 | BJ2: 45737 | BK2: 45744 | BL2: 45751 | BM2: =BL2+7 -> 45758 | BN2: =BM2+7 -> 45765 | BO2: =BN2+7 -> 45772 | BP2: =BO2+7 -> 45779 | BQ2: =BP2+7 -> 45786 | BR2: =BQ2+7 -> 45793 | BS2: =BR2+7 -> 45800 | BT2: =BS2+7 -> 45807 | ... EL2: =EK2+7 -> 46297
B3: Beginning Cash | C3: 2862667.4 | D3: =C23 -> 2288807.5 | E3: =D23 -> 2604552.4 | F3: =E23 -> 1994376.4 | G3: =F23 -> 2251105.2 | H3: =G23 -> 1595981.2 | I3: =H23 -> 1633425.3 | J3: =I23 -> 1364115.8 | K3: =J23 -> 1102620.9 | ... EL3: =EK23 -> 10584975
B5: Cash In
B6: From Signed Contracts | C6: 577355.68 | D6: 350179.33 | E6: 255119 | F6: 291250 | G6: 404489.39 | H6: 133965.47 | I6: 351395 | J6: 36246 | K6: 187600 | L6: 61920 | M6: 93057.55 | N6: 109250.4 | O6: 130293 | P6: 0 | Q6: 0 | R6: 0 | S6: 0 | T6: 1784872.9 | U6: 465002 | V6: 202128 | W6: 127840 | X6: 264560.27 | Y6: 1101416.2 | Z6: 222930 | AA6: 287760.11 | AB6: 146160 | AC6: 413707.8 | AD6: 49781.2 | AE6: 209731 | AF6: 418221.27 | AG6: =551093.51+2700 -> 553793.51 | AH6: 422712.26 | AI6: =298700.38+22650 -> 321350.38 | AJ6: 124679.25 | AK6: =757789+1001215 -> 1759004 | AL6: =-49900+680960.42+9000 -> 640060.42 | AM6: 389310 | AN6: 261855.32 | AO6: 312301.37 | AP6: =600629.64+55646 -> 656275.64 | AQ6: =393367.96+5320 -> 398687.96 | AR6: =269523.08+162648.87 -> 432171.95 | AS6: =696113.8+18065 -> 714178.8 | AT6: =199060.96+42960 -> 242020.96 | AU6: =547827.64+188883.64+49950 -> 786661.28 | AV6: 702792.8 | AW6: =295109+1866.69 -> 296975.69 | AX6: 928667.37 | AY6: =1023665.35+50240 -> 1073905.4 | AZ6: 527136.59 | BA6: =449417.34+626838 -> 1076255.3 | BB6: =547504.69+434093.31 -> 981598 | BC6: =277595.58+235859.82 -> 513455.4 | BD6: =172220.16+361231.6 -> 533451.76 | BE6: =131489.4 -> 131489.4 | BF6: =36975+4560+3120+68511.34+68750 -> 181916.34 | BG6: =178081.6+4082.08 -> 182163.68 | BH6: =34270+128242.38 -> 162512.38 | BI6: =50250+83159.38 -> 133409.38 | BJ6: =373137.5+588710.72 -> 961848.22 | BK6: =490775.48+67320 -> 558095.48 | BL6: =718301.19+193335.81 -> 911637 | BM6: =509848.98+254215 -> 764063.98 | BN6: =175936+141500 -> 317436 | BO6: =132030+1324777 -> 1456807 | BP6: =645986.27+353854.5 -> 999840.77 | BQ6: =561719.65+379593.29 -> 941312.94 | BR6: =559436.75+171130 -> 730566.75 | BS6: =99831.86+249128.58 -> 348960.44 | BT6: =48237.5+33134+19200 -> 100571.5 | BU6: =636665.88+439935.16 -> 1076601 | BV6: =83671.12+ 222379.08 -> 306050.2 | BW6: =197658.39+ 197207.58 -> 394865.97 | BX6: =327218.86+24960 -> 352178.86 | BY6: =334398.75+184175 -> 518573.75 | BZ6: =231945.01+134139.58+15390+13199.85+29529.58+1209.51 -> 425413.53 | CA6: =163775.02+451047 -> 614822.02 | CB6: =285108.66+454884.58 -> 739993.24 | CC6: =431858.18+391157.45 -> 823015.63 | CD6: =126379.26+331928.55 -> 458307.81 | CE6: =378441.4+72800+135023.88 -> 586265.28 | CF6: =261864+470747.58 -> 732611.58 | CG6: =618836+107754.75 -> 726590.75 | CH6: =153218+446177.82 -> 599395.82 | CI6: =183640.1+422819.69+25000 -> 631459.79 | CJ6: =66769+272583.05 -> 339352.05 | CK6: =66578+360613.55 -> 427191.55 | CL6: =371509.52+120091+898463.66 -> 1390064.2 | CM6: =108115+784429+75600 -> 968144 | CN6: =29700+555834.21+170944 -> 756478.21 | CO6: =491091.61+93538.87+38800 -> 623430.48 | CP6: =104185.6+931344.73 -> 1035530.3 | CQ6: =856704.96+740210.32 -> 1596915.3 | CR6: =166490+455489.72 -> 621979.72 | CS6: =487934.4+169831.16 -> 657765.56 | CT6: =65560+735597.91 -> 801157.91 | CU6: =1696717.5+65475 -> 1762192.5 | CV6: =63077.4+230322+62100 -> 355499.4 | CW6: =1727606.3+52000 -> 1779606.3 | CX6: =61843.75+476164.58 -> 538008.33 | CY6: =477992+585766.08 -> 1063758.1 | CZ6: =368297.93+268500.5 -> 636798.43 | DA6: =214455.6+746479.75 -> 960935.35 | DB6: =421077.24+162810.58 -> 583887.82 | DC6: =540817.6+367688.88+622976+14400 -> 1545882.5 | DD6: =442488.81+896309.06 -> 1338797.9 | DE6: =846381.07+221543.24 -> 1067924.3 | DF6: =513075.3+110637.3 -> 623712.6 | DG6: =443651.5+707527.1 -> 1151178.6 | DH6: =358010.25+855581.13 -> 1213591.4 | DI6: =335938+308875.97+420661.2 -> 1065475.2 | DJ6: =258810.6+272026.5+101920 -> 632757.1 | DK6: =45892.8+196721.58 -> 242614.38 | DL6: =579871+287763.49+332732.8 -> 1200367.3 | DM6: =279234.5+315484 -> 594718.5 | DN6: =134608.33+760891.89+25300.58 -> 920800.8 | DO6: =96838.29+98741.5+34494.7+22007.7+72160+55250+50000+26500+7000+187782+44236.75+10640+18240+85000 -> 808890.94 | DP6: =96981+18892.8+16398.4+11072.12+23.74+159947.52+153356.67+292.95+33480+75+50064+8736 -> 549320.2 | DQ6: =59500+556982+2600+0.05+97643.1+1117000+110532+95635+95635+29700+19.46+159200+60480+26880+21600 -> 2433406.6 | DR6: =39218.85+21562.5+10368+267105.6+118750-95635+111210.4+36960+1.36+80105.2+71456 -> 661102.91 | DS6: =3800+18892.8+14235+647990+37666.4+135160+75000+34560+132980+43970+110400+24910+22.26+48750+20000 -> 1348336.5 | DT6: =55250+22558.2+96981+141463+116298.83+97920+19387.5+3360+18000+46080+36960+7000 -> 661258.53 | DU6: =2071.02+276680+85710+69120+38016+29981 -> 501578.02 | DV6: =68040+30240+93324 -> 191604 | DW6: {=XLOOKUP(DW$2,'AR Aging 20260320'!$S:$S,'AR Aging 20260320'!$U:$U)} -> 49761.6 | DX6: {=XLOOKUP(DX$2,'AR Aging 20260320'!$S:$S,'AR Aging 20260320'!$U:$U)} -> 0 | DY6: {=XLOOKUP(DY$2,'AR Aging 20260320'!$S:$S,'AR Aging 20260320'!$U:$U)} -> 1914366.8 | DZ6: {=XLOOKUP(DZ$2,'AR Aging 20260320'!$S:$S,'AR Aging 20260320'!$U:$U)} -> 307517 | EA6: {=XLOOKUP(EA$2,'AR Aging 20260320'!$S:$S,'AR Aging 20260320'!$U:$U)} -> 2467646.6 | EB6: {=XLOOKUP(EB$2,'AR Aging 20260320'!$S:$S,'AR Aging 20260320'!$U:$U)} -> 0 | EC6: {=XLOOKUP(EC$2,'AR Aging 20260320'!$S:$S,'AR Aging 20260320'!$U:$U)} -> 1802824.8 | ED6: {=XLOOKUP(ED$2,'AR Aging 20260320'!$S:$S,'AR Aging 20260320'!$U:$U)} -> 282700.5 | ... EL6: {=XLOOKUP(EL$2,'AR Aging 20260320'!$S:$S,'AR Aging 20260320'!$U:$U)} -> 1528567.5
B7: From Bookings | C7: 0 | D7: 0 | E7: 0 | F7: 0 | G7: 0 | H7: 0 | I7: 0 | J7: 0 | K7: 0 | L7: 0 | M7: 770000 | N7: 0 | O7: 0 | P7: 0 | Q7: 0 | R7: 0 | S7: 0 | T7: 0 | U7: 0 | V7: 0 | W7: 0 | X7: 0 | Y7: 0 | Z7: 0 | AA7: 0 | AB7: 0 | AC7: 0 | AD7: 0 | AE7: 0 | AF7: 0 | AG7: 0 | AH7: 0 | AI7: 0 | AJ7: 0 | AK7: 0 | AL7: 0 | AM7: 0 | AN7: 0 | AO7: 0 | AP7: 0 | AQ7: 0 | AR7: 0 | AS7: 0 | AT7: 0 | AU7: =SUMIFS(Bookings!$W:$W,Bookings!$T:$T,'Wkly Cash Flow'!AU$2) -> 0 | AV7: =SUMIFS(Bookings!$W:$W,Bookings!$T:$T,'Wkly Cash Flow'!AV$2) -> 0 | AW7: =SUMIFS(Bookings!$W:$W,Bookings!$T:$T,'Wkly Cash Flow'!AW$2) -> 0 | AX7: =SUMIFS(Bookings!$W:$W,Bookings!$T:$T,'Wkly Cash Flow'!AX$2) -> 0 | AY7: =SUMIFS(Bookings!$W:$W,Bookings!$T:$T,'Wkly Cash Flow'!AY$2) -> 0 | AZ7: =SUMIFS(Bookings!$W:$W,Bookings!$T:$T,'Wkly Cash Flow'!AZ$2) -> 0 | BA7: =SUMIFS(Bookings!$W:$W,Bookings!$T:$T,'Wkly Cash Flow'!BA$2) -> 0 | BB7: =SUMIFS(Bookings!$W:$W,Bookings!$T:$T,'Wkly Cash Flow'!BB$2) -> 0 | BC7: =SUMIFS(Bookings!$W:$W,Bookings!$T:$T,'Wkly Cash Flow'!BC$2) -> 0 | BD7: 0 | BE7: =SUMIFS(Bookings!$W:$W,Bookings!$T:$T,'Wkly Cash Flow'!BE$2) -> 0 | BF7: =SUMIFS(Bookings!$W:$W,Bookings!$T:$T,'Wkly Cash Flow'!BF$2) -> 0 | BX7: =SUMIFS(Bookings!$W:$W,Bookings!$T:$T,'Wkly Cash Flow'!BX$2) -> 0 | BY7: =SUMIFS(Bookings!$W:$W,Bookings!$T:$T,'Wkly Cash Flow'!BY$2) -> 0 | BZ7: =SUMIFS(Bookings!$W:$W,Bookings!$T:$T,'Wkly Cash Flow'!BZ$2) -> 0 | CA7: =SUMIFS(Bookings!$W:$W,Bookings!$T:$T,'Wkly Cash Flow'!CA$2) -> 0 | CB7: =SUMIFS(Bookings!$W:$W,Bookings!$T:$T,'Wkly Cash Flow'!CB$2) -> 0 | CC7: =SUMIFS(Bookings!$W:$W,Bookings!$T:$T,'Wkly Cash Flow'!CC$2) -> 0 | CD7: =SUMIFS(Bookings!$W:$W,Bookings!$T:$T,'Wkly Cash Flow'!CD$2) -> 0 | CE7: =SUMIFS(Bookings!$W:$W,Bookings!$T:$T,'Wkly Cash Flow'!CE$2) -> 0 | CF7: =SUMIFS(Bookings!$W:$W,Bookings!$T:$T,'Wkly Cash Flow'!CF$2) -> 0 | CH7: =SUMIFS(Bookings!$W:$W,Bookings!$T:$T,'Wkly Cash Flow'!CH$2) -> 0 | CI7: =SUMIFS(Bookings!$W:$W,Bookings!$T:$T,'Wkly Cash Flow'!CI$2) -> 0 | CJ7: =SUMIFS(Bookings!$W:$W,Bookings!$T:$T,'Wkly Cash Flow'!CJ$2) -> 0 | CL7: =SUMIFS(Bookings!$W:$W,Bookings!$T:$T,'Wkly Cash Flow'!CL$2) -> 0 | CM7: =SUMIFS(Bookings!$W:$W,Bookings!$T:$T,'Wkly Cash Flow'!CM$2) -> 0 | CN7: =SUMIFS(Bookings!$W:$W,Bookings!$T:$T,'Wkly Cash Flow'!CN$2) -> 0 | CS7: =SUMIFS(Bookings!$W:$W,Bookings!$T:$T,'Wkly Cash Flow'!CS$2) -> 0 | CU7: 0 | CV7: =SUMIFS(Bookings!$W:$W,Bookings!$T:$T,'Wkly Cash Flow'!CV$2) -> 0 | CX7: =SUMIFS(Bookings!$W:$W,Bookings!$T:$T,'Wkly Cash Flow'!CX$2) -> 0 | DH7: {=XLOOKUP(DH$2,Bookings!$T:$T,Bookings!$W:$W)} -> 0 | DK7: {=XLOOKUP(DK$2,Bookings!$T:$T,Bookings!$W:$W)} -> 0 | DM7: {=XLOOKUP(DM$2,Bookings!$T:$T,Bookings!$W:$W)} -> 0 | DW7: {=XLOOKUP(DW$2,Bookings!$T:$T,Bookings!$W:$W)} -> 0 | DX7: {=XLOOKUP(DX$2,Bookings!$T:$T,Bookings!$W:$W)} -> 0 | DY7: {=XLOOKUP(DY$2,Bookings!$T:$T,Bookings!$W:$W)} -> 1000000 | DZ7: {=XLOOKUP(DZ$2,Bookings!$T:$T,Bookings!$W:$W)} -> 0 | EA7: {=XLOOKUP(EA$2,Bookings!$T:$T,Bookings!$W:$W)} -> 0 | EB7: {=XLOOKUP(EB$2,Bookings!$T:$T,Bookings!$W:$W)} -> 0 | EC7: {=XLOOKUP(EC$2,Bookings!$T:$T,Bookings!$W:$W)} -> 2000000 | ED7: {=XLOOKUP(ED$2,Bookings!$T:$T,Bookings!$W:$W)} -> 0 | ... EL7: {=XLOOKUP(EL$2,Bookings!$T:$T,Bookings!$W:$W)} -> 4000000
B8: External Funding | L8: 500000 | N8: 1940000 | O8: 952054.59 | Y8: 550000 | Z8: 689000 | AG8: 600000 | AV8: 430000 | BF8: 600000 | BH8: 200000 | BI8: 400000 | BK8: 200000 | BU8: 500000 | BW8: 1500000 | BX8: 700000 | CA8: =300000 -> 300000 | CE8: =18094708.55 -> 18094709 | CR8: 213795 | CT8: =204312 -> 204312
B9: Cash Out
B10: Payroll | C10: -486239.44 | E10: -479000 | G10: -457093.02 | I10: -469959.91 | J10: 21.49 | K10: -471832.45 | M10: -485000 | O10: -485000 | Q10: -490000 | S10: -490000 | U10: -450603.76 | W10: -507095.7 | Y10: -460000 | AA10: -460000 | AC10: -490000 | AE10: -488297.24 | AG10: =-713222.48-AG11 -> -521554.18 | AI10: -525173.09 | AK10: =-672927+117564.09 -> -555362.91 | AM10: -500072.79 | AO10: -579638.45 | AQ10: -521222.51 | AS10: -553535.47 | AU10: -524725.96 | AV10: -1958.14 | AW10: -626469.52 | AY10: -571065.76 | BA10: -557810.57 | BC10: -577090.03 | BE10: -559835 | BG10: -564444.79 | BI10: -556561.81 | BK10: -579826.37 | BM10: -558465.81 | BO10: -557392.87 | BQ10: -578607.75 | BS10: =-588831.05-3280.07+1478.1 -> -590633.02 | BU10: -583994.98 | BW10: -614501.64 | BY10: =-598670.19 -> -598670.19 | CA10: =-604531.81 -> -604531.81 | CC10: -616962 | CE10: =-633064.48 -> -633064.48 | CG10: -822215.94 | CI10: -624037.09 | CK10: -678441.1 | CM10: -740246.79 | CO10: =-685708.64 -> -685708.64 | CP10: =-308529.71 -> -308529.71 | CQ10: =-684765.8 -> -684765.8 | CS10: =-761855.96 -> -761855.96 | CT10: -298101.66 | CU10: -746662.23 | CW10: =-764439.25 -> -764439.25 | CY10: =-824720.16 -> -824720.16 | DA10: -841297.88 | DC10: =-1506934.58 -> -1506934.6 | DE10: =-802575.13 -> -802575.13 | DG10: -1080029.4 | DI10: =-836039.47 -> -836039.47 | DK10: =-834536.36 -> -834536.36 | DM10: =-845077.81 -> -845077.81 | DO10: =-873802.67 -> -873802.67 | DP10: =-216237.85 -> -216237.85 | DQ10: =-865577.09 -> -865577.09 | DS10: =-869127.85 -> -869127.85 | DT10: =-270475.11 -> -270475.11 | DU10: =-859997.84 -> -859997.84 | DW10: -900000 | DY10: -900000 | EA10: -900000 | EC10: -900000 | EE10: -910000 | EG10: -910000 | EI10: -910000 | EK10: -910000
B11: Commission/Bonuses | C11: -106753.96 | G11: -235369.33 | K11: -86851.37 | O11: -100000 | T11: -292849 | X11: -135000 | AC11: -150000 | AG11: =-191668.3 -> -191668.3 | AK11: -131717.46 | AP11: -150968.47 | AT11: -189304.86 | AX11: -147897.35 | AY11: -194609.73 | BC11: -254504.33 | BE11: -8796.32 | BG11: -265882.85 | BK11: -98622.43 | BO11: -156573.57 | BP11: -223996.81 | BT11: -480222.88 | BX11: -177215.52 | CC11: -185940.88 | CF11: -17629224 | CL11: -131031.48 | CY11: =-315545.79 -> -315545.79 | DL11: -420008.56 | DX11: -250000 | EC11: -250000 | EG11: -250000 | EK11: -250000
B12: Health Insurance | C12: -85053.24 | G12: -78906.19 | L12: -78000 | P12: -78000 | U12: -74429.3 | Y12: -78000 | AC12: -78000 | AH12: -86047.42 | AL12: -72792.41 | AP12: -115474.84 | AU12: -102027.2 | AY12: -104693.15 | BD12: =-100200.84-3364.89 -> -103565.73 | BH12: =-106343.19-2205.82 -> -108549.01 | BL12: -103571.15 | BP12: -108967.13 | BU12: -116241.15 | BY12: =-110585.38 -> -110585.38 | CA12: =-179.1 -> -179.1 | CB12: -70271.89 | CC12: -181343.38 | CE12: =-73464.74-363.79 -> -73828.53 | CG12: =-75985.49 -> -75985.49 | CH12: =-111266.15 -> -111266.15 | CI12: -77160.92 | CJ12: =-429.84 -> -429.84 | CL12: -132521.39 | CM12: -90103.71 | CO12: -87574.68 | CP12: =-10000 -> -10000 | CQ12: =-249028.7 -> -249028.7 | CU12: -250505.51 | CW12: =-93327.42 -> -93327.42 | CY12: =-165682.73 -> -165682.73 | CZ12: =-104132.05 -> -104132.05 | DA12: =-101280.94 -> -101280.94 | DC12: -99371.87 | DD12: =-179485.14 -> -179485.14 | DE12: =-102116.03 -> -102116.03 | DH12: =-178326.85 -> -178326.85 | DI12: =-109690.73 -> -109690.73 | DL12: =-180322.52 -> -180322.52 | DM12: =-113261.19 -> -113261.19 | DO12: =-111470.73 -> -111470.73 | DP12: =-60910.59-60486.99-48794.54-2549.45-220 -> -172961.57 | DQ12: =-110567.26 -> -110567.26 | DS12: =-111903.07 -> -111903.07 | DU12: =-111786.75-57702.09-40263.59-28204.41-4936.64 -> -242893.48 | DW12: -100000 | DX12: -10000 | DY12: -175000 | ED12: -175000 | EH12: -270000 | EL12: -175000
B13: Other Benefits | C13: -64666.1 | D13: -410.23 | E13: -51000 | F13: -589.21 | G13: -55973.41 | H13: -12640.81 | I13: -55907.52 | J13: -1199.52 | K13: -3270.66 | M13: -56000 | O13: -56000 | Q13: -56000 | S13: -56000 | U13: -65049.56 | V13: 1743.15 | W13: -57151.02 | X13: -4642.18 | Y13: -60000 | AA13: -60000 | AC13: -60000 | AE13: 976.15 | AF13: =-763.96-57764 -> -58527.96 | AG13: =-251.95-63613.42+19.9 -> -63845.47 | AH13: -2296.96 | AI13: =3901.91-61933.73 -> -58031.82 | AJ13: =-263.88-2091.18 -> -2355.06 | AK13: -74610 | AL13: -14439.93 | AM13: =-55780.75-789.65 -> -56570.4 | AN13: -8597.61 | AO13: -62129.14 | AP13: =-9409.09-108.89 -> -9517.98 | AQ13: -69638.84 | AR13: -14941.94 | AS13: -61253.47 | AT13: -11775.93 | AU13: -73212.22 | AV13: -10172.42 | AW13: -69095.65 | AX13: -11029.49 | AY13: -77089.8 | AZ13: -10945.52 | BA13: -66746.59 | BB13: =-8755.85-460 -> -9215.85 | BC13: -68038.7 | BD13: =-20807.62-274 -> -21081.62 | BE13: -68880.61 | BF13: =-8018.8-181.95 -> -8200.75 | BG13: =-65561.23-370.7 -> -65931.93 | BH13: -23978.86 | BI13: -67803.26 | BJ13: -7207.5 | BK13: -72265.59 | BL13: -20125.49 | BM13: -69054.44 | BN13: -8647.51 | BO13: -68522.39 | BP13: -6779.2 | BQ13: -84648.18 | BR13: =-268.65-6844.36 -> -7113.01 | BS13: =-923.06-70895 -> -71818.06 | BT13: =-6831.05-4863.6 -> -11694.65 | BU13: -85624.72 | BV13: -6624.8 | BW13: =-73386.4-89.55 -> -73475.95 | BX13: =-9397.94 -> -9397.94 | BY13: =-19111.17-71387.42 -> -90498.59 | BZ13: =-441.28-1312.62 -> -1753.9 | CA13: -5574.37 | CB13: -5828.84 | CC13: -5437.08 | CD13: =-5022.88 -> -5022.88 | CE13: =-913.93 -> -913.93 | CF13: =-6796.03-452.17-288.45 -> -7536.65 | CG13: =-832.96 -> -832.96 | CH13: =-6592.99 -> -6592.99 | CI13: -791.56 | CJ13: =-4285.9- 53.48 -> -4339.38 | CK13: -5151.61 | CN13: -8444.84 | CO13: =-7060.16 -> -7060.16 | CP13: =-589.34-119.82 -> -709.16 | CQ13: =-15902.43-1678.56 -> -17580.99 | CR13: =-647.87 -> -647.87 | CS13: =-1238.71-88957.39-89.55 -> -90285.65 | CT13: =-8608.58 -> -8608.58 | CU13: -54492.27 | CV13: -10512.61 | CW13: =-1353.91 -> -1353.91 | CX13: =-8819.24 -> -8819.24 | CY13: =-6964.65 -> -6964.65 | CZ13: =-23474.87-84 -> -23558.87 | DA13: =-179.1-5163.61 -> -5342.71 | DB13: =2102.73-9259.44 -> -7156.71 | DC13: =-3005.51 -> -3005.51 | DD13: =-13713.59 -> -13713.59 | DE13: =-951.06 -> -951.06 | DF13: =-9808.77 -> -9808.77 | DG13: =-3494.6-108523.97 -> -112018.57 | DH13: =-12865.48 -> -12865.48 | DI13: =-1215.07 -> -1215.07 | DJ13: =-10018.94 -> -10018.94 | DK13: =-121380.06 -> -121380.06 | DL13: =-25245.82 -> -25245.82 | DM13: =-1741.56 -> -1741.56 | DN13: =-14602.41-461.39 -> -15063.8 | DO13: =-483.15-78.23-2237.02-132.08-82.73-36.84-25-191.76-128.37 -> -3395.18 | DP13: =-2854.94-108.3-4.8-34.1-11.3-6.5-4.8-90-6484.34-2730.66-192.3-144.51 -> -12666.55 | DQ13: =-454-61.66-15-1.7-17410.39-406.41-80.75-6.5-182.78 -> -18619.19 | DR13: =-2.3-162.32-57.33-15.81-1149.9-65.66-36.27-10-6484.34-2730.66-506.6-114 -> -11335.19 | DS13: =-490.8-22.4-2236.94-72.13-94.17-21.95-5.1-158.72 -> -3102.21 | DT13: =-500-21.7-487-370-301.8-54-6934.34-2653.74-205.52 -> -11528.1 | DU13: =-22.45-1760-17436.14-172-1.7-2937.27-122.65-91.32-1284.14-104.67 -> -23932.34 | DV13: =-192-119.87-29.36-768-437.4-60.47-42.28-25.49-13.12-6384.34-2576.82-883.21-192.3 -> -11724.66 | DW13: -10000 | DX13: -10000 | DY13: -10000 | DZ13: -10000 | EA13: -10000 | EB13: -10000 | EC13: -10000 | ED13: -10000 | EE13: -10000 | EF13: -10000 | EG13: -10000 | EH13: -10000 | EI13: -10000 | EJ13: -10000 | EK13: -10000
B14: Credit Cards | D14: -7639.83 | E14: -295000 | F14: -28000 | H14: -7095.26 | I14: -78581.11 | J14: -192788.83 | M14: 7000 | N14: -250000.38 | O14: -50000 | Q14: 7000 | R14: -225000 | S14: -50000 | U14: -247520.21 | V14: -154282.23 | W14: -36073.11 | Y14: -72821.68 | AA14: -226530.09 | AD14: 7000 | AE14: -40000 | AF14: -178145.39 | AH14: =-5427.14-169099.3 -> -174526.44 | AI14: -75000 | AJ14: =-128937.38-501.27 -> -129438.65 | AK14: -50016 | AL14: -25000 | AM14: =-9296.36-25000-41813.41 -> -76109.77 | AN14: =-25000-228.89 -> -25228.89 | AO14: =-40000-174282.69 -> -214282.69 | AP14: -35000 | AQ14: =-57888.44-31554.98 -> -89443.42 | AR14: =-50000-124.78 -> -50124.78 | AS14: -128111.97 | AT14: -25000 | AU14: =-100000-98133.45-7835.34 -> -205968.79 | AV14: -25000 | AW14: -137232.12 | AX14: -15.94 | AZ14: =-12513.16-145575.65 -> -158088.81 | BA14: -75132.16 | BB14: -208560.93 | BC14: -149012.29 | BD14: =-7490.24-50000 -> -57490.24 | BE14: -100000 | BF14: -130521.36 | BG14: -25015.94 | BH14: =-8192.73-109339.54 -> -117532.27 | BI14: -50000 | BJ14: -260623.07 | BK14: -100000 | BL14: -109782.88 | BM14: =-16262.39-75000 -> -91262.39 | BN14: -80000 | BP14: -75000 | BQ14: =-2812.54-100000-53045.18 -> -155857.72 | BR14: -50000 | BS14: -202443.54 | BT14: -25000 | BU14: =-122545.72-10580.93 -> -133126.65 | BV14: =-150000 -> -150000 | BW14: =-229599.44 -> -229599.44 | BX14: -75000 | BY14: =-50000+7280 -> -42720 | BZ14: =-19961.25-155933.03-29529.58 -> -205423.86 | CA14: =-25000 -> -25000 | CB14: =-233139.47 -> -233139.47 | CC14: =-95000 -> -95000 | CD14: =-107674.85-3453.39 -> -111128.24 | CE14: =-50000 -> -50000 | CF14: -169796.14 | CG14: -50000 | CH14: =-299297 -> -299297 | CI14: =-29625.29-116638.07 -> -146263.36 | CJ14: -100000 | CK14: -190289.73 | CL14: -50000 | CM14: =-10935.72-161278.04 -> -172213.76 | CN14: -25000 | CO14: =-137554.39 -> -137554.39 | CP14: =-25000 -> -25000 | CQ14: =-174954.19-12577.32 -> -187531.51 | CS14: =-204856.01 -> -204856.01 | CU14: -50000 | CV14: =25850-10415.68-11806.11 -> 3628.21 | CX14: =-118554.35 -> -118554.35 | CY14: =-91965.51 -> -91965.51 | CZ14: =-43327.07+5000-33007.08 -> -71334.15 | DA14: =-192420.18 -> -192420.18 | DB14: =-50000-25000 -> -75000 | DC14: -50000 | DD14: =-129423.64-95421.93 -> -224845.57 | DF14: =-373584.76 -> -373584.76 | DG14: -15.94 | DH14: =-172550.74 -> -172550.74 | DI14: =-150000 -> -150000 | DJ14: =-200000 -> -200000 | DM14: =-276546.06 -> -276546.06 | DO14: =-31.88-146764.35 -> -146796.23 | DQ14: =-27883.01-151.13-375412.9-45519.31 -> -448966.35 | DS14: =-365.94-63161.77 -> -63527.71 | DT14: =-379519.52 -> -379519.52 | DU14: =-55004.91 -> -55004.91 | DV14: =-153267.9-33093.55 -> -186361.45 | DW14: -100000 | DX14: -10000 | DY14: -100000 | DZ14: -50000 | EA14: -100000 | ED14: -100000 | EE14: -50000 | EF14: -100000 | EH14: -100000 | EI14: -50000 | EJ14: -100000
B15: Office Rent | C15: -71000 | E15: -5885 | G15: -71031.15 | L15: -71000 | P15: -71000 | U15: -71031 | Y15: -71000 | AC15: -71000 | AH15: =-47373.08-25000 -> -72373.08 | AL15: -100 | AM15: -72373.08 | AP15: -25000 | AQ15: -47373.08 | AU15: -25000 | AV15: -47373.08 | BD15: =-47373.08-25000 -> -72373.08 | BH15: =-47373.08-25000 -> -72373.08 | BL15: -47373.08 | BP15: -25000 | BQ15: -47373.08 | BV15: -100134.08 | CC15: -31500 | CH15: -25000 | CU15: -48755.28 | DD15: =-58259.35 -> -58259.35 | DM15: -48755.28 | DQ15: =-48755.28 -> -48755.28 | DU15: =-48755.28 -> -48755.28 | DY15: -48755.28 | ED15: -48755.28 | EH15: -48755.28
B16: International EE's | C16: -50514.18 | D16: -16669.96 | G16: -115000 | H16: 35140.8 | K16: -98981.99 | O16: -115000 | T16: -115000 | X16: -99000 | AB16: -110000 | AG16: -111756.12 | AK16: -117564.09 | AP16: -107427.21 | AT16: -107975.3 | AX16: -99187.85 | AY16: -6479.12 | BB16: -22995.38 | BC16: =-101515.24-4995.71 -> -106510.95 | BG16: -127805.9 | BK16: -136855.9 | BM16: -24099.43 | BN16: -16424.04 | BO16: -141883.03 | BP16: =-12170.03-13400.91 -> -25570.94 | BS16: -2805.67 | BT16: -183813.17 | BX16: -232223.99 | CC16: -200817.64 | CG16: -234773.39 | CI16: -19467.13 | CL16: -201840.51 | CP16: -135667.97 | CT16: =-187183.96 -> -187183.96 | CW16: =-21950.71 -> -21950.71 | CX16: -197275.83 | CY16: =-9995.95 -> -9995.95 | DC16: -236673.32 | DG16: -236435.99 | DK16: =-261524.26 -> -261524.26 | DN16: =-12834.44 -> -12834.44 | DO16: =-250302.59 -> -250302.59 | DP16: =-493.49 -> -493.49 | DT16: =-223824.32 -> -223824.32 | DX16: -230000 | EC16: -230000 | EG16: -230000 | EK16: -230000
B17: Contractors | U17: -32000 | V17: 30000 | X17: -30000 | AB17: -30000 | AG17: -40000 | BD17: -12000 | BG17: -12000
B18: Marketing Expenses | E18: -22410 | N18: -50000 | R18: -50000 | W18: -47125.14 | AA18: -50000 | AM18: 25000 | AS18: -19751.91 | BM18: -1410.49 | BX18: -15000 | DG18: -27500 | DO18: =-2000-25000 -> -27000 | DR18: =-6150-154394-2850 -> -163394 | DT18: =-5750-2071.02 -> -7821.02 | DU18: =-20500-2076.63-10000 -> -32576.63
B19: Other Misc Expenses | C19: -8000 | D19: -9714.41 | E19: -12000 | F19: -5932 | G19: -1161.28 | H19: -11926.13 | I19: -16255.92 | J19: -103774.01 | K19: -20384.05 | L19: -10000 | M19: -10000 | N19: -10000 | O19: -10000 | P19: -10000 | Q19: -10000 | R19: -10000 | S19: -239526 | T19: -10000 | U19: -10063.16 | V19: -27847.8 | W19: -29036.06 | X19: -95000 | Y19: -10000 | Z19: -60000 | AA19: -60000 | AB19: -10000 | AC19: -25000 | AD19: =-60000-10845 -> -70845 | AE19: =-3002.07-2426- 27177.9 -> -32605.97 | AF19: =-22934.5-2598.94 -> -25533.44 | AG19: =-988.79-25500-9149 -> -35637.79 | AH19: =-300000-24651.83+300000 -> -24651.83 | AI19: =-300000-1945.7+300000-4807.5 -> -6753.2 | AJ19: =-306333.13+300000 -> -6333.13 | AK19: =-47187.81-4433 -> -51620.81 | AL19: =-11897.31-83446 -> -95343.31 | AM19: =-28793.79-500000+492363.61 -> -36430.18 | AN19: =-304206.99+273750 -> -30456.99 | AO19: =-813157.27+795798.33 -> -17358.94 | AP19: =-4731.99-25000 -> -29731.99 | AQ19: =-37934.4-700000-423.54+669750 -> -68607.94 | AR19: =-6868.85-24529.01 -> -31397.86 | AS19: =-554852.12+544448.89 -> -10403.23 | AT19: =-509092.21+338250 -> -170842.21 | AU19: =-507659.49+665340.71-200000-1501 -> -43819.78 | AV19: =-6045.67-12033.97 -> -18079.64 | AW19: =-1019473.79+849944.19+150785 -> -18744.6 | AX19: =-238326.96-45616.73+230000 -> -53943.69 | AY19: =-1511720.6+1461393.6 -> -50327 | AZ19: =-24164.38-374484-423.54+288107.53 -> -110964.39 | BA19: =-121779.19+45610.01 -> -76169.18 | BB19: =-752753.9+701003.21 -> -51750.69 | BC19: =-157230.23-20103.06+67.29 -> -177266 | BD19: =-412654.34+315462.95+25000 -> -72191.39 | BE19: =-87542.12+69582.35 -> -17959.77 | BF19: =-53792.32-35511.34+39035.33-7680+7680-1591.11 -> -51859.44 | BG19: =-837431.6+655298.57+ 148719.55+12000 -> -21413.48 | BH19: =-9850.77+247628.11+5147.24-262678.12-0.06 -> -19753.6 | BI19: =518134.14-522840.88 -> -4706.74 | BJ19: =-284484.43+278766.83-40743.07-476.88 -> -46937.55 | BK19: =-490298.6+457710.73 -> -32587.87 | BL19: =-758633.25+631460.84 -> -127172.41 | BM19: =-346515.06-255328.98+537214.83-315.84-11675.81 -> -76620.86 | BN19: =-176441.37-1464.34 -> -177905.71 | BO19: =-46760.21-165761.62+32932.79 -> -179589.04 | BP19: =-602815.85+496538.77 -> -106277.08 | BQ19: =-85639.61+472518.18-450886.5 -> -64007.93 | BR19: =-108257.98+10000+85974.26-18745.99 -> -31029.71 | BS19: =-323474.43-19605.79+171022.9+130125 -> -41932.32 | BT19: =-1457.91-81501.55 -> -82959.46 | BU19: =152299.94-204676.16 -> -52376.22 | BV19: =48246.62-59165.06 -> -10918.44 | BW19: =-172073.9+146895.93 -> -25177.97 | BX19: =-54705.96-554468.86+550392.86 -> -58781.96 | BY19: =-154706.62+870647.18-910176.21 -> -194235.65 | BZ19: =-156621.29+184048.47-15390-13199.85+1312.62-1209.51-45443.9 -> -46503.46 | CA19: =-354425.98+302523.71 -> -51902.27 | CB19: =-183364.28+154800.19 -> -28564.09 | CC19: =529421.94-566157.58 -> -36735.64 | CD19: =159725.5-265976.16 -> -106250.66 | CE19: =67237.01 - 91423.81 -> -24186.8 | CF19: =-196099.28+180026.88 -> -16072.4 | CG19: =24224.04-64178.73 -> -39954.69 | CH19: =316883.78-391717.46 -> -74833.68 | CI19: =-54977.13+40063.32 -> -14913.81 | CJ19: =-163413.22+116510.62 -> -46902.6 | CK19: -31730.81 | CL19: =-11646.65-468317.37-57011.9 -> -536975.92 | CM19: =-108999.5-22796.51+55000 -> -76796.01 | CN19: =-89079.5-28725.45 -> -117804.95 | CO19: =-95237.26+99279.01-161141.52 -> -157099.77 | CP19: =10835.24-10136.25-2983.83-18078.6 -> -20363.44 | CQ19: =727381.36-12273.55-727633 -> -12525.19 | CR19: =-177902.09+167017.94-169013.53 -> -179897.68 | CS19: =128546.16-183601.27-95389.74 -> -150444.85 | CT19: =-65772.7-17420.06 -> -83192.76 | CU19: -229823.28 | CV19: =-72576.78+63968.52-427948.05 -> -436556.31 | CW19: =-124539.36+53545.52-51905.01 -> -122898.85 | CX19: =-61843.75-52627.26+59343.75 -> -55127.26 | CY19: =-10840.89+585495.13-585766.08 -> -11111.84 | CZ19: =-324970.86+324066.46-112838.74 -> -113743.14 | DA19: =-89826.71-8616.11+123312.26+27360 -> 52229.44 | DB19: =-511172.23+380340.44+124449.79-38856.88 -> -45238.88 | DC19: -69849.83 | DD19: =947286.27-89464+58259.35-1258968.82 -> -342887.2 | DE19: =47370.23-73495.39-75444.39 -> -101569.55 | DF19: =74032.31-58899.94-130722.92 -> -115590.55 | DG19: =459137.4-43777.97-2598.18-459137.4-2000 -> -48376.15 | DH19: =1092160.79-128058.55-1132562.13 -> -168459.89 | DI19: =640191.68-24549.43-221625.47-420661.2 -> -26644.42 | DJ19: -31080.46 | DK19: =-45892.8+47104.8-11591.57 -> -10379.57 | DL19: =-595531+473921-98820.71 -> -220430.71 | DM19: -16729.45 | DN19: -80922.49 | DO19: =-1500-500-2429.23 -> -4429.23 | DP19: =-221.29-10001.19-693.24-1951.04 -> -12866.76 | DQ19: =-1000-3950-1200-5509.23-2161.45 -> -13820.68 | DR19: =-94.99-22341.42-2000-119.8-50.27-28.5-608.22-3064.3-2093.7-1699.85-14390.1-1239.75 -> -47730.9 | DS19: =-1280.5-1000-2418.8 -> -4699.3 | DT19: =-14981.12-250.07-4063.5-2187.01-134-2431.79 -> -24047.49 | DU19: =-1500-1200-14924.85-6160.26-2487.44-17407.64-461.05 -> -44141.24 | DV19: =-140.55-94.99-41.14-26.76-392.23-885.69-2536.72-70-1126.64 -> -5314.72 | DW19: -110000 | DX19: -110000 | DY19: -110000 | DZ19: -110000 | EA19: -110000 | EB19: -110000 | EC19: -110000 | ED19: -110000 | EE19: -110000 | EF19: -110000 | EG19: -110000 | EH19: -110000 | EI19: -110000 | EJ19: -110000 | EK19: -110000 | EL19: -110000
B20: Draw | C20: -250000 | H20: -100000 | L20: -100000 | P20: -100000 | AE20: -293633.88 | AH20: -100000 | AL20: -30000 | AO20: =-100000-100000 -> -200000 | AP20: -50000 | AW20: -150785 | BA20: -250000 | BO20: -75000 | BR20: -100000 | BS20: -110000 | BU20: -125000 | BV20: =-25000-22779.07 -> -47779.07 | BW20: -1275000 | BX20: -25000 | BY20: =-25000 -> -25000 | BZ20: =-25000 -> -25000 | CA20: =-100000 -> -100000 | CB20: =-75000 -> -75000 | CC20: 175000 | CD20: -25000 | CE20: -25000 | CF20: -25000 | CG20: -25000 | CI20: =-100000 -> -100000 | CJ20: 100000.03 | CM20: -55000
B21: Payments on Funding | C21: -28988.61 | G21: -45079 | L21: -45079 | P21: =-47222-45079 -> -92301 | Q21: -47222 | R21: -47222 | S21: -47222 | T21: -47222 | U21: -47222 | V21: -47222 | W21: -47222.2 | X21: -47222.2 | Y21: =-47222-32000 -> -79222 | AC21: -45079 | AE21: =-300000+300000 -> 0 | AF21: =-300000+300000 -> 0 | AG21: =-400000+400000 -> 0 | AH21: -91528.5 | AL21: -95266.2 | AN21: -43200 | AP21: -95920.17 | AU21: -94841.2 | AY21: -98255.31 | BB21: -43200 | BD21: -99067.53 | BG21: -56224 | BH21: -95526.03 | BJ21: -50000 | BK21: -50000 | BL21: -98602.9 | BP21: =-50000-97488.78 -> -147488.78 | BS21: -72000 | BT21: =-5000-50000 -> -55000 | BU21: =-98656.01-25000 -> -123656.01 | BX21: -25000 | BY21: =-97488.77 -> -97488.77 | CB21: -20000 | CC21: -98656.01 | CD21: -45000 | CF21: -20000 | CJ21: 141298.97 | CK21: =-145669-62208+66578.03 -> -141298.97
B23: Ending Cash | C23: =SUM(C3:C22) -> 2288807.5 | D23: =SUM(D3:D22) -> 2604552.4 | E23: =SUM(E3:E22) -> 1994376.4 | F23: =SUM(F3:F22) -> 2251105.2 | G23: =SUM(G3:G22) -> 1595981.2 | H23: =SUM(H3:H22) -> 1633425.3 | I23: =SUM(I3:I22) -> 1364115.8 | J23: =SUM(J3:J22) -> 1102620.9 | ... EL23: =SUM(EL3:EL22) -> 15828543
B24: Cash Inflow/Outflow | CV24: =CV23-CU23 -> -87941.31 | CW24: =CW23-CV23 -> 775636.16 | CX24: =CX23-CW23 -> 158231.65 | CY24: =CY23-CX23 -> -362228.55 | CZ24: =CZ23-CY23 -> 324030.22 | DA24: =DA23-CZ23 -> -127176.92 | DB24: =DB23-DA23 -> 456492.23 | DC24: =DC23-DB23 -> -419952.63 | ... EL24: =EL23-EK23 -> 5243567.5
B26: Prior Fcst (20260127) | U26: 1815788.5 | V26: 1707304.5 | W26: 1088371.9 | X26: 1078140.3 | Y26: 1898512.9 | Z26: 2750442.9 | AA26: 2181672.9 | AB26: 2177832.9 | AC26: 1672461.7 | AD26: 1658397.9 | AE26: 1014567.9 | AF26: 1170582.4 | AG26: 1359914.1 | AH26: 1231202.1 | AI26: 887594.36 | AJ26: 874146.77 | AK26: 1652259.5 | AL26: 1959378.1 | AM26: 1632131.9 | AN26: 1786503.7 | AO26: 1025395.8 | AP26: 1062630.8 | AQ26: 665032.98 | AR26: 1000740.4 | AS26: 941863.1 | AT26: 678985.76 | AU26: 396051.89 | AV26: 1426261.4 | AW26: 720910.21 | AX26: 922139.42 | AY26: 1308888.7 | AZ26: 1556026.6 | BA26: 1606423.5 | BB26: 2252298.6 | BC26: 1433331.7 | BD26: 1529013.9 | BE26: 905031.57 | BF26: 1496366.4 | BG26: 539811.15 | BH26: 464610.68 | BI26: 318948.25 | BJ26: 916028.35 | BK26: 603965.67 | BL26: 1008974.8 | BM26: 952125.32 | BN26: 986584.06 | BO26: 1264430.2 | BP26: 1545191 | BQ26: 1556009.3 | BR26: 2098433.3 | BS26: 1355761.1 | BT26: 617642.47 | BU26: 974223.78 | BV26: 964817.59 | BW26: 641928.56 | BX26: 1076488 | BY26: 435863.18 | BZ26: 582595.49 | CA26: 713880.82 | CB26: 119680.82 | CC26: -52240.54 | CD26: -69224.9 | CE26: 83185.1 | CF26: 3185.1 | CG26: 129583.1 | CH26: -307789.98 | CI26: 396121.02 | CJ26: 46121.02 | CK26: -578878.98 | CL26: 782166.02 | CM26: 782166.02 | CN26: 782166.02 | CO26: 782166.02 | CP26: 782166.02 | CQ26: 782166.02 | CR26: 782166.02 | CS26: 782166.02 | CT26: 782166.02 | CU26: 2708001.7 | CV26: 2620060.3 | CW26: 3395696.5 | CX26: 3553928.1 | CY26: 3191699.6 | CZ26: 3515729.8 | DA26: 3388552.9 | DB26: 3845045.1 | DC26: 4215565.7 | DD26: 4964367.7 | DE26: 5632200.1 | DF26: 5848852.3 | DG26: 5410791.3 | DH26: 5145447.5 | DI26: 4106397.5 | DJ26: 6988732 | DK26: 5418732 | DL26: 6949897.2 | DM26: 5799897.2 | DN26: 7906021.4 | DO26: 6326021.4 | DP26: 7527720.6 | DQ26: 6367720.6 | DR26: 8329607.6 | DS26: 7219607.6 | DT26: 7704608.4 | DU26: 6355853.1 | DV26: 6909469.2 | DW26: 5839469.2 | DX26: 5459469.2 | DY26: 4583012.7 | DZ26: 4583013.7 | EA26: 4583014.7 | EB26: 4583015.7 | EC26: 4583016.7 | ED26: 4583017.7 | EE26: 4583018.7 | EF26: 4583019.7 | EG26: 4583020.7 | EH26: 4583021.7 | EI26: 4583022.7 | EJ26: 4583023.7 | EK26: 4583024.7 | EL26: 4583025.7
B27: Change from last Fcst | U27: =U23-U26 -> 2.3283064e-10 | V27: =V23-V26 -> 113003.12 | W27: =W23-W26 -> 136072.55 | X27: =X23-X26 -> 2.3283064e-10 | Y27: =Y23-Y26 -> 2.3283064e-10 | Z27: =Z23-Z26 -> -4.6566129e-10 | AA27: =AA23-AA26 -> -4.6566129e-10 | AB27: =AB23-AB26 -> -4.6566129e-10 | ... EL27: =EL23-EL26 -> 11245517
B29: Ending Bank Bal
B30: BOA | X30: 962287.64 | Y30: 1063205.2 | Z30: 1665588.4 | AA30: 932923 | AB30: 1100457.6 | AC30: 261394.1 | AD30: 783718.13 | AE30: 395363.33 | AF30: 489886.14 | AG30: 614238.91 | AH30: 448451.7 | AI30: 467856.38 | AJ30: 285938.62 | AK30: 996539.81 | AL30: 1512810.5 | AM30: 1316657.3 | AN30: 1206105.6 | AO30: 465249.71 | AP30: 835672.52 | AQ30: 390741.02 | AR30: 603395.25 | AS30: 724905.02 | AT30: 414873.77 | AU30: 120705.58 | AV30: 770079.63 | AW30: 45714.84 | AX30: 736055.25 | AY30: 248000 | AZ30: 363551.51 | BA30: 441189.66 | BB30: 235940.45 | BC30: 356305.8 | BD30: 108381.38 | BE30: 152328.66 | BF30: 768750 | BG30: 109400 | BH30: 141771.5 | BI30: 102090 | BJ30: 99523.12 | BK30: 250000 | BL30: 209667.94 | BM30: 99684.16 | BN30: 99178.79 | BO30: 109448.58 | BP30: 77619 | BQ30: 100000 | BR30: 460910.12 | BS30: 127267.55 | BT30: 48100 | BU30: 122778.07 | BV30: 99505.06 | BW30: 350000 | BX30: 797750 | BY30: 196972.54 | BZ30: 84085.68 | CA30: 93255.62 | CB30: 100000 | CC30: 68500 | CD30: 60999 | CE30: 79235.28 | CF30: 100000 | CG30: 68576.02 | CH30: 98036.38 | CI30: 97074.06 | CJ30: 241299 | CK30: 100000 | CL30: 121271.25 | CM30: 188182.15 | CN30: 128802.65 | CO30: 12425.32 | CP30: 127446.16 | CQ30: 100000 | CR30: 88587.91 | CS30: 100000 | CT30: 99787.3 | CU30: 121210.5 | CV30: 99905.01 | CW30: 100000 | CX30: 100000 | CY30: 100000 | CZ30: 100000 | DA30: 224449.79 | DB30: 134354.8 | DC30: 462659.76 | DD30: 4578.07 | DE30: 150676.92 | DF30: 130591.3 | DG30: 376981 | DH30: 100000 | DI30: 187250.5 | DJ30: 100000 | DK30: 100000 | DL30: 84340 | DM30: 221562.5 | DN30: 172777.63 | DO30: 326151.5 | DP30: 259947.52 | DQ30: 100000 | DR30: 99389.48 | DS30: 100000 | DT30: 100000 | DU30: 100000 | DV30: 99696.56
B31: NB | Y31: 549498.47 | Z31: 1036610.1 | AA31: 1036610.1 | AB31: 1036610.1 | AC31: 973001.72 | AD31: 874679.51 | AE31: 619204.37 | AF31: 680696.31 | AG31: 745675.19 | AH31: 782750.43 | AI31: 419738.02 | AJ31: 588208.19 | AK31: 655719.69 | AL31: 446567.56 | AM31: 315474.57 | AN31: 580398.07 | AO31: 560146.12 | AP31: 226958.29 | AQ31: 274291.96 | AR31: 397345.1 | AS31: 216958.08 | AT31: 264111.99 | AU31: 275346.31 | AV31: 656181.78 | AW31: 675195.37 | AX31: 601448.01 | AY31: 1060888.7 | AZ31: 1192475.1 | BA31: 1165233.8 | BB31: 2016358.1 | BC31: 1077025.9 | BD31: 1420632.5 | BE31: 752702.91 | BF31: 727616.36 | BG31: 430411.15 | BH31: 322839.18 | BI31: 216858.25 | BJ31: 816505.23 | BK31: 353965.67 | BL31: 799306.82 | BM31: 852441.16 | BN31: 887405.27 | BO31: 1154981.6 | BP31: 1467572 | BQ31: 1456009.3 | BR31: 1637523.2 | BS31: 1228493.6 | BT31: 569542.47 | BU31: 851445.71 | BV31: 865312.53 | BW31: 291928.56 | BX31: 278738.01 | BY31: 238890.64 | BZ31: 498509.81 | CA31: 616974.34 | CB31: 917418.91 | CC31: 494541.91 | CD31: 667948.94 | CE31: 18523693 | CF31: 1367910.7 | CG31: 877163 | CH31: 930108.64 | CI31: 579896.88 | CJ31: 864651.17 | CK31: 386229.5 | CL31: 702653.13 | CM31: 469525.96 | CN31: =1054607.05+79526.83 -> 1134133.9 | CO31: 798944.05 | CP31: 1219183.3 | CQ31: 1692112.5 | CR31: 2358753.8 | CS31: 1797664.8 | CT31: 2226260.4 | CU31: 2586791.1 | CV31: 2520155.3 | CW31: 3295696.5 | CX31: 3453928.1 | CY31: 3091699.6 | CZ31: 3415729.8 | DA31: 3164103.1 | DB31: 3710690.3 | DC31: 2962432.7 | DD31: 3940121.5 | DE31: 3854735.1 | DF31: 3999549.3 | DG31: 3399962.1 | DH31: 4358331.6 | DI31: 4212966.5 | DJ31: 4691874.7 | DK31: 3706668.9 | DL31: 4076688.5 | DM31: 3232073.2 | DN31: 4092838.1 | DO31: 3331158.6 | DP31: 3531456.5 | DQ31: 4618504.8 | DR31: 5057758.2 | DS31: 5353124 | DT31: 5097166.9 | DU31: 4291443.2 | DV31: 4279949.8
B32: Total Bank Ending Bal | X32: =SUM(X30:X31) -> 962287.64 | Y32: =SUM(Y30:Y31) -> 1612703.6 | Z32: =SUM(Z30:Z31) -> 2702198.6 | AA32: =SUM(AA30:AA31) -> 1969533.1 | AB32: =SUM(AB30:AB31) -> 2137067.7 | AC32: =SUM(AC30:AC31) -> 1234395.8 | AD32: =SUM(AD30:AD31) -> 1658397.6 | AE32: =SUM(AE30:AE31) -> 1014567.7 | ... EL32: =SUM(EL30:EL31) -> 0
B33: Variance | X33: =X23-X32 -> 115852.66 | Y33: =Y23-Y32 -> 285809.2 | Z33: =Z23-Z32 -> 48244.29 | AA33: =AA23-AA32 -> 212139.74 | AB33: =AB23-AB32 -> 40765.17 | AC33: =AC23-AC32 -> 438065.85 | AD33: =AD23-AD32 -> 0.23 | AE33: =AE23-AE32 -> 0.23 | ... EL33: =EL23-EL32 -> 15828543
B35: AR Balance (End Of Week) | O35: {=_xludf.XLOOKUP(O$2,'AR Aging Balance'!$A:$A,'AR Aging Balance'!$F:$F)} -> #NAME? | P35: {=_xludf.XLOOKUP(P$2,'AR Aging Balance'!$A:$A,'AR Aging Balance'!$F:$F)} -> #NAME? | Q35: {=_xludf.XLOOKUP(Q$2,'AR Aging Balance'!$A:$A,'AR Aging Balance'!$F:$F)} -> #NAME? | R35: {=_xludf.XLOOKUP(R$2,'AR Aging Balance'!$A:$A,'AR Aging Balance'!$F:$F)} -> #NAME? | S35: {=_xludf.XLOOKUP(S$2,'AR Aging Balance'!$A:$A,'AR Aging Balance'!$F:$F)} -> #NAME? | T35: {=_xludf.XLOOKUP(T$2,'AR Aging Balance'!$A:$A,'AR Aging Balance'!$F:$F)} -> #NAME? | U35: {=_xludf.XLOOKUP(U$2,'AR Aging Balance'!$A:$A,'AR Aging Balance'!$F:$F)} -> #NAME? | V35: {=_xludf.XLOOKUP(V$2,'AR Aging Balance'!$A:$A,'AR Aging Balance'!$F:$F)} -> #NAME? | CL35: {=XLOOKUP(CL$2,'AR Aging Balance'!$A:$A,'AR Aging Balance'!$F:$F)} -> #N/A | CM35: {=XLOOKUP(CM$2,'AR Aging Balance'!$A:$A,'AR Aging Balance'!$F:$F)} -> #N/A | CN35: {=XLOOKUP(CN$2,'AR Aging Balance'!$A:$A,'AR Aging Balance'!$F:$F)} -> #N/A | CO35: {=XLOOKUP(CO$2,'AR Aging Balance'!$A:$A,'AR Aging Balance'!$F:$F)} -> #N/A | CP35: {=XLOOKUP(CP$2,'AR Aging Balance'!$A:$A,'AR Aging Balance'!$F:$F)} -> #N/A | CQ35: {=XLOOKUP(CQ$2,'AR Aging Balance'!$A:$A,'AR Aging Balance'!$F:$F)} -> #N/A | CR35: {=XLOOKUP(CR$2,'AR Aging Balance'!$A:$A,'AR Aging Balance'!$F:$F)} -> #N/A | CS35: {=XLOOKUP(CS$2,'AR Aging Balance'!$A:$A,'AR Aging Balance'!$F:$F)} -> #N/A | CT35: {=XLOOKUP(CT$2,'AR Aging Balance'!$A:$A,'AR Aging Balance'!$F:$F)} -> #N/A | CU35: 0 | CV35: 0 | CW35: 0 | CX35: 0 | CY35: {=XLOOKUP(CY$2,'AR Aging Balance'!$A:$A,'AR Aging Balance'!$F:$F)} -> 0 | CZ35: {=XLOOKUP(CZ$2,'AR Aging Balance'!$A:$A,'AR Aging Balance'!$F:$F)} -> 0 | DA35: {=XLOOKUP(DA$2,'AR Aging Balance'!$A:$A,'AR Aging Balance'!$F:$F)} -> 0 | DB35: {=XLOOKUP(DB$2,'AR Aging Balance'!$A:$A,'AR Aging Balance'!$F:$F)} -> 0 | DC35: {=XLOOKUP(DC$2,'AR Aging Balance'!$A:$A,'AR Aging Balance'!$F:$F)} -> 0 | DD35: {=XLOOKUP(DD$2,'AR Aging Balance'!$A:$A,'AR Aging Balance'!$F:$F)} -> 0 | DE35: {=XLOOKUP(DE$2,'AR Aging Balance'!$A:$A,'AR Aging Balance'!$F:$F)} -> 0 | DF35: {=XLOOKUP(DF$2,'AR Aging Balance'!$A:$A,'AR Aging Balance'!$F:$F)} -> 0 | ... EL35: {=XLOOKUP(EL$2,'AR Aging Balance'!$A:$A,'AR Aging Balance'!$F:$F)} -> 15901379
B37: Cash Out
B38: Operations | X38: =SUM(U10:X17,U18:X19) -> -2141207.1 | AB38: =SUM(Y10:AB17,Y18:AB19) -> -1818351.8 | AG38: =SUM(AC10:AG17,AC18:AG19) -> -2724440.7 | AK38: =SUM(AH10:AK17,AH18:AK19) -> -2143872 | AO38: =SUM(AL10:AO17,AL18:AO19) -> -1861924.6 | AT38: =SUM(AP10:AT17,AP18:AT19) -> -2643825.2 | AX38: =SUM(AU10:AX17,AU18:AX19) -> -2240953.4 | BC38: =SUM(AY10:BC17,AY18:BC19) -> -3685066.9 | BG38: =SUM(BD10:BG17,BD18:BG19) -> -2367250.2 | BK38: =SUM(BH10:BK17,BH18:BK19) -> -2356184.9 | BO38: =SUM(BL10:BO17,BL18:BO19) -> -2615876.6 | BT38: =SUM(BP10:BT17,BP18:BT19) -> -3283551.3 | BX38: =SUM(BU10:BX17,BU18:BX19) -> -2749415.5 | CB38: =SUM(BY10:CB17,BY18:CB19) -> -2315382.9 | CG38: =SUM(CC10:CG17,CC18:CG19) -> -21404523 | CK38: =SUM(CH10:CK17,CH18:CK19) -> -2456908.8
B39: Financing | X39: =SUM(U21:X21) -> -188888.4 | AB39: =SUM(Y21:AB21) -> -79222 | AG39: =SUM(AC21:AG21) -> -45079 | AK39: =SUM(AH21:AK21) -> -91528.5 | AO39: =SUM(AL21:AO21) -> -138466.2 | AT39: =SUM(AP21:AT21) -> -95920.17 | AX39: =SUM(AU21:AX21) -> -94841.2 | BC39: =SUM(AY21:BC21) -> -141455.31 | BG39: =SUM(BD21:BG21) -> -155291.53 | BK39: =SUM(BH21:BK21) -> -195526.03 | BO39: =SUM(BL21:BO21) -> -98602.9 | BT39: =SUM(BP21:BT21) -> -274488.78 | BX39: =SUM(BU21:BX21) -> -148656.01 | CB39: =SUM(BY21:CB21) -> -117488.77 | CG39: =SUM(CC21:CG21) -> -163656.01 | CK39: =SUM(CH21:CK21) -> 0
B40: Draw | X40: =SUM(U20:X20) -> 0 | AB40: =SUM(Y20:AB20) -> 0 | AG40: =SUM(AC20:AG20) -> -293633.88 | AK40: =SUM(AH20:AK20) -> -100000 | AO40: =SUM(AL20:AO20) -> -230000 | AT40: =SUM(AP20:AT20) -> -50000 | AX40: =SUM(AU20:AX20) -> -150785 | BC40: =SUM(AY20:BC20) -> -250000 | BG40: =SUM(BD20:BG20) -> 0 | BK40: =SUM(BH20:BK20) -> 0 | BO40: =SUM(BL20:BO20) -> -75000 | BT40: =SUM(BQ20:BT20) -> -210000 | BX40: =SUM(BU20:BX20) -> -1472779.1 | CB40: =SUM(BY20:CB20) -> -225000 | CG40: =SUM(CD20:CG20) -> -100000 | CK40: =SUM(CH20:CK20) -> 0.03
B41: Total Cash Out | X41: =SUM(X38:X40) -> -2330095.5 | AB41: =SUM(AB38:AB40) -> -1897573.8 | AG41: =SUM(AG38:AG40) -> -3063153.6 | AK41: =SUM(AK38:AK40) -> -2335400.5 | AO41: =SUM(AO38:AO40) -> -2230390.8 | AT41: =SUM(AT38:AT40) -> -2789745.4 | AX41: =SUM(AX38:AX40) -> -2486579.6 | BC41: =SUM(BC38:BC40) -> -4076522.2 | BG41: =SUM(BG38:BG40) -> -2522541.7 | BK41: =SUM(BK38:BK40) -> -2551710.9 | BO41: =SUM(BO38:BO40) -> -2789479.5 | BT41: =SUM(BT38:BT40) -> -3768040.1 | BX41: =SUM(BX38:BX40) -> -4370850.5 | CB41: =SUM(CB38:CB40) -> -2657871.6 | CG41: =SUM(CG38:CG40) -> -21668179 | CK41: =SUM(CK38:CK40) -> -2456908.7
AS43: =2.6*3 -> 7.8 | BH43: 816505.23
AL44: 996539.81 | BH44: 216858.25
AL45: 1512810.5 | BH45: 322839.18
AL46: 1206105.6
AL47: 465249.71 | BD47: Libertas Payments | BF47: 25 | BG47: 25 | BH47: 25 | BI47: 25 | BJ47: 25 | BK47: 25 | BL47: 25 | BM47: 25 | BN47: 25 | BO47: 25 | BP47: 25 | BQ47: 25 | BR47: 25 | BS47: 25 | BT47: 25 | BU47: 25 | BV47: 25 | BW47: 25 | BX47: 25 | BY47: 25 | BZ47: 25 | CA47: 25 | CB47: 25 | CC47: 25 | CD47: 25 | CE47: 25 | CF47: 25 | CG47: 25 | CH47: 25 | CI47: 25 | CJ47: 25 | CK47: 25
...

Sheet AR Aging Balance
A2: Week End Date | B2: Year | C2: Week | D2: Inovice Sent | E2: AR Collected | F2: End Balance
A3: 46024 | B3: 2026 | C3: 1 | D3: =SUMIFS('AR Aging 20260320'!$H:$H,'AR Aging 20260320'!$J:$J,$B3,'AR Aging 20260320'!$K:$K,$C3)+SUMIFS(Bookings!$E:$E,Bookings!$L:$L,$B3,Bookings!$K:$K,$C3) -> 300800 | E3: =SUMIFS('AR Aging 20260320'!$H:$H, 'AR Aging 20260320'!$N:$N,$C3,'AR Aging 20260320'!$M:$M,$B3)+SUMIFS(Bookings!$E:$E,Bookings!$P:$P,$B3,Bookings!$O:$O,$C3) -> 0 | F3: 0
A4: =A3+7 -> 46031 | B4: 2026 | C4: 2 | D4: =SUMIFS('AR Aging 20260320'!$H:$H,'AR Aging 20260320'!$J:$J,$B4,'AR Aging 20260320'!$K:$K,$C4)+SUMIFS(Bookings!$E:$E,Bookings!$L:$L,$B4,Bookings!$K:$K,$C4) -> 0 | E4: =SUMIFS('AR Aging 20260320'!$H:$H, 'AR Aging 20260320'!$N:$N,$C4,'AR Aging 20260320'!$M:$M,$B4)+SUMIFS(Bookings!$E:$E,Bookings!$P:$P,$B4,Bookings!$O:$O,$C4) -> 0 | F4: 0
A5: =A4+7 -> 46038 | B5: 2026 | C5: 3 | D5: =SUMIFS('AR Aging 20260320'!$H:$H,'AR Aging 20260320'!$J:$J,$B5,'AR Aging 20260320'!$K:$K,$C5)+SUMIFS(Bookings!$E:$E,Bookings!$L:$L,$B5,Bookings!$K:$K,$C5) -> 209760 | E5: =SUMIFS('AR Aging 20260320'!$H:$H, 'AR Aging 20260320'!$N:$N,$C5,'AR Aging 20260320'!$M:$M,$B5)+SUMIFS(Bookings!$E:$E,Bookings!$P:$P,$B5,Bookings!$O:$O,$C5) -> 297412.6 | F5: 0
A6: =A5+7 -> 46045 | B6: 2026 | C6: 4 | D6: =SUMIFS('AR Aging 20260320'!$H:$H,'AR Aging 20260320'!$J:$J,$B6,'AR Aging 20260320'!$K:$K,$C6)+SUMIFS(Bookings!$E:$E,Bookings!$L:$L,$B6,Bookings!$K:$K,$C6) -> 21592.9 | E6: =SUMIFS('AR Aging 20260320'!$H:$H, 'AR Aging 20260320'!$N:$N,$C6,'AR Aging 20260320'!$M:$M,$B6)+SUMIFS(Bookings!$E:$E,Bookings!$P:$P,$B6,Bookings!$O:$O,$C6) -> 0 | F6: 0
A7: =A6+7 -> 46052 | B7: 2026 | C7: 5 | D7: =SUMIFS('AR Aging 20260320'!$H:$H,'AR Aging 20260320'!$J:$J,$B7,'AR Aging 20260320'!$K:$K,$C7)+SUMIFS(Bookings!$E:$E,Bookings!$L:$L,$B7,Bookings!$K:$K,$C7) -> 419605 | E7: =SUMIFS('AR Aging 20260320'!$H:$H, 'AR Aging 20260320'!$N:$N,$C7,'AR Aging 20260320'!$M:$M,$B7)+SUMIFS(Bookings!$E:$E,Bookings!$P:$P,$B7,Bookings!$O:$O,$C7) -> 0 | F7: 0
A8: =A7+7 -> 46059 | B8: 2026 | C8: 6 | D8: =SUMIFS('AR Aging 20260320'!$H:$H,'AR Aging 20260320'!$J:$J,$B8,'AR Aging 20260320'!$K:$K,$C8)+SUMIFS(Bookings!$E:$E,Bookings!$L:$L,$B8,Bookings!$K:$K,$C8) -> 104761.6 | E8: =SUMIFS('AR Aging 20260320'!$H:$H, 'AR Aging 20260320'!$N:$N,$C8,'AR Aging 20260320'!$M:$M,$B8)+SUMIFS(Bookings!$E:$E,Bookings!$P:$P,$B8,Bookings!$O:$O,$C8) -> 0 | F8: 0
A9: =A8+7 -> 46066 | B9: 2026 | C9: 7 | D9: =SUMIFS('AR Aging 20260320'!$H:$H,'AR Aging 20260320'!$J:$J,$B9,'AR Aging 20260320'!$K:$K,$C9)+SUMIFS(Bookings!$E:$E,Bookings!$L:$L,$B9,Bookings!$K:$K,$C9) -> 0 | E9: =SUMIFS('AR Aging 20260320'!$H:$H, 'AR Aging 20260320'!$N:$N,$C9,'AR Aging 20260320'!$M:$M,$B9)+SUMIFS(Bookings!$E:$E,Bookings!$P:$P,$B9,Bookings!$O:$O,$C9) -> 272280 | F9: 0
A10: =A9+7 -> 46073 | B10: 2026 | C10: 8 | D10: =SUMIFS('AR Aging 20260320'!$H:$H,'AR Aging 20260320'!$J:$J,$B10,'AR Aging 20260320'!$K:$K,$C10)+SUMIFS(Bookings!$E:$E,Bookings!$L:$L,$B10,Bookings!$K:$K,$C10) -> 412451.4 | E10: =SUMIFS('AR Aging 20260320'!$H:$H, 'AR Aging 20260320'!$N:$N,$C10,'AR Aging 20260320'!$M:$M,$B10)+SUMIFS(Bookings!$E:$E,Bookings!$P:$P,$B10,Bookings!$O:$O,$C10) -> 33667.2 | F10: 0
A11: =A10+7 -> 46080 | B11: 2026 | C11: 9 | D11: =SUMIFS('AR Aging 20260320'!$H:$H,'AR Aging 20260320'!$J:$J,$B11,'AR Aging 20260320'!$K:$K,$C11)+SUMIFS(Bookings!$E:$E,Bookings!$L:$L,$B11,Bookings!$K:$K,$C11) -> 461827.26 | E11: =SUMIFS('AR Aging 20260320'!$H:$H, 'AR Aging 20260320'!$N:$N,$C11,'AR Aging 20260320'!$M:$M,$B11)+SUMIFS(Bookings!$E:$E,Bookings!$P:$P,$B11,Bookings!$O:$O,$C11) -> 209760
A12: =A11+7 -> 46087 | B12: 2026 | C12: 10 | D12: =SUMIFS('AR Aging 20260320'!$H:$H,'AR Aging 20260320'!$J:$J,$B12,'AR Aging 20260320'!$K:$K,$C12)+SUMIFS(Bookings!$E:$E,Bookings!$L:$L,$B12,Bookings!$K:$K,$C12) -> 222163.5 | E12: =SUMIFS('AR Aging 20260320'!$H:$H, 'AR Aging 20260320'!$N:$N,$C12,'AR Aging 20260320'!$M:$M,$B12)+SUMIFS(Bookings!$E:$E,Bookings!$P:$P,$B12,Bookings!$O:$O,$C12) -> 0
A13: =A12+7 -> 46094 | B13: 2026 | C13: 11 | D13: =SUMIFS('AR Aging 20260320'!$H:$H,'AR Aging 20260320'!$J:$J,$B13,'AR Aging 20260320'!$K:$K,$C13)+SUMIFS(Bookings!$E:$E,Bookings!$L:$L,$B13,Bookings!$K:$K,$C13) -> 1128000 | E13: =SUMIFS('AR Aging 20260320'!$H:$H, 'AR Aging 20260320'!$N:$N,$C13,'AR Aging 20260320'!$M:$M,$B13)+SUMIFS(Bookings!$E:$E,Bookings!$P:$P,$B13,Bookings!$O:$O,$C13) -> 4315.72
A14: =A13+7 -> 46101 | B14: 2026 | C14: 12 | D14: =SUMIFS('AR Aging 20260320'!$H:$H,'AR Aging 20260320'!$J:$J,$B14,'AR Aging 20260320'!$K:$K,$C14)+SUMIFS(Bookings!$E:$E,Bookings!$L:$L,$B14,Bookings!$K:$K,$C14) -> 347953 | E14: =SUMIFS('AR Aging 20260320'!$H:$H, 'AR Aging 20260320'!$N:$N,$C14,'AR Aging 20260320'!$M:$M,$B14)+SUMIFS(Bookings!$E:$E,Bookings!$P:$P,$B14,Bookings!$O:$O,$C14) -> 80420
A15: =A14+7 -> 46108 | B15: 2026 | C15: 13 | D15: =SUMIFS('AR Aging 20260320'!$H:$H,'AR Aging 20260320'!$J:$J,$B15,'AR Aging 20260320'!$K:$K,$C15)+SUMIFS(Bookings!$E:$E,Bookings!$L:$L,$B15,Bookings!$K:$K,$C15) -> 1036710.3 | E15: =SUMIFS('AR Aging 20260320'!$H:$H, 'AR Aging 20260320'!$N:$N,$C15,'AR Aging 20260320'!$M:$M,$B15)+SUMIFS(Bookings!$E:$E,Bookings!$P:$P,$B15,Bookings!$O:$O,$C15) -> 172530
A16: =A15+7 -> 46115 | B16: 2026 | C16: 14 | D16: =SUMIFS('AR Aging 20260320'!$H:$H,'AR Aging 20260320'!$J:$J,$B16,'AR Aging 20260320'!$K:$K,$C16)+SUMIFS(Bookings!$E:$E,Bookings!$L:$L,$B16,Bookings!$K:$K,$C16) -> 1904566.7 | E16: =SUMIFS('AR Aging 20260320'!$H:$H, 'AR Aging 20260320'!$N:$N,$C16,'AR Aging 20260320'!$M:$M,$B16)+SUMIFS(Bookings!$E:$E,Bookings!$P:$P,$B16,Bookings!$O:$O,$C16) -> 368726.4 | F16: 9461543
A17: =A16+7 -> 46122 | B17: 2026 | C17: 15 | D17: =SUMIFS('AR Aging 20260320'!$H:$H,'AR Aging 20260320'!$J:$J,$B17,'AR Aging 20260320'!$K:$K,$C17)+SUMIFS(Bookings!$E:$E,Bookings!$L:$L,$B17,Bookings!$K:$K,$C17) -> 0 | E17: =SUMIFS('AR Aging 20260320'!$H:$H, 'AR Aging 20260320'!$N:$N,$C17,'AR Aging 20260320'!$M:$M,$B17)+SUMIFS(Bookings!$E:$E,Bookings!$P:$P,$B17,Bookings!$O:$O,$C17) -> 41126.66 | F17: =F16+D17-E17 -> 9420416.3
A18: =A17+7 -> 46129 | B18: 2026 | C18: 16 | D18: =SUMIFS('AR Aging 20260320'!$H:$H,'AR Aging 20260320'!$J:$J,$B18,'AR Aging 20260320'!$K:$K,$C18)+SUMIFS(Bookings!$E:$E,Bookings!$L:$L,$B18,Bookings!$K:$K,$C18) -> 946169.81 | E18: =SUMIFS('AR Aging 20260320'!$H:$H, 'AR Aging 20260320'!$N:$N,$C18,'AR Aging 20260320'!$M:$M,$B18)+SUMIFS(Bookings!$E:$E,Bookings!$P:$P,$B18,Bookings!$O:$O,$C18) -> 285706.8 | F18: =F17+D18-E18 -> 10080879
A19: =A18+7 -> 46136 | B19: 2026 | C19: 17 | D19: =SUMIFS('AR Aging 20260320'!$H:$H,'AR Aging 20260320'!$J:$J,$B19,'AR Aging 20260320'!$K:$K,$C19)+SUMIFS(Bookings!$E:$E,Bookings!$L:$L,$B19,Bookings!$K:$K,$C19) -> 267244.5 | E19: =SUMIFS('AR Aging 20260320'!$H:$H, 'AR Aging 20260320'!$N:$N,$C19,'AR Aging 20260320'!$M:$M,$B19)+SUMIFS(Bookings!$E:$E,Bookings!$P:$P,$B19,Bookings!$O:$O,$C19) -> 11000 | F19: =F18+D19-E19 -> 10337124
A20: =A19+7 -> 46143 | B20: 2026 | C20: 18 | D20: =SUMIFS('AR Aging 20260320'!$H:$H,'AR Aging 20260320'!$J:$J,$B20,'AR Aging 20260320'!$K:$K,$C20)+SUMIFS(Bookings!$E:$E,Bookings!$L:$L,$B20,Bookings!$K:$K,$C20) -> 5692757.1 | E20: =SUMIFS('AR Aging 20260320'!$H:$H, 'AR Aging 20260320'!$N:$N,$C20,'AR Aging 20260320'!$M:$M,$B20)+SUMIFS(Bookings!$E:$E,Bookings!$P:$P,$B20,Bookings!$O:$O,$C20) -> 430690.5 | F20: =F19+D20-E20 -> 15599190
A21: =A20+7 -> 46150 | B21: 2026 | C21: 19 | D21: =SUMIFS('AR Aging 20260320'!$H:$H,'AR Aging 20260320'!$J:$J,$B21,'AR Aging 20260320'!$K:$K,$C21)+SUMIFS(Bookings!$E:$E,Bookings!$L:$L,$B21,Bookings!$K:$K,$C21) -> 0 | E21: =SUMIFS('AR Aging 20260320'!$H:$H, 'AR Aging 20260320'!$N:$N,$C21,'AR Aging 20260320'!$M:$M,$B21)+SUMIFS(Bookings!$E:$E,Bookings!$P:$P,$B21,Bookings!$O:$O,$C21) -> 1398444.2 | F21: =F20+D21-E21 -> 14200746
A22: =A21+7 -> 46157 | B22: 2026 | C22: 20 | D22: =SUMIFS('AR Aging 20260320'!$H:$H,'AR Aging 20260320'!$J:$J,$B22,'AR Aging 20260320'!$K:$K,$C22)+SUMIFS(Bookings!$E:$E,Bookings!$L:$L,$B22,Bookings!$K:$K,$C22) -> 0 | E22: =SUMIFS('AR Aging 20260320'!$H:$H, 'AR Aging 20260320'!$N:$N,$C22,'AR Aging 20260320'!$M:$M,$B22)+SUMIFS(Bookings!$E:$E,Bookings!$P:$P,$B22,Bookings!$O:$O,$C22) -> 981511.67 | F22: =F21+D22-E22 -> 13219235
A23: =A22+7 -> 46164 | B23: 2026 | C23: 21 | D23: =SUMIFS('AR Aging 20260320'!$H:$H,'AR Aging 20260320'!$J:$J,$B23,'AR Aging 20260320'!$K:$K,$C23)+SUMIFS(Bookings!$E:$E,Bookings!$L:$L,$B23,Bookings!$K:$K,$C23) -> 0 | E23: =SUMIFS('AR Aging 20260320'!$H:$H, 'AR Aging 20260320'!$N:$N,$C23,'AR Aging 20260320'!$M:$M,$B23)+SUMIFS(Bookings!$E:$E,Bookings!$P:$P,$B23,Bookings!$O:$O,$C23) -> 0 | F23: =F22+D23-E23 -> 13219235
A24: =A23+7 -> 46171 | B24: 2026 | C24: 22 | D24: =SUMIFS('AR Aging 20260320'!$H:$H,'AR Aging 20260320'!$J:$J,$B24,'AR Aging 20260320'!$K:$K,$C24)+SUMIFS(Bookings!$E:$E,Bookings!$L:$L,$B24,Bookings!$K:$K,$C24) -> 0 | E24: =SUMIFS('AR Aging 20260320'!$H:$H, 'AR Aging 20260320'!$N:$N,$C24,'AR Aging 20260320'!$M:$M,$B24)+SUMIFS(Bookings!$E:$E,Bookings!$P:$P,$B24,Bookings!$O:$O,$C24) -> 2522706.8 | F24: =F23+D24-E24 -> 10696528
A25: =A24+7 -> 46178 | B25: 2026 | C25: 23 | D25: =SUMIFS('AR Aging 20260320'!$H:$H,'AR Aging 20260320'!$J:$J,$B25,'AR Aging 20260320'!$K:$K,$C25)+SUMIFS(Bookings!$E:$E,Bookings!$L:$L,$B25,Bookings!$K:$K,$C25) -> 6768980.2 | E25: =SUMIFS('AR Aging 20260320'!$H:$H, 'AR Aging 20260320'!$N:$N,$C25,'AR Aging 20260320'!$M:$M,$B25)+SUMIFS(Bookings!$E:$E,Bookings!$P:$P,$B25,Bookings!$O:$O,$C25) -> 177216.75 | F25: =F24+D25-E25 -> 17288291
A26: =A25+7 -> 46185 | B26: 2026 | C26: 24 | D26: =SUMIFS('AR Aging 20260320'!$H:$H,'AR Aging 20260320'!$J:$J,$B26,'AR Aging 20260320'!$K:$K,$C26)+SUMIFS(Bookings!$E:$E,Bookings!$L:$L,$B26,Bookings!$K:$K,$C26) -> 0 | E26: =SUMIFS('AR Aging 20260320'!$H:$H, 'AR Aging 20260320'!$N:$N,$C26,'AR Aging 20260320'!$M:$M,$B26)+SUMIFS(Bookings!$E:$E,Bookings!$P:$P,$B26,Bookings!$O:$O,$C26) -> 2735404.5 | F26: =F25+D26-E26 -> 14552887
A27: =A26+7 -> 46192 | B27: 2026 | C27: 25 | D27: =SUMIFS('AR Aging 20260320'!$H:$H,'AR Aging 20260320'!$J:$J,$B27,'AR Aging 20260320'!$K:$K,$C27)+SUMIFS(Bookings!$E:$E,Bookings!$L:$L,$B27,Bookings!$K:$K,$C27) -> 0 | E27: =SUMIFS('AR Aging 20260320'!$H:$H, 'AR Aging 20260320'!$N:$N,$C27,'AR Aging 20260320'!$M:$M,$B27)+SUMIFS(Bookings!$E:$E,Bookings!$P:$P,$B27,Bookings!$O:$O,$C27) -> 49761.6 | F27: =F26+D27-E27 -> 14503125
A28: =A27+7 -> 46199 | B28: 2026 | C28: 26 | D28: =SUMIFS('AR Aging 20260320'!$H:$H,'AR Aging 20260320'!$J:$J,$B28,'AR Aging 20260320'!$K:$K,$C28)+SUMIFS(Bookings!$E:$E,Bookings!$L:$L,$B28,Bookings!$K:$K,$C28) -> 0 | E28: =SUMIFS('AR Aging 20260320'!$H:$H, 'AR Aging 20260320'!$N:$N,$C28,'AR Aging 20260320'!$M:$M,$B28)+SUMIFS(Bookings!$E:$E,Bookings!$P:$P,$B28,Bookings!$O:$O,$C28) -> 0 | F28: =F27+D28-E28 -> 14503125
... A107: =A106+7 -> 46752 | B107: 2027 | C107: 53 | D107: =SUMIFS('AR Aging 20260320'!$H:$H,'AR Aging 20260320'!$J:$J,$B107,'AR Aging 20260320'!$K:$K,$C107)+SUMIFS(Bookings!$E:$E,Bookings!$L:$L,$B107,Bookings!$K:$K,$C107) -> 0 | E107: =SUMIFS('AR Aging 20260320'!$H:$H, 'AR Aging 20260320'!$N:$N,$C107,'AR Aging 20260320'!$M:$M,$B107)+SUMIFS(Bookings!$E:$E,Bookings!$P:$P,$B107,Bookings!$O:$O,$C107) -> 0 | F107: =F106+D107-E107 -> 1865056
D111: =SUM(D3:D109) -> 54287218 | E111: =SUM(E3:E32) -> 15762212
D112: =D111-'AR Aging 20260320'!H4-Bookings!E1 -> -2465407.3 | E112: =SUM(Bookings!$E$1,'AR Aging 20260320'!$H$4)-'AR Aging Balance'!E111 -> 40990414

Sheet Bookings
E1: =SUBTOTAL(9,$E$3:$E$4919) -> 30000000 | I1: Check | J1: =SUM($E$3:$E$4920)-SUM($W:$W) -> 0 | N1: # Weeks Past Due | O1: ='AR Aging 20260320'!$N$2 -> 2 | R1: Receivables Summary
B2: Est Close Date | C2: Customer | D2: Deal Name | E2: Inv Amt | F2: Inv Date | G2: Payment Terms | H2: Due Date | I2: Bookings Month | J2: Bookings Year | K2: Inv Week | L2: Inv Year | M2: Due Week # | N2: Due Year | O2: Expected Pmt Wk # | P2: Expcted Pmt Year | R2: Year | S2: Wk # | T2: Wk Ending | U2: Est. Amt | V2: Adj | W2: Amt for Fcst
R3: 2026 | S3: 1 | T3: 46024 | U3: =SUMIFS($E:$E,$O:$O,$S3,$P:$P,$R3) -> 0 | W3: =SUM(U3:V3) -> 0
R4: 2026 | S4: 2 | T4: =T3+7 -> 46031 | U4: =SUMIFS($E:$E,$O:$O,$S4,$P:$P,$R4) -> 0 | W4: =SUM(U4:V4) -> 0
R5: 2026 | S5: 3 | T5: =T4+7 -> 46038 | U5: =SUMIFS($E:$E,$O:$O,$S5,$P:$P,$R5) -> 0 | W5: =SUM(U5:V5) -> 0
R6: 2026 | S6: 4 | T6: =T5+7 -> 46045 | U6: =SUMIFS($E:$E,$O:$O,$S6,$P:$P,$R6) -> 0 | W6: =SUM(U6:V6) -> 0
R7: 2026 | S7: 5 | T7: =T6+7 -> 46052 | U7: =SUMIFS($E:$E,$O:$O,$S7,$P:$P,$R7) -> 0 | W7: =SUM(U7:V7) -> 0
B8: 46142 | C8: Q2 Bookings Plug ($15M) -$5M Apr, $5M May, $5M Jun | E8: 1000000 | F8: 46142 | G8: 45 | H8: =F8+G8 -> 46187 | I8: =MONTH(B8) -> 4 | J8: =YEAR(B8) -> 2026 | K8: =WEEKNUM($F8) -> 18 | L8: =YEAR($F8) -> 2026 | M8: =WEEKNUM($H8) -> 25 | N8: =YEAR(H8) -> 2026 | O8: =IF(ISBLANK($B8),"",IF($M8<51,$M8+$O$1,$M8-52+$O$1)) -> 27 | P8: =IF(ISBLANK($B8),"",IF($M8<51,YEAR($H8),YEAR($H8)+1)) -> 2026 | R8: 2026 | S8: 6 | T8: =T7+7 -> 46059 | U8: =SUMIFS($E:$E,$O:$O,$S8,$P:$P,$R8) -> 0 | W8: =SUM(U8:V8) -> 0
B9: 46142 | C9: Q2 Bookings Plug ($15M) -$5M Apr, $5M May, $5M Jun | E9: 1000000 | F9: 46173 | G9: 45 | H9: =F9+G9 -> 46218 | I9: =MONTH(B9) -> 4 | J9: =YEAR(B9) -> 2026 | K9: =WEEKNUM($F9) -> 23 | L9: =YEAR($F9) -> 2026 | M9: =WEEKNUM($H9) -> 29 | N9: =YEAR(H9) -> 2026 | O9: =IF(ISBLANK($B9),"",IF($M9<51,$M9+$O$1,$M9-52+$O$1)) -> 31 | P9: =IF(ISBLANK($B9),"",IF($M9<51,YEAR($H9),YEAR($H9)+1)) -> 2026 | R9: 2026 | S9: 7 | T9: =T8+7 -> 46066 | U9: =SUMIFS($E:$E,$O:$O,$S9,$P:$P,$R9) -> 0 | W9: =SUM(U9:V9) -> 0
B10: 46142 | C10: Q2 Bookings Plug ($15M) -$5M Apr, $5M May, $5M Jun | E10: 1000000 | F10: 46203 | G10: 45 | H10: =F10+G10 -> 46248 | I10: =MONTH(B10) -> 4 | J10: =YEAR(B10) -> 2026 | K10: =WEEKNUM($F10) -> 27 | L10: =YEAR($F10) -> 2026 | M10: =WEEKNUM($H10) -> 33 | N10: =YEAR(H10) -> 2026 | O10: =IF(ISBLANK($B10),"",IF($M10<51,$M10+$O$1,$M10-52+$O$1)) -> 35 | P10: =IF(ISBLANK($B10),"",IF($M10<51,YEAR($H10),YEAR($H10)+1)) -> 2026 | R10: 2026 | S10: 8 | T10: =T9+7 -> 46073 | U10: =SUMIFS($E:$E,$O:$O,$S10,$P:$P,$R10) -> 0 | W10: =SUM(U10:V10) -> 0
B11: 46142 | C11: Q2 Bookings Plug ($15M) -$5M Apr, $5M May, $5M Jun | E11: 1000000 | F11: 46234 | G11: 45 | H11: =F11+G11 -> 46279 | I11: =MONTH(B11) -> 4 | J11: =YEAR(B11) -> 2026 | K11: =WEEKNUM($F11) -> 31 | L11: =YEAR($F11) -> 2026 | M11: =WEEKNUM($H11) -> 38 | N11: =YEAR(H11) -> 2026 | O11: =IF(ISBLANK($B11),"",IF($M11<51,$M11+$O$1,$M11-52+$O$1)) -> 40 | P11: =IF(ISBLANK($B11),"",IF($M11<51,YEAR($H11),YEAR($H11)+1)) -> 2026 | R11: 2026 | S11: 9 | T11: =T10+7 -> 46080 | U11: =SUMIFS($E:$E,$O:$O,$S11,$P:$P,$R11) -> 0 | W11: =SUM(U11:V11) -> 0
B12: 46142 | C12: Q2 Bookings Plug ($15M) -$5M Apr, $5M May, $5M Jun | E12: 1000000 | F12: 46265 | G12: 45 | H12: =F12+G12 -> 46310 | I12: =MONTH(B12) -> 4 | J12: =YEAR(B12) -> 2026 | K12: =WEEKNUM($F12) -> 36 | L12: =YEAR($F12) -> 2026 | M12: =WEEKNUM($H12) -> 42 | N12: =YEAR(H12) -> 2026 | O12: =IF(ISBLANK($B12),"",IF($M12<51,$M12+$O$1,$M12-52+$O$1)) -> 44 | P12: =IF(ISBLANK($B12),"",IF($M12<51,YEAR($H12),YEAR($H12)+1)) -> 2026 | R12: 2026 | S12: 10 | T12: =T11+7 -> 46087 | U12: =SUMIFS($E:$E,$O:$O,$S12,$P:$P,$R12) -> 0 | W12: =SUM(U12:V12) -> 0
B13: 46173 | C13: Q2 Bookings Plug ($15M) -$5M Apr, $5M May, $5M Jun | E13: 1000000 | F13: 46173 | G13: 45 | H13: =F13+G13 -> 46218 | I13: =MONTH(B13) -> 5 | J13: =YEAR(B13) -> 2026 | K13: =WEEKNUM($F13) -> 23 | L13: =YEAR($F13) -> 2026 | M13: =WEEKNUM($H13) -> 29 | N13: =YEAR(H13) -> 2026 | O13: =IF(ISBLANK($B13),"",IF($M13<51,$M13+$O$1,$M13-52+$O$1)) -> 31 | P13: =IF(ISBLANK($B13),"",IF($M13<51,YEAR($H13),YEAR($H13)+1)) -> 2026 | R13: 2026 | S13: 11 | T13: =T12+7 -> 46094 | U13: =SUMIFS($E:$E,$O:$O,$S13,$P:$P,$R13) -> 0 | W13: =SUM(U13:V13) -> 0
B14: 46173 | C14: Q2 Bookings Plug ($15M) -$5M Apr, $5M May, $5M Jun | E14: 1000000 | F14: 46203 | G14: 45 | H14: =F14+G14 -> 46248 | I14: =MONTH(B14) -> 5 | J14: =YEAR(B14) -> 2026 | K14: =WEEKNUM($F14) -> 27 | L14: =YEAR($F14) -> 2026 | M14: =WEEKNUM($H14) -> 33 | N14: =YEAR(H14) -> 2026 | O14: =IF(ISBLANK($B14),"",IF($M14<51,$M14+$O$1,$M14-52+$O$1)) -> 35 | P14: =IF(ISBLANK($B14),"",IF($M14<51,YEAR($H14),YEAR($H14)+1)) -> 2026 | R14: 2026 | S14: 12 | T14: =T13+7 -> 46101 | U14: =SUMIFS($E:$E,$O:$O,$S14,$P:$P,$R14) -> 0 | W14: =SUM(U14:V14) -> 0
B15: 46173 | C15: Q2 Bookings Plug ($15M) -$5M Apr, $5M May, $5M Jun | E15: 1000000 | F15: 46234 | G15: 45 | H15: =F15+G15 -> 46279 | I15: =MONTH(B15) -> 5 | J15: =YEAR(B15) -> 2026 | K15: =WEEKNUM($F15) -> 31 | L15: =YEAR($F15) -> 2026 | M15: =WEEKNUM($H15) -> 38 | N15: =YEAR(H15) -> 2026 | O15: =IF(ISBLANK($B15),"",IF($M15<51,$M15+$O$1,$M15-52+$O$1)) -> 40 | P15: =IF(ISBLANK($B15),"",IF($M15<51,YEAR($H15),YEAR($H15)+1)) -> 2026 | R15: 2026 | S15: 13 | T15: =T14+7 -> 46108 | U15: =SUMIFS($E:$E,$O:$O,$S15,$P:$P,$R15) -> 0 | W15: =SUM(U15:V15) -> 0
